Workbook

Sheet ALGLIB_SSA_XAUUSD
A1: timestamp_h3 | B1: symbol_h3 | C1: timeframe_h3 | D1: close_h3 | E1: ssa_h3 | F1: ema_ssa_h3 | G1: ssa_high_h3 | H1: ssa_low_h3 | I1: SSA Crossing_h3 | K1: convert_to_readable_datetime_h3 | L1: round_to_nearest_datetime_h3 | M1: timestamp_adjusted_h3 | O1: timestamp_m15 | P1: symbol_m15 | Q1: timeframe_m15 | R1: close_m15 | S1: ssa_m15 | T1: ema_ssa_m15 | U1: ssa_high_m15 | V1: ssa_low_m15 | W1: SSA Crossing_m15 | Y1: convert_to_readable_datetime_m15 | Z1: round_to_nearest_datetime_15m | AA1: timestamp_adjusted_m15
A2: 1773802803 | B2: XAUUSD | C2: H3 | D2: 4997.77 | E2: 4945.2479 | F2: 4945.2479 | G2: 4985.407 | H2: 4941.7135 | I2: 0 | K2: =(A2/86400)+25569 | L2: =CEILING(INT(K2*1440)/1440*288,1)/288 | M2: =MROUND((L2-25569)*86400,300) | O2: 1775134802 | P2: XAUUSD | Q2: M15 | R2: 4587.61 | S2: 4587.0464 | T2: 4587.0464 | U2: 4599.9826 | V2: 4572.4429 | W2: 0 | Y2: =(O2/86400)+25569 | Z2: =CEILING(INT(Y2*1440)/1440*288,1)/288 | AA2: =MROUND((Z2-25569)*86400,300)
A3: 1773813603 | B3: XAUUSD | C3: H3 | D3: 4987.52 | E3: 4921.8946 | F3: 4933.5713 | G3: 4965.0176 | H3: 4912.8359 | I3: 1 | K3: =(A3/86400)+25569 | L3: =CEILING(INT(K3*1440)/1440*288,1)/288 | M3: =MROUND((L3-25569)*86400,300) | O3: 1775135702 | P3: XAUUSD | Q3: M15 | R3: 4597.48 | S3: 4601.537 | T3: 4594.2917 | U3: 4610.3844 | V3: 4582.0216 | W3: 1 | Y3: =(O3/86400)+25569 | Z3: =CEILING(INT(Y3*1440)/1440*288,1)/288 | AA3: =MROUND((Z3-25569)*86400,300)
A4: 1773824403 | B4: XAUUSD | C4: H3 | D4: 4930.17 | E4: 4905.8186 | F4: 4919.695 | G4: 4946.1305 | H4: 4888.39 | I4: 0 | K4: =(A4/86400)+25569 | L4: =CEILING(INT(K4*1440)/1440*288,1)/288 | M4: =MROUND((L4-25569)*86400,300) | O4: 1775136602 | P4: XAUUSD | Q4: M15 | R4: 4602.13 | S4: 4619.0836 | T4: 4606.6876 | U4: 4627.2687 | V4: 4596.2005 | W4: 0 | Y4: =(O4/86400)+25569 | Z4: =CEILING(INT(Y4*1440)/1440*288,1)/288 | AA4: =MROUND((Z4-25569)*86400,300)
A5: 1773835203 | B5: XAUUSD | C5: H3 | D5: 4869.56 | E5: 4899.657 | F5: 4909.676 | G5: 4933.8055 | H5: 4873.7965 | I5: 0 | K5: =(A5/86400)+25569 | L5: =CEILING(INT(K5*1440)/1440*288,1)/288 | M5: =MROUND((L5-25569)*86400,300) | O5: 1775137502 | P5: XAUUSD | Q5: M15 | R5: 4645.33 | S5: 4638.6621 | T5: 4622.6749 | U5: 4646.7384 | V5: 4613.1924 | W5: 0 | Y5: =(O5/86400)+25569 | Z5: =CEILING(INT(Y5*1440)/1440*288,1)/288 | AA5: =MROUND((Z5-25569)*86400,300)
A6: 1773846003 | B6: XAUUSD | C6: H3 | D6: 4890.22 | E6: 4897.3257 | F6: 4903.5008 | G6: 4927.9807 | H6: 4870.7734 | I6: 0 | K6: =(A6/86400)+25569 | L6: =CEILING(INT(K6*1440)/1440*288,1)/288 | M6: =MROUND((L6-25569)*86400,300) | O6: 1775138402 | P6: XAUUSD | Q6: M15 | R6: 4647.77 | S6: 4654.6839 | T6: 4638.6794 | U6: 4663.1351 | V6: 4630.4708 | W6: 0 | Y6: =(O6/86400)+25569 | Z6: =CEILING(INT(Y6*1440)/1440*288,1)/288 | AA6: =MROUND((Z6-25569)*86400,300)
A7: 1773856803 | B7: XAUUSD | C7: H3 | D7: 4818.77 | E7: 4885.5502 | F7: 4894.5255 | G7: 4921.2513 | H7: 4862.2747 | I7: 0 | K7: =(A7/86400)+25569 | L7: =CEILING(INT(K7*1440)/1440*288,1)/288 | M7: =MROUND((L7-25569)*86400,300) | O7: 1775139302 | P7: XAUUSD | Q7: M15 | R7: 4665.41 | S7: 4667.2635 | T7: 4652.9714 | U7: 4675.9958 | V7: 4644.8229 | W7: 0 | Y7: =(O7/86400)+25569 | Z7: =CEILING(INT(Y7*1440)/1440*288,1)/288 | AA7: =MROUND((Z7-25569)*86400,300)
A8: 1773867603 | B8: XAUUSD | C8: H3 | D8: 4836.88 | E8: 4862.5063 | F8: 4878.5159 | G8: 4904.4755 | H8: 4843.6713 | I8: 0 | K8: =(A8/86400)+25569 | L8: =CEILING(INT(K8*1440)/1440*288,1)/288 | M8: =MROUND((L8-25569)*86400,300) | O8: 1775140202 | P8: XAUUSD | Q8: M15 | R8: 4693.91 | S8: 4675.0847 | T8: 4664.028 | U8: 4684.1645 | V8: 4655.2958 | W8: 0 | Y8: =(O8/86400)+25569 | Z8: =CEILING(INT(Y8*1440)/1440*288,1)/288 | AA8: =MROUND((Z8-25569)*86400,300)
A9: 1773878403 | B9: XAUUSD | C9: H3 | D9: 4858.76 | E9: 4823.4021 | F9: 4850.959 | G9: 4875.5557 | H9: 4807.4425 | I9: 0 | K9: =(A9/86400)+25569 | L9: =CEILING(INT(K9*1440)/1440*288,1)/288 | M9: =MROUND((L9-25569)*86400,300) | O9: 1775141102 | P9: XAUUSD | Q9: M15 | R9: 4681.32 | S9: 4677.1831 | T9: 4670.6056 | U9: 4686.8626 | V9: 4661.4444 | W9: 0 | Y9: =(O9/86400)+25569 | Z9: =CEILING(INT(Y9*1440)/1440*288,1)/288 | AA9: =MROUND((Z9-25569)*86400,300)
A10: 1773889203 | B10: XAUUSD | C10: H3 | D10: 4827.59 | E10: 4769.048 | F10: 4810.0035 | G10: 4831.3971 | H10: 4751.9931 | I10: 0 | K10: =(A10/86400)+25569 | L10: =CEILING(INT(K10*1440)/1440*288,1)/288 | M10: =MROUND((L10-25569)*86400,300) | O10: 1775142002 | P10: XAUUSD | Q10: M15 | R10: 4672.36 | S10: 4675.7013 | T10: 4673.1534 | U10: 4685.6584 | V10: 4663.348 | W10: 0 | Y10: =(O10/86400)+25569 | Z10: =CEILING(INT(Y10*1440)/1440*288,1)/288 | AA10: =MROUND((Z10-25569)*86400,300)
A11: 1773900003 | B11: XAUUSD | C11: H3 | D11: 4708.97 | E11: 4709.0354 | F11: 4759.5194 | G11: 4776.5025 | H11: 4684.9126 | I11: 0 | K11: =(A11/86400)+25569 | L11: =CEILING(INT(K11*1440)/1440*288,1)/288 | M11: =MROUND((L11-25569)*86400,300) | O11: 1775142902 | P11: XAUUSD | Q11: M15 | R11: 4672.5 | S11: 4672.2946 | T11: 4672.724 | U11: 4682.3058 | V11: 4662.3509 | W11: 1 | Y11: =(O11/86400)+25569 | Z11: =CEILING(INT(Y11*1440)/1440*288,1)/288 | AA11: =MROUND((Z11-25569)*86400,300)
A12: 1773910803 | B12: XAUUSD | C12: H3 | D12: 4652.42 | E12: 4658.7662 | F12: 4709.1428 | G12: 4720.8329 | H12: 4624.9879 | I12: 0 | K12: =(A12/86400)+25569 | L12: =CEILING(INT(K12*1440)/1440*288,1)/288 | M12: =MROUND((L12-25569)*86400,300) | O12: 1775143802 | P12: XAUUSD | Q12: M15 | R12: 4666 | S12: 4667.9634 | T12: 4670.3437 | U12: 4677.9523 | V12: 4659.8997 | W12: 0 | Y12: =(O12/86400)+25569 | Z12: =CEILING(INT(Y12*1440)/1440*288,1)/288 | AA12: =MROUND((Z12-25569)*86400,300)
A13: 1773921603 | B13: XAUUSD | C13: H3 | D13: 4602.2 | E13: 4628.2226 | F13: 4668.6827 | G13: 4678.8141 | H13: 4583.4694 | I13: 0 | K13: =(A13/86400)+25569 | L13: =CEILING(INT(K13*1440)/1440*288,1)/288 | M13: =MROUND((L13-25569)*86400,300) | O13: 1775144702 | P13: XAUUSD | Q13: M15 | R13: 4661.06 | S13: 4663.6967 | T13: 4667.0202 | U13: 4673.5906 | V13: 4656.7687 | W13: 0 | Y13: =(O13/86400)+25569 | Z13: =CEILING(INT(Y13*1440)/1440*288,1)/288 | AA13: =MROUND((Z13-25569)*86400,300)
... A301: 1778500803 | B301: XAUUSD | C301: H3 | D301: 4728.94 | E301: 4688.5247 | F301: 4688.0941 | G301: 4708.8513 | H301: 4665.1287 | I301: 1 | K301: =(A301/86400)+25569 | L301: =CEILING(INT(K301*1440)/1440*288,1)/288 | M301: =MROUND((L301-25569)*86400,300) | O301: 1775673902 | P301: XAUUSD | Q301: M15 | R301: 4705.56 | S301: 4714.1757 | T301: 4718.5566 | U301: 4723.7843 | V301: 4707.2316 | W301: 0 | Y301: =(O301/86400)+25569 | Z301: =CEILING(INT(Y301*1440)/1440*288,1)/288 | AA301: =MROUND((Z301-25569)*86400,300)
O302: 1775674802 | P302: XAUUSD | Q302: M15 | R302: 4715.71 | S302: 4714.1215 | T302: 4716.339 | U302: 4721.7875 | V302: 4707.0571 | W302: 0 | Y302: =(O302/86400)+25569 | Z302: =CEILING(INT(Y302*1440)/1440*288,1)/288 | AA302: =MROUND((Z302-25569)*86400,300)
O303: 1775675702 | P303: XAUUSD | Q303: M15 | R303: 4708.81 | S303: 4715.827 | T303: 4716.083 | U303: 4721.8668 | V303: 4709.1111 | W303: 0 | Y303: =(O303/86400)+25569 | Z303: =CEILING(INT(Y303*1440)/1440*288,1)/288 | AA303: =MROUND((Z303-25569)*86400,300)
O304: 1775676602 | P304: XAUUSD | Q304: M15 | R304: 4722.03 | S304: 4718.6827 | T304: 4717.3829 | U304: 4723.4265 | V304: 4712.39 | W304: 1 | Y304: =(O304/86400)+25569 | Z304: =CEILING(INT(Y304*1440)/1440*288,1)/288 | AA304: =MROUND((Z304-25569)*86400,300)
O305: 1775677502 | P305: XAUUSD | Q305: M15 | R305: 4730.94 | S305: 4721.437 | T305: 4719.4099 | U305: 4725.5739 | V305: 4715.9362 | W305: 0 | Y305: =(O305/86400)+25569 | Z305: =CEILING(INT(Y305*1440)/1440*288,1)/288 | AA305: =MROUND((Z305-25569)*86400,300)
O306: 1775678402 | P306: XAUUSD | Q306: M15 | R306: 4728.02 | S306: 4723.1559 | T306: 4721.2829 | U306: 4727.4228 | V306: 4718.5502 | W306: 0 | Y306: =(O306/86400)+25569 | Z306: =CEILING(INT(Y306*1440)/1440*288,1)/288 | AA306: =MROUND((Z306-25569)*86400,300)
O307: 1775679302 | P307: XAUUSD | Q307: M15 | R307: 4723.3 | S307: 4723.5353 | T307: 4722.4091 | U307: 4728.4587 | V307: 4719.554 | W307: 0 | Y307: =(O307/86400)+25569 | Z307: =CEILING(INT(Y307*1440)/1440*288,1)/288 | AA307: =MROUND((Z307-25569)*86400,300)
O308: 1775680202 | P308: XAUUSD | Q308: M15 | R308: 4722.43 | S308: 4722.6802 | T308: 4722.5447 | U308: 4728.4844 | V308: 4718.9304 | W308: 0 | Y308: =(O308/86400)+25569 | Z308: =CEILING(INT(Y308*1440)/1440*288,1)/288 | AA308: =MROUND((Z308-25569)*86400,300)
O309: 1775681102 | P309: XAUUSD | Q309: M15 | R309: 4719.3 | S309: 4720.8558 | T309: 4721.7003 | U309: 4727.6487 | V309: 4716.9418 | W309: 1 | Y309: =(O309/86400)+25569 | Z309: =CEILING(INT(Y309*1440)/1440*288,1)/288 | AA309: =MROUND((Z309-25569)*86400,300)
O310: 1775685602 | P310: XAUUSD | Q310: M15 | R310: 4711.97 | S310: 4718.5014 | T310: 4720.1008 | U310: 4726.0856 | V310: 4714.1751 | W310: 0 | Y310: =(O310/86400)+25569 | Z310: =CEILING(INT(Y310*1440)/1440*288,1)/288 | AA310: =MROUND((Z310-25569)*86400,300)
O311: 1775686502 | P311: XAUUSD | Q311: M15 | R311: 4713.31 | S311: 4716.1892 | T311: 4718.145 | U311: 4723.8053 | V311: 4711.3849 | W311: 0 | Y311: =(O311/86400)+25569 | Z311: =CEILING(INT(Y311*1440)/1440*288,1)/288 | AA311: =MROUND((Z311-25569)*86400,300)
O312: 1775687402 | P312: XAUUSD | Q312: M15 | R312: 4712.92 | S312: 4714.1249 | T312: 4716.135 | U312: 4721.5161 | V312: 4709.1122 | W312: 0 | Y312: =(O312/86400)+25569 | Z312: =CEILING(INT(Y312*1440)/1440*288,1)/288 | AA312: =MROUND((Z312-25569)*86400,300)
O313: 1775688302 | P313: XAUUSD | Q313: M15 | R313: 4717.7 | S313: 4712.4147 | T313: 4714.2748 | U313: 4719.3713 | V313: 4707.5052 | W313: 0 | Y313: =(O313/86400)+25569 | Z313: =CEILING(INT(Y313*1440)/1440*288,1)/288 | AA313: =MROUND((Z313-25569)*86400,300)
... O2401: 1778510702 | P2401: XAUUSD | Q2401: M15 | R2401: 4729.58 | S2401: 4729.3332 | T2401: 4731.2178 | U2401: 4734.9105 | V2401: 4725.1106 | W2401: 0 | Y2401: =(O2401/86400)+25569 | Z2401: =CEILING(INT(Y2401*1440)/1440*288,1)/288 | AA2401: =MROUND((Z2401-25569)*86400,300)

Sheet Mapped_H3_M15_Interporate
A1: timestamp_m15 | B1: symbol_h3 | C1: timeframe_h3 | D1: block_index_h3 | E1: close_h3 | F1: ssa_h3 | G1: ema_ssa_h3 | H1: ssa_high_h3 | I1: ssa_low_h3 | J1: symbol_m15 | K1: timeframe_m15 | L1: close_m15 | M1: ssa_m15 | N1: ema_ssa_m15 | O1: ssa_high_m15 | P1: ssa_low_m15 | S1: timestamp | T1: symbol | U1: timeframe | V1: block_index_m15 | W1: close | X1: ssa_m15_interpolation | Y1: ema_ssa_m15_interpolation | Z1: ssa_m15 | AA1: ema_ssa_m15 | AB1: ssa_high_m15_interpolation | AC1: ssa_high_m15 | AD1: ssa_low_m15_interpolation | AE1: ssa_low_m15 | AH1: timestamp_forward | AI1: symbol_forward | AJ1: timeframe_forward | AK1: close | AL1: =X1 | AM1: =Y1 | AN1: ssa_emassa_m15_interpolation_diff | AO1: ssa_m15_interpolation_trend | AP1: ssa_m15_interpolation_trend_projection | AQ1: =AB1 | AR1: =AD1 | AS1: x_count_regression | AT1: slope_12_ssa_high_m15_interpolation | AU1: slope_12_ssa_low_m15_interpolation | AV1: ssa_high_m15_regression | AW1: ssa_low_m15_regression | AX1: ssa_high_m15_projection | AY1: ssa_low_m15_projection | BA1: ssa_high_error | BB1: ssa_low_error | BD1: =AH1 | BE1: =AI1 | BF1: =AJ1 | BG1: =L1 | BH1: =X1 | BI1: =Y1 | BJ1: =Z1 | BK1: =AA1 | BL1: =AX1 | BM1: =AY1
A2: =ALGLIB_SSA_XAUUSD!AA2 | B2: =IF($A2="","",INDEX(ALGLIB_SSA_XAUUSD!$B$2:$B$2401,MATCH($A2,ALGLIB_SSA_XAUUSD!$A$2:$A$2401,1))) | C2: =IF($A2="","",INDEX(ALGLIB_SSA_XAUUSD!$C$2:$C$2401,MATCH($A2,ALGLIB_SSA_XAUUSD!$A$2:$A$2401,1))) | D2: =IF($A2="","",INT((ROW()-2)/12)+1) | E2: =IF($A2="","",INDEX(ALGLIB_SSA_XAUUSD!$D$2:$D$2401,MATCH($A2,ALGLIB_SSA_XAUUSD!$A$2:$A$2401,1))) | F2: =IF($A2="","",INDEX(ALGLIB_SSA_XAUUSD!$E$2:$E$2401,MATCH($A2,ALGLIB_SSA_XAUUSD!$A$2:$A$2401,1))) | G2: =IF($A2="","",INDEX(ALGLIB_SSA_XAUUSD!$F$2:$F$2401,MATCH($A2,ALGLIB_SSA_XAUUSD!$A$2:$A$2401,1))) | H2: =IF($A2="","",INDEX(ALGLIB_SSA_XAUUSD!$G$2:$G$2401,MATCH($A2,ALGLIB_SSA_XAUUSD!$A$2:$A$2401,1))) | I2: =IF($A2="","",INDEX(ALGLIB_SSA_XAUUSD!$H$2:$H$2401,MATCH($A2,ALGLIB_SSA_XAUUSD!$A$2:$A$2401,1))) | J2: =_xlfn.XLOOKUP($A2,ALGLIB_SSA_XAUUSD!$AA$2:$AA$2401,ALGLIB_SSA_XAUUSD!$P$2:$P$2401,"",0) | K2: =_xlfn.XLOOKUP($A2,ALGLIB_SSA_XAUUSD!$AA$2:$AA$2401,ALGLIB_SSA_XAUUSD!$Q$2:$Q$2401,"",0) | L2: =_xlfn.XLOOKUP($A2,ALGLIB_SSA_XAUUSD!$AA$2:$AA$2401,ALGLIB_SSA_XAUUSD!$R$2:$R$2401,"",0) | M2: =_xlfn.XLOOKUP($A2,ALGLIB_SSA_XAUUSD!$AA$2:$AA$2401,ALGLIB_SSA_XAUUSD!$S$2:$S$2401,"",0) | N2: =_xlfn.XLOOKUP($A2,ALGLIB_SSA_XAUUSD!$AA$2:$AA$2401,ALGLIB_SSA_XAUUSD!$T$2:$T$2401,"",0) | O2: =_xlfn.XLOOKUP($A2,ALGLIB_SSA_XAUUSD!$AA$2:$AA$2401,ALGLIB_SSA_XAUUSD!$U$2:$U$2401,"",0) | P2: =_xlfn.XLOOKUP($A2,ALGLIB_SSA_XAUUSD!$AA$2:$AA$2401,ALGLIB_SSA_XAUUSD!$V$2:$V$2401,"",0) | S2: =A2 | T2: =J2 | U2: =K2 | V2: =IF($A2="","",MOD(ROW()-2,12)+1) | W2: =L2 | X2: =IF(F2="","",F2) | Y2: =IF(G2="","",G2) | Z2: =M2 | AA2: =N2 | AB2: =IF(H2="","",H2) | AC2: =O2 | AD2: =IF(I2="","",I2) | AE2: =P2 | AH2: =IF(S2<>"",S2,"") | AI2: =IF(T2<>"",T2,AI1) | AJ2: =IF(U2<>"",U2,AJ1) | AK2: =IF(W2<>"",W2,"") | AL2: =IF(X2<>"",X2,"") | AM2: =IF(Y2<>"",Y2,"") | AN2: =IF(OR(AL2="",AM2=""),"",AL2-AM2) | AO2: =IF(AN2="","",IF(AN2>0,"Bullish","Bearish")) | AP2: =AO2 | AQ2: =IF(AB2<>"",AB2,"") | AR2: =IF(AD2<>"",AD2,"") | AS2: =IF(C2="","",1) | BD2: =AH2 | BE2: =AI2 | BF2: =AJ2 | BG2: =L2 | BH2: =IF(X2="","",X2) | BI2: =IF(Y2="","",Y2) | BJ2: =Z2 | BK2: =AA2
A3: =ALGLIB_SSA_XAUUSD!AA3 | B3: =IF($A3="","",INDEX(ALGLIB_SSA_XAUUSD!$B$2:$B$2401,MATCH($A3,ALGLIB_SSA_XAUUSD!$A$2:$A$2401,1))) | C3: =IF($A3="","",INDEX(ALGLIB_SSA_XAUUSD!$C$2:$C$2401,MATCH($A3,ALGLIB_SSA_XAUUSD!$A$2:$A$2401,1))) | D3: =IF($A3="","",INT((ROW()-2)/12)+1) | E3: =IF(AND(E14<>"",D14=D2+1),E2+(E14-E2)*1/12,"") | F3: =IF(AND(F14<>"",D14=D2+1),F2+(F14-F2)*1/12,"") | G3: =IF(AND(G14<>"",D14=D2+1),G2+(G14-G2)*1/12,"") | H3: =IF(AND(H14<>"",D14=D2+1),H2+(H14-H2)*1/12,"") | I3: =IF(AND(L14<>"",D14=D2+1),I2+(I14-I2)*1/12,"") | J3: =_xlfn.XLOOKUP($A3,ALGLIB_SSA_XAUUSD!$AA$2:$AA$2401,ALGLIB_SSA_XAUUSD!$P$2:$P$2401,"",0) | K3: =_xlfn.XLOOKUP($A3,ALGLIB_SSA_XAUUSD!$AA$2:$AA$2401,ALGLIB_SSA_XAUUSD!$Q$2:$Q$2401,"",0) | L3: =_xlfn.XLOOKUP($A3,ALGLIB_SSA_XAUUSD!$AA$2:$AA$2401,ALGLIB_SSA_XAUUSD!$R$2:$R$2401,"",0) | M3: =_xlfn.XLOOKUP($A3,ALGLIB_SSA_XAUUSD!$AA$2:$AA$2401,ALGLIB_SSA_XAUUSD!$S$2:$S$2401,"",0) | N3: =_xlfn.XLOOKUP($A3,ALGLIB_SSA_XAUUSD!$AA$2:$AA$2401,ALGLIB_SSA_XAUUSD!$T$2:$T$2401,"",0) | O3: =_xlfn.XLOOKUP($A3,ALGLIB_SSA_XAUUSD!$AA$2:$AA$2401,ALGLIB_SSA_XAUUSD!$U$2:$U$2401,"",0) | P3: =_xlfn.XLOOKUP($A3,ALGLIB_SSA_XAUUSD!$AA$2:$AA$2401,ALGLIB_SSA_XAUUSD!$V$2:$V$2401,"",0) | S3: =A3 | T3: =J3 | U3: =K3 | V3: =IF($A3="","",MOD(ROW()-2,12)+1) | W3: =L3 | X3: =IF(F3="","",F3) | Y3: =IF(G3="","",G3) | Z3: =M3 | AA3: =N3 | AB3: =IF(H3="","",H3) | AC3: =O3 | AD3: =IF(I3="","",I3) | AE3: =P3 | AH3: =IF(S3<>"",S3,AH2+900) | AI3: =IF(T3<>"",T3,AI2) | AJ3: =IF(U3<>"",U3,AJ2) | AK3: =IF(W3<>"",W3,"") | AL3: =IF(X3<>"",X3,"") | AM3: =IF(Y3<>"",Y3,"") | AN3: =IF(OR(AL3="",AM3=""),"",AL3-AM3) | AO3: =IF(AN3="","",IF(AN3>0,"Bullish","Bearish")) | AP3: =IF(AO3="",AP2,AO3) | AQ3: =IF(AB3<>"",AB3,"") | AR3: =IF(AD3<>"",AD3,"") | AS3: =IF(AS2+1=13,1,AS2+1) | BD3: =AH3 | BE3: =AI3 | BF3: =AJ3 | BG3: =L3 | BH3: =IF(X3="","",X3) | BI3: =IF(Y3="","",Y3) | BJ3: =Z3 | BK3: =AA3
A4: =ALGLIB_SSA_XAUUSD!AA4 | B4: =IF($A4="","",INDEX(ALGLIB_SSA_XAUUSD!$B$2:$B$2401,MATCH($A4,ALGLIB_SSA_XAUUSD!$A$2:$A$2401,1))) | C4: =IF($A4="","",INDEX(ALGLIB_SSA_XAUUSD!$C$2:$C$2401,MATCH($A4,ALGLIB_SSA_XAUUSD!$A$2:$A$2401,1))) | D4: =IF($A4="","",INT((ROW()-2)/12)+1) | E4: =IF(AND(E14<>"",D14=D2+1),E2+(E14-E2)*2/12,"") | F4: =IF(AND(F14<>"",D14=D2+1),F2+(F14-F2)*2/12,"") | G4: =IF(AND(G14<>"",D14=D2+1),G2+(G14-G2)*2/12,"") | H4: =IF(AND(H14<>"",D14=D2+1),H2+(H14-H2)*2/12,"") | I4: =IF(AND(L14<>"",D14=D2+1),I2+(I14-I2)*2/12,"") | J4: =_xlfn.XLOOKUP($A4,ALGLIB_SSA_XAUUSD!$AA$2:$AA$2401,ALGLIB_SSA_XAUUSD!$P$2:$P$2401,"",0) | K4: =_xlfn.XLOOKUP($A4,ALGLIB_SSA_XAUUSD!$AA$2:$AA$2401,ALGLIB_SSA_XAUUSD!$Q$2:$Q$2401,"",0) | L4: =_xlfn.XLOOKUP($A4,ALGLIB_SSA_XAUUSD!$AA$2:$AA$2401,ALGLIB_SSA_XAUUSD!$R$2:$R$2401,"",0) | M4: =_xlfn.XLOOKUP($A4,ALGLIB_SSA_XAUUSD!$AA$2:$AA$2401,ALGLIB_SSA_XAUUSD!$S$2:$S$2401,"",0) | N4: =_xlfn.XLOOKUP($A4,ALGLIB_SSA_XAUUSD!$AA$2:$AA$2401,ALGLIB_SSA_XAUUSD!$T$2:$T$2401,"",0) | O4: =_xlfn.XLOOKUP($A4,ALGLIB_SSA_XAUUSD!$AA$2:$AA$2401,ALGLIB_SSA_XAUUSD!$U$2:$U$2401,"",0) | P4: =_xlfn.XLOOKUP($A4,ALGLIB_SSA_XAUUSD!$AA$2:$AA$2401,ALGLIB_SSA_XAUUSD!$V$2:$V$2401,"",0) | S4: =A4 | T4: =J4 | U4: =K4 | V4: =IF($A4="","",MOD(ROW()-2,12)+1) | W4: =L4 | X4: =IF(F4="","",F4) | Y4: =IF(G4="","",G4) | Z4: =M4 | AA4: =N4 | AB4: =IF(H4="","",H4) | AC4: =O4 | AD4: =IF(I4="","",I4) | AE4: =P4 | AH4: =IF(S4<>"",S4,AH3+900) | AI4: =IF(T4<>"",T4,AI3) | AJ4: =IF(U4<>"",U4,AJ3) | AK4: =IF(W4<>"",W4,"") | AL4: =IF(X4<>"",X4,"") | AM4: =IF(Y4<>"",Y4,"") | AN4: =IF(OR(AL4="",AM4=""),"",AL4-AM4) | AO4: =IF(AN4="","",IF(AN4>0,"Bullish","Bearish")) | AP4: =IF(AO4="",AP3,AO4) | AQ4: =IF(AB4<>"",AB4,"") | AR4: =IF(AD4<>"",AD4,"") | AS4: =IF(AS3+1=13,1,AS3+1) | BD4: =AH4 | BE4: =AI4 | BF4: =AJ4 | BG4: =L4 | BH4: =IF(X4="","",X4) | BI4: =IF(Y4="","",Y4) | BJ4: =Z4 | BK4: =AA4
A5: =ALGLIB_SSA_XAUUSD!AA5 | B5: =IF($A5="","",INDEX(ALGLIB_SSA_XAUUSD!$B$2:$B$2401,MATCH($A5,ALGLIB_SSA_XAUUSD!$A$2:$A$2401,1))) | C5: =IF($A5="","",INDEX(ALGLIB_SSA_XAUUSD!$C$2:$C$2401,MATCH($A5,ALGLIB_SSA_XAUUSD!$A$2:$A$2401,1))) | D5: =IF($A5="","",INT((ROW()-2)/12)+1) | E5: =IF(AND(E14<>"",D14=D2+1),E2+(E14-E2)*3/12,"") | F5: =IF(AND(F14<>"",D14=D2+1),F2+(F14-F2)*3/12,"") | G5: =IF(AND(G14<>"",D14=D2+1),G2+(G14-G2)*3/12,"") | H5: =IF(AND(H14<>"",D14=D2+1),H2+(H14-H2)*3/12,"") | I5: =IF(AND(L14<>"",D14=D2+1),I2+(I14-I2)*3/12,"") | J5: =_xlfn.XLOOKUP($A5,ALGLIB_SSA_XAUUSD!$AA$2:$AA$2401,ALGLIB_SSA_XAUUSD!$P$2:$P$2401,"",0) | K5: =_xlfn.XLOOKUP($A5,ALGLIB_SSA_XAUUSD!$AA$2:$AA$2401,ALGLIB_SSA_XAUUSD!$Q$2:$Q$2401,"",0) | L5: =_xlfn.XLOOKUP($A5,ALGLIB_SSA_XAUUSD!$AA$2:$AA$2401,ALGLIB_SSA_XAUUSD!$R$2:$R$2401,"",0) | M5: =_xlfn.XLOOKUP($A5,ALGLIB_SSA_XAUUSD!$AA$2:$AA$2401,ALGLIB_SSA_XAUUSD!$S$2:$S$2401,"",0) | N5: =_xlfn.XLOOKUP($A5,ALGLIB_SSA_XAUUSD!$AA$2:$AA$2401,ALGLIB_SSA_XAUUSD!$T$2:$T$2401,"",0) | O5: =_xlfn.XLOOKUP($A5,ALGLIB_SSA_XAUUSD!$AA$2:$AA$2401,ALGLIB_SSA_XAUUSD!$U$2:$U$2401,"",0) | P5: =_xlfn.XLOOKUP($A5,ALGLIB_SSA_XAUUSD!$AA$2:$AA$2401,ALGLIB_SSA_XAUUSD!$V$2:$V$2401,"",0) | S5: =A5 | T5: =J5 | U5: =K5 | V5: =IF($A5="","",MOD(ROW()-2,12)+1) | W5: =L5 | X5: =IF(F5="","",F5) | Y5: =IF(G5="","",G5) | Z5: =M5 | AA5: =N5 | AB5: =IF(H5="","",H5) | AC5: =O5 | AD5: =IF(I5="","",I5) | AE5: =P5 | AH5: =IF(S5<>"",S5,AH4+900) | AI5: =IF(T5<>"",T5,AI4) | AJ5: =IF(U5<>"",U5,AJ4) | AK5: =IF(W5<>"",W5,"") | AL5: =IF(X5<>"",X5,"") | AM5: =IF(Y5<>"",Y5,"") | AN5: =IF(OR(AL5="",AM5=""),"",AL5-AM5) | AO5: =IF(AN5="","",IF(AN5>0,"Bullish","Bearish")) | AP5: =IF(AO5="",AP4,AO5) | AQ5: =IF(AB5<>"",AB5,"") | AR5: =IF(AD5<>"",AD5,"") | AS5: =IF(AS4+1=13,1,AS4+1) | BD5: =AH5 | BE5: =AI5 | BF5: =AJ5 | BG5: =L5 | BH5: =IF(X5="","",X5) | BI5: =IF(Y5="","",Y5) | BJ5: =Z5 | BK5: =AA5
A6: =ALGLIB_SSA_XAUUSD!AA6 | B6: =IF($A6="","",INDEX(ALGLIB_SSA_XAUUSD!$B$2:$B$2401,MATCH($A6,ALGLIB_SSA_XAUUSD!$A$2:$A$2401,1))) | C6: =IF($A6="","",INDEX(ALGLIB_SSA_XAUUSD!$C$2:$C$2401,MATCH($A6,ALGLIB_SSA_XAUUSD!$A$2:$A$2401,1))) | D6: =IF($A6="","",INT((ROW()-2)/12)+1) | E6: =IF(AND(E14<>"",D14=D2+1),E2+(E14-E2)*4/12,"") | F6: =IF(AND(F14<>"",D14=D2+1),F2+(F14-F2)*4/12,"") | G6: =IF(AND(G14<>"",D14=D2+1),G2+(G14-G2)*4/12,"") | H6: =IF(AND(H14<>"",D14=D2+1),H2+(H14-H2)*4/12,"") | I6: =IF(AND(L14<>"",D14=D2+1),I2+(I14-I2)*4/12,"") | J6: =_xlfn.XLOOKUP($A6,ALGLIB_SSA_XAUUSD!$AA$2:$AA$2401,ALGLIB_SSA_XAUUSD!$P$2:$P$2401,"",0) | K6: =_xlfn.XLOOKUP($A6,ALGLIB_SSA_XAUUSD!$AA$2:$AA$2401,ALGLIB_SSA_XAUUSD!$Q$2:$Q$2401,"",0) | L6: =_xlfn.XLOOKUP($A6,ALGLIB_SSA_XAUUSD!$AA$2:$AA$2401,ALGLIB_SSA_XAUUSD!$R$2:$R$2401,"",0) | M6: =_xlfn.XLOOKUP($A6,ALGLIB_SSA_XAUUSD!$AA$2:$AA$2401,ALGLIB_SSA_XAUUSD!$S$2:$S$2401,"",0) | N6: =_xlfn.XLOOKUP($A6,ALGLIB_SSA_XAUUSD!$AA$2:$AA$2401,ALGLIB_SSA_XAUUSD!$T$2:$T$2401,"",0) | O6: =_xlfn.XLOOKUP($A6,ALGLIB_SSA_XAUUSD!$AA$2:$AA$2401,ALGLIB_SSA_XAUUSD!$U$2:$U$2401,"",0) | P6: =_xlfn.XLOOKUP($A6,ALGLIB_SSA_XAUUSD!$AA$2:$AA$2401,ALGLIB_SSA_XAUUSD!$V$2:$V$2401,"",0) | S6: =A6 | T6: =J6 | U6: =K6 | V6: =IF($A6="","",MOD(ROW()-2,12)+1) | W6: =L6 | X6: =IF(F6="","",F6) | Y6: =IF(G6="","",G6) | Z6: =M6 | AA6: =N6 | AB6: =IF(H6="","",H6) | AC6: =O6 | AD6: =IF(I6="","",I6) | AE6: =P6 | AH6: =IF(S6<>"",S6,AH5+900) | AI6: =IF(T6<>"",T6,AI5) | AJ6: =IF(U6<>"",U6,AJ5) | AK6: =IF(W6<>"",W6,"") | AL6: =IF(X6<>"",X6,"") | AM6: =IF(Y6<>"",Y6,"") | AN6: =IF(OR(AL6="",AM6=""),"",AL6-AM6) | AO6: =IF(AN6="","",IF(AN6>0,"Bullish","Bearish")) | AP6: =IF(AO6="",AP5,AO6) | AQ6: =IF(AB6<>"",AB6,"") | AR6: =IF(AD6<>"",AD6,"") | AS6: =IF(AS5+1=13,1,AS5+1) | BD6: =AH6 | BE6: =AI6 | BF6: =AJ6 | BG6: =L6 | BH6: =IF(X6="","",X6) | BI6: =IF(Y6="","",Y6) | BJ6: =Z6 | BK6: =AA6
A7: =ALGLIB_SSA_XAUUSD!AA7 | B7: =IF($A7="","",INDEX(ALGLIB_SSA_XAUUSD!$B$2:$B$2401,MATCH($A7,ALGLIB_SSA_XAUUSD!$A$2:$A$2401,1))) | C7: =IF($A7="","",INDEX(ALGLIB_SSA_XAUUSD!$C$2:$C$2401,MATCH($A7,ALGLIB_SSA_XAUUSD!$A$2:$A$2401,1))) | D7: =IF($A7="","",INT((ROW()-2)/12)+1) | E7: =IF(AND(E14<>"",D14=D2+1),E2+(E14-E2)*5/12,"") | F7: =IF(AND(F14<>"",D14=D2+1),F2+(F14-F2)*5/12,"") | G7: =IF(AND(G14<>"",D14=D2+1),G2+(G14-G2)*5/12,"") | H7: =IF(AND(H14<>"",D14=D2+1),H2+(H14-H2)*5/12,"") | I7: =IF(AND(L14<>"",D14=D2+1),I2+(I14-I2)*5/12,"") | J7: =_xlfn.XLOOKUP($A7,ALGLIB_SSA_XAUUSD!$AA$2:$AA$2401,ALGLIB_SSA_XAUUSD!$P$2:$P$2401,"",0) | K7: =_xlfn.XLOOKUP($A7,ALGLIB_SSA_XAUUSD!$AA$2:$AA$2401,ALGLIB_SSA_XAUUSD!$Q$2:$Q$2401,"",0) | L7: =_xlfn.XLOOKUP($A7,ALGLIB_SSA_XAUUSD!$AA$2:$AA$2401,ALGLIB_SSA_XAUUSD!$R$2:$R$2401,"",0) | M7: =_xlfn.XLOOKUP($A7,ALGLIB_SSA_XAUUSD!$AA$2:$AA$2401,ALGLIB_SSA_XAUUSD!$S$2:$S$2401,"",0) | N7: =_xlfn.XLOOKUP($A7,ALGLIB_SSA_XAUUSD!$AA$2:$AA$2401,ALGLIB_SSA_XAUUSD!$T$2:$T$2401,"",0) | O7: =_xlfn.XLOOKUP($A7,ALGLIB_SSA_XAUUSD!$AA$2:$AA$2401,ALGLIB_SSA_XAUUSD!$U$2:$U$2401,"",0) | P7: =_xlfn.XLOOKUP($A7,ALGLIB_SSA_XAUUSD!$AA$2:$AA$2401,ALGLIB_SSA_XAUUSD!$V$2:$V$2401,"",0) | S7: =A7 | T7: =J7 | U7: =K7 | V7: =IF($A7="","",MOD(ROW()-2,12)+1) | W7: =L7 | X7: =IF(F7="","",F7) | Y7: =IF(G7="","",G7) | Z7: =M7 | AA7: =N7 | AB7: =IF(H7="","",H7) | AC7: =O7 | AD7: =IF(I7="","",I7) | AE7: =P7 | AH7: =IF(S7<>"",S7,AH6+900) | AI7: =IF(T7<>"",T7,AI6) | AJ7: =IF(U7<>"",U7,AJ6) | AK7: =IF(W7<>"",W7,"") | AL7: =IF(X7<>"",X7,"") | AM7: =IF(Y7<>"",Y7,"") | AN7: =IF(OR(AL7="",AM7=""),"",AL7-AM7) | AO7: =IF(AN7="","",IF(AN7>0,"Bullish","Bearish")) | AP7: =IF(AO7="",AP6,AO7) | AQ7: =IF(AB7<>"",AB7,"") | AR7: =IF(AD7<>"",AD7,"") | AS7: =IF(AS6+1=13,1,AS6+1) | BD7: =AH7 | BE7: =AI7 | BF7: =AJ7 | BG7: =L7 | BH7: =IF(X7="","",X7) | BI7: =IF(Y7="","",Y7) | BJ7: =Z7 | BK7: =AA7
A8: =ALGLIB_SSA_XAUUSD!AA8 | B8: =IF($A8="","",INDEX(ALGLIB_SSA_XAUUSD!$B$2:$B$2401,MATCH($A8,ALGLIB_SSA_XAUUSD!$A$2:$A$2401,1))) | C8: =IF($A8="","",INDEX(ALGLIB_SSA_XAUUSD!$C$2:$C$2401,MATCH($A8,ALGLIB_SSA_XAUUSD!$A$2:$A$2401,1))) | D8: =IF($A8="","",INT((ROW()-2)/12)+1) | E8: =IF(AND(E14<>"",D14=D2+1),E2+(E14-E2)*6/12,"") | F8: =IF(AND(F14<>"",D14=D2+1),F2+(F14-F2)*6/12,"") | G8: =IF(AND(G14<>"",D14=D2+1),G2+(G14-G2)*6/12,"") | H8: =IF(AND(H14<>"",D14=D2+1),H2+(H14-H2)*6/12,"") | I8: =IF(AND(L14<>"",D14=D2+1),I2+(I14-I2)*6/12,"") | J8: =_xlfn.XLOOKUP($A8,ALGLIB_SSA_XAUUSD!$AA$2:$AA$2401,ALGLIB_SSA_XAUUSD!$P$2:$P$2401,"",0) | K8: =_xlfn.XLOOKUP($A8,ALGLIB_SSA_XAUUSD!$AA$2:$AA$2401,ALGLIB_SSA_XAUUSD!$Q$2:$Q$2401,"",0) | L8: =_xlfn.XLOOKUP($A8,ALGLIB_SSA_XAUUSD!$AA$2:$AA$2401,ALGLIB_SSA_XAUUSD!$R$2:$R$2401,"",0) | M8: =_xlfn.XLOOKUP($A8,ALGLIB_SSA_XAUUSD!$AA$2:$AA$2401,ALGLIB_SSA_XAUUSD!$S$2:$S$2401,"",0) | N8: =_xlfn.XLOOKUP($A8,ALGLIB_SSA_XAUUSD!$AA$2:$AA$2401,ALGLIB_SSA_XAUUSD!$T$2:$T$2401,"",0) | O8: =_xlfn.XLOOKUP($A8,ALGLIB_SSA_XAUUSD!$AA$2:$AA$2401,ALGLIB_SSA_XAUUSD!$U$2:$U$2401,"",0) | P8: =_xlfn.XLOOKUP($A8,ALGLIB_SSA_XAUUSD!$AA$2:$AA$2401,ALGLIB_SSA_XAUUSD!$V$2:$V$2401,"",0) | S8: =A8 | T8: =J8 | U8: =K8 | V8: =IF($A8="","",MOD(ROW()-2,12)+1) | W8: =L8 | X8: =IF(F8="","",F8) | Y8: =IF(G8="","",G8) | Z8: =M8 | AA8: =N8 | AB8: =IF(H8="","",H8) | AC8: =O8 | AD8: =IF(I8="","",I8) | AE8: =P8 | AH8: =IF(S8<>"",S8,AH7+900) | AI8: =IF(T8<>"",T8,AI7) | AJ8: =IF(U8<>"",U8,AJ7) | AK8: =IF(W8<>"",W8,"") | AL8: =IF(X8<>"",X8,"") | AM8: =IF(Y8<>"",Y8,"") | AN8: =IF(OR(AL8="",AM8=""),"",AL8-AM8) | AO8: =IF(AN8="","",IF(AN8>0,"Bullish","Bearish")) | AP8: =IF(AO8="",AP7,AO8) | AQ8: =IF(AB8<>"",AB8,"") | AR8: =IF(AD8<>"",AD8,"") | AS8: =IF(AS7+1=13,1,AS7+1) | BD8: =AH8 | BE8: =AI8 | BF8: =AJ8 | BG8: =L8 | BH8: =IF(X8="","",X8) | BI8: =IF(Y8="","",Y8) | BJ8: =Z8 | BK8: =AA8
A9: =ALGLIB_SSA_XAUUSD!AA9 | B9: =IF($A9="","",INDEX(ALGLIB_SSA_XAUUSD!$B$2:$B$2401,MATCH($A9,ALGLIB_SSA_XAUUSD!$A$2:$A$2401,1))) | C9: =IF($A9="","",INDEX(ALGLIB_SSA_XAUUSD!$C$2:$C$2401,MATCH($A9,ALGLIB_SSA_XAUUSD!$A$2:$A$2401,1))) | D9: =IF($A9="","",INT((ROW()-2)/12)+1) | E9: =IF(AND(E14<>"",D14=D2+1),E2+(E14-E2)*7/12,"") | F9: =IF(AND(F14<>"",D14=D2+1),F2+(F14-F2)*7/12,"") | G9: =IF(AND(G14<>"",D14=D2+1),G2+(G14-G2)*7/12,"") | H9: =IF(AND(H14<>"",D14=D2+1),H2+(H14-H2)*7/12,"") | I9: =IF(AND(L14<>"",D14=D2+1),I2+(I14-I2)*7/12,"") | J9: =_xlfn.XLOOKUP($A9,ALGLIB_SSA_XAUUSD!$AA$2:$AA$2401,ALGLIB_SSA_XAUUSD!$P$2:$P$2401,"",0) | K9: =_xlfn.XLOOKUP($A9,ALGLIB_SSA_XAUUSD!$AA$2:$AA$2401,ALGLIB_SSA_XAUUSD!$Q$2:$Q$2401,"",0) | L9: =_xlfn.XLOOKUP($A9,ALGLIB_SSA_XAUUSD!$AA$2:$AA$2401,ALGLIB_SSA_XAUUSD!$R$2:$R$2401,"",0) | M9: =_xlfn.XLOOKUP($A9,ALGLIB_SSA_XAUUSD!$AA$2:$AA$2401,ALGLIB_SSA_XAUUSD!$S$2:$S$2401,"",0) | N9: =_xlfn.XLOOKUP($A9,ALGLIB_SSA_XAUUSD!$AA$2:$AA$2401,ALGLIB_SSA_XAUUSD!$T$2:$T$2401,"",0) | O9: =_xlfn.XLOOKUP($A9,ALGLIB_SSA_XAUUSD!$AA$2:$AA$2401,ALGLIB_SSA_XAUUSD!$U$2:$U$2401,"",0) | P9: =_xlfn.XLOOKUP($A9,ALGLIB_SSA_XAUUSD!$AA$2:$AA$2401,ALGLIB_SSA_XAUUSD!$V$2:$V$2401,"",0) | S9: =A9 | T9: =J9 | U9: =K9 | V9: =IF($A9="","",MOD(ROW()-2,12)+1) | W9: =L9 | X9: =IF(F9="","",F9) | Y9: =IF(G9="","",G9) | Z9: =M9 | AA9: =N9 | AB9: =IF(H9="","",H9) | AC9: =O9 | AD9: =IF(I9="","",I9) | AE9: =P9 | AH9: =IF(S9<>"",S9,AH8+900) | AI9: =IF(T9<>"",T9,AI8) | AJ9: =IF(U9<>"",U9,AJ8) | AK9: =IF(W9<>"",W9,"") | AL9: =IF(X9<>"",X9,"") | AM9: =IF(Y9<>"",Y9,"") | AN9: =IF(OR(AL9="",AM9=""),"",AL9-AM9) | AO9: =IF(AN9="","",IF(AN9>0,"Bullish","Bearish")) | AP9: =IF(AO9="",AP8,AO9) | AQ9: =IF(AB9<>"",AB9,"") | AR9: =IF(AD9<>"",AD9,"") | AS9: =IF(AS8+1=13,1,AS8+1) | BD9: =AH9 | BE9: =AI9 | BF9: =AJ9 | BG9: =L9 | BH9: =IF(X9="","",X9) | BI9: =IF(Y9="","",Y9) | BJ9: =Z9 | BK9: =AA9
A10: =ALGLIB_SSA_XAUUSD!AA10 | B10: =IF($A10="","",INDEX(ALGLIB_SSA_XAUUSD!$B$2:$B$2401,MATCH($A10,ALGLIB_SSA_XAUUSD!$A$2:$A$2401,1))) | C10: =IF($A10="","",INDEX(ALGLIB_SSA_XAUUSD!$C$2:$C$2401,MATCH($A10,ALGLIB_SSA_XAUUSD!$A$2:$A$2401,1))) | D10: =IF($A10="","",INT((ROW()-2)/12)+1) | E10: =IF(AND(E14<>"",D14=D2+1),E2+(E14-E2)*8/12,"") | F10: =IF(AND(F14<>"",D14=D2+1),F2+(F14-F2)*8/12,"") | G10: =IF(AND(G14<>"",D14=D2+1),G2+(G14-G2)*8/12,"") | H10: =IF(AND(H14<>"",D14=D2+1),H2+(H14-H2)*8/12,"") | I10: =IF(AND(L14<>"",D14=D2+1),I2+(I14-I2)*8/12,"") | J10: =_xlfn.XLOOKUP($A10,ALGLIB_SSA_XAUUSD!$AA$2:$AA$2401,ALGLIB_SSA_XAUUSD!$P$2:$P$2401,"",0) | K10: =_xlfn.XLOOKUP($A10,ALGLIB_SSA_XAUUSD!$AA$2:$AA$2401,ALGLIB_SSA_XAUUSD!$Q$2:$Q$2401,"",0) | L10: =_xlfn.XLOOKUP($A10,ALGLIB_SSA_XAUUSD!$AA$2:$AA$2401,ALGLIB_SSA_XAUUSD!$R$2:$R$2401,"",0) | M10: =_xlfn.XLOOKUP($A10,ALGLIB_SSA_XAUUSD!$AA$2:$AA$2401,ALGLIB_SSA_XAUUSD!$S$2:$S$2401,"",0) | N10: =_xlfn.XLOOKUP($A10,ALGLIB_SSA_XAUUSD!$AA$2:$AA$2401,ALGLIB_SSA_XAUUSD!$T$2:$T$2401,"",0) | O10: =_xlfn.XLOOKUP($A10,ALGLIB_SSA_XAUUSD!$AA$2:$AA$2401,ALGLIB_SSA_XAUUSD!$U$2:$U$2401,"",0) | P10: =_xlfn.XLOOKUP($A10,ALGLIB_SSA_XAUUSD!$AA$2:$AA$2401,ALGLIB_SSA_XAUUSD!$V$2:$V$2401,"",0) | S10: =A10 | T10: =J10 | U10: =K10 | V10: =IF($A10="","",MOD(ROW()-2,12)+1) | W10: =L10 | X10: =IF(F10="","",F10) | Y10: =IF(G10="","",G10) | Z10: =M10 | AA10: =N10 | AB10: =IF(H10="","",H10) | AC10: =O10 | AD10: =IF(I10="","",I10) | AE10: =P10 | AH10: =IF(S10<>"",S10,AH9+900) | AI10: =IF(T10<>"",T10,AI9) | AJ10: =IF(U10<>"",U10,AJ9) | AK10: =IF(W10<>"",W10,"") | AL10: =IF(X10<>"",X10,"") | AM10: =IF(Y10<>"",Y10,"") | AN10: =IF(OR(AL10="",AM10=""),"",AL10-AM10) | AO10: =IF(AN10="","",IF(AN10>0,"Bullish","Bearish")) | AP10: =IF(AO10="",AP9,AO10) | AQ10: =IF(AB10<>"",AB10,"") | AR10: =IF(AD10<>"",AD10,"") | AS10: =IF(AS9+1=13,1,AS9+1) | BD10: =AH10 | BE10: =AI10 | BF10: =AJ10 | BG10: =L10 | BH10: =IF(X10="","",X10) | BI10: =IF(Y10="","",Y10) | BJ10: =Z10 | BK10: =AA10
A11: =ALGLIB_SSA_XAUUSD!AA11 | B11: =IF($A11="","",INDEX(ALGLIB_SSA_XAUUSD!$B$2:$B$2401,MATCH($A11,ALGLIB_SSA_XAUUSD!$A$2:$A$2401,1))) | C11: =IF($A11="","",INDEX(ALGLIB_SSA_XAUUSD!$C$2:$C$2401,MATCH($A11,ALGLIB_SSA_XAUUSD!$A$2:$A$2401,1))) | D11: =IF($A11="","",INT((ROW()-2)/12)+1) | E11: =IF(AND(E14<>"",D14=D2+1),E2+(E14-E2)*9/12,"") | F11: =IF(AND(F14<>"",D14=D2+1),F2+(F14-F2)*9/12,"") | G11: =IF(AND(G14<>"",D14=D2+1),G2+(G14-G2)*9/12,"") | H11: =IF(AND(H14<>"",D14=D2+1),H2+(H14-H2)*9/12,"") | I11: =IF(AND(L14<>"",D14=D2+1),I2+(I14-I2)*9/12,"") | J11: =_xlfn.XLOOKUP($A11,ALGLIB_SSA_XAUUSD!$AA$2:$AA$2401,ALGLIB_SSA_XAUUSD!$P$2:$P$2401,"",0) | K11: =_xlfn.XLOOKUP($A11,ALGLIB_SSA_XAUUSD!$AA$2:$AA$2401,ALGLIB_SSA_XAUUSD!$Q$2:$Q$2401,"",0) | L11: =_xlfn.XLOOKUP($A11,ALGLIB_SSA_XAUUSD!$AA$2:$AA$2401,ALGLIB_SSA_XAUUSD!$R$2:$R$2401,"",0) | M11: =_xlfn.XLOOKUP($A11,ALGLIB_SSA_XAUUSD!$AA$2:$AA$2401,ALGLIB_SSA_XAUUSD!$S$2:$S$2401,"",0) | N11: =_xlfn.XLOOKUP($A11,ALGLIB_SSA_XAUUSD!$AA$2:$AA$2401,ALGLIB_SSA_XAUUSD!$T$2:$T$2401,"",0) | O11: =_xlfn.XLOOKUP($A11,ALGLIB_SSA_XAUUSD!$AA$2:$AA$2401,ALGLIB_SSA_XAUUSD!$U$2:$U$2401,"",0) | P11: =_xlfn.XLOOKUP($A11,ALGLIB_SSA_XAUUSD!$AA$2:$AA$2401,ALGLIB_SSA_XAUUSD!$V$2:$V$2401,"",0) | S11: =A11 | T11: =J11 | U11: =K11 | V11: =IF($A11="","",MOD(ROW()-2,12)+1) | W11: =L11 | X11: =IF(F11="","",F11) | Y11: =IF(G11="","",G11) | Z11: =M11 | AA11: =N11 | AB11: =IF(H11="","",H11) | AC11: =O11 | AD11: =IF(I11="","",I11) | AE11: =P11 | AH11: =IF(S11<>"",S11,AH10+900) | AI11: =IF(T11<>"",T11,AI10) | AJ11: =IF(U11<>"",U11,AJ10) | AK11: =IF(W11<>"",W11,"") | AL11: =IF(X11<>"",X11,"") | AM11: =IF(Y11<>"",Y11,"") | AN11: =IF(OR(AL11="",AM11=""),"",AL11-AM11) | AO11: =IF(AN11="","",IF(AN11>0,"Bullish","Bearish")) | AP11: =IF(AO11="",AP10,AO11) | AQ11: =IF(AB11<>"",AB11,"") | AR11: =IF(AD11<>"",AD11,"") | AS11: =IF(AS10+1=13,1,AS10+1) | BD11: =AH11 | BE11: =AI11 | BF11: =AJ11 | BG11: =L11 | BH11: =IF(X11="","",X11) | BI11: =IF(Y11="","",Y11) | BJ11: =Z11 | BK11: =AA11
A12: =ALGLIB_SSA_XAUUSD!AA12 | B12: =IF($A12="","",INDEX(ALGLIB_SSA_XAUUSD!$B$2:$B$2401,MATCH($A12,ALGLIB_SSA_XAUUSD!$A$2:$A$2401,1))) | C12: =IF($A12="","",INDEX(ALGLIB_SSA_XAUUSD!$C$2:$C$2401,MATCH($A12,ALGLIB_SSA_XAUUSD!$A$2:$A$2401,1))) | D12: =IF($A12="","",INT((ROW()-2)/12)+1) | E12: =IF(AND(E14<>"",D14=D2+1),E2+(E14-E2)*10/12,"") | F12: =IF(AND(F14<>"",D14=D2+1),F2+(F14-F2)*10/12,"") | G12: =IF(AND(G14<>"",D14=D2+1),G2+(G14-G2)*10/12,"") | H12: =IF(AND(H14<>"",D14=D2+1),H2+(H14-H2)*10/12,"") | I12: =IF(AND(L14<>"",D14=D2+1),I2+(I14-I2)*10/12,"") | J12: =_xlfn.XLOOKUP($A12,ALGLIB_SSA_XAUUSD!$AA$2:$AA$2401,ALGLIB_SSA_XAUUSD!$P$2:$P$2401,"",0) | K12: =_xlfn.XLOOKUP($A12,ALGLIB_SSA_XAUUSD!$AA$2:$AA$2401,ALGLIB_SSA_XAUUSD!$Q$2:$Q$2401,"",0) | L12: =_xlfn.XLOOKUP($A12,ALGLIB_SSA_XAUUSD!$AA$2:$AA$2401,ALGLIB_SSA_XAUUSD!$R$2:$R$2401,"",0) | M12: =_xlfn.XLOOKUP($A12,ALGLIB_SSA_XAUUSD!$AA$2:$AA$2401,ALGLIB_SSA_XAUUSD!$S$2:$S$2401,"",0) | N12: =_xlfn.XLOOKUP($A12,ALGLIB_SSA_XAUUSD!$AA$2:$AA$2401,ALGLIB_SSA_XAUUSD!$T$2:$T$2401,"",0) | O12: =_xlfn.XLOOKUP($A12,ALGLIB_SSA_XAUUSD!$AA$2:$AA$2401,ALGLIB_SSA_XAUUSD!$U$2:$U$2401,"",0) | P12: =_xlfn.XLOOKUP($A12,ALGLIB_SSA_XAUUSD!$AA$2:$AA$2401,ALGLIB_SSA_XAUUSD!$V$2:$V$2401,"",0) | S12: =A12 | T12: =J12 | U12: =K12 | V12: =IF($A12="","",MOD(ROW()-2,12)+1) | W12: =L12 | X12: =IF(F12="","",F12) | Y12: =IF(G12="","",G12) | Z12: =M12 | AA12: =N12 | AB12: =IF(H12="","",H12) | AC12: =O12 | AD12: =IF(I12="","",I12) | AE12: =P12 | AH12: =IF(S12<>"",S12,AH11+900) | AI12: =IF(T12<>"",T12,AI11) | AJ12: =IF(U12<>"",U12,AJ11) | AK12: =IF(W12<>"",W12,"") | AL12: =IF(X12<>"",X12,"") | AM12: =IF(Y12<>"",Y12,"") | AN12: =IF(OR(AL12="",AM12=""),"",AL12-AM12) | AO12: =IF(AN12="","",IF(AN12>0,"Bullish","Bearish")) | AP12: =IF(AO12="",AP11,AO12) | AQ12: =IF(AB12<>"",AB12,"") | AR12: =IF(AD12<>"",AD12,"") | AS12: =IF(AS11+1=13,1,AS11+1) | BD12: =AH12 | BE12: =AI12 | BF12: =AJ12 | BG12: =L12 | BH12: =IF(X12="","",X12) | BI12: =IF(Y12="","",Y12) | BJ12: =Z12 | BK12: =AA12
A13: =ALGLIB_SSA_XAUUSD!AA13 | B13: =IF($A13="","",INDEX(ALGLIB_SSA_XAUUSD!$B$2:$B$2401,MATCH($A13,ALGLIB_SSA_XAUUSD!$A$2:$A$2401,1))) | C13: =IF($A13="","",INDEX(ALGLIB_SSA_XAUUSD!$C$2:$C$2401,MATCH($A13,ALGLIB_SSA_XAUUSD!$A$2:$A$2401,1))) | D13: =IF($A13="","",INT((ROW()-2)/12)+1) | E13: =IF(AND(E14<>"",D14=D2+1),E2+(E14-E2)*11/12,"") | F13: =IF(AND(F14<>"",D14=D2+1),F2+(F14-F2)*11/12,"") | G13: =IF(AND(G14<>"",D14=D2+1),G2+(G14-G2)*11/12,"") | H13: =IF(AND(H14<>"",D14=D2+1),H2+(H14-H2)*11/12,"") | I13: =IF(AND(L14<>"",D14=D2+1),I2+(I14-I2)*11/12,"") | J13: =_xlfn.XLOOKUP($A13,ALGLIB_SSA_XAUUSD!$AA$2:$AA$2401,ALGLIB_SSA_XAUUSD!$P$2:$P$2401,"",0) | K13: =_xlfn.XLOOKUP($A13,ALGLIB_SSA_XAUUSD!$AA$2:$AA$2401,ALGLIB_SSA_XAUUSD!$Q$2:$Q$2401,"",0) | L13: =_xlfn.XLOOKUP($A13,ALGLIB_SSA_XAUUSD!$AA$2:$AA$2401,ALGLIB_SSA_XAUUSD!$R$2:$R$2401,"",0) | M13: =_xlfn.XLOOKUP($A13,ALGLIB_SSA_XAUUSD!$AA$2:$AA$2401,ALGLIB_SSA_XAUUSD!$S$2:$S$2401,"",0) | N13: =_xlfn.XLOOKUP($A13,ALGLIB_SSA_XAUUSD!$AA$2:$AA$2401,ALGLIB_SSA_XAUUSD!$T$2:$T$2401,"",0) | O13: =_xlfn.XLOOKUP($A13,ALGLIB_SSA_XAUUSD!$AA$2:$AA$2401,ALGLIB_SSA_XAUUSD!$U$2:$U$2401,"",0) | P13: =_xlfn.XLOOKUP($A13,ALGLIB_SSA_XAUUSD!$AA$2:$AA$2401,ALGLIB_SSA_XAUUSD!$V$2:$V$2401,"",0) | S13: =A13 | T13: =J13 | U13: =K13 | V13: =IF($A13="","",MOD(ROW()-2,12)+1) | W13: =L13 | X13: =IF(F13="","",F13) | Y13: =IF(G13="","",G13) | Z13: =M13 | AA13: =N13 | AB13: =IF(H13="","",H13) | AC13: =O13 | AD13: =IF(I13="","",I13) | AE13: =P13 | AH13: =IF(S13<>"",S13,AH12+900) | AI13: =IF(T13<>"",T13,AI12) | AJ13: =IF(U13<>"",U13,AJ12) | AK13: =IF(W13<>"",W13,"") | AL13: =IF(X13<>"",X13,"") | AM13: =IF(Y13<>"",Y13,"") | AN13: =IF(OR(AL13="",AM13=""),"",AL13-AM13) | AO13: =IF(AN13="","",IF(AN13>0,"Bullish","Bearish")) | AP13: =IF(AO13="",AP12,AO13) | AQ13: =IF(AB13<>"",AB13,"") | AR13: =IF(AD13<>"",AD13,"") | AS13: =IF(AS12+1=13,1,AS12+1) | BD13: =AH13 | BE13: =AI13 | BF13: =AJ13 | BG13: =L13 | BH13: =IF(X13="","",X13) | BI13: =IF(Y13="","",Y13) | BJ13: =Z13 | BK13: =AA13
A14: =ALGLIB_SSA_XAUUSD!AA14 | B14: =IF($A14="","",INDEX(ALGLIB_SSA_XAUUSD!$B$2:$B$2401,MATCH($A14,ALGLIB_SSA_XAUUSD!$A$2:$A$2401,1))) | C14: =IF($A14="","",INDEX(ALGLIB_SSA_XAUUSD!$C$2:$C$2401,MATCH($A14,ALGLIB_SSA_XAUUSD!$A$2:$A$2401,1))) | D14: =IF($A14="","",INT((ROW()-2)/12)+1) | E14: =IF($A14="","",INDEX(ALGLIB_SSA_XAUUSD!$D$2:$D$2401,MATCH($A14,ALGLIB_SSA_XAUUSD!$A$2:$A$2401,1))) | F14: =IF($A14="","",INDEX(ALGLIB_SSA_XAUUSD!$E$2:$E$2401,MATCH($A14,ALGLIB_SSA_XAUUSD!$A$2:$A$2401,1))) | G14: =IF($A14="","",INDEX(ALGLIB_SSA_XAUUSD!$F$2:$F$2401,MATCH($A14,ALGLIB_SSA_XAUUSD!$A$2:$A$2401,1))) | H14: =IF($A14="","",INDEX(ALGLIB_SSA_XAUUSD!$G$2:$G$2401,MATCH($A14,ALGLIB_SSA_XAUUSD!$A$2:$A$2401,1))) | I14: =IF($A14="","",INDEX(ALGLIB_SSA_XAUUSD!$H$2:$H$2401,MATCH($A14,ALGLIB_SSA_XAUUSD!$A$2:$A$2401,1))) | J14: =_xlfn.XLOOKUP($A14,ALGLIB_SSA_XAUUSD!$AA$2:$AA$2401,ALGLIB_SSA_XAUUSD!$P$2:$P$2401,"",0) | K14: =_xlfn.XLOOKUP($A14,ALGLIB_SSA_XAUUSD!$AA$2:$AA$2401,ALGLIB_SSA_XAUUSD!$Q$2:$Q$2401,"",0) | L14: =_xlfn.XLOOKUP($A14,ALGLIB_SSA_XAUUSD!$AA$2:$AA$2401,ALGLIB_SSA_XAUUSD!$R$2:$R$2401,"",0) | M14: =_xlfn.XLOOKUP($A14,ALGLIB_SSA_XAUUSD!$AA$2:$AA$2401,ALGLIB_SSA_XAUUSD!$S$2:$S$2401,"",0) | N14: =_xlfn.XLOOKUP($A14,ALGLIB_SSA_XAUUSD!$AA$2:$AA$2401,ALGLIB_SSA_XAUUSD!$T$2:$T$2401,"",0) | O14: =_xlfn.XLOOKUP($A14,ALGLIB_SSA_XAUUSD!$AA$2:$AA$2401,ALGLIB_SSA_XAUUSD!$U$2:$U$2401,"",0) | P14: =_xlfn.XLOOKUP($A14,ALGLIB_SSA_XAUUSD!$AA$2:$AA$2401,ALGLIB_SSA_XAUUSD!$V$2:$V$2401,"",0) | S14: =A14 | T14: =J14 | U14: =K14 | V14: =IF($A14="","",MOD(ROW()-2,12)+1) | W14: =L14 | X14: =IF(F14="","",F14) | Y14: =IF(G14="","",G14) | Z14: =M14 | AA14: =N14 | AB14: =IF(H14="","",H14) | AC14: =O14 | AD14: =IF(I14="","",I14) | AE14: =P14 | AH14: =IF(S14<>"",S14,AH13+900) | AI14: =IF(T14<>"",T14,AI13) | AJ14: =IF(U14<>"",U14,AJ13) | AK14: =IF(W14<>"",W14,"") | AL14: =IF(X14<>"",X14,"") | AM14: =IF(Y14<>"",Y14,"") | AN14: =IF(OR(AL14="",AM14=""),"",AL14-AM14) | AO14: =IF(AN14="","",IF(AN14>0,"Bullish","Bearish")) | AP14: =IF(AO14="",AP13,AO14) | AQ14: =IF(AB14<>"",AB14,"") | AR14: =IF(AD14<>"",AD14,"") | AS14: =IF(AS13+1=13,1,AS13+1) | AT14: =IFERROR(IF(SLOPE($AQ$2:$AQ$13,$AS$2:$AS$13)>0,MIN(3,ABS(SLOPE($AQ$2:$AQ$13,$AS$2:$AS$13))),IF(SLOPE($AQ$2:$AQ$13,$AS$2:$AS$13)<-0.5,-0.5,0)),0) | AU14: =IFERROR(IF(SLOPE($AR$2:$AR$13,$AS$2:$AS$13)<0,MAX(-3,-ABS(SLOPE($AR$2:$AR$13,$AS$2:$AS$13))),IF(SLOPE($AR$2:$AR$13,$AS$2:$AS$13)>0.5,0.5,0)),0) | AV14: =($AQ$14+(AT14*(AS14-1))) | AW14: =($AR$14+(AU14*(AS14-1))) | AX14: =IF(AT14>0,AV14+AT14,AV14) | AY14: =IF(AU14<0,AW14+AU14,AW14) | BA14: =IFERROR(AX14-AQ14,"") | BB14: =IFERROR(AY14-AR14,"") | BD14: =AH14 | BE14: =AI14 | BF14: =AJ14 | BG14: =L14 | BH14: =IF(X14="","",X14) | BI14: =IF(Y14="","",Y14) | BJ14: =Z14 | BK14: =AA14 | BL14: =IFERROR(AX14,"") | BM14: =IFERROR(AY14,"")
A15: =ALGLIB_SSA_XAUUSD!AA15 | B15: =IF($A15="","",INDEX(ALGLIB_SSA_XAUUSD!$B$2:$B$2401,MATCH($A15,ALGLIB_SSA_XAUUSD!$A$2:$A$2401,1))) | C15: =IF($A15="","",INDEX(ALGLIB_SSA_XAUUSD!$C$2:$C$2401,MATCH($A15,ALGLIB_SSA_XAUUSD!$A$2:$A$2401,1))) | D15: =IF($A15="","",INT((ROW()-2)/12)+1) | E15: =IF(AND(E26<>"",D26=D14+1),E14+(E26-E14)*1/12,"") | F15: =IF(AND(F26<>"",D26=D14+1),F14+(F26-F14)*1/12,"") | G15: =IF(AND(G26<>"",D26=D14+1),G14+(G26-G14)*1/12,"") | H15: =IF(AND(H26<>"",D26=D14+1),H14+(H26-H14)*1/12,"") | I15: =IF(AND(L26<>"",D26=D14+1),I14+(I26-I14)*1/12,"") | J15: =_xlfn.XLOOKUP($A15,ALGLIB_SSA_XAUUSD!$AA$2:$AA$2401,ALGLIB_SSA_XAUUSD!$P$2:$P$2401,"",0) | K15: =_xlfn.XLOOKUP($A15,ALGLIB_SSA_XAUUSD!$AA$2:$AA$2401,ALGLIB_SSA_XAUUSD!$Q$2:$Q$2401,"",0) | L15: =_xlfn.XLOOKUP($A15,ALGLIB_SSA_XAUUSD!$AA$2:$AA$2401,ALGLIB_SSA_XAUUSD!$R$2:$R$2401,"",0) | M15: =_xlfn.XLOOKUP($A15,ALGLIB_SSA_XAUUSD!$AA$2:$AA$2401,ALGLIB_SSA_XAUUSD!$S$2:$S$2401,"",0) | N15: =_xlfn.XLOOKUP($A15,ALGLIB_SSA_XAUUSD!$AA$2:$AA$2401,ALGLIB_SSA_XAUUSD!$T$2:$T$2401,"",0) | O15: =_xlfn.XLOOKUP($A15,ALGLIB_SSA_XAUUSD!$AA$2:$AA$2401,ALGLIB_SSA_XAUUSD!$U$2:$U$2401,"",0) | P15: =_xlfn.XLOOKUP($A15,ALGLIB_SSA_XAUUSD!$AA$2:$AA$2401,ALGLIB_SSA_XAUUSD!$V$2:$V$2401,"",0) | S15: =A15 | T15: =J15 | U15: =K15 | V15: =IF($A15="","",MOD(ROW()-2,12)+1) | W15: =L15 | X15: =IF(F15="","",F15) | Y15: =IF(G15="","",G15) | Z15: =M15 | AA15: =N15 | AB15: =IF(H15="","",H15) | AC15: =O15 | AD15: =IF(I15="","",I15) | AE15: =P15 | AH15: =IF(S15<>"",S15,AH14+900) | AI15: =IF(T15<>"",T15,AI14) | AJ15: =IF(U15<>"",U15,AJ14) | AK15: =IF(W15<>"",W15,"") | AL15: =IF(X15<>"",X15,"") | AM15: =IF(Y15<>"",Y15,"") | AN15: =IF(OR(AL15="",AM15=""),"",AL15-AM15) | AO15: =IF(AN15="","",IF(AN15>0,"Bullish","Bearish")) | AP15: =IF(AO15="",AP14,AO15) | AQ15: =IF(AB15<>"",AB15,"") | AR15: =IF(AD15<>"",AD15,"") | AS15: =IF(AS14+1=13,1,AS14+1) | AT15: =IFERROR(IF(SLOPE($AQ$2:$AQ$13,$AS$2:$AS$13)>0,MIN(3,ABS(SLOPE($AQ$2:$AQ$13,$AS$2:$AS$13))),IF(SLOPE($AQ$2:$AQ$13,$AS$2:$AS$13)<-0.5,-0.5,0)),0) | AU15: =IFERROR(IF(SLOPE($AR$2:$AR$13,$AS$2:$AS$13)<0,MAX(-3,-ABS(SLOPE($AR$2:$AR$13,$AS$2:$AS$13))),IF(SLOPE($AR$2:$AR$13,$AS$2:$AS$13)>0.5,0.5,0)),0) | AV15: =($AQ$14+(AT15*(AS15-1))) | AW15: =($AR$14+(AU15*(AS15-1))) | AX15: =IF(AT15>0,AV15+AT15,AV15) | AY15: =IF(AU15<0,AW15+AU15,AW15) | BA15: =IFERROR(AX15-AQ15,"") | BB15: =IFERROR(AY15-AR15,"") | BD15: =AH15 | BE15: =AI15 | BF15: =AJ15 | BG15: =L15 | BH15: =IF(X15="","",X15) | BI15: =IF(Y15="","",Y15) | BJ15: =Z15 | BK15: =AA15 | BL15: =IFERROR(AX15,"") | BM15: =IFERROR(AY15,"")
A16: =ALGLIB_SSA_XAUUSD!AA16 | B16: =IF($A16="","",INDEX(ALGLIB_SSA_XAUUSD!$B$2:$B$2401,MATCH($A16,ALGLIB_SSA_XAUUSD!$A$2:$A$2401,1))) | C16: =IF($A16="","",INDEX(ALGLIB_SSA_XAUUSD!$C$2:$C$2401,MATCH($A16,ALGLIB_SSA_XAUUSD!$A$2:$A$2401,1))) | D16: =IF($A16="","",INT((ROW()-2)/12)+1) | E16: =IF(AND(E26<>"",D26=D14+1),E14+(E26-E14)*2/12,"") | F16: =IF(AND(F26<>"",D26=D14+1),F14+(F26-F14)*2/12,"") | G16: =IF(AND(G26<>"",D26=D14+1),G14+(G26-G14)*2/12,"") | H16: =IF(AND(H26<>"",D26=D14+1),H14+(H26-H14)*2/12,"") | I16: =IF(AND(L26<>"",D26=D14+1),I14+(I26-I14)*2/12,"") | J16: =_xlfn.XLOOKUP($A16,ALGLIB_SSA_XAUUSD!$AA$2:$AA$2401,ALGLIB_SSA_XAUUSD!$P$2:$P$2401,"",0) | K16: =_xlfn.XLOOKUP($A16,ALGLIB_SSA_XAUUSD!$AA$2:$AA$2401,ALGLIB_SSA_XAUUSD!$Q$2:$Q$2401,"",0) | L16: =_xlfn.XLOOKUP($A16,ALGLIB_SSA_XAUUSD!$AA$2:$AA$2401,ALGLIB_SSA_XAUUSD!$R$2:$R$2401,"",0) | M16: =_xlfn.XLOOKUP($A16,ALGLIB_SSA_XAUUSD!$AA$2:$AA$2401,ALGLIB_SSA_XAUUSD!$S$2:$S$2401,"",0) | N16: =_xlfn.XLOOKUP($A16,ALGLIB_SSA_XAUUSD!$AA$2:$AA$2401,ALGLIB_SSA_XAUUSD!$T$2:$T$2401,"",0) | O16: =_xlfn.XLOOKUP($A16,ALGLIB_SSA_XAUUSD!$AA$2:$AA$2401,ALGLIB_SSA_XAUUSD!$U$2:$U$2401,"",0) | P16: =_xlfn.XLOOKUP($A16,ALGLIB_SSA_XAUUSD!$AA$2:$AA$2401,ALGLIB_SSA_XAUUSD!$V$2:$V$2401,"",0) | S16: =A16 | T16: =J16 | U16: =K16 | V16: =IF($A16="","",MOD(ROW()-2,12)+1) | W16: =L16 | X16: =IF(F16="","",F16) | Y16: =IF(G16="","",G16) | Z16: =M16 | AA16: =N16 | AB16: =IF(H16="","",H16) | AC16: =O16 | AD16: =IF(I16="","",I16) | AE16: =P16 | AH16: =IF(S16<>"",S16,AH15+900) | AI16: =IF(T16<>"",T16,AI15) | AJ16: =IF(U16<>"",U16,AJ15) | AK16: =IF(W16<>"",W16,"") | AL16: =IF(X16<>"",X16,"") | AM16: =IF(Y16<>"",Y16,"") | AN16: =IF(OR(AL16="",AM16=""),"",AL16-AM16) | AO16: =IF(AN16="","",IF(AN16>0,"Bullish","Bearish")) | AP16: =IF(AO16="",AP15,AO16) | AQ16: =IF(AB16<>"",AB16,"") | AR16: =IF(AD16<>"",AD16,"") | AS16: =IF(AS15+1=13,1,AS15+1) | AT16: =IFERROR(IF(SLOPE($AQ$2:$AQ$13,$AS$2:$AS$13)>0,MIN(3,ABS(SLOPE($AQ$2:$AQ$13,$AS$2:$AS$13))),IF(SLOPE($AQ$2:$AQ$13,$AS$2:$AS$13)<-0.5,-0.5,0)),0) | AU16: =IFERROR(IF(SLOPE($AR$2:$AR$13,$AS$2:$AS$13)<0,MAX(-3,-ABS(SLOPE($AR$2:$AR$13,$AS$2:$AS$13))),IF(SLOPE($AR$2:$AR$13,$AS$2:$AS$13)>0.5,0.5,0)),0) | AV16: =($AQ$14+(AT16*(AS16-1))) | AW16: =($AR$14+(AU16*(AS16-1))) | AX16: =IF(AT16>0,AV16+AT16,AV16) | AY16: =IF(AU16<0,AW16+AU16,AW16) | BA16: =IFERROR(AX16-AQ16,"") | BB16: =IFERROR(AY16-AR16,"") | BD16: =AH16 | BE16: =AI16 | BF16: =AJ16 | BG16: =L16 | BH16: =IF(X16="","",X16) | BI16: =IF(Y16="","",Y16) | BJ16: =Z16 | BK16: =AA16 | BL16: =IFERROR(AX16,"") | BM16: =IFERROR(AY16,"")
A17: =ALGLIB_SSA_XAUUSD!AA17 | B17: =IF($A17="","",INDEX(ALGLIB_SSA_XAUUSD!$B$2:$B$2401,MATCH($A17,ALGLIB_SSA_XAUUSD!$A$2:$A$2401,1))) | C17: =IF($A17="","",INDEX(ALGLIB_SSA_XAUUSD!$C$2:$C$2401,MATCH($A17,ALGLIB_SSA_XAUUSD!$A$2:$A$2401,1))) | D17: =IF($A17="","",INT((ROW()-2)/12)+1) | E17: =IF(AND(E26<>"",D26=D14+1),E14+(E26-E14)*3/12,"") | F17: =IF(AND(F26<>"",D26=D14+1),F14+(F26-F14)*3/12,"") | G17: =IF(AND(G26<>"",D26=D14+1),G14+(G26-G14)*3/12,"") | H17: =IF(AND(H26<>"",D26=D14+1),H14+(H26-H14)*3/12,"") | I17: =IF(AND(L26<>"",D26=D14+1),I14+(I26-I14)*3/12,"") | J17: =_xlfn.XLOOKUP($A17,ALGLIB_SSA_XAUUSD!$AA$2:$AA$2401,ALGLIB_SSA_XAUUSD!$P$2:$P$2401,"",0) | K17: =_xlfn.XLOOKUP($A17,ALGLIB_SSA_XAUUSD!$AA$2:$AA$2401,ALGLIB_SSA_XAUUSD!$Q$2:$Q$2401,"",0) | L17: =_xlfn.XLOOKUP($A17,ALGLIB_SSA_XAUUSD!$AA$2:$AA$2401,ALGLIB_SSA_XAUUSD!$R$2:$R$2401,"",0) | M17: =_xlfn.XLOOKUP($A17,ALGLIB_SSA_XAUUSD!$AA$2:$AA$2401,ALGLIB_SSA_XAUUSD!$S$2:$S$2401,"",0) | N17: =_xlfn.XLOOKUP($A17,ALGLIB_SSA_XAUUSD!$AA$2:$AA$2401,ALGLIB_SSA_XAUUSD!$T$2:$T$2401,"",0) | O17: =_xlfn.XLOOKUP($A17,ALGLIB_SSA_XAUUSD!$AA$2:$AA$2401,ALGLIB_SSA_XAUUSD!$U$2:$U$2401,"",0) | P17: =_xlfn.XLOOKUP($A17,ALGLIB_SSA_XAUUSD!$AA$2:$AA$2401,ALGLIB_SSA_XAUUSD!$V$2:$V$2401,"",0) | S17: =A17 | T17: =J17 | U17: =K17 | V17: =IF($A17="","",MOD(ROW()-2,12)+1) | W17: =L17 | X17: =IF(F17="","",F17) | Y17: =IF(G17="","",G17) | Z17: =M17 | AA17: =N17 | AB17: =IF(H17="","",H17) | AC17: =O17 | AD17: =IF(I17="","",I17) | AE17: =P17 | AH17: =IF(S17<>"",S17,AH16+900) | AI17: =IF(T17<>"",T17,AI16) | AJ17: =IF(U17<>"",U17,AJ16) | AK17: =IF(W17<>"",W17,"") | AL17: =IF(X17<>"",X17,"") | AM17: =IF(Y17<>"",Y17,"") | AN17: =IF(OR(AL17="",AM17=""),"",AL17-AM17) | AO17: =IF(AN17="","",IF(AN17>0,"Bullish","Bearish")) | AP17: =IF(AO17="",AP16,AO17) | AQ17: =IF(AB17<>"",AB17,"") | AR17: =IF(AD17<>"",AD17,"") | AS17: =IF(AS16+1=13,1,AS16+1) | AT17: =IFERROR(IF(SLOPE($AQ$2:$AQ$13,$AS$2:$AS$13)>0,MIN(3,ABS(SLOPE($AQ$2:$AQ$13,$AS$2:$AS$13))),IF(SLOPE($AQ$2:$AQ$13,$AS$2:$AS$13)<-0.5,-0.5,0)),0) | AU17: =IFERROR(IF(SLOPE($AR$2:$AR$13,$AS$2:$AS$13)<0,MAX(-3,-ABS(SLOPE($AR$2:$AR$13,$AS$2:$AS$13))),IF(SLOPE($AR$2:$AR$13,$AS$2:$AS$13)>0.5,0.5,0)),0) | AV17: =($AQ$14+(AT17*(AS17-1))) | AW17: =($AR$14+(AU17*(AS17-1))) | AX17: =IF(AT17>0,AV17+AT17,AV17) | AY17: =IF(AU17<0,AW17+AU17,AW17) | BA17: =IFERROR(AX17-AQ17,"") | BB17: =IFERROR(AY17-AR17,"") | BD17: =AH17 | BE17: =AI17 | BF17: =AJ17 | BG17: =L17 | BH17: =IF(X17="","",X17) | BI17: =IF(Y17="","",Y17) | BJ17: =Z17 | BK17: =AA17 | BL17: =IFERROR(AX17,"") | BM17: =IFERROR(AY17,"")
A18: =ALGLIB_SSA_XAUUSD!AA18 | B18: =IF($A18="","",INDEX(ALGLIB_SSA_XAUUSD!$B$2:$B$2401,MATCH($A18,ALGLIB_SSA_XAUUSD!$A$2:$A$2401,1))) | C18: =IF($A18="","",INDEX(ALGLIB_SSA_XAUUSD!$C$2:$C$2401,MATCH($A18,ALGLIB_SSA_XAUUSD!$A$2:$A$2401,1))) | D18: =IF($A18="","",INT((ROW()-2)/12)+1) | E18: =IF(AND(E26<>"",D26=D14+1),E14+(E26-E14)*4/12,"") | F18: =IF(AND(F26<>"",D26=D14+1),F14+(F26-F14)*4/12,"") | G18: =IF(AND(G26<>"",D26=D14+1),G14+(G26-G14)*4/12,"") | H18: =IF(AND(H26<>"",D26=D14+1),H14+(H26-H14)*4/12,"") | I18: =IF(AND(L26<>"",D26=D14+1),I14+(I26-I14)*4/12,"") | J18: =_xlfn.XLOOKUP($A18,ALGLIB_SSA_XAUUSD!$AA$2:$AA$2401,ALGLIB_SSA_XAUUSD!$P$2:$P$2401,"",0) | K18: =_xlfn.XLOOKUP($A18,ALGLIB_SSA_XAUUSD!$AA$2:$AA$2401,ALGLIB_SSA_XAUUSD!$Q$2:$Q$2401,"",0) | L18: =_xlfn.XLOOKUP($A18,ALGLIB_SSA_XAUUSD!$AA$2:$AA$2401,ALGLIB_SSA_XAUUSD!$R$2:$R$2401,"",0) | M18: =_xlfn.XLOOKUP($A18,ALGLIB_SSA_XAUUSD!$AA$2:$AA$2401,ALGLIB_SSA_XAUUSD!$S$2:$S$2401,"",0) | N18: =_xlfn.XLOOKUP($A18,ALGLIB_SSA_XAUUSD!$AA$2:$AA$2401,ALGLIB_SSA_XAUUSD!$T$2:$T$2401,"",0) | O18: =_xlfn.XLOOKUP($A18,ALGLIB_SSA_XAUUSD!$AA$2:$AA$2401,ALGLIB_SSA_XAUUSD!$U$2:$U$2401,"",0) | P18: =_xlfn.XLOOKUP($A18,ALGLIB_SSA_XAUUSD!$AA$2:$AA$2401,ALGLIB_SSA_XAUUSD!$V$2:$V$2401,"",0) | S18: =A18 | T18: =J18 | U18: =K18 | V18: =IF($A18="","",MOD(ROW()-2,12)+1) | W18: =L18 | X18: =IF(F18="","",F18) | Y18: =IF(G18="","",G18) | Z18: =M18 | AA18: =N18 | AB18: =IF(H18="","",H18) | AC18: =O18 | AD18: =IF(I18="","",I18) | AE18: =P18 | AH18: =IF(S18<>"",S18,AH17+900) | AI18: =IF(T18<>"",T18,AI17) | AJ18: =IF(U18<>"",U18,AJ17) | AK18: =IF(W18<>"",W18,"") | AL18: =IF(X18<>"",X18,"") | AM18: =IF(Y18<>"",Y18,"") | AN18: =IF(OR(AL18="",AM18=""),"",AL18-AM18) | AO18: =IF(AN18="","",IF(AN18>0,"Bullish","Bearish")) | AP18: =IF(AO18="",AP17,AO18) | AQ18: =IF(AB18<>"",AB18,"") | AR18: =IF(AD18<>"",AD18,"") | AS18: =IF(AS17+1=13,1,AS17+1) | AT18: =IFERROR(IF(SLOPE($AQ$2:$AQ$13,$AS$2:$AS$13)>0,MIN(3,ABS(SLOPE($AQ$2:$AQ$13,$AS$2:$AS$13))),IF(SLOPE($AQ$2:$AQ$13,$AS$2:$AS$13)<-0.5,-0.5,0)),0) | AU18: =IFERROR(IF(SLOPE($AR$2:$AR$13,$AS$2:$AS$13)<0,MAX(-3,-ABS(SLOPE($AR$2:$AR$13,$AS$2:$AS$13))),IF(SLOPE($AR$2:$AR$13,$AS$2:$AS$13)>0.5,0.5,0)),0) | AV18: =($AQ$14+(AT18*(AS18-1))) | AW18: =($AR$14+(AU18*(AS18-1))) | AX18: =IF(AT18>0,AV18+AT18,AV18) | AY18: =IF(AU18<0,AW18+AU18,AW18) | BA18: =IFERROR(AX18-AQ18,"") | BB18: =IFERROR(AY18-AR18,"") | BD18: =AH18 | BE18: =AI18 | BF18: =AJ18 | BG18: =L18 | BH18: =IF(X18="","",X18) | BI18: =IF(Y18="","",Y18) | BJ18: =Z18 | BK18: =AA18 | BL18: =IFERROR(AX18,"") | BM18: =IFERROR(AY18,"")
A19: =ALGLIB_SSA_XAUUSD!AA19 | B19: =IF($A19="","",INDEX(ALGLIB_SSA_XAUUSD!$B$2:$B$2401,MATCH($A19,ALGLIB_SSA_XAUUSD!$A$2:$A$2401,1))) | C19: =IF($A19="","",INDEX(ALGLIB_SSA_XAUUSD!$C$2:$C$2401,MATCH($A19,ALGLIB_SSA_XAUUSD!$A$2:$A$2401,1))) | D19: =IF($A19="","",INT((ROW()-2)/12)+1) | E19: =IF(AND(E26<>"",D26=D14+1),E14+(E26-E14)*5/12,"") | F19: =IF(AND(F26<>"",D26=D14+1),F14+(F26-F14)*5/12,"") | G19: =IF(AND(G26<>"",D26=D14+1),G14+(G26-G14)*5/12,"") | H19: =IF(AND(H26<>"",D26=D14+1),H14+(H26-H14)*5/12,"") | I19: =IF(AND(L26<>"",D26=D14+1),I14+(I26-I14)*5/12,"") | J19: =_xlfn.XLOOKUP($A19,ALGLIB_SSA_XAUUSD!$AA$2:$AA$2401,ALGLIB_SSA_XAUUSD!$P$2:$P$2401,"",0) | K19: =_xlfn.XLOOKUP($A19,ALGLIB_SSA_XAUUSD!$AA$2:$AA$2401,ALGLIB_SSA_XAUUSD!$Q$2:$Q$2401,"",0) | L19: =_xlfn.XLOOKUP($A19,ALGLIB_SSA_XAUUSD!$AA$2:$AA$2401,ALGLIB_SSA_XAUUSD!$R$2:$R$2401,"",0) | M19: =_xlfn.XLOOKUP($A19,ALGLIB_SSA_XAUUSD!$AA$2:$AA$2401,ALGLIB_SSA_XAUUSD!$S$2:$S$2401,"",0) | N19: =_xlfn.XLOOKUP($A19,ALGLIB_SSA_XAUUSD!$AA$2:$AA$2401,ALGLIB_SSA_XAUUSD!$T$2:$T$2401,"",0) | O19: =_xlfn.XLOOKUP($A19,ALGLIB_SSA_XAUUSD!$AA$2:$AA$2401,ALGLIB_SSA_XAUUSD!$U$2:$U$2401,"",0) | P19: =_xlfn.XLOOKUP($A19,ALGLIB_SSA_XAUUSD!$AA$2:$AA$2401,ALGLIB_SSA_XAUUSD!$V$2:$V$2401,"",0) | S19: =A19 | T19: =J19 | U19: =K19 | V19: =IF($A19="","",MOD(ROW()-2,12)+1) | W19: =L19 | X19: =IF(F19="","",F19) | Y19: =IF(G19="","",G19) | Z19: =M19 | AA19: =N19 | AB19: =IF(H19="","",H19) | AC19: =O19 | AD19: =IF(I19="","",I19) | AE19: =P19 | AH19: =IF(S19<>"",S19,AH18+900) | AI19: =IF(T19<>"",T19,AI18) | AJ19: =IF(U19<>"",U19,AJ18) | AK19: =IF(W19<>"",W19,"") | AL19: =IF(X19<>"",X19,"") | AM19: =IF(Y19<>"",Y19,"") | AN19: =IF(OR(AL19="",AM19=""),"",AL19-AM19) | AO19: =IF(AN19="","",IF(AN19>0,"Bullish","Bearish")) | AP19: =IF(AO19="",AP18,AO19) | AQ19: =IF(AB19<>"",AB19,"") | AR19: =IF(AD19<>"",AD19,"") | AS19: =IF(AS18+1=13,1,AS18+1) | AT19: =IFERROR(IF(SLOPE($AQ$2:$AQ$13,$AS$2:$AS$13)>0,MIN(3,ABS(SLOPE($AQ$2:$AQ$13,$AS$2:$AS$13))),IF(SLOPE($AQ$2:$AQ$13,$AS$2:$AS$13)<-0.5,-0.5,0)),0) | AU19: =IFERROR(IF(SLOPE($AR$2:$AR$13,$AS$2:$AS$13)<0,MAX(-3,-ABS(SLOPE($AR$2:$AR$13,$AS$2:$AS$13))),IF(SLOPE($AR$2:$AR$13,$AS$2:$AS$13)>0.5,0.5,0)),0) | AV19: =($AQ$14+(AT19*(AS19-1))) | AW19: =($AR$14+(AU19*(AS19-1))) | AX19: =IF(AT19>0,AV19+AT19,AV19) | AY19: =IF(AU19<0,AW19+AU19,AW19) | BA19: =IFERROR(AX19-AQ19,"") | BB19: =IFERROR(AY19-AR19,"") | BD19: =AH19 | BE19: =AI19 | BF19: =AJ19 | BG19: =L19 | BH19: =IF(X19="","",X19) | BI19: =IF(Y19="","",Y19) | BJ19: =Z19 | BK19: =AA19 | BL19: =IFERROR(AX19,"") | BM19: =IFERROR(AY19,"")
A20: =ALGLIB_SSA_XAUUSD!AA20 | B20: =IF($A20="","",INDEX(ALGLIB_SSA_XAUUSD!$B$2:$B$2401,MATCH($A20,ALGLIB_SSA_XAUUSD!$A$2:$A$2401,1))) | C20: =IF($A20="","",INDEX(ALGLIB_SSA_XAUUSD!$C$2:$C$2401,MATCH($A20,ALGLIB_SSA_XAUUSD!$A$2:$A$2401,1))) | D20: =IF($A20="","",INT((ROW()-2)/12)+1) | E20: =IF(AND(E26<>"",D26=D14+1),E14+(E26-E14)*6/12,"") | F20: =IF(AND(F26<>"",D26=D14+1),F14+(F26-F14)*6/12,"") | G20: =IF(AND(G26<>"",D26=D14+1),G14+(G26-G14)*6/12,"") | H20: =IF(AND(H26<>"",D26=D14+1),H14+(H26-H14)*6/12,"") | I20: =IF(AND(L26<>"",D26=D14+1),I14+(I26-I14)*6/12,"") | J20: =_xlfn.XLOOKUP($A20,ALGLIB_SSA_XAUUSD!$AA$2:$AA$2401,ALGLIB_SSA_XAUUSD!$P$2:$P$2401,"",0) | K20: =_xlfn.XLOOKUP($A20,ALGLIB_SSA_XAUUSD!$AA$2:$AA$2401,ALGLIB_SSA_XAUUSD!$Q$2:$Q$2401,"",0) | L20: =_xlfn.XLOOKUP($A20,ALGLIB_SSA_XAUUSD!$AA$2:$AA$2401,ALGLIB_SSA_XAUUSD!$R$2:$R$2401,"",0) | M20: =_xlfn.XLOOKUP($A20,ALGLIB_SSA_XAUUSD!$AA$2:$AA$2401,ALGLIB_SSA_XAUUSD!$S$2:$S$2401,"",0) | N20: =_xlfn.XLOOKUP($A20,ALGLIB_SSA_XAUUSD!$AA$2:$AA$2401,ALGLIB_SSA_XAUUSD!$T$2:$T$2401,"",0) | O20: =_xlfn.XLOOKUP($A20,ALGLIB_SSA_XAUUSD!$AA$2:$AA$2401,ALGLIB_SSA_XAUUSD!$U$2:$U$2401,"",0) | P20: =_xlfn.XLOOKUP($A20,ALGLIB_SSA_XAUUSD!$AA$2:$AA$2401,ALGLIB_SSA_XAUUSD!$V$2:$V$2401,"",0) | S20: =A20 | T20: =J20 | U20: =K20 | V20: =IF($A20="","",MOD(ROW()-2,12)+1) | W20: =L20 | X20: =IF(F20="","",F20) | Y20: =IF(G20="","",G20) | Z20: =M20 | AA20: =N20 | AB20: =IF(H20="","",H20) | AC20: =O20 | AD20: =IF(I20="","",I20) | AE20: =P20 | AH20: =IF(S20<>"",S20,AH19+900) | AI20: =IF(T20<>"",T20,AI19) | AJ20: =IF(U20<>"",U20,AJ19) | AK20: =IF(W20<>"",W20,"") | AL20: =IF(X20<>"",X20,"") | AM20: =IF(Y20<>"",Y20,"") | AN20: =IF(OR(AL20="",AM20=""),"",AL20-AM20) | AO20: =IF(AN20="","",IF(AN20>0,"Bullish","Bearish")) | AP20: =IF(AO20="",AP19,AO20) | AQ20: =IF(AB20<>"",AB20,"") | AR20: =IF(AD20<>"",AD20,"") | AS20: =IF(AS19+1=13,1,AS19+1) | AT20: =IFERROR(IF(SLOPE($AQ$2:$AQ$13,$AS$2:$AS$13)>0,MIN(3,ABS(SLOPE($AQ$2:$AQ$13,$AS$2:$AS$13))),IF(SLOPE($AQ$2:$AQ$13,$AS$2:$AS$13)<-0.5,-0.5,0)),0) | AU20: =IFERROR(IF(SLOPE($AR$2:$AR$13,$AS$2:$AS$13)<0,MAX(-3,-ABS(SLOPE($AR$2:$AR$13,$AS$2:$AS$13))),IF(SLOPE($AR$2:$AR$13,$AS$2:$AS$13)>0.5,0.5,0)),0) | AV20: =($AQ$14+(AT20*(AS20-1))) | AW20: =($AR$14+(AU20*(AS20-1))) | AX20: =IF(AT20>0,AV20+AT20,AV20) | AY20: =IF(AU20<0,AW20+AU20,AW20) | BA20: =IFERROR(AX20-AQ20,"") | BB20: =IFERROR(AY20-AR20,"") | BD20: =AH20 | BE20: =AI20 | BF20: =AJ20 | BG20: =L20 | BH20: =IF(X20="","",X20) | BI20: =IF(Y20="","",Y20) | BJ20: =Z20 | BK20: =AA20 | BL20: =IFERROR(AX20,"") | BM20: =IFERROR(AY20,"")
A21: =ALGLIB_SSA_XAUUSD!AA21 | B21: =IF($A21="","",INDEX(ALGLIB_SSA_XAUUSD!$B$2:$B$2401,MATCH($A21,ALGLIB_SSA_XAUUSD!$A$2:$A$2401,1))) | C21: =IF($A21="","",INDEX(ALGLIB_SSA_XAUUSD!$C$2:$C$2401,MATCH($A21,ALGLIB_SSA_XAUUSD!$A$2:$A$2401,1))) | D21: =IF($A21="","",INT((ROW()-2)/12)+1) | E21: =IF(AND(E26<>"",D26=D14+1),E14+(E26-E14)*7/12,"") | F21: =IF(AND(F26<>"",D26=D14+1),F14+(F26-F14)*7/12,"") | G21: =IF(AND(G26<>"",D26=D14+1),G14+(G26-G14)*7/12,"") | H21: =IF(AND(H26<>"",D26=D14+1),H14+(H26-H14)*7/12,"") | I21: =IF(AND(L26<>"",D26=D14+1),I14+(I26-I14)*7/12,"") | J21: =_xlfn.XLOOKUP($A21,ALGLIB_SSA_XAUUSD!$AA$2:$AA$2401,ALGLIB_SSA_XAUUSD!$P$2:$P$2401,"",0) | K21: =_xlfn.XLOOKUP($A21,ALGLIB_SSA_XAUUSD!$AA$2:$AA$2401,ALGLIB_SSA_XAUUSD!$Q$2:$Q$2401,"",0) | L21: =_xlfn.XLOOKUP($A21,ALGLIB_SSA_XAUUSD!$AA$2:$AA$2401,ALGLIB_SSA_XAUUSD!$R$2:$R$2401,"",0) | M21: =_xlfn.XLOOKUP($A21,ALGLIB_SSA_XAUUSD!$AA$2:$AA$2401,ALGLIB_SSA_XAUUSD!$S$2:$S$2401,"",0) | N21: =_xlfn.XLOOKUP($A21,ALGLIB_SSA_XAUUSD!$AA$2:$AA$2401,ALGLIB_SSA_XAUUSD!$T$2:$T$2401,"",0) | O21: =_xlfn.XLOOKUP($A21,ALGLIB_SSA_XAUUSD!$AA$2:$AA$2401,ALGLIB_SSA_XAUUSD!$U$2:$U$2401,"",0) | P21: =_xlfn.XLOOKUP($A21,ALGLIB_SSA_XAUUSD!$AA$2:$AA$2401,ALGLIB_SSA_XAUUSD!$V$2:$V$2401,"",0) | S21: =A21 | T21: =J21 | U21: =K21 | V21: =IF($A21="","",MOD(ROW()-2,12)+1) | W21: =L21 | X21: =IF(F21="","",F21) | Y21: =IF(G21="","",G21) | Z21: =M21 | AA21: =N21 | AB21: =IF(H21="","",H21) | AC21: =O21 | AD21: =IF(I21="","",I21) | AE21: =P21 | AH21: =IF(S21<>"",S21,AH20+900) | AI21: =IF(T21<>"",T21,AI20) | AJ21: =IF(U21<>"",U21,AJ20) | AK21: =IF(W21<>"",W21,"") | AL21: =IF(X21<>"",X21,"") | AM21: =IF(Y21<>"",Y21,"") | AN21: =IF(OR(AL21="",AM21=""),"",AL21-AM21) | AO21: =IF(AN21="","",IF(AN21>0,"Bullish","Bearish")) | AP21: =IF(AO21="",AP20,AO21) | AQ21: =IF(AB21<>"",AB21,"") | AR21: =IF(AD21<>"",AD21,"") | AS21: =IF(AS20+1=13,1,AS20+1) | AT21: =IFERROR(IF(SLOPE($AQ$2:$AQ$13,$AS$2:$AS$13)>0,MIN(3,ABS(SLOPE($AQ$2:$AQ$13,$AS$2:$AS$13))),IF(SLOPE($AQ$2:$AQ$13,$AS$2:$AS$13)<-0.5,-0.5,0)),0) | AU21: =IFERROR(IF(SLOPE($AR$2:$AR$13,$AS$2:$AS$13)<0,MAX(-3,-ABS(SLOPE($AR$2:$AR$13,$AS$2:$AS$13))),IF(SLOPE($AR$2:$AR$13,$AS$2:$AS$13)>0.5,0.5,0)),0) | AV21: =($AQ$14+(AT21*(AS21-1))) | AW21: =($AR$14+(AU21*(AS21-1))) | AX21: =IF(AT21>0,AV21+AT21,AV21) | AY21: =IF(AU21<0,AW21+AU21,AW21) | BA21: =IFERROR(AX21-AQ21,"") | BB21: =IFERROR(AY21-AR21,"") | BD21: =AH21 | BE21: =AI21 | BF21: =AJ21 | BG21: =L21 | BH21: =IF(X21="","",X21) | BI21: =IF(Y21="","",Y21) | BJ21: =Z21 | BK21: =AA21 | BL21: =IFERROR(AX21,"") | BM21: =IFERROR(AY21,"")
A22: =ALGLIB_SSA_XAUUSD!AA22 | B22: =IF($A22="","",INDEX(ALGLIB_SSA_XAUUSD!$B$2:$B$2401,MATCH($A22,ALGLIB_SSA_XAUUSD!$A$2:$A$2401,1))) | C22: =IF($A22="","",INDEX(ALGLIB_SSA_XAUUSD!$C$2:$C$2401,MATCH($A22,ALGLIB_SSA_XAUUSD!$A$2:$A$2401,1))) | D22: =IF($A22="","",INT((ROW()-2)/12)+1) | E22: =IF(AND(E26<>"",D26=D14+1),E14+(E26-E14)*8/12,"") | F22: =IF(AND(F26<>"",D26=D14+1),F14+(F26-F14)*8/12,"") | G22: =IF(AND(G26<>"",D26=D14+1),G14+(G26-G14)*8/12,"") | H22: =IF(AND(H26<>"",D26=D14+1),H14+(H26-H14)*8/12,"") | I22: =IF(AND(L26<>"",D26=D14+1),I14+(I26-I14)*8/12,"") | J22: =_xlfn.XLOOKUP($A22,ALGLIB_SSA_XAUUSD!$AA$2:$AA$2401,ALGLIB_SSA_XAUUSD!$P$2:$P$2401,"",0) | K22: =_xlfn.XLOOKUP($A22,ALGLIB_SSA_XAUUSD!$AA$2:$AA$2401,ALGLIB_SSA_XAUUSD!$Q$2:$Q$2401,"",0) | L22: =_xlfn.XLOOKUP($A22,ALGLIB_SSA_XAUUSD!$AA$2:$AA$2401,ALGLIB_SSA_XAUUSD!$R$2:$R$2401,"",0) | M22: =_xlfn.XLOOKUP($A22,ALGLIB_SSA_XAUUSD!$AA$2:$AA$2401,ALGLIB_SSA_XAUUSD!$S$2:$S$2401,"",0) | N22: =_xlfn.XLOOKUP($A22,ALGLIB_SSA_XAUUSD!$AA$2:$AA$2401,ALGLIB_SSA_XAUUSD!$T$2:$T$2401,"",0) | O22: =_xlfn.XLOOKUP($A22,ALGLIB_SSA_XAUUSD!$AA$2:$AA$2401,ALGLIB_SSA_XAUUSD!$U$2:$U$2401,"",0) | P22: =_xlfn.XLOOKUP($A22,ALGLIB_SSA_XAUUSD!$AA$2:$AA$2401,ALGLIB_SSA_XAUUSD!$V$2:$V$2401,"",0) | S22: =A22 | T22: =J22 | U22: =K22 | V22: =IF($A22="","",MOD(ROW()-2,12)+1) | W22: =L22 | X22: =IF(F22="","",F22) | Y22: =IF(G22="","",G22) | Z22: =M22 | AA22: =N22 | AB22: =IF(H22="","",H22) | AC22: =O22 | AD22: =IF(I22="","",I22) | AE22: =P22 | AH22: =IF(S22<>"",S22,AH21+900) | AI22: =IF(T22<>"",T22,AI21) | AJ22: =IF(U22<>"",U22,AJ21) | AK22: =IF(W22<>"",W22,"") | AL22: =IF(X22<>"",X22,"") | AM22: =IF(Y22<>"",Y22,"") | AN22: =IF(OR(AL22="",AM22=""),"",AL22-AM22) | AO22: =IF(AN22="","",IF(AN22>0,"Bullish","Bearish")) | AP22: =IF(AO22="",AP21,AO22) | AQ22: =IF(AB22<>"",AB22,"") | AR22: =IF(AD22<>"",AD22,"") | AS22: =IF(AS21+1=13,1,AS21+1) | AT22: =IFERROR(IF(SLOPE($AQ$2:$AQ$13,$AS$2:$AS$13)>0,MIN(3,ABS(SLOPE($AQ$2:$AQ$13,$AS$2:$AS$13))),IF(SLOPE($AQ$2:$AQ$13,$AS$2:$AS$13)<-0.5,-0.5,0)),0) | AU22: =IFERROR(IF(SLOPE($AR$2:$AR$13,$AS$2:$AS$13)<0,MAX(-3,-ABS(SLOPE($AR$2:$AR$13,$AS$2:$AS$13))),IF(SLOPE($AR$2:$AR$13,$AS$2:$AS$13)>0.5,0.5,0)),0) | AV22: =($AQ$14+(AT22*(AS22-1))) | AW22: =($AR$14+(AU22*(AS22-1))) | AX22: =IF(AT22>0,AV22+AT22,AV22) | AY22: =IF(AU22<0,AW22+AU22,AW22) | BA22: =IFERROR(AX22-AQ22,"") | BB22: =IFERROR(AY22-AR22,"") | BD22: =AH22 | BE22: =AI22 | BF22: =AJ22 | BG22: =L22 | BH22: =IF(X22="","",X22) | BI22: =IF(Y22="","",Y22) | BJ22: =Z22 | BK22: =AA22 | BL22: =IFERROR(AX22,"") | BM22: =IFERROR(AY22,"")
