Workbook

Sheet Price
A1: timestamp | B1: symbol | C1: timeframe | D1: close | E1: open | F1: high | G1: low | H1: volume | J1: convert_to_readable_datetime | K1: round_to_nearest_datetime_5m | L1: timestamp_adjusted
A2: 1772024998 | B2: XAUUSD | C2: M5 | D2: 5187.2 | E2: 5188.44 | F2: 5189.22 | G2: 5185.5 | H2: 567 | J2: =(A2/86400)+25569 -> 46078.549 | K2: =CEILING(INT(J2*1440)/1440*288,1)/288 -> 46078.549 | L2: =MROUND((K2-25569)*86400,300) -> 1772025000
A3: 1772025298 | B3: XAUUSD | C3: M5 | D3: 5187 | E3: 5187.22 | F3: 5189.54 | G3: 5185.97 | H3: 574 | J3: =(A3/86400)+25569 -> 46078.552 | K3: =CEILING(INT(J3*1440)/1440*288,1)/288 -> 46078.552 | L3: =MROUND((K3-25569)*86400,300) -> 1772025300
A4: 1772025598 | B4: XAUUSD | C4: M5 | D4: 5191.13 | E4: 5186.81 | F4: 5191.47 | G4: 5186.14 | H4: 583 | J4: =(A4/86400)+25569 -> 46078.556 | K4: =CEILING(INT(J4*1440)/1440*288,1)/288 -> 46078.556 | L4: =MROUND((K4-25569)*86400,300) -> 1772025600
A5: 1772025898 | B5: XAUUSD | C5: M5 | D5: 5188.07 | E5: 5191.14 | F5: 5191.36 | G5: 5186.93 | H5: 547 | J5: =(A5/86400)+25569 -> 46078.559 | K5: =CEILING(INT(J5*1440)/1440*288,1)/288 -> 46078.559 | L5: =MROUND((K5-25569)*86400,300) -> 1772025900
A6: 1772026198 | B6: XAUUSD | C6: M5 | D6: 5188.16 | E6: 5188.07 | F6: 5190.35 | G6: 5186.62 | H6: 516 | J6: =(A6/86400)+25569 -> 46078.562 | K6: =CEILING(INT(J6*1440)/1440*288,1)/288 -> 46078.562 | L6: =MROUND((K6-25569)*86400,300) -> 1772026200
A7: 1772026498 | B7: XAUUSD | C7: M5 | D7: 5189.61 | E7: 5188.16 | F7: 5190.35 | G7: 5187.73 | H7: 524 | J7: =(A7/86400)+25569 -> 46078.566 | K7: =CEILING(INT(J7*1440)/1440*288,1)/288 -> 46078.566 | L7: =MROUND((K7-25569)*86400,300) -> 1772026500
A8: 1772026798 | B8: XAUUSD | C8: M5 | D8: 5186.84 | E8: 5189.93 | F8: 5191.33 | G8: 5182.03 | H8: 660 | J8: =(A8/86400)+25569 -> 46078.569 | K8: =CEILING(INT(J8*1440)/1440*288,1)/288 -> 46078.569 | L8: =MROUND((K8-25569)*86400,300) -> 1772026800
A9: 1772027098 | B9: XAUUSD | C9: M5 | D9: 5186.59 | E9: 5187.12 | F9: 5191.12 | G9: 5185.65 | H9: 585 | J9: =(A9/86400)+25569 -> 46078.573 | K9: =CEILING(INT(J9*1440)/1440*288,1)/288 -> 46078.573 | L9: =MROUND((K9-25569)*86400,300) -> 1772027100
A10: 1772027398 | B10: XAUUSD | C10: M5 | D10: 5186.07 | E10: 5187.03 | F10: 5187.42 | G10: 5184.3 | H10: 628 | J10: =(A10/86400)+25569 -> 46078.576 | K10: =CEILING(INT(J10*1440)/1440*288,1)/288 -> 46078.576 | L10: =MROUND((K10-25569)*86400,300) -> 1772027400
A11: 1772027698 | B11: XAUUSD | C11: M5 | D11: 5185.23 | E11: 5186.04 | F11: 5188.5 | G11: 5184.76 | H11: 572 | J11: =(A11/86400)+25569 -> 46078.58 | K11: =CEILING(INT(J11*1440)/1440*288,1)/288 -> 46078.58 | L11: =MROUND((K11-25569)*86400,300) -> 1772027700
A12: 1772027998 | B12: XAUUSD | C12: M5 | D12: 5187.18 | E12: 5185.22 | F12: 5187.34 | G12: 5183.76 | H12: 641 | J12: =(A12/86400)+25569 -> 46078.583 | K12: =CEILING(INT(J12*1440)/1440*288,1)/288 -> 46078.583 | L12: =MROUND((K12-25569)*86400,300) -> 1772028000
A13: 1772028298 | B13: XAUUSD | C13: M5 | D13: 5189.99 | E13: 5187.18 | F13: 5191.07 | G13: 5186.8 | H13: 582 | J13: =(A13/86400)+25569 -> 46078.587 | K13: =CEILING(INT(J13*1440)/1440*288,1)/288 -> 46078.587 | L13: =MROUND((K13-25569)*86400,300) -> 1772028300
... A501: 1772181898 | B501: XAUUSD | C501: M5 | D501: 5181.66 | E501: 5180.32 | F501: 5182.14 | G501: 5179.99 | H501: 92 | J501: =(A501/86400)+25569 -> 46080.365 | K501: =CEILING(INT(J501*1440)/1440*288,1)/288 -> 46080.365 | L501: =MROUND((K501-25569)*86400,300) -> 1772181900

Sheet Diagonals
A1: timestamp | B1: symbol | C1: timeframe | D1: close | E1: diag_asc_line_1 | F1: diag_asc_line_2 | G1: diag_asc_line_3 | H1: diag_desc_line_1 | I1: diag_desc_line_2 | J1: diag_desc_line_3 | K1: diag_high_map | L1: diag_low_map | O1: convert_to_readable_datetime | P1: round_to_nearest_datetime_5m | Q1: timestamp_adjusted
A2: 1772024998 | B2: XAUUSD | C2: M5 | D2: 5187.2 | K2: 0 | L2: 0 | O2: =(A2/86400)+25569 -> 46078.549 | P2: =CEILING(INT(O2*1440)/1440*288,1)/288 -> 46078.549 | Q2: =MROUND((P2-25569)*86400,300) -> 1772025000
A3: 1772025298 | B3: XAUUSD | C3: M5 | D3: 5187 | K3: 0 | L3: 0 | O3: =(A3/86400)+25569 -> 46078.552 | P3: =CEILING(INT(O3*1440)/1440*288,1)/288 -> 46078.552 | Q3: =MROUND((P3-25569)*86400,300) -> 1772025300
A4: 1772025598 | B4: XAUUSD | C4: M5 | D4: 5191.13 | K4: 5191.47 | L4: 0 | O4: =(A4/86400)+25569 -> 46078.556 | P4: =CEILING(INT(O4*1440)/1440*288,1)/288 -> 46078.556 | Q4: =MROUND((P4-25569)*86400,300) -> 1772025600
A5: 1772025898 | B5: XAUUSD | C5: M5 | D5: 5188.07 | K5: 0 | L5: 0 | O5: =(A5/86400)+25569 -> 46078.559 | P5: =CEILING(INT(O5*1440)/1440*288,1)/288 -> 46078.559 | Q5: =MROUND((P5-25569)*86400,300) -> 1772025900
A6: 1772026198 | B6: XAUUSD | C6: M5 | D6: 5188.16 | K6: 0 | L6: 0 | O6: =(A6/86400)+25569 -> 46078.562 | P6: =CEILING(INT(O6*1440)/1440*288,1)/288 -> 46078.562 | Q6: =MROUND((P6-25569)*86400,300) -> 1772026200
A7: 1772026498 | B7: XAUUSD | C7: M5 | D7: 5189.61 | K7: 0 | L7: 0 | O7: =(A7/86400)+25569 -> 46078.566 | P7: =CEILING(INT(O7*1440)/1440*288,1)/288 -> 46078.566 | Q7: =MROUND((P7-25569)*86400,300) -> 1772026500
A8: 1772026798 | B8: XAUUSD | C8: M5 | D8: 5186.84 | K8: 0 | L8: 0 | O8: =(A8/86400)+25569 -> 46078.569 | P8: =CEILING(INT(O8*1440)/1440*288,1)/288 -> 46078.569 | Q8: =MROUND((P8-25569)*86400,300) -> 1772026800
A9: 1772027098 | B9: XAUUSD | C9: M5 | D9: 5186.59 | K9: 0 | L9: 0 | O9: =(A9/86400)+25569 -> 46078.573 | P9: =CEILING(INT(O9*1440)/1440*288,1)/288 -> 46078.573 | Q9: =MROUND((P9-25569)*86400,300) -> 1772027100
A10: 1772027398 | B10: XAUUSD | C10: M5 | D10: 5186.07 | K10: 0 | L10: 0 | O10: =(A10/86400)+25569 -> 46078.576 | P10: =CEILING(INT(O10*1440)/1440*288,1)/288 -> 46078.576 | Q10: =MROUND((P10-25569)*86400,300) -> 1772027400
A11: 1772027698 | B11: XAUUSD | C11: M5 | D11: 5185.23 | K11: 0 | L11: 0 | O11: =(A11/86400)+25569 -> 46078.58 | P11: =CEILING(INT(O11*1440)/1440*288,1)/288 -> 46078.58 | Q11: =MROUND((P11-25569)*86400,300) -> 1772027700
A12: 1772027998 | B12: XAUUSD | C12: M5 | D12: 5187.18 | K12: 0 | L12: 0 | O12: =(A12/86400)+25569 -> 46078.583 | P12: =CEILING(INT(O12*1440)/1440*288,1)/288 -> 46078.583 | Q12: =MROUND((P12-25569)*86400,300) -> 1772028000
A13: 1772028298 | B13: XAUUSD | C13: M5 | D13: 5189.99 | K13: 0 | L13: 0 | O13: =(A13/86400)+25569 -> 46078.587 | P13: =CEILING(INT(O13*1440)/1440*288,1)/288 -> 46078.587 | Q13: =MROUND((P13-25569)*86400,300) -> 1772028300
... A131: 1772067298 | B131: XAUUSD | C131: M5 | D131: 5188.31 | K131: 0 | L131: 0 | O131: =(A131/86400)+25569 -> 46079.038 | P131: =CEILING(INT(O131*1440)/1440*288,1)/288 -> 46079.038 | Q131: =MROUND((P131-25569)*86400,300) -> 1772067300
A132: 1772067598 | B132: XAUUSD | C132: M5 | D132: 5194.75 | H132: 5198.49 | K132: 5198.49 | L132: 0 | O132: =(A132/86400)+25569 -> 46079.042 | P132: =CEILING(INT(O132*1440)/1440*288,1)/288 -> 46079.042 | Q132: =MROUND((P132-25569)*86400,300) -> 1772067600
A133: 1772067898 | B133: XAUUSD | C133: M5 | D133: 5183.93 | H133: 5198.16 | K133: 0 | L133: 0 | O133: =(A133/86400)+25569 -> 46079.045 | P133: =CEILING(INT(O133*1440)/1440*288,1)/288 -> 46079.045 | Q133: =MROUND((P133-25569)*86400,300) -> 1772067900
A134: 1772068198 | B134: XAUUSD | C134: M5 | D134: 5187.53 | H134: 5197.83 | K134: 0 | L134: 0 | O134: =(A134/86400)+25569 -> 46079.049 | P134: =CEILING(INT(O134*1440)/1440*288,1)/288 -> 46079.049 | Q134: =MROUND((P134-25569)*86400,300) -> 1772068200
A135: 1772068498 | B135: XAUUSD | C135: M5 | D135: 5189.46 | H135: 5197.5 | K135: 0 | L135: 0 | O135: =(A135/86400)+25569 -> 46079.052 | P135: =CEILING(INT(O135*1440)/1440*288,1)/288 -> 46079.052 | Q135: =MROUND((P135-25569)*86400,300) -> 1772068500
A136: 1772068798 | B136: XAUUSD | C136: M5 | D136: 5186.05 | H136: 5197.17 | K136: 0 | L136: 0 | O136: =(A136/86400)+25569 -> 46079.056 | P136: =CEILING(INT(O136*1440)/1440*288,1)/288 -> 46079.056 | Q136: =MROUND((P136-25569)*86400,300) -> 1772068800
A137: 1772069098 | B137: XAUUSD | C137: M5 | D137: 5180.54 | H137: 5196.85 | K137: 0 | L137: 0 | O137: =(A137/86400)+25569 -> 46079.059 | P137: =CEILING(INT(O137*1440)/1440*288,1)/288 -> 46079.059 | Q137: =MROUND((P137-25569)*86400,300) -> 1772069100
A138: 1772069398 | B138: XAUUSD | C138: M5 | D138: 5187.99 | H138: 5196.52 | K138: 0 | L138: 0 | O138: =(A138/86400)+25569 -> 46079.062 | P138: =CEILING(INT(O138*1440)/1440*288,1)/288 -> 46079.062 | Q138: =MROUND((P138-25569)*86400,300) -> 1772069400
A139: 1772069698 | B139: XAUUSD | C139: M5 | D139: 5185.42 | H139: 5196.19 | K139: 0 | L139: 0 | O139: =(A139/86400)+25569 -> 46079.066 | P139: =CEILING(INT(O139*1440)/1440*288,1)/288 -> 46079.066 | Q139: =MROUND((P139-25569)*86400,300) -> 1772069700
A140: 1772069998 | B140: XAUUSD | C140: M5 | D140: 5189.54 | H140: 5195.86 | K140: 0 | L140: 0 | O140: =(A140/86400)+25569 -> 46079.069 | P140: =CEILING(INT(O140*1440)/1440*288,1)/288 -> 46079.069 | Q140: =MROUND((P140-25569)*86400,300) -> 1772070000
A141: 1772070298 | B141: XAUUSD | C141: M5 | D141: 5189.93 | H141: 5195.53 | K141: 0 | L141: 0 | O141: =(A141/86400)+25569 -> 46079.073 | P141: =CEILING(INT(O141*1440)/1440*288,1)/288 -> 46079.073 | Q141: =MROUND((P141-25569)*86400,300) -> 1772070300
A142: 1772070598 | B142: XAUUSD | C142: M5 | D142: 5191.16 | H142: 5195.2 | K142: 0 | L142: 0 | O142: =(A142/86400)+25569 -> 46079.076 | P142: =CEILING(INT(O142*1440)/1440*288,1)/288 -> 46079.076 | Q142: =MROUND((P142-25569)*86400,300) -> 1772070600
A143: 1772070898 | B143: XAUUSD | C143: M5 | D143: 5191.71 | H143: 5194.87 | K143: 0 | L143: 0 | O143: =(A143/86400)+25569 -> 46079.08 | P143: =CEILING(INT(O143*1440)/1440*288,1)/288 -> 46079.08 | Q143: =MROUND((P143-25569)*86400,300) -> 1772070900
... A151: 1772073298 | B151: XAUUSD | C151: M5 | D151: 5180.52 | H151: 5192.24 | K151: 0 | L151: 0 | O151: =(A151/86400)+25569 -> 46079.108 | P151: =CEILING(INT(O151*1440)/1440*288,1)/288 -> 46079.108 | Q151: =MROUND((P151-25569)*86400,300) -> 1772073300
A152: 1772073598 | B152: XAUUSD | C152: M5 | D152: 5176.09 | E152: 5174.34 | H152: 5191.91 | K152: 0 | L152: 5174.34 | O152: =(A152/86400)+25569 -> 46079.111 | P152: =CEILING(INT(O152*1440)/1440*288,1)/288 -> 46079.111 | Q152: =MROUND((P152-25569)*86400,300) -> 1772073600
A153: 1772073898 | B153: XAUUSD | C153: M5 | D153: 5180.78 | E153: 5174.52 | H153: 5191.58 | K153: 0 | L153: 0 | O153: =(A153/86400)+25569 -> 46079.115 | P153: =CEILING(INT(O153*1440)/1440*288,1)/288 -> 46079.115 | Q153: =MROUND((P153-25569)*86400,300) -> 1772073900
A154: 1772074198 | B154: XAUUSD | C154: M5 | D154: 5184.69 | E154: 5174.69 | H154: 5191.26 | K154: 0 | L154: 0 | O154: =(A154/86400)+25569 -> 46079.118 | P154: =CEILING(INT(O154*1440)/1440*288,1)/288 -> 46079.118 | Q154: =MROUND((P154-25569)*86400,300) -> 1772074200
A155: 1772074498 | B155: XAUUSD | C155: M5 | D155: 5184.34 | E155: 5174.87 | H155: 5190.93 | K155: 0 | L155: 0 | O155: =(A155/86400)+25569 -> 46079.122 | P155: =CEILING(INT(O155*1440)/1440*288,1)/288 -> 46079.122 | Q155: =MROUND((P155-25569)*86400,300) -> 1772074500
A156: 1772074798 | B156: XAUUSD | C156: M5 | D156: 5187.44 | E156: 5175.05 | H156: 5190.6 | K156: 0 | L156: 0 | O156: =(A156/86400)+25569 -> 46079.125 | P156: =CEILING(INT(O156*1440)/1440*288,1)/288 -> 46079.125 | Q156: =MROUND((P156-25569)*86400,300) -> 1772074800
A157: 1772075098 | B157: XAUUSD | C157: M5 | D157: 5185.97 | E157: 5175.23 | H157: 5190.27 | K157: 0 | L157: 0 | O157: =(A157/86400)+25569 -> 46079.128 | P157: =CEILING(INT(O157*1440)/1440*288,1)/288 -> 46079.128 | Q157: =MROUND((P157-25569)*86400,300) -> 1772075100
A158: 1772075398 | B158: XAUUSD | C158: M5 | D158: 5187.26 | E158: 5175.4 | H158: 5189.94 | K158: 0 | L158: 0 | O158: =(A158/86400)+25569 -> 46079.132 | P158: =CEILING(INT(O158*1440)/1440*288,1)/288 -> 46079.132 | Q158: =MROUND((P158-25569)*86400,300) -> 1772075400
A159: 1772075698 | B159: XAUUSD | C159: M5 | D159: 5190.19 | E159: 5175.58 | H159: 5189.61 | K159: 0 | L159: 0 | O159: =(A159/86400)+25569 -> 46079.135 | P159: =CEILING(INT(O159*1440)/1440*288,1)/288 -> 46079.135 | Q159: =MROUND((P159-25569)*86400,300) -> 1772075700
A160: 1772075998 | B160: XAUUSD | C160: M5 | D160: 5191.04 | E160: 5175.76 | H160: 5189.28 | K160: 0 | L160: 0 | O160: =(A160/86400)+25569 -> 46079.139 | P160: =CEILING(INT(O160*1440)/1440*288,1)/288 -> 46079.139 | Q160: =MROUND((P160-25569)*86400,300) -> 1772076000
A161: 1772076298 | B161: XAUUSD | C161: M5 | D161: 5188.35 | E161: 5175.93 | H161: 5188.95 | K161: 0 | L161: 0 | O161: =(A161/86400)+25569 -> 46079.142 | P161: =CEILING(INT(O161*1440)/1440*288,1)/288 -> 46079.142 | Q161: =MROUND((P161-25569)*86400,300) -> 1772076300
A162: 1772076598 | B162: XAUUSD | C162: M5 | D162: 5188.56 | E162: 5176.11 | H162: 5188.63 | K162: 0 | L162: 0 | O162: =(A162/86400)+25569 -> 46079.146 | P162: =CEILING(INT(O162*1440)/1440*288,1)/288 -> 46079.146 | Q162: =MROUND((P162-25569)*86400,300) -> 1772076600
A163: 1772076898 | B163: XAUUSD | C163: M5 | D163: 5186.58 | E163: 5176.29 | H163: 5188.3 | K163: 0 | L163: 0 | O163: =(A163/86400)+25569 -> 46079.149 | P163: =CEILING(INT(O163*1440)/1440*288,1)/288 -> 46079.149 | Q163: =MROUND((P163-25569)*86400,300) -> 1772076900
... A501: 1772181898 | B501: XAUUSD | C501: M5 | D501: 5180.42 | E501: 5236.14 | H501: 5077.16 | K501: 0 | L501: 0 | O501: =(A501/86400)+25569 -> 46080.365 | P501: =CEILING(INT(O501*1440)/1440*288,1)/288 -> 46080.365 | Q501: =MROUND((P501-25569)*86400,300) -> 1772181900

Sheet Trendlines
A1: timestamp | B1: symbol | C1: timeframe | D1: close | E1: horiz_peak_line_1 | F1: horiz_peak_line_2 | G1: horiz_peak_line_3 | H1: horiz_bottom_line_1 | I1: horiz_bottom_line_2 | J1: horiz_bottom_line_3 | K1: horiz_high_map | L1: horiz_low_map | O1: convert_to_readable_datetime | P1: round_to_nearest_datetime_5m | Q1: timestamp_adjusted
A2: 1772024999 | B2: XAUUSD | C2: M5 | D2: 5187.2 | O2: =(A2/86400)+25569 -> 46078.549 | P2: =CEILING(INT(O2*1440)/1440*288,1)/288 -> 46078.549 | Q2: =MROUND((P2-25569)*86400,300) -> 1772025000
A3: 1772025299 | B3: XAUUSD | C3: M5 | D3: 5187 | O3: =(A3/86400)+25569 -> 46078.552 | P3: =CEILING(INT(O3*1440)/1440*288,1)/288 -> 46078.552 | Q3: =MROUND((P3-25569)*86400,300) -> 1772025300
A4: 1772025599 | B4: XAUUSD | C4: M5 | D4: 5191.13 | K4: 5191.47 | O4: =(A4/86400)+25569 -> 46078.556 | P4: =CEILING(INT(O4*1440)/1440*288,1)/288 -> 46078.556 | Q4: =MROUND((P4-25569)*86400,300) -> 1772025600
A5: 1772025899 | B5: XAUUSD | C5: M5 | D5: 5188.07 | O5: =(A5/86400)+25569 -> 46078.559 | P5: =CEILING(INT(O5*1440)/1440*288,1)/288 -> 46078.559 | Q5: =MROUND((P5-25569)*86400,300) -> 1772025900
A6: 1772026199 | B6: XAUUSD | C6: M5 | D6: 5188.16 | O6: =(A6/86400)+25569 -> 46078.562 | P6: =CEILING(INT(O6*1440)/1440*288,1)/288 -> 46078.562 | Q6: =MROUND((P6-25569)*86400,300) -> 1772026200
A7: 1772026499 | B7: XAUUSD | C7: M5 | D7: 5189.61 | O7: =(A7/86400)+25569 -> 46078.566 | P7: =CEILING(INT(O7*1440)/1440*288,1)/288 -> 46078.566 | Q7: =MROUND((P7-25569)*86400,300) -> 1772026500
A8: 1772026799 | B8: XAUUSD | C8: M5 | D8: 5186.84 | O8: =(A8/86400)+25569 -> 46078.569 | P8: =CEILING(INT(O8*1440)/1440*288,1)/288 -> 46078.569 | Q8: =MROUND((P8-25569)*86400,300) -> 1772026800
A9: 1772027099 | B9: XAUUSD | C9: M5 | D9: 5186.59 | O9: =(A9/86400)+25569 -> 46078.573 | P9: =CEILING(INT(O9*1440)/1440*288,1)/288 -> 46078.573 | Q9: =MROUND((P9-25569)*86400,300) -> 1772027100
A10: 1772027399 | B10: XAUUSD | C10: M5 | D10: 5186.07 | O10: =(A10/86400)+25569 -> 46078.576 | P10: =CEILING(INT(O10*1440)/1440*288,1)/288 -> 46078.576 | Q10: =MROUND((P10-25569)*86400,300) -> 1772027400
A11: 1772027699 | B11: XAUUSD | C11: M5 | D11: 5185.23 | O11: =(A11/86400)+25569 -> 46078.58 | P11: =CEILING(INT(O11*1440)/1440*288,1)/288 -> 46078.58 | Q11: =MROUND((P11-25569)*86400,300) -> 1772027700
A12: 1772027999 | B12: XAUUSD | C12: M5 | D12: 5187.18 | O12: =(A12/86400)+25569 -> 46078.583 | P12: =CEILING(INT(O12*1440)/1440*288,1)/288 -> 46078.583 | Q12: =MROUND((P12-25569)*86400,300) -> 1772028000
A13: 1772028299 | B13: XAUUSD | C13: M5 | D13: 5189.99 | O13: =(A13/86400)+25569 -> 46078.587 | P13: =CEILING(INT(O13*1440)/1440*288,1)/288 -> 46078.587 | Q13: =MROUND((P13-25569)*86400,300) -> 1772028300
A14: 1772028599 | B14: XAUUSD | C14: M5 | D14: 5185.44 | O14: =(A14/86400)+25569 -> 46078.59 | P14: =CEILING(INT(O14*1440)/1440*288,1)/288 -> 46078.59 | Q14: =MROUND((P14-25569)*86400,300) -> 1772028600
A15: 1772028899 | B15: XAUUSD | C15: M5 | D15: 5182.68 | O15: =(A15/86400)+25569 -> 46078.594 | P15: =CEILING(INT(O15*1440)/1440*288,1)/288 -> 46078.594 | Q15: =MROUND((P15-25569)*86400,300) -> 1772028900
A16: 1772029199 | B16: XAUUSD | C16: M5 | D16: 5181.49 | O16: =(A16/86400)+25569 -> 46078.597 | P16: =CEILING(INT(O16*1440)/1440*288,1)/288 -> 46078.597 | Q16: =MROUND((P16-25569)*86400,300) -> 1772029200
... A18: 1772029799 | B18: XAUUSD | C18: M5 | D18: 5174.14 | O18: =(A18/86400)+25569 -> 46078.604 | P18: =CEILING(INT(O18*1440)/1440*288,1)/288 -> 46078.604 | Q18: =MROUND((P18-25569)*86400,300) -> 1772029800
A19: 1772030099 | B19: XAUUSD | C19: M5 | D19: 5159.73 | L19: 5158.94 | O19: =(A19/86400)+25569 -> 46078.608 | P19: =CEILING(INT(O19*1440)/1440*288,1)/288 -> 46078.608 | Q19: =MROUND((P19-25569)*86400,300) -> 1772030100
A20: 1772030399 | B20: XAUUSD | C20: M5 | D20: 5174.91 | O20: =(A20/86400)+25569 -> 46078.611 | P20: =CEILING(INT(O20*1440)/1440*288,1)/288 -> 46078.611 | Q20: =MROUND((P20-25569)*86400,300) -> 1772030400
A21: 1772030699 | B21: XAUUSD | C21: M5 | D21: 5181.79 | O21: =(A21/86400)+25569 -> 46078.615 | P21: =CEILING(INT(O21*1440)/1440*288,1)/288 -> 46078.615 | Q21: =MROUND((P21-25569)*86400,300) -> 1772030700
A22: 1772030999 | B22: XAUUSD | C22: M5 | D22: 5188.55 | O22: =(A22/86400)+25569 -> 46078.618 | P22: =CEILING(INT(O22*1440)/1440*288,1)/288 -> 46078.618 | Q22: =MROUND((P22-25569)*86400,300) -> 1772031000
A23: 1772031299 | B23: XAUUSD | C23: M5 | D23: 5191.25 | O23: =(A23/86400)+25569 -> 46078.622 | P23: =CEILING(INT(O23*1440)/1440*288,1)/288 -> 46078.622 | Q23: =MROUND((P23-25569)*86400,300) -> 1772031300
A24: 1772031599 | B24: XAUUSD | C24: M5 | D24: 5198.64 | O24: =(A24/86400)+25569 -> 46078.625 | P24: =CEILING(INT(O24*1440)/1440*288,1)/288 -> 46078.625 | Q24: =MROUND((P24-25569)*86400,300) -> 1772031600
A25: 1772031899 | B25: XAUUSD | C25: M5 | D25: 5195.89 | O25: =(A25/86400)+25569 -> 46078.628 | P25: =CEILING(INT(O25*1440)/1440*288,1)/288 -> 46078.628 | Q25: =MROUND((P25-25569)*86400,300) -> 1772031900
A26: 1772032199 | B26: XAUUSD | C26: M5 | D26: 5193.17 | O26: =(A26/86400)+25569 -> 46078.632 | P26: =CEILING(INT(O26*1440)/1440*288,1)/288 -> 46078.632 | Q26: =MROUND((P26-25569)*86400,300) -> 1772032200
A27: 1772032499 | B27: XAUUSD | C27: M5 | D27: 5188.97 | O27: =(A27/86400)+25569 -> 46078.635 | P27: =CEILING(INT(O27*1440)/1440*288,1)/288 -> 46078.635 | Q27: =MROUND((P27-25569)*86400,300) -> 1772032500
A28: 1772032799 | B28: XAUUSD | C28: M5 | D28: 5185.46 | O28: =(A28/86400)+25569 -> 46078.639 | P28: =CEILING(INT(O28*1440)/1440*288,1)/288 -> 46078.639 | Q28: =MROUND((P28-25569)*86400,300) -> 1772032800
A29: 1772033099 | B29: XAUUSD | C29: M5 | D29: 5180.33 | O29: =(A29/86400)+25569 -> 46078.642 | P29: =CEILING(INT(O29*1440)/1440*288,1)/288 -> 46078.642 | Q29: =MROUND((P29-25569)*86400,300) -> 1772033100
A30: 1772033399 | B30: XAUUSD | C30: M5 | D30: 5181.68 | O30: =(A30/86400)+25569 -> 46078.646 | P30: =CEILING(INT(O30*1440)/1440*288,1)/288 -> 46078.646 | Q30: =MROUND((P30-25569)*86400,300) -> 1772033400
A31: 1772033699 | B31: XAUUSD | C31: M5 | D31: 5187.95 | O31: =(A31/86400)+25569 -> 46078.649 | P31: =CEILING(INT(O31*1440)/1440*288,1)/288 -> 46078.649 | Q31: =MROUND((P31-25569)*86400,300) -> 1772033700
... A49: 1772039099 | B49: XAUUSD | C49: M5 | D49: 5214.69 | O49: =(A49/86400)+25569 -> 46078.712 | P49: =CEILING(INT(O49*1440)/1440*288,1)/288 -> 46078.712 | Q49: =MROUND((P49-25569)*86400,300) -> 1772039100
A50: 1772039399 | B50: XAUUSD | C50: M5 | D50: 5215.17 | K50: 5217.63 | O50: =(A50/86400)+25569 -> 46078.715 | P50: =CEILING(INT(O50*1440)/1440*288,1)/288 -> 46078.715 | Q50: =MROUND((P50-25569)*86400,300) -> 1772039400
A51: 1772039699 | B51: XAUUSD | C51: M5 | D51: 5214.53 | O51: =(A51/86400)+25569 -> 46078.719 | P51: =CEILING(INT(O51*1440)/1440*288,1)/288 -> 46078.719 | Q51: =MROUND((P51-25569)*86400,300) -> 1772039700
A52: 1772039999 | B52: XAUUSD | C52: M5 | D52: 5213.27 | O52: =(A52/86400)+25569 -> 46078.722 | P52: =CEILING(INT(O52*1440)/1440*288,1)/288 -> 46078.722 | Q52: =MROUND((P52-25569)*86400,300) -> 1772040000
A53: 1772040299 | B53: XAUUSD | C53: M5 | D53: 5213.1 | O53: =(A53/86400)+25569 -> 46078.726 | P53: =CEILING(INT(O53*1440)/1440*288,1)/288 -> 46078.726 | Q53: =MROUND((P53-25569)*86400,300) -> 1772040300
A54: 1772040599 | B54: XAUUSD | C54: M5 | D54: 5211.85 | O54: =(A54/86400)+25569 -> 46078.729 | P54: =CEILING(INT(O54*1440)/1440*288,1)/288 -> 46078.729 | Q54: =MROUND((P54-25569)*86400,300) -> 1772040600
A55: 1772040899 | B55: XAUUSD | C55: M5 | D55: 5213.17 | O55: =(A55/86400)+25569 -> 46078.733 | P55: =CEILING(INT(O55*1440)/1440*288,1)/288 -> 46078.733 | Q55: =MROUND((P55-25569)*86400,300) -> 1772040900
A56: 1772041199 | B56: XAUUSD | C56: M5 | D56: 5208.33 | O56: =(A56/86400)+25569 -> 46078.736 | P56: =CEILING(INT(O56*1440)/1440*288,1)/288 -> 46078.736 | Q56: =MROUND((P56-25569)*86400,300) -> 1772041200
A57: 1772041499 | B57: XAUUSD | C57: M5 | D57: 5206.71 | O57: =(A57/86400)+25569 -> 46078.74 | P57: =CEILING(INT(O57*1440)/1440*288,1)/288 -> 46078.74 | Q57: =MROUND((P57-25569)*86400,300) -> 1772041500
A58: 1772041799 | B58: XAUUSD | C58: M5 | D58: 5206.32 | O58: =(A58/86400)+25569 -> 46078.743 | P58: =CEILING(INT(O58*1440)/1440*288,1)/288 -> 46078.743 | Q58: =MROUND((P58-25569)*86400,300) -> 1772041800
...

Sheet Tema_Hrma_Smma
A1: timestamp | B1: symbol | C1: timeframe | D1: close | E1: tema | F1: hrma | G1: smma | I1: convert_to_readable_datetime | J1: round_to_nearest_datetime_5m | K1: timestamp_adjusted
A2: 1772024999 | B2: XAUUSD | C2: M5 | D2: 5187.2 | E2: 5186.65 | F2: 5185.18 | G2: 5181.39 | I2: =(A2/86400)+25569 -> 46078.549 | J2: =CEILING(INT(I2*1440)/1440*288,1)/288 -> 46078.549 | K2: =MROUND((J2-25569)*86400,300) -> 1772025000
A3: 1772025299 | B3: XAUUSD | C3: M5 | D3: 5187 | E3: 5187.4 | F3: 5185.92 | G3: 5181.56 | I3: =(A3/86400)+25569 -> 46078.552 | J3: =CEILING(INT(I3*1440)/1440*288,1)/288 -> 46078.552 | K3: =MROUND((J3-25569)*86400,300) -> 1772025300
A4: 1772025599 | B4: XAUUSD | C4: M5 | D4: 5191.13 | E4: 5188.81 | F4: 5186.82 | G4: 5181.75 | I4: =(A4/86400)+25569 -> 46078.556 | J4: =CEILING(INT(I4*1440)/1440*288,1)/288 -> 46078.556 | K4: =MROUND((J4-25569)*86400,300) -> 1772025600
A5: 1772025899 | B5: XAUUSD | C5: M5 | D5: 5188.07 | E5: 5189.24 | F5: 5187.61 | G5: 5181.96 | I5: =(A5/86400)+25569 -> 46078.559 | J5: =CEILING(INT(I5*1440)/1440*288,1)/288 -> 46078.559 | K5: =MROUND((J5-25569)*86400,300) -> 1772025900
A6: 1772026199 | B6: XAUUSD | C6: M5 | D6: 5188.16 | E6: 5189.22 | F6: 5188.22 | G6: 5182.14 | I6: =(A6/86400)+25569 -> 46078.562 | J6: =CEILING(INT(I6*1440)/1440*288,1)/288 -> 46078.562 | K6: =MROUND((J6-25569)*86400,300) -> 1772026200
A7: 1772026499 | B7: XAUUSD | C7: M5 | D7: 5189.61 | E7: 5189.54 | F7: 5188.77 | G7: 5182.33 | I7: =(A7/86400)+25569 -> 46078.566 | J7: =CEILING(INT(I7*1440)/1440*288,1)/288 -> 46078.566 | K7: =MROUND((J7-25569)*86400,300) -> 1772026500
A8: 1772026799 | B8: XAUUSD | C8: M5 | D8: 5186.84 | E8: 5188.45 | F8: 5188.96 | G8: 5182.49 | I8: =(A8/86400)+25569 -> 46078.569 | J8: =CEILING(INT(I8*1440)/1440*288,1)/288 -> 46078.569 | K8: =MROUND((J8-25569)*86400,300) -> 1772026800
A9: 1772027099 | B9: XAUUSD | C9: M5 | D9: 5186.59 | E9: 5188.21 | F9: 5189.06 | G9: 5182.62 | I9: =(A9/86400)+25569 -> 46078.573 | J9: =CEILING(INT(I9*1440)/1440*288,1)/288 -> 46078.573 | K9: =MROUND((J9-25569)*86400,300) -> 1772027100
A10: 1772027399 | B10: XAUUSD | C10: M5 | D10: 5186.07 | E10: 5187.12 | F10: 5188.89 | G10: 5182.74 | I10: =(A10/86400)+25569 -> 46078.576 | J10: =CEILING(INT(I10*1440)/1440*288,1)/288 -> 46078.576 | K10: =MROUND((J10-25569)*86400,300) -> 1772027400
A11: 1772027699 | B11: XAUUSD | C11: M5 | D11: 5185.23 | E11: 5186.52 | F11: 5188.62 | G11: 5182.83 | I11: =(A11/86400)+25569 -> 46078.58 | J11: =CEILING(INT(I11*1440)/1440*288,1)/288 -> 46078.58 | K11: =MROUND((J11-25569)*86400,300) -> 1772027700
A12: 1772027999 | B12: XAUUSD | C12: M5 | D12: 5187.18 | E12: 5186.12 | F12: 5188.32 | G12: 5182.92 | I12: =(A12/86400)+25569 -> 46078.583 | J12: =CEILING(INT(I12*1440)/1440*288,1)/288 -> 46078.583 | K12: =MROUND((J12-25569)*86400,300) -> 1772028000
A13: 1772028299 | B13: XAUUSD | C13: M5 | D13: 5189.99 | E13: 5187.43 | F13: 5188.38 | G13: 5183.05 | I13: =(A13/86400)+25569 -> 46078.587 | J13: =CEILING(INT(I13*1440)/1440*288,1)/288 -> 46078.587 | K13: =MROUND((J13-25569)*86400,300) -> 1772028300
... A501: 1772181899 | B501: XAUUSD | C501: M5 | D501: 5181.35 | E501: 5180.9 | F501: 5178.27 | G501: 5184.84 | I501: =(A501/86400)+25569 -> 46080.365 | J501: =CEILING(INT(I501*1440)/1440*288,1)/288 -> 46080.365 | K501: =MROUND((J501-25569)*86400,300) -> 1772181900

Sheet ZScore
A1: timestamp | B1: symbol | C1: timeframe | D1: close | E1: open | F1: high | G1: low | H1: body_direction | I1: body_size | J1: body_classification | M1: convert_to_readable_datetime | N1: round_to_nearest_datetime_5m | O1: timestamp_adjusted
A2: 1772024999 | B2: XAUUSD | C2: M5 | D2: 5187.2 | E2: 5188.44 | F2: 5189.22 | G2: 5185.5 | H2: -1 | I2: 0.67147 | J2: 3 | M2: =(A2/86400)+25569 -> 46078.549 | N2: =CEILING(INT(M2*1440)/1440*288,1)/288 -> 46078.549 | O2: =MROUND((N2-25569)*86400,300) -> 1772025000
A3: 1772025299 | B3: XAUUSD | C3: M5 | D3: 5187 | E3: 5187.22 | F3: 5189.54 | G3: 5185.97 | H3: -1 | I3: 0.97818 | J3: 3 | M3: =(A3/86400)+25569 -> 46078.552 | N3: =CEILING(INT(M3*1440)/1440*288,1)/288 -> 46078.552 | O3: =MROUND((N3-25569)*86400,300) -> 1772025300
A4: 1772025599 | B4: XAUUSD | C4: M5 | D4: 5191.13 | E4: 5186.81 | F4: 5191.47 | G4: 5186.14 | H4: 1 | I4: 0.2613 | J4: 0 | M4: =(A4/86400)+25569 -> 46078.556 | N4: =CEILING(INT(M4*1440)/1440*288,1)/288 -> 46078.556 | O4: =MROUND((N4-25569)*86400,300) -> 1772025600
A5: 1772025899 | B5: XAUUSD | C5: M5 | D5: 5188.07 | E5: 5191.14 | F5: 5191.36 | G5: 5186.93 | H5: -1 | I5: 0.11243 | J5: 3 | M5: =(A5/86400)+25569 -> 46078.559 | N5: =CEILING(INT(M5*1440)/1440*288,1)/288 -> 46078.559 | O5: =MROUND((N5-25569)*86400,300) -> 1772025900
A6: 1772026199 | B6: XAUUSD | C6: M5 | D6: 5188.16 | E6: 5188.07 | F6: 5190.35 | G6: 5186.62 | H6: 1 | I6: 1.01543 | J6: 0 | M6: =(A6/86400)+25569 -> 46078.562 | N6: =CEILING(INT(M6*1440)/1440*288,1)/288 -> 46078.562 | O6: =MROUND((N6-25569)*86400,300) -> 1772026200
A7: 1772026499 | B7: XAUUSD | C7: M5 | D7: 5189.61 | E7: 5188.16 | F7: 5190.35 | G7: 5187.73 | H7: 1 | I7: 0.60318 | J7: 0 | M7: =(A7/86400)+25569 -> 46078.566 | N7: =CEILING(INT(M7*1440)/1440*288,1)/288 -> 46078.566 | O7: =MROUND((N7-25569)*86400,300) -> 1772026500
A8: 1772026799 | B8: XAUUSD | C8: M5 | D8: 5186.84 | E8: 5189.93 | F8: 5191.33 | G8: 5182.03 | H8: -1 | I8: 0.10542 | J8: 3 | M8: =(A8/86400)+25569 -> 46078.569 | N8: =CEILING(INT(M8*1440)/1440*288,1)/288 -> 46078.569 | O8: =MROUND((N8-25569)*86400,300) -> 1772026800
A9: 1772027099 | B9: XAUUSD | C9: M5 | D9: 5186.59 | E9: 5187.12 | F9: 5191.12 | G9: 5185.65 | H9: -1 | I9: 0.88255 | J9: 3 | M9: =(A9/86400)+25569 -> 46078.573 | N9: =CEILING(INT(M9*1440)/1440*288,1)/288 -> 46078.573 | O9: =MROUND((N9-25569)*86400,300) -> 1772027100
A10: 1772027399 | B10: XAUUSD | C10: M5 | D10: 5186.07 | E10: 5187.03 | F10: 5187.42 | G10: 5184.3 | H10: -1 | I10: 0.75041 | J10: 3 | M10: =(A10/86400)+25569 -> 46078.576 | N10: =CEILING(INT(M10*1440)/1440*288,1)/288 -> 46078.576 | O10: =MROUND((N10-25569)*86400,300) -> 1772027400
A11: 1772027699 | B11: XAUUSD | C11: M5 | D11: 5185.23 | E11: 5186.04 | F11: 5188.5 | G11: 5184.76 | H11: -1 | I11: 0.79372 | J11: 3 | M11: =(A11/86400)+25569 -> 46078.58 | N11: =CEILING(INT(M11*1440)/1440*288,1)/288 -> 46078.58 | O11: =MROUND((N11-25569)*86400,300) -> 1772027700
A12: 1772027999 | B12: XAUUSD | C12: M5 | D12: 5187.18 | E12: 5185.22 | F12: 5187.34 | G12: 5183.76 | H12: 1 | I12: 0.44135 | J12: 0 | M12: =(A12/86400)+25569 -> 46078.583 | N12: =CEILING(INT(M12*1440)/1440*288,1)/288 -> 46078.583 | O12: =MROUND((N12-25569)*86400,300) -> 1772028000
A13: 1772028299 | B13: XAUUSD | C13: M5 | D13: 5189.99 | E13: 5187.18 | F13: 5191.07 | G13: 5186.8 | H13: 1 | I13: 0.18033 | J13: 0 | M13: =(A13/86400)+25569 -> 46078.587 | N13: =CEILING(INT(M13*1440)/1440*288,1)/288 -> 46078.587 | O13: =MROUND((N13-25569)*86400,300) -> 1772028300
... A501: 1772181899 | B501: XAUUSD | C501: M5 | D501: 5180.52 | E501: 5180.32 | F501: 5182.14 | G501: 5179.99 | H501: 1 | I501: 0.98364 | J501: 0 | M501: =(A501/86400)+25569 -> 46080.365 | N501: =CEILING(INT(M501*1440)/1440*288,1)/288 -> 46080.365 | O501: =MROUND((N501-25569)*86400,300) -> 1772181900

Sheet HA
A1: timestamp | B1: symbol | C1: timeframe | D1: close | E1: ha_open | F1: ha_high | G1: ha_low | H1: ha_close | I1: ha_color | J1: ha_body_size | K1: ha_body_zscore | L1: ha_trend | N1: convert_to_readable_datetime | O1: round_to_nearest_datetime_5m | P1: timestamp_adjusted
A2: 1772024998 | B2: XAUUSD | C2: M5 | D2: 5187.2 | E2: 5185.05 | F2: 5189.22 | G2: 5185.05 | H2: 5187.59 | I2: 1 | J2: 2.54 | K2: -0.27754 | L2: 1 | N2: =(A2/86400)+25569 -> 46078.549 | O2: =CEILING(INT(N2*1440)/1440*288,1)/288 -> 46078.549 | P2: =MROUND((O2-25569)*86400,300) -> 1772025000
A3: 1772025298 | B3: XAUUSD | C3: M5 | D3: 5187 | E3: 5186.32 | F3: 5189.54 | G3: 5185.97 | H3: 5187.43 | I3: 1 | J3: 1.11 | K3: -0.74682 | L3: 2 | N3: =(A3/86400)+25569 -> 46078.552 | O3: =CEILING(INT(N3*1440)/1440*288,1)/288 -> 46078.552 | P3: =MROUND((O3-25569)*86400,300) -> 1772025300
A4: 1772025598 | B4: XAUUSD | C4: M5 | D4: 5191.13 | E4: 5186.88 | F4: 5191.47 | G4: 5186.14 | H4: 5188.89 | I4: 1 | J4: 2.01 | K4: -0.4404 | L4: 3 | N4: =(A4/86400)+25569 -> 46078.556 | O4: =CEILING(INT(N4*1440)/1440*288,1)/288 -> 46078.556 | P4: =MROUND((O4-25569)*86400,300) -> 1772025600
A5: 1772025898 | B5: XAUUSD | C5: M5 | D5: 5188.07 | E5: 5187.88 | F5: 5191.36 | G5: 5186.93 | H5: 5189.38 | I5: 1 | J5: 1.49 | K5: -0.61721 | L5: 4 | N5: =(A5/86400)+25569 -> 46078.559 | O5: =CEILING(INT(N5*1440)/1440*288,1)/288 -> 46078.559 | P5: =MROUND((O5-25569)*86400,300) -> 1772025900
A6: 1772026198 | B6: XAUUSD | C6: M5 | D6: 5188.16 | E6: 5188.63 | F6: 5190.35 | G6: 5186.62 | H6: 5188.3 | I6: -1 | J6: 0.33 | K6: -1.00918 | L6: -1 | N6: =(A6/86400)+25569 -> 46078.562 | O6: =CEILING(INT(N6*1440)/1440*288,1)/288 -> 46078.562 | P6: =MROUND((O6-25569)*86400,300) -> 1772026200
A7: 1772026498 | B7: XAUUSD | C7: M5 | D7: 5189.61 | E7: 5188.46 | F7: 5190.35 | G7: 5187.73 | H7: 5188.96 | I7: 1 | J7: 0.5 | K7: -0.94748 | L7: 1 | N7: =(A7/86400)+25569 -> 46078.566 | O7: =CEILING(INT(N7*1440)/1440*288,1)/288 -> 46078.566 | P7: =MROUND((O7-25569)*86400,300) -> 1772026500
A8: 1772026798 | B8: XAUUSD | C8: M5 | D8: 5186.84 | E8: 5188.71 | F8: 5191.33 | G8: 5182.03 | H8: 5187.53 | I8: -1 | J8: 1.18 | K8: -0.71688 | L8: -1 | N8: =(A8/86400)+25569 -> 46078.569 | O8: =CEILING(INT(N8*1440)/1440*288,1)/288 -> 46078.569 | P8: =MROUND((O8-25569)*86400,300) -> 1772026800
A9: 1772027098 | B9: XAUUSD | C9: M5 | D9: 5186.59 | E9: 5188.12 | F9: 5191.12 | G9: 5185.65 | H9: 5187.62 | I9: -1 | J9: 0.5 | K9: -0.94268 | L9: -2 | N9: =(A9/86400)+25569 -> 46078.573 | O9: =CEILING(INT(N9*1440)/1440*288,1)/288 -> 46078.573 | P9: =MROUND((O9-25569)*86400,300) -> 1772027100
A10: 1772027398 | B10: XAUUSD | C10: M5 | D10: 5186.07 | E10: 5187.87 | F10: 5187.87 | G10: 5184.3 | H10: 5186.2 | I10: -1 | J10: 1.67 | K10: -0.54678 | L10: -3 | N10: =(A10/86400)+25569 -> 46078.576 | O10: =CEILING(INT(N10*1440)/1440*288,1)/288 -> 46078.576 | P10: =MROUND((O10-25569)*86400,300) -> 1772027400
A11: 1772027698 | B11: XAUUSD | C11: M5 | D11: 5185.23 | E11: 5187.04 | F11: 5188.5 | G11: 5184.76 | H11: 5186.13 | I11: -1 | J11: 0.91 | K11: -0.79817 | L11: -4 | N11: =(A11/86400)+25569 -> 46078.58 | O11: =CEILING(INT(N11*1440)/1440*288,1)/288 -> 46078.58 | P11: =MROUND((O11-25569)*86400,300) -> 1772027700
A12: 1772027998 | B12: XAUUSD | C12: M5 | D12: 5187.18 | E12: 5186.59 | F12: 5187.34 | G12: 5183.76 | H12: 5185.88 | I12: -1 | J12: 0.71 | K12: -0.86053 | L12: -5 | N12: =(A12/86400)+25569 -> 46078.583 | O12: =CEILING(INT(N12*1440)/1440*288,1)/288 -> 46078.583 | P12: =MROUND((O12-25569)*86400,300) -> 1772028000
A13: 1772028298 | B13: XAUUSD | C13: M5 | D13: 5189.99 | E13: 5186.23 | F13: 5191.07 | G13: 5186.23 | H13: 5188.76 | I13: 1 | J13: 2.53 | K13: -0.24864 | L13: 1 | N13: =(A13/86400)+25569 -> 46078.587 | O13: =CEILING(INT(N13*1440)/1440*288,1)/288 -> 46078.587 | P13: =MROUND((O13-25569)*86400,300) -> 1772028300
... A501: 1772181898 | B501: XAUUSD | C501: M5 | D501: 5180.18 | E501: 5180.07 | F501: 5182.14 | G501: 5179.99 | H501: 5180.66 | I501: 1 | J501: 0.58 | K501: -0.83989 | L501: 4 | N501: =(A501/86400)+25569 -> 46080.365 | O501: =CEILING(INT(N501*1440)/1440*288,1)/288 -> 46080.365 | P501: =MROUND((O501-25569)*86400,300) -> 1772181900

Sheet KC
A1: timestamp | B1: symbol | C1: timeframe | D1: close | E1: kc_ultra_extreme_upper | F1: kc_extreme_upper | G1: kc_uppermost | H1: kc_upper | I1: kc_upper_middle | J1: kc_lower_middle | K1: kc_lower | L1: kc_lowermost | M1: kc_extreme_lower | N1: kc_ultra_extreme_lower | P1: convert_to_readable_datetime | Q1: round_to_nearest_datetime_5m | R1: timestamp_adjusted
A2: 1772024998 | B2: XAUUSD | C2: M5 | D2: 5187.2 | E2: 5203.5649 | F2: 5197.9728 | G2: 5192.3807 | H2: 5186.7886 | I2: 5181.1965 | J2: 5176.7378 | K2: 5171.1457 | L2: 5165.5536 | M2: 5159.9615 | N2: 5154.3694 | P2: =(A2/86400)+25569 -> 46078.549 | Q2: =CEILING(INT(P2*1440)/1440*288,1)/288 -> 46078.549 | R2: =MROUND((Q2-25569)*86400,300) -> 1772025000
A3: 1772025298 | B3: XAUUSD | C3: M5 | D3: 5187 | E3: 5204.097 | F3: 5198.5184 | G3: 5192.9398 | H3: 5187.3612 | I3: 5181.7826 | J3: 5177.3726 | K3: 5171.794 | L3: 5166.2154 | M3: 5160.6368 | N3: 5155.0582 | P3: =(A3/86400)+25569 -> 46078.552 | Q3: =CEILING(INT(P3*1440)/1440*288,1)/288 -> 46078.552 | R3: =MROUND((Q3-25569)*86400,300) -> 1772025300
A4: 1772025598 | B4: XAUUSD | C4: M5 | D4: 5191.13 | E4: 5204.7919 | F4: 5199.2005 | G4: 5193.6092 | H4: 5188.0178 | I4: 5182.4264 | J4: 5178.0295 | K4: 5172.4382 | L4: 5166.8468 | M4: 5161.2555 | N4: 5155.6641 | P4: =(A4/86400)+25569 -> 46078.556 | Q4: =CEILING(INT(P4*1440)/1440*288,1)/288 -> 46078.556 | R4: =MROUND((Q4-25569)*86400,300) -> 1772025600
A5: 1772025898 | B5: XAUUSD | C5: M5 | D5: 5188.07 | E5: 5205.4578 | F5: 5199.8671 | G5: 5194.2763 | H5: 5188.6856 | I5: 5183.0949 | J5: 5178.709 | K5: 5173.1183 | L5: 5167.5275 | M5: 5161.9368 | N5: 5156.3461 | P5: =(A5/86400)+25569 -> 46078.559 | Q5: =CEILING(INT(P5*1440)/1440*288,1)/288 -> 46078.559 | R5: =MROUND((Q5-25569)*86400,300) -> 1772025900
A6: 1772026198 | B6: XAUUSD | C6: M5 | D6: 5188.16 | E6: 5205.954 | F6: 5200.4008 | G6: 5194.8476 | H6: 5189.2944 | I6: 5183.7412 | J6: 5179.3825 | K6: 5173.8293 | L6: 5168.2761 | M6: 5162.7229 | N6: 5157.1697 | P6: =(A6/86400)+25569 -> 46078.562 | Q6: =CEILING(INT(P6*1440)/1440*288,1)/288 -> 46078.562 | R6: =MROUND((Q6-25569)*86400,300) -> 1772026200
A7: 1772026498 | B7: XAUUSD | C7: M5 | D7: 5189.61 | E7: 5206.483 | F7: 5200.952 | G7: 5195.421 | H7: 5189.8901 | I7: 5184.3591 | J7: 5180.0665 | K7: 5174.5355 | L7: 5169.0045 | M7: 5163.4735 | N7: 5157.9425 | P7: =(A7/86400)+25569 -> 46078.566 | Q7: =CEILING(INT(P7*1440)/1440*288,1)/288 -> 46078.566 | R7: =MROUND((Q7-25569)*86400,300) -> 1772026500
A8: 1772026798 | B8: XAUUSD | C8: M5 | D8: 5186.84 | E8: 5207.2125 | F8: 5201.6517 | G8: 5196.091 | H8: 5190.5303 | I8: 5184.9695 | J8: 5180.5984 | K8: 5175.0376 | L8: 5169.4769 | M8: 5163.9161 | N8: 5158.3554 | P8: =(A8/86400)+25569 -> 46078.569 | Q8: =CEILING(INT(P8*1440)/1440*288,1)/288 -> 46078.569 | R8: =MROUND((Q8-25569)*86400,300) -> 1772026800
A9: 1772027098 | B9: XAUUSD | C9: M5 | D9: 5186.59 | E9: 5207.7905 | F9: 5202.2321 | G9: 5196.6737 | H9: 5191.1153 | I9: 5185.5569 | J9: 5181.1055 | K9: 5175.5471 | L9: 5169.9887 | M9: 5164.4303 | N9: 5158.8719 | P9: =(A9/86400)+25569 -> 46078.573 | Q9: =CEILING(INT(P9*1440)/1440*288,1)/288 -> 46078.573 | R9: =MROUND((Q9-25569)*86400,300) -> 1772027100
A10: 1772027398 | B10: XAUUSD | C10: M5 | D10: 5186.07 | E10: 5208.245 | F10: 5202.6892 | G10: 5197.1334 | H10: 5191.5775 | I10: 5186.0217 | J10: 5181.5504 | K10: 5175.9946 | L10: 5170.4388 | M10: 5164.883 | N10: 5159.3272 | P10: =(A10/86400)+25569 -> 46078.576 | Q10: =CEILING(INT(P10*1440)/1440*288,1)/288 -> 46078.576 | R10: =MROUND((Q10-25569)*86400,300) -> 1772027400
A11: 1772027698 | B11: XAUUSD | C11: M5 | D11: 5185.23 | E11: 5208.6115 | F11: 5203.0634 | G11: 5197.5153 | H11: 5191.9671 | I11: 5186.419 | J11: 5181.9543 | K11: 5176.4062 | L11: 5170.8581 | M11: 5165.3099 | N11: 5159.7618 | P11: =(A11/86400)+25569 -> 46078.58 | Q11: =CEILING(INT(P11*1440)/1440*288,1)/288 -> 46078.58 | R11: =MROUND((Q11-25569)*86400,300) -> 1772027700
A12: 1772027998 | B12: XAUUSD | C12: M5 | D12: 5187.18 | E12: 5208.7392 | F12: 5203.2372 | G12: 5197.7351 | H12: 5192.2331 | I12: 5186.7311 | J12: 5182.2957 | K12: 5176.7936 | L12: 5171.2916 | M12: 5165.7896 | N12: 5160.2875 | P12: =(A12/86400)+25569 -> 46078.583 | Q12: =CEILING(INT(P12*1440)/1440*288,1)/288 -> 46078.583 | R12: =MROUND((Q12-25569)*86400,300) -> 1772028000
A13: 1772028298 | B13: XAUUSD | C13: M5 | D13: 5189.99 | E13: 5208.9546 | F13: 5203.484 | G13: 5198.0134 | H13: 5192.5429 | I13: 5187.0723 | J13: 5182.6636 | K13: 5177.193 | L13: 5171.7225 | M13: 5166.2519 | N13: 5160.7814 | P13: =(A13/86400)+25569 -> 46078.587 | Q13: =CEILING(INT(P13*1440)/1440*288,1)/288 -> 46078.587 | R13: =MROUND((Q13-25569)*86400,300) -> 1772028300
... A501: 1772181898 | B501: XAUUSD | C501: M5 | D501: 5182.07 | E501: 5201.8111 | F501: 5197.1884 | G501: 5192.5656 | H501: 5187.9429 | I501: 5183.3202 | J501: 5179.0684 | K501: 5174.4457 | L501: 5169.823 | M501: 5165.2003 | N501: 5160.5775 | P501: =(A501/86400)+25569 -> 46080.365 | Q501: =CEILING(INT(P501*1440)/1440*288,1)/288 -> 46080.365 | R501: =MROUND((Q501-25569)*86400,300) -> 1772181900

Sheet SR_Levels
A1: timestamp | B1: symbol | C1: timeframe | D1: close | E1: sr_1 | F1: sr_2 | G1: sr_3 | H1: sr_4 | I1: sr_5 | J1: sr_6 | K1: sr_7 | L1: sr_8 | N1: convert_to_readable_datetime | O1: round_to_nearest_datetime_5m | P1: timestamp_adjusted
A2: 1772024998 | B2: XAUUSD | C2: M5 | D2: 5187.2 | E2: 5178.6 | F2: 5161.89 | G2: 5135.85 | I2: 5193.35 | J2: 5205.31 | N2: =(A2/86400)+25569 -> 46078.549 | O2: =CEILING(INT(N2*1440)/1440*288,1)/288 -> 46078.549 | P2: =MROUND((O2-25569)*86400,300) -> 1772025000
A3: 1772025298 | B3: XAUUSD | C3: M5 | D3: 5187 | E3: 5178.6 | F3: 5161.89 | G3: 5135.85 | I3: 5193.35 | J3: 5205.31 | N3: =(A3/86400)+25569 -> 46078.552 | O3: =CEILING(INT(N3*1440)/1440*288,1)/288 -> 46078.552 | P3: =MROUND((O3-25569)*86400,300) -> 1772025300
A4: 1772025598 | B4: XAUUSD | C4: M5 | D4: 5191.13 | E4: 5178.6 | F4: 5161.89 | G4: 5135.85 | I4: 5193.35 | J4: 5205.31 | N4: =(A4/86400)+25569 -> 46078.556 | O4: =CEILING(INT(N4*1440)/1440*288,1)/288 -> 46078.556 | P4: =MROUND((O4-25569)*86400,300) -> 1772025600
A5: 1772025898 | B5: XAUUSD | C5: M5 | D5: 5188.07 | E5: 5178.6 | F5: 5161.89 | G5: 5135.85 | I5: 5193.35 | J5: 5205.31 | N5: =(A5/86400)+25569 -> 46078.559 | O5: =CEILING(INT(N5*1440)/1440*288,1)/288 -> 46078.559 | P5: =MROUND((O5-25569)*86400,300) -> 1772025900
A6: 1772026198 | B6: XAUUSD | C6: M5 | D6: 5188.16 | E6: 5178.6 | F6: 5161.89 | G6: 5135.85 | I6: 5193.35 | J6: 5205.31 | N6: =(A6/86400)+25569 -> 46078.562 | O6: =CEILING(INT(N6*1440)/1440*288,1)/288 -> 46078.562 | P6: =MROUND((O6-25569)*86400,300) -> 1772026200
A7: 1772026498 | B7: XAUUSD | C7: M5 | D7: 5189.61 | E7: 5178.6 | F7: 5161.89 | G7: 5135.85 | I7: 5193.35 | J7: 5205.31 | N7: =(A7/86400)+25569 -> 46078.566 | O7: =CEILING(INT(N7*1440)/1440*288,1)/288 -> 46078.566 | P7: =MROUND((O7-25569)*86400,300) -> 1772026500
A8: 1772026798 | B8: XAUUSD | C8: M5 | D8: 5186.84 | E8: 5178.6 | F8: 5161.89 | G8: 5135.85 | I8: 5193.35 | J8: 5205.31 | N8: =(A8/86400)+25569 -> 46078.569 | O8: =CEILING(INT(N8*1440)/1440*288,1)/288 -> 46078.569 | P8: =MROUND((O8-25569)*86400,300) -> 1772026800
A9: 1772027098 | B9: XAUUSD | C9: M5 | D9: 5186.59 | E9: 5178.6 | F9: 5161.89 | G9: 5135.85 | I9: 5193.35 | J9: 5205.31 | N9: =(A9/86400)+25569 -> 46078.573 | O9: =CEILING(INT(N9*1440)/1440*288,1)/288 -> 46078.573 | P9: =MROUND((O9-25569)*86400,300) -> 1772027100
A10: 1772027398 | B10: XAUUSD | C10: M5 | D10: 5186.07 | E10: 5178.6 | F10: 5161.89 | G10: 5135.85 | I10: 5193.35 | J10: 5205.31 | N10: =(A10/86400)+25569 -> 46078.576 | O10: =CEILING(INT(N10*1440)/1440*288,1)/288 -> 46078.576 | P10: =MROUND((O10-25569)*86400,300) -> 1772027400
A11: 1772027698 | B11: XAUUSD | C11: M5 | D11: 5185.23 | E11: 5178.6 | F11: 5161.89 | G11: 5135.85 | I11: 5193.35 | J11: 5205.31 | N11: =(A11/86400)+25569 -> 46078.58 | O11: =CEILING(INT(N11*1440)/1440*288,1)/288 -> 46078.58 | P11: =MROUND((O11-25569)*86400,300) -> 1772027700
A12: 1772027998 | B12: XAUUSD | C12: M5 | D12: 5187.18 | E12: 5178.6 | F12: 5161.89 | G12: 5135.85 | I12: 5193.35 | J12: 5205.31 | N12: =(A12/86400)+25569 -> 46078.583 | O12: =CEILING(INT(N12*1440)/1440*288,1)/288 -> 46078.583 | P12: =MROUND((O12-25569)*86400,300) -> 1772028000
A13: 1772028298 | B13: XAUUSD | C13: M5 | D13: 5189.99 | E13: 5178.6 | F13: 5161.89 | G13: 5135.85 | I13: 5193.35 | J13: 5205.31 | N13: =(A13/86400)+25569 -> 46078.587 | O13: =CEILING(INT(N13*1440)/1440*288,1)/288 -> 46078.587 | P13: =MROUND((O13-25569)*86400,300) -> 1772028300
... A16: 1772029198 | B16: XAUUSD | C16: M5 | D16: 5181.49 | E16: 5178.6 | F16: 5161.89 | G16: 5135.85 | I16: 5193.35 | J16: 5205.31 | N16: =(A16/86400)+25569 -> 46078.597 | O16: =CEILING(INT(N16*1440)/1440*288,1)/288 -> 46078.597 | P16: =MROUND((O16-25569)*86400,300) -> 1772029200
A17: 1772029498 | B17: XAUUSD | C17: M5 | D17: 5177.91 | E17: 5161.89 | F17: 5135.85 | I17: 5178.6 | J17: 5193.35 | K17: 5205.31 | N17: =(A17/86400)+25569 -> 46078.601 | O17: =CEILING(INT(N17*1440)/1440*288,1)/288 -> 46078.601 | P17: =MROUND((O17-25569)*86400,300) -> 1772029500
A18: 1772029798 | B18: XAUUSD | C18: M5 | D18: 5174.14 | E18: 5161.89 | F18: 5135.85 | I18: 5178.6 | J18: 5193.35 | K18: 5205.31 | N18: =(A18/86400)+25569 -> 46078.604 | O18: =CEILING(INT(N18*1440)/1440*288,1)/288 -> 46078.604 | P18: =MROUND((O18-25569)*86400,300) -> 1772029800
A19: 1772030098 | B19: XAUUSD | C19: M5 | D19: 5159.73 | E19: 5135.85 | I19: 5161.89 | J19: 5178.6 | K19: 5193.35 | L19: 5205.31 | N19: =(A19/86400)+25569 -> 46078.608 | O19: =CEILING(INT(N19*1440)/1440*288,1)/288 -> 46078.608 | P19: =MROUND((O19-25569)*86400,300) -> 1772030100
A20: 1772030398 | B20: XAUUSD | C20: M5 | D20: 5174.91 | E20: 5161.89 | F20: 5135.85 | I20: 5178.6 | J20: 5193.35 | K20: 5205.31 | N20: =(A20/86400)+25569 -> 46078.611 | O20: =CEILING(INT(N20*1440)/1440*288,1)/288 -> 46078.611 | P20: =MROUND((O20-25569)*86400,300) -> 1772030400
A21: 1772030698 | B21: XAUUSD | C21: M5 | D21: 5181.79 | E21: 5178.6 | F21: 5161.89 | G21: 5135.85 | I21: 5193.35 | J21: 5205.31 | N21: =(A21/86400)+25569 -> 46078.615 | O21: =CEILING(INT(N21*1440)/1440*288,1)/288 -> 46078.615 | P21: =MROUND((O21-25569)*86400,300) -> 1772030700
A22: 1772030998 | B22: XAUUSD | C22: M5 | D22: 5188.55 | E22: 5178.6 | F22: 5161.89 | G22: 5135.85 | I22: 5193.35 | J22: 5205.31 | N22: =(A22/86400)+25569 -> 46078.618 | O22: =CEILING(INT(N22*1440)/1440*288,1)/288 -> 46078.618 | P22: =MROUND((O22-25569)*86400,300) -> 1772031000
A23: 1772031298 | B23: XAUUSD | C23: M5 | D23: 5191.25 | E23: 5178.6 | F23: 5161.89 | G23: 5135.85 | I23: 5193.35 | J23: 5205.31 | N23: =(A23/86400)+25569 -> 46078.622 | O23: =CEILING(INT(N23*1440)/1440*288,1)/288 -> 46078.622 | P23: =MROUND((O23-25569)*86400,300) -> 1772031300
A24: 1772031598 | B24: XAUUSD | C24: M5 | D24: 5198.64 | E24: 5193.35 | F24: 5178.6 | G24: 5161.89 | H24: 5135.85 | I24: 5205.31 | N24: =(A24/86400)+25569 -> 46078.625 | O24: =CEILING(INT(N24*1440)/1440*288,1)/288 -> 46078.625 | P24: =MROUND((O24-25569)*86400,300) -> 1772031600
A25: 1772031898 | B25: XAUUSD | C25: M5 | D25: 5195.89 | E25: 5193.35 | F25: 5178.6 | G25: 5161.89 | H25: 5135.85 | I25: 5205.31 | N25: =(A25/86400)+25569 -> 46078.628 | O25: =CEILING(INT(N25*1440)/1440*288,1)/288 -> 46078.628 | P25: =MROUND((O25-25569)*86400,300) -> 1772031900
A26: 1772032198 | B26: XAUUSD | C26: M5 | D26: 5193.17 | E26: 5178.6 | F26: 5161.89 | G26: 5135.85 | I26: 5193.35 | J26: 5205.31 | N26: =(A26/86400)+25569 -> 46078.632 | O26: =CEILING(INT(N26*1440)/1440*288,1)/288 -> 46078.632 | P26: =MROUND((O26-25569)*86400,300) -> 1772032200
A27: 1772032498 | B27: XAUUSD | C27: M5 | D27: 5188.97 | E27: 5178.6 | F27: 5161.89 | G27: 5135.85 | I27: 5193.35 | J27: 5205.31 | N27: =(A27/86400)+25569 -> 46078.635 | O27: =CEILING(INT(N27*1440)/1440*288,1)/288 -> 46078.635 | P27: =MROUND((O27-25569)*86400,300) -> 1772032500
A28: 1772032798 | B28: XAUUSD | C28: M5 | D28: 5185.46 | E28: 5178.6 | F28: 5161.89 | G28: 5135.85 | I28: 5193.35 | J28: 5205.31 | N28: =(A28/86400)+25569 -> 46078.639 | O28: =CEILING(INT(N28*1440)/1440*288,1)/288 -> 46078.639 | P28: =MROUND((O28-25569)*86400,300) -> 1772032800
A29: 1772033098 | B29: XAUUSD | C29: M5 | D29: 5180.33 | E29: 5178.6 | F29: 5161.89 | G29: 5135.85 | I29: 5193.35 | J29: 5205.31 | N29: =(A29/86400)+25569 -> 46078.642 | O29: =CEILING(INT(N29*1440)/1440*288,1)/288 -> 46078.642 | P29: =MROUND((O29-25569)*86400,300) -> 1772033100
A30: 1772033398 | B30: XAUUSD | C30: M5 | D30: 5181.68 | E30: 5178.6 | F30: 5161.89 | G30: 5135.85 | I30: 5193.35 | J30: 5205.31 | N30: =(A30/86400)+25569 -> 46078.646 | O30: =CEILING(INT(N30*1440)/1440*288,1)/288 -> 46078.646 | P30: =MROUND((O30-25569)*86400,300) -> 1772033400
A31: 1772033698 | B31: XAUUSD | C31: M5 | D31: 5187.95 | E31: 5178.6 | F31: 5161.89 | G31: 5135.85 | I31: 5193.35 | J31: 5205.31 | N31: =(A31/86400)+25569 -> 46078.649 | O31: =CEILING(INT(N31*1440)/1440*288,1)/288 -> 46078.649 | P31: =MROUND((O31-25569)*86400,300) -> 1772033700
A32: 1772033998 | B32: XAUUSD | C32: M5 | D32: 5191 | E32: 5178.6 | F32: 5161.89 | G32: 5135.85 | I32: 5193.35 | J32: 5205.31 | N32: =(A32/86400)+25569 -> 46078.653 | O32: =CEILING(INT(N32*1440)/1440*288,1)/288 -> 46078.653 | P32: =MROUND((O32-25569)*86400,300) -> 1772034000
A33: 1772034298 | B33: XAUUSD | C33: M5 | D33: 5197.9 | E33: 5193.35 | F33: 5178.6 | G33: 5161.89 | H33: 5135.85 | I33: 5205.31 | N33: =(A33/86400)+25569 -> 46078.656 | O33: =CEILING(INT(N33*1440)/1440*288,1)/288 -> 46078.656 | P33: =MROUND((O33-25569)*86400,300) -> 1772034300
A34: 1772034598 | B34: XAUUSD | C34: M5 | D34: 5195.48 | E34: 5193.35 | F34: 5178.6 | G34: 5161.89 | H34: 5135.85 | I34: 5205.31 | N34: =(A34/86400)+25569 -> 46078.66 | O34: =CEILING(INT(N34*1440)/1440*288,1)/288 -> 46078.66 | P34: =MROUND((O34-25569)*86400,300) -> 1772034600
A35: 1772034898 | B35: XAUUSD | C35: M5 | D35: 5194.5 | E35: 5193.35 | F35: 5178.6 | G35: 5161.89 | H35: 5135.85 | I35: 5205.31 | N35: =(A35/86400)+25569 -> 46078.663 | O35: =CEILING(INT(N35*1440)/1440*288,1)/288 -> 46078.663 | P35: =MROUND((O35-25569)*86400,300) -> 1772034900
A36: 1772035198 | B36: XAUUSD | C36: M5 | D36: 5194.37 | E36: 5193.35 | F36: 5178.6 | G36: 5161.89 | H36: 5135.85 | I36: 5205.31 | N36: =(A36/86400)+25569 -> 46078.667 | O36: =CEILING(INT(N36*1440)/1440*288,1)/288 -> 46078.667 | P36: =MROUND((O36-25569)*86400,300) -> 1772035200
A37: 1772035498 | B37: XAUUSD | C37: M5 | D37: 5191.37 | E37: 5178.6 | F37: 5161.89 | G37: 5135.85 | I37: 5193.35 | J37: 5205.31 | N37: =(A37/86400)+25569 -> 46078.67 | O37: =CEILING(INT(N37*1440)/1440*288,1)/288 -> 46078.67 | P37: =MROUND((O37-25569)*86400,300) -> 1772035500
A38: 1772035798 | B38: XAUUSD | C38: M5 | D38: 5192.52 | E38: 5178.6 | F38: 5161.89 | G38: 5135.85 | I38: 5193.35 | J38: 5205.31 | N38: =(A38/86400)+25569 -> 46078.674 | O38: =CEILING(INT(N38*1440)/1440*288,1)/288 -> 46078.674 | P38: =MROUND((O38-25569)*86400,300) -> 1772035800
A39: 1772036098 | B39: XAUUSD | C39: M5 | D39: 5197.05 | E39: 5193.35 | F39: 5178.6 | G39: 5161.89 | H39: 5135.85 | I39: 5205.31 | N39: =(A39/86400)+25569 -> 46078.677 | O39: =CEILING(INT(N39*1440)/1440*288,1)/288 -> 46078.677 | P39: =MROUND((O39-25569)*86400,300) -> 1772036100
A40: 1772036398 | B40: XAUUSD | C40: M5 | D40: 5205.29 | E40: 5193.35 | F40: 5178.6 | G40: 5161.89 | H40: 5135.85 | I40: 5205.31 | N40: =(A40/86400)+25569 -> 46078.681 | O40: =CEILING(INT(N40*1440)/1440*288,1)/288 -> 46078.681 | P40: =MROUND((O40-25569)*86400,300) -> 1772036400
A41: 1772036698 | B41: XAUUSD | C41: M5 | D41: 5203.22 | E41: 5193.35 | F41: 5178.6 | G41: 5161.89 | H41: 5135.85 | I41: 5205.31 | N41: =(A41/86400)+25569 -> 46078.684 | O41: =CEILING(INT(N41*1440)/1440*288,1)/288 -> 46078.684 | P41: =MROUND((O41-25569)*86400,300) -> 1772036700
A42: 1772036998 | B42: XAUUSD | C42: M5 | D42: 5206.56 | E42: 5205.31 | F42: 5193.35 | G42: 5178.6 | H42: 5161.89 | N42: =(A42/86400)+25569 -> 46078.687 | O42: =CEILING(INT(N42*1440)/1440*288,1)/288 -> 46078.688 | P42: =MROUND((O42-25569)*86400,300) -> 1772037000
...

Sheet ZigZag
A1: timestamp | B1: symbol | C1: timeframe | D1: close | E1: zigzag_high | F1: zigzag_low | G1: ema | I1: convert_to_readable_datetime | J1: round_to_nearest_datetime_5m | K1: timestamp_adjusted
A2: 1772024998 | B2: XAUUSD | C2: M5 | D2: 5187.2 | E2: 0 | F2: 0 | G2: 5181.08 | I2: =(A2/86400)+25569 -> 46078.549 | J2: =CEILING(INT(I2*1440)/1440*288,1)/288 -> 46078.549 | K2: =MROUND((J2-25569)*86400,300) -> 1772025000
A3: 1772025298 | B3: XAUUSD | C3: M5 | D3: 5187 | E3: 0 | F3: 0 | G3: 5181.54 | I3: =(A3/86400)+25569 -> 46078.552 | J3: =CEILING(INT(I3*1440)/1440*288,1)/288 -> 46078.552 | K3: =MROUND((J3-25569)*86400,300) -> 1772025300
A4: 1772025598 | B4: XAUUSD | C4: M5 | D4: 5191.13 | E4: 5191.47 | F4: 0 | G4: 5182.12 | I4: =(A4/86400)+25569 -> 46078.556 | J4: =CEILING(INT(I4*1440)/1440*288,1)/288 -> 46078.556 | K4: =MROUND((J4-25569)*86400,300) -> 1772025600
A5: 1772025898 | B5: XAUUSD | C5: M5 | D5: 5188.07 | E5: 0 | F5: 0 | G5: 5182.59 | I5: =(A5/86400)+25569 -> 46078.559 | J5: =CEILING(INT(I5*1440)/1440*288,1)/288 -> 46078.559 | K5: =MROUND((J5-25569)*86400,300) -> 1772025900
A6: 1772026198 | B6: XAUUSD | C6: M5 | D6: 5188.16 | E6: 0 | F6: 0 | G6: 5183 | I6: =(A6/86400)+25569 -> 46078.562 | J6: =CEILING(INT(I6*1440)/1440*288,1)/288 -> 46078.562 | K6: =MROUND((J6-25569)*86400,300) -> 1772026200
A7: 1772026498 | B7: XAUUSD | C7: M5 | D7: 5189.61 | E7: 0 | F7: 0 | G7: 5183.45 | I7: =(A7/86400)+25569 -> 46078.566 | J7: =CEILING(INT(I7*1440)/1440*288,1)/288 -> 46078.566 | K7: =MROUND((J7-25569)*86400,300) -> 1772026500
A8: 1772026798 | B8: XAUUSD | C8: M5 | D8: 5186.84 | E8: 0 | F8: 0 | G8: 5183.68 | I8: =(A8/86400)+25569 -> 46078.569 | J8: =CEILING(INT(I8*1440)/1440*288,1)/288 -> 46078.569 | K8: =MROUND((J8-25569)*86400,300) -> 1772026800
A9: 1772027098 | B9: XAUUSD | C9: M5 | D9: 5186.59 | E9: 0 | F9: 0 | G9: 5183.98 | I9: =(A9/86400)+25569 -> 46078.573 | J9: =CEILING(INT(I9*1440)/1440*288,1)/288 -> 46078.573 | K9: =MROUND((J9-25569)*86400,300) -> 1772027100
A10: 1772027398 | B10: XAUUSD | C10: M5 | D10: 5186.07 | E10: 0 | F10: 0 | G10: 5184.12 | I10: =(A10/86400)+25569 -> 46078.576 | J10: =CEILING(INT(I10*1440)/1440*288,1)/288 -> 46078.576 | K10: =MROUND((J10-25569)*86400,300) -> 1772027400
A11: 1772027698 | B11: XAUUSD | C11: M5 | D11: 5185.23 | E11: 0 | F11: 0 | G11: 5184.26 | I11: =(A11/86400)+25569 -> 46078.58 | J11: =CEILING(INT(I11*1440)/1440*288,1)/288 -> 46078.58 | K11: =MROUND((J11-25569)*86400,300) -> 1772027700
A12: 1772027998 | B12: XAUUSD | C12: M5 | D12: 5187.18 | E12: 0 | F12: 0 | G12: 5184.39 | I12: =(A12/86400)+25569 -> 46078.583 | J12: =CEILING(INT(I12*1440)/1440*288,1)/288 -> 46078.583 | K12: =MROUND((J12-25569)*86400,300) -> 1772028000
A13: 1772028298 | B13: XAUUSD | C13: M5 | D13: 5189.99 | E13: 0 | F13: 0 | G13: 5184.74 | I13: =(A13/86400)+25569 -> 46078.587 | J13: =CEILING(INT(I13*1440)/1440*288,1)/288 -> 46078.587 | K13: =MROUND((J13-25569)*86400,300) -> 1772028300
... A501: 1772181898 | B501: XAUUSD | C501: M5 | D501: 5180.67 | E501: 0 | F501: 0 | G501: 5182.26 | I501: =(A501/86400)+25569 -> 46080.365 | J501: =CEILING(INT(I501*1440)/1440*288,1)/288 -> 46080.365 | K501: =MROUND((J501-25569)*86400,300) -> 1772181900

Sheet Dual_Tema
A1: timestamp | B1: symbol | C1: timeframe | D1: close | E1: dual_tema_high | F1: dual_tema_low | H1: convert_to_readable_datetime | I1: round_to_nearest_datetime_5m | J1: timestamp_adjusted
A2: 1772024998 | B2: XAUUSD | C2: M5 | D2: 5187.2 | E2: 5188.55 | F2: 5184.29 | H2: =(A2/86400)+25569 -> 46078.549 | I2: =CEILING(INT(H2*1440)/1440*288,1)/288 -> 46078.549 | J2: =MROUND((I2-25569)*86400,300) -> 1772025000
A3: 1772025298 | B3: XAUUSD | C3: M5 | D3: 5187 | E3: 5189.36 | F3: 5185.43 | H3: =(A3/86400)+25569 -> 46078.552 | I3: =CEILING(INT(H3*1440)/1440*288,1)/288 -> 46078.552 | J3: =MROUND((I3-25569)*86400,300) -> 1772025300
A4: 1772025598 | B4: XAUUSD | C4: M5 | D4: 5191.13 | E4: 5190.73 | F4: 5186.16 | H4: =(A4/86400)+25569 -> 46078.556 | I4: =CEILING(INT(H4*1440)/1440*288,1)/288 -> 46078.556 | J4: =MROUND((I4-25569)*86400,300) -> 1772025600
A5: 1772025898 | B5: XAUUSD | C5: M5 | D5: 5188.07 | E5: 5191.47 | F5: 5186.92 | H5: =(A5/86400)+25569 -> 46078.559 | I5: =CEILING(INT(H5*1440)/1440*288,1)/288 -> 46078.559 | J5: =MROUND((I5-25569)*86400,300) -> 1772025900
A6: 1772026198 | B6: XAUUSD | C6: M5 | D6: 5188.16 | E6: 5191.36 | F6: 5187.17 | H6: =(A6/86400)+25569 -> 46078.562 | I6: =CEILING(INT(H6*1440)/1440*288,1)/288 -> 46078.562 | J6: =MROUND((I6-25569)*86400,300) -> 1772026200
A7: 1772026498 | B7: XAUUSD | C7: M5 | D7: 5189.61 | E7: 5191.2 | F7: 5187.78 | H7: =(A7/86400)+25569 -> 46078.566 | I7: =CEILING(INT(H7*1440)/1440*288,1)/288 -> 46078.566 | J7: =MROUND((I7-25569)*86400,300) -> 1772026500
A8: 1772026798 | B8: XAUUSD | C8: M5 | D8: 5186.84 | E8: 5191.5 | F8: 5185.31 | H8: =(A8/86400)+25569 -> 46078.569 | I8: =CEILING(INT(H8*1440)/1440*288,1)/288 -> 46078.569 | J8: =MROUND((I8-25569)*86400,300) -> 1772026800
A9: 1772027098 | B9: XAUUSD | C9: M5 | D9: 5186.59 | E9: 5191.53 | F9: 5185.45 | H9: =(A9/86400)+25569 -> 46078.573 | I9: =CEILING(INT(H9*1440)/1440*288,1)/288 -> 46078.573 | J9: =MROUND((I9-25569)*86400,300) -> 1772027100
A10: 1772027398 | B10: XAUUSD | C10: M5 | D10: 5186.07 | E10: 5189.69 | F10: 5184.86 | H10: =(A10/86400)+25569 -> 46078.576 | I10: =CEILING(INT(H10*1440)/1440*288,1)/288 -> 46078.576 | J10: =MROUND((I10-25569)*86400,300) -> 1772027400
A11: 1772027698 | B11: XAUUSD | C11: M5 | D11: 5185.23 | E11: 5189.01 | F11: 5184.7 | H11: =(A11/86400)+25569 -> 46078.58 | I11: =CEILING(INT(H11*1440)/1440*288,1)/288 -> 46078.58 | J11: =MROUND((I11-25569)*86400,300) -> 1772027700
A12: 1772027998 | B12: XAUUSD | C12: M5 | D12: 5187.18 | E12: 5188.01 | F12: 5184.11 | H12: =(A12/86400)+25569 -> 46078.583 | I12: =CEILING(INT(H12*1440)/1440*288,1)/288 -> 46078.583 | J12: =MROUND((I12-25569)*86400,300) -> 1772028000
A13: 1772028298 | B13: XAUUSD | C13: M5 | D13: 5189.99 | E13: 5189.22 | F13: 5185.22 | H13: =(A13/86400)+25569 -> 46078.587 | I13: =CEILING(INT(H13*1440)/1440*288,1)/288 -> 46078.587 | J13: =MROUND((I13-25569)*86400,300) -> 1772028300
... A501: 1772181898 | B501: XAUUSD | C501: M5 | D501: 5180 | E501: 5181.09 | F501: 5179.72 | H501: =(A501/86400)+25569 -> 46080.365 | I501: =CEILING(INT(H501*1440)/1440*288,1)/288 -> 46080.365 | J501: =MROUND((I501-25569)*86400,300) -> 1772181900

Sheet Pinbar
A1: timestamp | B1: symbol | C1: timeframe | D1: close | E1: pinbar | G1: convert_to_readable_datetime | H1: round_to_nearest_datetime_5m | I1: timestamp_adjusted
A2: 1772024998 | B2: XAUUSD | C2: M5 | D2: 5187.2 | E2: 0 | G2: =(A2/86400)+25569 -> 46078.549 | H2: =CEILING(INT(G2*1440)/1440*288,1)/288 -> 46078.549 | I2: =MROUND((H2-25569)*86400,300) -> 1772025000
A3: 1772025298 | B3: XAUUSD | C3: M5 | D3: 5187 | E3: 0 | G3: =(A3/86400)+25569 -> 46078.552 | H3: =CEILING(INT(G3*1440)/1440*288,1)/288 -> 46078.552 | I3: =MROUND((H3-25569)*86400,300) -> 1772025300
A4: 1772025598 | B4: XAUUSD | C4: M5 | D4: 5191.13 | E4: 0 | G4: =(A4/86400)+25569 -> 46078.556 | H4: =CEILING(INT(G4*1440)/1440*288,1)/288 -> 46078.556 | I4: =MROUND((H4-25569)*86400,300) -> 1772025600
A5: 1772025898 | B5: XAUUSD | C5: M5 | D5: 5188.07 | E5: 0 | G5: =(A5/86400)+25569 -> 46078.559 | H5: =CEILING(INT(G5*1440)/1440*288,1)/288 -> 46078.559 | I5: =MROUND((H5-25569)*86400,300) -> 1772025900
A6: 1772026198 | B6: XAUUSD | C6: M5 | D6: 5188.16 | E6: 0 | G6: =(A6/86400)+25569 -> 46078.562 | H6: =CEILING(INT(G6*1440)/1440*288,1)/288 -> 46078.562 | I6: =MROUND((H6-25569)*86400,300) -> 1772026200
A7: 1772026498 | B7: XAUUSD | C7: M5 | D7: 5189.61 | E7: 0 | G7: =(A7/86400)+25569 -> 46078.566 | H7: =CEILING(INT(G7*1440)/1440*288,1)/288 -> 46078.566 | I7: =MROUND((H7-25569)*86400,300) -> 1772026500
A8: 1772026798 | B8: XAUUSD | C8: M5 | D8: 5186.84 | E8: 0 | G8: =(A8/86400)+25569 -> 46078.569 | H8: =CEILING(INT(G8*1440)/1440*288,1)/288 -> 46078.569 | I8: =MROUND((H8-25569)*86400,300) -> 1772026800
A9: 1772027098 | B9: XAUUSD | C9: M5 | D9: 5186.59 | E9: 0 | G9: =(A9/86400)+25569 -> 46078.573 | H9: =CEILING(INT(G9*1440)/1440*288,1)/288 -> 46078.573 | I9: =MROUND((H9-25569)*86400,300) -> 1772027100
A10: 1772027398 | B10: XAUUSD | C10: M5 | D10: 5186.07 | E10: 0 | G10: =(A10/86400)+25569 -> 46078.576 | H10: =CEILING(INT(G10*1440)/1440*288,1)/288 -> 46078.576 | I10: =MROUND((H10-25569)*86400,300) -> 1772027400
A11: 1772027698 | B11: XAUUSD | C11: M5 | D11: 5185.23 | E11: 0 | G11: =(A11/86400)+25569 -> 46078.58 | H11: =CEILING(INT(G11*1440)/1440*288,1)/288 -> 46078.58 | I11: =MROUND((H11-25569)*86400,300) -> 1772027700
A12: 1772027998 | B12: XAUUSD | C12: M5 | D12: 5187.18 | E12: 0 | G12: =(A12/86400)+25569 -> 46078.583 | H12: =CEILING(INT(G12*1440)/1440*288,1)/288 -> 46078.583 | I12: =MROUND((H12-25569)*86400,300) -> 1772028000
A13: 1772028298 | B13: XAUUSD | C13: M5 | D13: 5189.99 | E13: 0 | G13: =(A13/86400)+25569 -> 46078.587 | H13: =CEILING(INT(G13*1440)/1440*288,1)/288 -> 46078.587 | I13: =MROUND((H13-25569)*86400,300) -> 1772028300
... A501: 1772181898 | B501: XAUUSD | C501: M5 | D501: 5181.1 | E501: 0 | G501: =(A501/86400)+25569 -> 46080.365 | H501: =CEILING(INT(G501*1440)/1440*288,1)/288 -> 46080.365 | I501: =MROUND((H501-25569)*86400,300) -> 1772181900

Sheet SSA
A1: timestamp | B1: symbol | C1: timeframe | D1: close | E1: ssa | F1: ema_ssa | H1: convert_to_readable_datetime | I1: round_to_nearest_datetime_5m | J1: timestamp_adjusted
A2: 1772025000 | B2: XAUUSD | C2: M5 | D2: 5187.2 | E2: 5187.5351 | F2: 5186.6253 | H2: =(A2/86400)+25569 -> 46078.549 | I2: =CEILING(INT(H2*1440)/1440*288,1)/288 -> 46078.549 | J2: =MROUND((I2-25569)*86400,300) -> 1772025000
A3: 1772025300 | B3: XAUUSD | C3: M5 | D3: 5187 | E3: 5187.9737 | F3: 5187.2995 | H3: =(A3/86400)+25569 -> 46078.552 | I3: =CEILING(INT(H3*1440)/1440*288,1)/288 -> 46078.552 | J3: =MROUND((I3-25569)*86400,300) -> 1772025300
A4: 1772025600 | B4: XAUUSD | C4: M5 | D4: 5191.13 | E4: 5188.112 | F4: 5187.7058 | H4: =(A4/86400)+25569 -> 46078.556 | I4: =CEILING(INT(H4*1440)/1440*288,1)/288 -> 46078.556 | J4: =MROUND((I4-25569)*86400,300) -> 1772025600
A5: 1772025900 | B5: XAUUSD | C5: M5 | D5: 5188.07 | E5: 5187.9842 | F5: 5187.845 | H5: =(A5/86400)+25569 -> 46078.559 | I5: =CEILING(INT(H5*1440)/1440*288,1)/288 -> 46078.559 | J5: =MROUND((I5-25569)*86400,300) -> 1772025900
A6: 1772026200 | B6: XAUUSD | C6: M5 | D6: 5188.16 | E6: 5187.8513 | F6: 5187.8481 | H6: =(A6/86400)+25569 -> 46078.562 | I6: =CEILING(INT(H6*1440)/1440*288,1)/288 -> 46078.562 | J6: =MROUND((I6-25569)*86400,300) -> 1772026200
