Workbook

Sheet Price
A1: timestamp | B1: symbol | C1: timeframe | D1: close | E1: open | F1: high | G1: low | H1: volume | J1: convert_to_readable_datetime | K1: round_to_nearest_datetime_5m | L1: timestamp_adjusted
A2: 1772024998 | B2: XAUUSD | C2: M5 | D2: 5187.2 | E2: 5188.44 | F2: 5189.22 | G2: 5185.5 | H2: 567 | J2: =(A2/86400)+25569 -> 46078.549 | K2: =CEILING(INT(J2*1440)/1440*288,1)/288 -> 46078.549 | L2: =MROUND((K2-25569)*86400,300) -> 1772025000
A3: 1772025298 | B3: XAUUSD | C3: M5 | D3: 5187 | E3: 5187.22 | F3: 5189.54 | G3: 5185.97 | H3: 574 | J3: =(A3/86400)+25569 -> 46078.552 | K3: =CEILING(INT(J3*1440)/1440*288,1)/288 -> 46078.552 | L3: =MROUND((K3-25569)*86400,300) -> 1772025300
A4: 1772025598 | B4: XAUUSD | C4: M5 | D4: 5191.13 | E4: 5186.81 | F4: 5191.47 | G4: 5186.14 | H4: 583 | J4: =(A4/86400)+25569 -> 46078.556 | K4: =CEILING(INT(J4*1440)/1440*288,1)/288 -> 46078.556 | L4: =MROUND((K4-25569)*86400,300) -> 1772025600
A5: 1772025898 | B5: XAUUSD | C5: M5 | D5: 5188.07 | E5: 5191.14 | F5: 5191.36 | G5: 5186.93 | H5: 547 | J5: =(A5/86400)+25569 -> 46078.559 | K5: =CEILING(INT(J5*1440)/1440*288,1)/288 -> 46078.559 | L5: =MROUND((K5-25569)*86400,300) -> 1772025900
A6: 1772026198 | B6: XAUUSD | C6: M5 | D6: 5188.16 | E6: 5188.07 | F6: 5190.35 | G6: 5186.62 | H6: 516 | J6: =(A6/86400)+25569 -> 46078.562 | K6: =CEILING(INT(J6*1440)/1440*288,1)/288 -> 46078.562 | L6: =MROUND((K6-25569)*86400,300) -> 1772026200
A7: 1772026498 | B7: XAUUSD | C7: M5 | D7: 5189.61 | E7: 5188.16 | F7: 5190.35 | G7: 5187.73 | H7: 524 | J7: =(A7/86400)+25569 -> 46078.566 | K7: =CEILING(INT(J7*1440)/1440*288,1)/288 -> 46078.566 | L7: =MROUND((K7-25569)*86400,300) -> 1772026500
A8: 1772026798 | B8: XAUUSD | C8: M5 | D8: 5186.84 | E8: 5189.93 | F8: 5191.33 | G8: 5182.03 | H8: 660 | J8: =(A8/86400)+25569 -> 46078.569 | K8: =CEILING(INT(J8*1440)/1440*288,1)/288 -> 46078.569 | L8: =MROUND((K8-25569)*86400,300) -> 1772026800
A9: 1772027098 | B9: XAUUSD | C9: M5 | D9: 5186.59 | E9: 5187.12 | F9: 5191.12 | G9: 5185.65 | H9: 585 | J9: =(A9/86400)+25569 -> 46078.573 | K9: =CEILING(INT(J9*1440)/1440*288,1)/288 -> 46078.573 | L9: =MROUND((K9-25569)*86400,300) -> 1772027100
A10: 1772027398 | B10: XAUUSD | C10: M5 | D10: 5186.07 | E10: 5187.03 | F10: 5187.42 | G10: 5184.3 | H10: 628 | J10: =(A10/86400)+25569 -> 46078.576 | K10: =CEILING(INT(J10*1440)/1440*288,1)/288 -> 46078.576 | L10: =MROUND((K10-25569)*86400,300) -> 1772027400
A11: 1772027698 | B11: XAUUSD | C11: M5 | D11: 5185.23 | E11: 5186.04 | F11: 5188.5 | G11: 5184.76 | H11: 572 | J11: =(A11/86400)+25569 -> 46078.58 | K11: =CEILING(INT(J11*1440)/1440*288,1)/288 -> 46078.58 | L11: =MROUND((K11-25569)*86400,300) -> 1772027700
A12: 1772027998 | B12: XAUUSD | C12: M5 | D12: 5187.18 | E12: 5185.22 | F12: 5187.34 | G12: 5183.76 | H12: 641 | J12: =(A12/86400)+25569 -> 46078.583 | K12: =CEILING(INT(J12*1440)/1440*288,1)/288 -> 46078.583 | L12: =MROUND((K12-25569)*86400,300) -> 1772028000
A13: 1772028298 | B13: XAUUSD | C13: M5 | D13: 5189.99 | E13: 5187.18 | F13: 5191.07 | G13: 5186.8 | H13: 582 | J13: =(A13/86400)+25569 -> 46078.587 | K13: =CEILING(INT(J13*1440)/1440*288,1)/288 -> 46078.587 | L13: =MROUND((K13-25569)*86400,300) -> 1772028300
... A501: 1772181898 | B501: XAUUSD | C501: M5 | D501: 5181.66 | E501: 5180.32 | F501: 5182.14 | G501: 5179.99 | H501: 92 | J501: =(A501/86400)+25569 -> 46080.365 | K501: =CEILING(INT(J501*1440)/1440*288,1)/288 -> 46080.365 | L501: =MROUND((K501-25569)*86400,300) -> 1772181900

Sheet Trendlines
A1: timestamp | B1: symbol | C1: timeframe | D1: close | E1: horiz_peak_line_1 | F1: horiz_peak_line_2 | G1: horiz_peak_line_3 | H1: horiz_bottom_line_1 | I1: horiz_bottom_line_2 | J1: horiz_bottom_line_3 | K1: horiz_high_map | L1: horiz_low_map | O1: convert_to_readable_datetime | P1: round_to_nearest_datetime_5m | Q1: timestamp_adjusted
A2: 1772024999 | B2: XAUUSD | C2: M5 | D2: 5187.2 | O2: =(A2/86400)+25569 -> 46078.549 | P2: =CEILING(INT(O2*1440)/1440*288,1)/288 -> 46078.549 | Q2: =MROUND((P2-25569)*86400,300) -> 1772025000
A3: 1772025299 | B3: XAUUSD | C3: M5 | D3: 5187 | O3: =(A3/86400)+25569 -> 46078.552 | P3: =CEILING(INT(O3*1440)/1440*288,1)/288 -> 46078.552 | Q3: =MROUND((P3-25569)*86400,300) -> 1772025300
A4: 1772025599 | B4: XAUUSD | C4: M5 | D4: 5191.13 | K4: 5191.47 | O4: =(A4/86400)+25569 -> 46078.556 | P4: =CEILING(INT(O4*1440)/1440*288,1)/288 -> 46078.556 | Q4: =MROUND((P4-25569)*86400,300) -> 1772025600
A5: 1772025899 | B5: XAUUSD | C5: M5 | D5: 5188.07 | O5: =(A5/86400)+25569 -> 46078.559 | P5: =CEILING(INT(O5*1440)/1440*288,1)/288 -> 46078.559 | Q5: =MROUND((P5-25569)*86400,300) -> 1772025900
A6: 1772026199 | B6: XAUUSD | C6: M5 | D6: 5188.16 | O6: =(A6/86400)+25569 -> 46078.562 | P6: =CEILING(INT(O6*1440)/1440*288,1)/288 -> 46078.562 | Q6: =MROUND((P6-25569)*86400,300) -> 1772026200
A7: 1772026499 | B7: XAUUSD | C7: M5 | D7: 5189.61 | O7: =(A7/86400)+25569 -> 46078.566 | P7: =CEILING(INT(O7*1440)/1440*288,1)/288 -> 46078.566 | Q7: =MROUND((P7-25569)*86400,300) -> 1772026500
A8: 1772026799 | B8: XAUUSD | C8: M5 | D8: 5186.84 | O8: =(A8/86400)+25569 -> 46078.569 | P8: =CEILING(INT(O8*1440)/1440*288,1)/288 -> 46078.569 | Q8: =MROUND((P8-25569)*86400,300) -> 1772026800
A9: 1772027099 | B9: XAUUSD | C9: M5 | D9: 5186.59 | O9: =(A9/86400)+25569 -> 46078.573 | P9: =CEILING(INT(O9*1440)/1440*288,1)/288 -> 46078.573 | Q9: =MROUND((P9-25569)*86400,300) -> 1772027100
A10: 1772027399 | B10: XAUUSD | C10: M5 | D10: 5186.07 | O10: =(A10/86400)+25569 -> 46078.576 | P10: =CEILING(INT(O10*1440)/1440*288,1)/288 -> 46078.576 | Q10: =MROUND((P10-25569)*86400,300) -> 1772027400
A11: 1772027699 | B11: XAUUSD | C11: M5 | D11: 5185.23 | O11: =(A11/86400)+25569 -> 46078.58 | P11: =CEILING(INT(O11*1440)/1440*288,1)/288 -> 46078.58 | Q11: =MROUND((P11-25569)*86400,300) -> 1772027700
A12: 1772027999 | B12: XAUUSD | C12: M5 | D12: 5187.18 | O12: =(A12/86400)+25569 -> 46078.583 | P12: =CEILING(INT(O12*1440)/1440*288,1)/288 -> 46078.583 | Q12: =MROUND((P12-25569)*86400,300) -> 1772028000
A13: 1772028299 | B13: XAUUSD | C13: M5 | D13: 5189.99 | O13: =(A13/86400)+25569 -> 46078.587 | P13: =CEILING(INT(O13*1440)/1440*288,1)/288 -> 46078.587 | Q13: =MROUND((P13-25569)*86400,300) -> 1772028300
A14: 1772028599 | B14: XAUUSD | C14: M5 | D14: 5185.44 | O14: =(A14/86400)+25569 -> 46078.59 | P14: =CEILING(INT(O14*1440)/1440*288,1)/288 -> 46078.59 | Q14: =MROUND((P14-25569)*86400,300) -> 1772028600
A15: 1772028899 | B15: XAUUSD | C15: M5 | D15: 5182.68 | O15: =(A15/86400)+25569 -> 46078.594 | P15: =CEILING(INT(O15*1440)/1440*288,1)/288 -> 46078.594 | Q15: =MROUND((P15-25569)*86400,300) -> 1772028900
A16: 1772029199 | B16: XAUUSD | C16: M5 | D16: 5181.49 | O16: =(A16/86400)+25569 -> 46078.597 | P16: =CEILING(INT(O16*1440)/1440*288,1)/288 -> 46078.597 | Q16: =MROUND((P16-25569)*86400,300) -> 1772029200
... A18: 1772029799 | B18: XAUUSD | C18: M5 | D18: 5174.14 | O18: =(A18/86400)+25569 -> 46078.604 | P18: =CEILING(INT(O18*1440)/1440*288,1)/288 -> 46078.604 | Q18: =MROUND((P18-25569)*86400,300) -> 1772029800
A19: 1772030099 | B19: XAUUSD | C19: M5 | D19: 5159.73 | L19: 5158.94 | O19: =(A19/86400)+25569 -> 46078.608 | P19: =CEILING(INT(O19*1440)/1440*288,1)/288 -> 46078.608 | Q19: =MROUND((P19-25569)*86400,300) -> 1772030100
A20: 1772030399 | B20: XAUUSD | C20: M5 | D20: 5174.91 | O20: =(A20/86400)+25569 -> 46078.611 | P20: =CEILING(INT(O20*1440)/1440*288,1)/288 -> 46078.611 | Q20: =MROUND((P20-25569)*86400,300) -> 1772030400
A21: 1772030699 | B21: XAUUSD | C21: M5 | D21: 5181.79 | O21: =(A21/86400)+25569 -> 46078.615 | P21: =CEILING(INT(O21*1440)/1440*288,1)/288 -> 46078.615 | Q21: =MROUND((P21-25569)*86400,300) -> 1772030700
A22: 1772030999 | B22: XAUUSD | C22: M5 | D22: 5188.55 | O22: =(A22/86400)+25569 -> 46078.618 | P22: =CEILING(INT(O22*1440)/1440*288,1)/288 -> 46078.618 | Q22: =MROUND((P22-25569)*86400,300) -> 1772031000
A23: 1772031299 | B23: XAUUSD | C23: M5 | D23: 5191.25 | O23: =(A23/86400)+25569 -> 46078.622 | P23: =CEILING(INT(O23*1440)/1440*288,1)/288 -> 46078.622 | Q23: =MROUND((P23-25569)*86400,300) -> 1772031300
A24: 1772031599 | B24: XAUUSD | C24: M5 | D24: 5198.64 | O24: =(A24/86400)+25569 -> 46078.625 | P24: =CEILING(INT(O24*1440)/1440*288,1)/288 -> 46078.625 | Q24: =MROUND((P24-25569)*86400,300) -> 1772031600
A25: 1772031899 | B25: XAUUSD | C25: M5 | D25: 5195.89 | O25: =(A25/86400)+25569 -> 46078.628 | P25: =CEILING(INT(O25*1440)/1440*288,1)/288 -> 46078.628 | Q25: =MROUND((P25-25569)*86400,300) -> 1772031900
A26: 1772032199 | B26: XAUUSD | C26: M5 | D26: 5193.17 | O26: =(A26/86400)+25569 -> 46078.632 | P26: =CEILING(INT(O26*1440)/1440*288,1)/288 -> 46078.632 | Q26: =MROUND((P26-25569)*86400,300) -> 1772032200
A27: 1772032499 | B27: XAUUSD | C27: M5 | D27: 5188.97 | O27: =(A27/86400)+25569 -> 46078.635 | P27: =CEILING(INT(O27*1440)/1440*288,1)/288 -> 46078.635 | Q27: =MROUND((P27-25569)*86400,300) -> 1772032500
A28: 1772032799 | B28: XAUUSD | C28: M5 | D28: 5185.46 | O28: =(A28/86400)+25569 -> 46078.639 | P28: =CEILING(INT(O28*1440)/1440*288,1)/288 -> 46078.639 | Q28: =MROUND((P28-25569)*86400,300) -> 1772032800
A29: 1772033099 | B29: XAUUSD | C29: M5 | D29: 5180.33 | O29: =(A29/86400)+25569 -> 46078.642 | P29: =CEILING(INT(O29*1440)/1440*288,1)/288 -> 46078.642 | Q29: =MROUND((P29-25569)*86400,300) -> 1772033100
A30: 1772033399 | B30: XAUUSD | C30: M5 | D30: 5181.68 | O30: =(A30/86400)+25569 -> 46078.646 | P30: =CEILING(INT(O30*1440)/1440*288,1)/288 -> 46078.646 | Q30: =MROUND((P30-25569)*86400,300) -> 1772033400
A31: 1772033699 | B31: XAUUSD | C31: M5 | D31: 5187.95 | O31: =(A31/86400)+25569 -> 46078.649 | P31: =CEILING(INT(O31*1440)/1440*288,1)/288 -> 46078.649 | Q31: =MROUND((P31-25569)*86400,300) -> 1772033700
... A49: 1772039099 | B49: XAUUSD | C49: M5 | D49: 5214.69 | O49: =(A49/86400)+25569 -> 46078.712 | P49: =CEILING(INT(O49*1440)/1440*288,1)/288 -> 46078.712 | Q49: =MROUND((P49-25569)*86400,300) -> 1772039100
A50: 1772039399 | B50: XAUUSD | C50: M5 | D50: 5215.17 | K50: 5217.63 | O50: =(A50/86400)+25569 -> 46078.715 | P50: =CEILING(INT(O50*1440)/1440*288,1)/288 -> 46078.715 | Q50: =MROUND((P50-25569)*86400,300) -> 1772039400
A51: 1772039699 | B51: XAUUSD | C51: M5 | D51: 5214.53 | O51: =(A51/86400)+25569 -> 46078.719 | P51: =CEILING(INT(O51*1440)/1440*288,1)/288 -> 46078.719 | Q51: =MROUND((P51-25569)*86400,300) -> 1772039700
A52: 1772039999 | B52: XAUUSD | C52: M5 | D52: 5213.27 | O52: =(A52/86400)+25569 -> 46078.722 | P52: =CEILING(INT(O52*1440)/1440*288,1)/288 -> 46078.722 | Q52: =MROUND((P52-25569)*86400,300) -> 1772040000
A53: 1772040299 | B53: XAUUSD | C53: M5 | D53: 5213.1 | O53: =(A53/86400)+25569 -> 46078.726 | P53: =CEILING(INT(O53*1440)/1440*288,1)/288 -> 46078.726 | Q53: =MROUND((P53-25569)*86400,300) -> 1772040300
A54: 1772040599 | B54: XAUUSD | C54: M5 | D54: 5211.85 | O54: =(A54/86400)+25569 -> 46078.729 | P54: =CEILING(INT(O54*1440)/1440*288,1)/288 -> 46078.729 | Q54: =MROUND((P54-25569)*86400,300) -> 1772040600
A55: 1772040899 | B55: XAUUSD | C55: M5 | D55: 5213.17 | O55: =(A55/86400)+25569 -> 46078.733 | P55: =CEILING(INT(O55*1440)/1440*288,1)/288 -> 46078.733 | Q55: =MROUND((P55-25569)*86400,300) -> 1772040900
A56: 1772041199 | B56: XAUUSD | C56: M5 | D56: 5208.33 | O56: =(A56/86400)+25569 -> 46078.736 | P56: =CEILING(INT(O56*1440)/1440*288,1)/288 -> 46078.736 | Q56: =MROUND((P56-25569)*86400,300) -> 1772041200
A57: 1772041499 | B57: XAUUSD | C57: M5 | D57: 5206.71 | O57: =(A57/86400)+25569 -> 46078.74 | P57: =CEILING(INT(O57*1440)/1440*288,1)/288 -> 46078.74 | Q57: =MROUND((P57-25569)*86400,300) -> 1772041500
A58: 1772041799 | B58: XAUUSD | C58: M5 | D58: 5206.32 | O58: =(A58/86400)+25569 -> 46078.743 | P58: =CEILING(INT(O58*1440)/1440*288,1)/288 -> 46078.743 | Q58: =MROUND((P58-25569)*86400,300) -> 1772041800
...

Sheet ZigZag
A1: timestamp | B1: symbol | C1: timeframe | D1: close | E1: zigzag_high | F1: zigzag_low | G1: ema | I1: convert_to_readable_datetime | J1: round_to_nearest_datetime_5m | K1: timestamp_adjusted
A2: 1772024998 | B2: XAUUSD | C2: M5 | D2: 5187.2 | E2: 0 | F2: 0 | G2: 5181.08 | I2: =(A2/86400)+25569 -> 46078.549 | J2: =CEILING(INT(I2*1440)/1440*288,1)/288 -> 46078.549 | K2: =MROUND((J2-25569)*86400,300) -> 1772025000
A3: 1772025298 | B3: XAUUSD | C3: M5 | D3: 5187 | E3: 0 | F3: 0 | G3: 5181.54 | I3: =(A3/86400)+25569 -> 46078.552 | J3: =CEILING(INT(I3*1440)/1440*288,1)/288 -> 46078.552 | K3: =MROUND((J3-25569)*86400,300) -> 1772025300
A4: 1772025598 | B4: XAUUSD | C4: M5 | D4: 5191.13 | E4: 5191.47 | F4: 0 | G4: 5182.12 | I4: =(A4/86400)+25569 -> 46078.556 | J4: =CEILING(INT(I4*1440)/1440*288,1)/288 -> 46078.556 | K4: =MROUND((J4-25569)*86400,300) -> 1772025600
A5: 1772025898 | B5: XAUUSD | C5: M5 | D5: 5188.07 | E5: 0 | F5: 0 | G5: 5182.59 | I5: =(A5/86400)+25569 -> 46078.559 | J5: =CEILING(INT(I5*1440)/1440*288,1)/288 -> 46078.559 | K5: =MROUND((J5-25569)*86400,300) -> 1772025900
A6: 1772026198 | B6: XAUUSD | C6: M5 | D6: 5188.16 | E6: 0 | F6: 0 | G6: 5183 | I6: =(A6/86400)+25569 -> 46078.562 | J6: =CEILING(INT(I6*1440)/1440*288,1)/288 -> 46078.562 | K6: =MROUND((J6-25569)*86400,300) -> 1772026200
A7: 1772026498 | B7: XAUUSD | C7: M5 | D7: 5189.61 | E7: 0 | F7: 0 | G7: 5183.45 | I7: =(A7/86400)+25569 -> 46078.566 | J7: =CEILING(INT(I7*1440)/1440*288,1)/288 -> 46078.566 | K7: =MROUND((J7-25569)*86400,300) -> 1772026500
A8: 1772026798 | B8: XAUUSD | C8: M5 | D8: 5186.84 | E8: 0 | F8: 0 | G8: 5183.68 | I8: =(A8/86400)+25569 -> 46078.569 | J8: =CEILING(INT(I8*1440)/1440*288,1)/288 -> 46078.569 | K8: =MROUND((J8-25569)*86400,300) -> 1772026800
A9: 1772027098 | B9: XAUUSD | C9: M5 | D9: 5186.59 | E9: 0 | F9: 0 | G9: 5183.98 | I9: =(A9/86400)+25569 -> 46078.573 | J9: =CEILING(INT(I9*1440)/1440*288,1)/288 -> 46078.573 | K9: =MROUND((J9-25569)*86400,300) -> 1772027100
A10: 1772027398 | B10: XAUUSD | C10: M5 | D10: 5186.07 | E10: 0 | F10: 0 | G10: 5184.12 | I10: =(A10/86400)+25569 -> 46078.576 | J10: =CEILING(INT(I10*1440)/1440*288,1)/288 -> 46078.576 | K10: =MROUND((J10-25569)*86400,300) -> 1772027400
A11: 1772027698 | B11: XAUUSD | C11: M5 | D11: 5185.23 | E11: 0 | F11: 0 | G11: 5184.26 | I11: =(A11/86400)+25569 -> 46078.58 | J11: =CEILING(INT(I11*1440)/1440*288,1)/288 -> 46078.58 | K11: =MROUND((J11-25569)*86400,300) -> 1772027700
A12: 1772027998 | B12: XAUUSD | C12: M5 | D12: 5187.18 | E12: 0 | F12: 0 | G12: 5184.39 | I12: =(A12/86400)+25569 -> 46078.583 | J12: =CEILING(INT(I12*1440)/1440*288,1)/288 -> 46078.583 | K12: =MROUND((J12-25569)*86400,300) -> 1772028000
A13: 1772028298 | B13: XAUUSD | C13: M5 | D13: 5189.99 | E13: 0 | F13: 0 | G13: 5184.74 | I13: =(A13/86400)+25569 -> 46078.587 | J13: =CEILING(INT(I13*1440)/1440*288,1)/288 -> 46078.587 | K13: =MROUND((J13-25569)*86400,300) -> 1772028300
... A501: 1772181898 | B501: XAUUSD | C501: M5 | D501: 5180.67 | E501: 0 | F501: 0 | G501: 5182.26 | I501: =(A501/86400)+25569 -> 46080.365 | J501: =CEILING(INT(I501*1440)/1440*288,1)/288 -> 46080.365 | K501: =MROUND((J501-25569)*86400,300) -> 1772181900

Sheet Pinbar
A1: timestamp | B1: symbol | C1: timeframe | D1: close | E1: pinbar | G1: convert_to_readable_datetime | H1: round_to_nearest_datetime_5m | I1: timestamp_adjusted
A2: 1772024998 | B2: XAUUSD | C2: M5 | D2: 5187.2 | E2: 0 | G2: =(A2/86400)+25569 -> 46078.549 | H2: =CEILING(INT(G2*1440)/1440*288,1)/288 -> 46078.549 | I2: =MROUND((H2-25569)*86400,300) -> 1772025000
A3: 1772025298 | B3: XAUUSD | C3: M5 | D3: 5187 | E3: 0 | G3: =(A3/86400)+25569 -> 46078.552 | H3: =CEILING(INT(G3*1440)/1440*288,1)/288 -> 46078.552 | I3: =MROUND((H3-25569)*86400,300) -> 1772025300
A4: 1772025598 | B4: XAUUSD | C4: M5 | D4: 5191.13 | E4: 0 | G4: =(A4/86400)+25569 -> 46078.556 | H4: =CEILING(INT(G4*1440)/1440*288,1)/288 -> 46078.556 | I4: =MROUND((H4-25569)*86400,300) -> 1772025600
A5: 1772025898 | B5: XAUUSD | C5: M5 | D5: 5188.07 | E5: 0 | G5: =(A5/86400)+25569 -> 46078.559 | H5: =CEILING(INT(G5*1440)/1440*288,1)/288 -> 46078.559 | I5: =MROUND((H5-25569)*86400,300) -> 1772025900
A6: 1772026198 | B6: XAUUSD | C6: M5 | D6: 5188.16 | E6: 0 | G6: =(A6/86400)+25569 -> 46078.562 | H6: =CEILING(INT(G6*1440)/1440*288,1)/288 -> 46078.562 | I6: =MROUND((H6-25569)*86400,300) -> 1772026200
A7: 1772026498 | B7: XAUUSD | C7: M5 | D7: 5189.61 | E7: 0 | G7: =(A7/86400)+25569 -> 46078.566 | H7: =CEILING(INT(G7*1440)/1440*288,1)/288 -> 46078.566 | I7: =MROUND((H7-25569)*86400,300) -> 1772026500
A8: 1772026798 | B8: XAUUSD | C8: M5 | D8: 5186.84 | E8: 0 | G8: =(A8/86400)+25569 -> 46078.569 | H8: =CEILING(INT(G8*1440)/1440*288,1)/288 -> 46078.569 | I8: =MROUND((H8-25569)*86400,300) -> 1772026800
A9: 1772027098 | B9: XAUUSD | C9: M5 | D9: 5186.59 | E9: 0 | G9: =(A9/86400)+25569 -> 46078.573 | H9: =CEILING(INT(G9*1440)/1440*288,1)/288 -> 46078.573 | I9: =MROUND((H9-25569)*86400,300) -> 1772027100
A10: 1772027398 | B10: XAUUSD | C10: M5 | D10: 5186.07 | E10: 0 | G10: =(A10/86400)+25569 -> 46078.576 | H10: =CEILING(INT(G10*1440)/1440*288,1)/288 -> 46078.576 | I10: =MROUND((H10-25569)*86400,300) -> 1772027400
A11: 1772027698 | B11: XAUUSD | C11: M5 | D11: 5185.23 | E11: 0 | G11: =(A11/86400)+25569 -> 46078.58 | H11: =CEILING(INT(G11*1440)/1440*288,1)/288 -> 46078.58 | I11: =MROUND((H11-25569)*86400,300) -> 1772027700
A12: 1772027998 | B12: XAUUSD | C12: M5 | D12: 5187.18 | E12: 0 | G12: =(A12/86400)+25569 -> 46078.583 | H12: =CEILING(INT(G12*1440)/1440*288,1)/288 -> 46078.583 | I12: =MROUND((H12-25569)*86400,300) -> 1772028000
A13: 1772028298 | B13: XAUUSD | C13: M5 | D13: 5189.99 | E13: 0 | G13: =(A13/86400)+25569 -> 46078.587 | H13: =CEILING(INT(G13*1440)/1440*288,1)/288 -> 46078.587 | I13: =MROUND((H13-25569)*86400,300) -> 1772028300
... A501: 1772181898 | B501: XAUUSD | C501: M5 | D501: 5181.1 | E501: 0 | G501: =(A501/86400)+25569 -> 46080.365 | H501: =CEILING(INT(G501*1440)/1440*288,1)/288 -> 46080.365 | I501: =MROUND((H501-25569)*86400,300) -> 1772181900

Sheet SSA
A1: timestamp | B1: symbol | C1: timeframe | D1: close | E1: ssa | F1: ema_ssa | G1: ssa_high | H1: ssa_low | J1: convert_to_readable_datetime | K1: round_to_nearest_datetime_5m | L1: timestamp_adjusted
A2: 1773636603 | B2: XAUUSD | C2: M5 | D2: 5187.2 | E2: 5013.6718 | F2: 5013.7627 | G2: 5015.5347 | H2: 5013.3035 | J2: =(A2/86400)+25569 -> 46097.201 | K2: =CEILING(INT(J2*1440)/1440*288,1)/288 -> 46097.201 | L2: =MROUND((K2-25569)*86400,300) -> 1773636600
A3: 1773636903 | B3: XAUUSD | C3: M5 | D3: 5187 | E3: 5013.4438 | F3: 5013.6033 | G3: 5015.3755 | H3: 5012.6907 | J3: =(A3/86400)+25569 -> 46097.205 | K3: =CEILING(INT(J3*1440)/1440*288,1)/288 -> 46097.205 | L3: =MROUND((K3-25569)*86400,300) -> 1773636900
A4: 1773637203 | B4: XAUUSD | C4: M5 | D4: 5191.13 | E4: 5013.2638 | F4: 5013.4335 | G4: 5015.2864 | H4: 5012.0865 | J4: =(A4/86400)+25569 -> 46097.208 | K4: =CEILING(INT(J4*1440)/1440*288,1)/288 -> 46097.208 | L4: =MROUND((K4-25569)*86400,300) -> 1773637200
A5: 1773637503 | B5: XAUUSD | C5: M5 | D5: 5188.07 | E5: 5012.8401 | F5: 5013.1368 | G5: 5015.0382 | H5: 5011.323 | J5: =(A5/86400)+25569 -> 46097.212 | K5: =CEILING(INT(J5*1440)/1440*288,1)/288 -> 46097.212 | L5: =MROUND((K5-25569)*86400,300) -> 1773637500
A6: 1773637803 | B6: XAUUSD | C6: M5 | D6: 5188.16 | E6: 5012.2479 | F6: 5012.6924 | G6: 5014.6268 | H6: 5010.4915 | J6: =(A6/86400)+25569 -> 46097.215 | K6: =CEILING(INT(J6*1440)/1440*288,1)/288 -> 46097.215 | L6: =MROUND((K6-25569)*86400,300) -> 1773637800
A7: 1773638103 | B7: XAUUSD | C7: M5 | D7: 5189.61 | E7: 5011.5365 | F7: 5012.1144 | G7: 5014.0961 | H7: 5009.5117 | J7: =(A7/86400)+25569 -> 46097.219 | K7: =CEILING(INT(J7*1440)/1440*288,1)/288 -> 46097.219 | L7: =MROUND((K7-25569)*86400,300) -> 1773638100
A8: 1773638403 | B8: XAUUSD | C8: M5 | D8: 5186.84 | E8: 5010.8773 | F8: 5011.4959 | G8: 5013.5584 | H8: 5008.6122 | J8: =(A8/86400)+25569 -> 46097.222 | K8: =CEILING(INT(J8*1440)/1440*288,1)/288 -> 46097.222 | L8: =MROUND((K8-25569)*86400,300) -> 1773638400
A9: 1773638703 | B9: XAUUSD | C9: M5 | D9: 5186.59 | E9: 5010.3514 | F9: 5010.9236 | G9: 5013.1017 | H9: 5007.8467 | J9: =(A9/86400)+25569 -> 46097.226 | K9: =CEILING(INT(J9*1440)/1440*288,1)/288 -> 46097.226 | L9: =MROUND((K9-25569)*86400,300) -> 1773638700
A10: 1773639003 | B10: XAUUSD | C10: M5 | D10: 5186.07 | E10: 5010.2166 | F10: 5010.5701 | G10: 5012.8825 | H10: 5007.391 | J10: =(A10/86400)+25569 -> 46097.229 | K10: =CEILING(INT(J10*1440)/1440*288,1)/288 -> 46097.229 | L10: =MROUND((K10-25569)*86400,300) -> 1773639000
A11: 1773639303 | B11: XAUUSD | C11: M5 | D11: 5185.23 | E11: 5010.9042 | F11: 5010.7372 | G11: 5013.1678 | H11: 5007.6073 | J11: =(A11/86400)+25569 -> 46097.233 | K11: =CEILING(INT(J11*1440)/1440*288,1)/288 -> 46097.233 | L11: =MROUND((K11-25569)*86400,300) -> 1773639300
A12: 1773639603 | B12: XAUUSD | C12: M5 | D12: 5187.18 | E12: 5012.2555 | F12: 5011.4963 | G12: 5014.087 | H12: 5008.6286 | J12: =(A12/86400)+25569 -> 46097.236 | K12: =CEILING(INT(J12*1440)/1440*288,1)/288 -> 46097.236 | L12: =MROUND((K12-25569)*86400,300) -> 1773639600
A13: 1773639903 | B13: XAUUSD | C13: M5 | D13: 5189.99 | E13: 5014.2112 | F13: 5012.8538 | G13: 5015.5945 | H13: 5010.2851 | J13: =(A13/86400)+25569 -> 46097.24 | K13: =CEILING(INT(J13*1440)/1440*288,1)/288 -> 46097.24 | L13: =MROUND((K13-25569)*86400,300) -> 1773639900
... A500: 1773793203 | B500: XAUUSD | C500: M5 | D500: 5180.32 | E500: 5008.2216 | F500: 5008.187 | G500: 5010.9969 | H500: 5006.9621 | J500: =(A500/86400)+25569 -> 46099.014 | K500: =CEILING(INT(J500*1440)/1440*288,1)/288 -> 46099.014 | L500: =MROUND((K500-25569)*86400,300) -> 1773793200

Sheet Data Validation
A1: =Price!L1 -> timestamp_adjusted | B1: timestamp_adjusted_check | C1: =Price!B1 -> symbol | D1: symbol_check | E1: =Price!C1 -> timeframe | F1: timeframe_check | G1: =Price!D1 -> close | H1: close_check | J1: check_all | K1: check_all_batch
A2: =Price!L2 -> 1772025000 | B2: =AND(Price!L2=Trendlines!Q2,Price!L2=ZigZag!K2,Price!L2=Pinbar!I2,Price!L2=SSA!L2) -> FALSE | C2: =Price!B2 -> XAUUSD | D2: =AND(Price!B2=Trendlines!B2,Price!B2=ZigZag!B2,Price!B2=Pinbar!B2,Price!B2=SSA!B2) -> TRUE | E2: =Price!C2 -> M5 | F2: =AND(Price!C2=Trendlines!C2,Price!C2=ZigZag!C2,Price!C2=Pinbar!C2,Price!C2=SSA!C2) -> TRUE | G2: =Price!D2 -> 5187.2 | H2: =AND(Price!D2=Trendlines!D2,Price!D2=ZigZag!D2,Price!D2=Pinbar!D2,Price!D2=SSA!D2) -> TRUE | J2: =AND(B2=TRUE,D2=TRUE,F2=TRUE,H2=TRUE) -> FALSE | K2: =AND(J2:J500) -> FALSE
A3: =Price!L3 -> 1772025300 | B3: =AND(Price!L3=Trendlines!Q3,Price!L3=ZigZag!K3,Price!L3=Pinbar!I3,Price!L3=SSA!L3) -> FALSE | C3: =Price!B3 -> XAUUSD | D3: =AND(Price!B3=Trendlines!B3,Price!B3=ZigZag!B3,Price!B3=Pinbar!B3,Price!B3=SSA!B3) -> TRUE | E3: =Price!C3 -> M5 | F3: =AND(Price!C3=Trendlines!C3,Price!C3=ZigZag!C3,Price!C3=Pinbar!C3,Price!C3=SSA!C3) -> TRUE | G3: =Price!D3 -> 5187 | H3: =AND(Price!D3=Trendlines!D3,Price!D3=ZigZag!D3,Price!D3=Pinbar!D3,Price!D3=SSA!D3) -> TRUE | J3: =AND(B3=TRUE,D3=TRUE,F3=TRUE,H3=TRUE) -> FALSE
A4: =Price!L4 -> 1772025600 | B4: =AND(Price!L4=Trendlines!Q4,Price!L4=ZigZag!K4,Price!L4=Pinbar!I4,Price!L4=SSA!L4) -> FALSE | C4: =Price!B4 -> XAUUSD | D4: =AND(Price!B4=Trendlines!B4,Price!B4=ZigZag!B4,Price!B4=Pinbar!B4,Price!B4=SSA!B4) -> TRUE | E4: =Price!C4 -> M5 | F4: =AND(Price!C4=Trendlines!C4,Price!C4=ZigZag!C4,Price!C4=Pinbar!C4,Price!C4=SSA!C4) -> TRUE | G4: =Price!D4 -> 5191.13 | H4: =AND(Price!D4=Trendlines!D4,Price!D4=ZigZag!D4,Price!D4=Pinbar!D4,Price!D4=SSA!D4) -> TRUE | J4: =AND(B4=TRUE,D4=TRUE,F4=TRUE,H4=TRUE) -> FALSE
A5: =Price!L5 -> 1772025900 | B5: =AND(Price!L5=Trendlines!Q5,Price!L5=ZigZag!K5,Price!L5=Pinbar!I5,Price!L5=SSA!L5) -> FALSE | C5: =Price!B5 -> XAUUSD | D5: =AND(Price!B5=Trendlines!B5,Price!B5=ZigZag!B5,Price!B5=Pinbar!B5,Price!B5=SSA!B5) -> TRUE | E5: =Price!C5 -> M5 | F5: =AND(Price!C5=Trendlines!C5,Price!C5=ZigZag!C5,Price!C5=Pinbar!C5,Price!C5=SSA!C5) -> TRUE | G5: =Price!D5 -> 5188.07 | H5: =AND(Price!D5=Trendlines!D5,Price!D5=ZigZag!D5,Price!D5=Pinbar!D5,Price!D5=SSA!D5) -> TRUE | J5: =AND(B5=TRUE,D5=TRUE,F5=TRUE,H5=TRUE) -> FALSE
A6: =Price!L6 -> 1772026200 | B6: =AND(Price!L6=Trendlines!Q6,Price!L6=ZigZag!K6,Price!L6=Pinbar!I6,Price!L6=SSA!L6) -> FALSE | C6: =Price!B6 -> XAUUSD | D6: =AND(Price!B6=Trendlines!B6,Price!B6=ZigZag!B6,Price!B6=Pinbar!B6,Price!B6=SSA!B6) -> TRUE | E6: =Price!C6 -> M5 | F6: =AND(Price!C6=Trendlines!C6,Price!C6=ZigZag!C6,Price!C6=Pinbar!C6,Price!C6=SSA!C6) -> TRUE | G6: =Price!D6 -> 5188.16 | H6: =AND(Price!D6=Trendlines!D6,Price!D6=ZigZag!D6,Price!D6=Pinbar!D6,Price!D6=SSA!D6) -> TRUE | J6: =AND(B6=TRUE,D6=TRUE,F6=TRUE,H6=TRUE) -> FALSE
A7: =Price!L7 -> 1772026500 | B7: =AND(Price!L7=Trendlines!Q7,Price!L7=ZigZag!K7,Price!L7=Pinbar!I7,Price!L7=SSA!L7) -> FALSE | C7: =Price!B7 -> XAUUSD | D7: =AND(Price!B7=Trendlines!B7,Price!B7=ZigZag!B7,Price!B7=Pinbar!B7,Price!B7=SSA!B7) -> TRUE | E7: =Price!C7 -> M5 | F7: =AND(Price!C7=Trendlines!C7,Price!C7=ZigZag!C7,Price!C7=Pinbar!C7,Price!C7=SSA!C7) -> TRUE | G7: =Price!D7 -> 5189.61 | H7: =AND(Price!D7=Trendlines!D7,Price!D7=ZigZag!D7,Price!D7=Pinbar!D7,Price!D7=SSA!D7) -> TRUE | J7: =AND(B7=TRUE,D7=TRUE,F7=TRUE,H7=TRUE) -> FALSE
A8: =Price!L8 -> 1772026800 | B8: =AND(Price!L8=Trendlines!Q8,Price!L8=ZigZag!K8,Price!L8=Pinbar!I8,Price!L8=SSA!L8) -> FALSE | C8: =Price!B8 -> XAUUSD | D8: =AND(Price!B8=Trendlines!B8,Price!B8=ZigZag!B8,Price!B8=Pinbar!B8,Price!B8=SSA!B8) -> TRUE | E8: =Price!C8 -> M5 | F8: =AND(Price!C8=Trendlines!C8,Price!C8=ZigZag!C8,Price!C8=Pinbar!C8,Price!C8=SSA!C8) -> TRUE | G8: =Price!D8 -> 5186.84 | H8: =AND(Price!D8=Trendlines!D8,Price!D8=ZigZag!D8,Price!D8=Pinbar!D8,Price!D8=SSA!D8) -> TRUE | J8: =AND(B8=TRUE,D8=TRUE,F8=TRUE,H8=TRUE) -> FALSE
A9: =Price!L9 -> 1772027100 | B9: =AND(Price!L9=Trendlines!Q9,Price!L9=ZigZag!K9,Price!L9=Pinbar!I9,Price!L9=SSA!L9) -> FALSE | C9: =Price!B9 -> XAUUSD | D9: =AND(Price!B9=Trendlines!B9,Price!B9=ZigZag!B9,Price!B9=Pinbar!B9,Price!B9=SSA!B9) -> TRUE | E9: =Price!C9 -> M5 | F9: =AND(Price!C9=Trendlines!C9,Price!C9=ZigZag!C9,Price!C9=Pinbar!C9,Price!C9=SSA!C9) -> TRUE | G9: =Price!D9 -> 5186.59 | H9: =AND(Price!D9=Trendlines!D9,Price!D9=ZigZag!D9,Price!D9=Pinbar!D9,Price!D9=SSA!D9) -> TRUE | J9: =AND(B9=TRUE,D9=TRUE,F9=TRUE,H9=TRUE) -> FALSE
A10: =Price!L10 -> 1772027400 | B10: =AND(Price!L10=Trendlines!Q10,Price!L10=ZigZag!K10,Price!L10=Pinbar!I10,Price!L10=SSA!L10) -> FALSE | C10: =Price!B10 -> XAUUSD | D10: =AND(Price!B10=Trendlines!B10,Price!B10=ZigZag!B10,Price!B10=Pinbar!B10,Price!B10=SSA!B10) -> TRUE | E10: =Price!C10 -> M5 | F10: =AND(Price!C10=Trendlines!C10,Price!C10=ZigZag!C10,Price!C10=Pinbar!C10,Price!C10=SSA!C10) -> TRUE | G10: =Price!D10 -> 5186.07 | H10: =AND(Price!D10=Trendlines!D10,Price!D10=ZigZag!D10,Price!D10=Pinbar!D10,Price!D10=SSA!D10) -> TRUE | J10: =AND(B10=TRUE,D10=TRUE,F10=TRUE,H10=TRUE) -> FALSE
A11: =Price!L11 -> 1772027700 | B11: =AND(Price!L11=Trendlines!Q11,Price!L11=ZigZag!K11,Price!L11=Pinbar!I11,Price!L11=SSA!L11) -> FALSE | C11: =Price!B11 -> XAUUSD | D11: =AND(Price!B11=Trendlines!B11,Price!B11=ZigZag!B11,Price!B11=Pinbar!B11,Price!B11=SSA!B11) -> TRUE | E11: =Price!C11 -> M5 | F11: =AND(Price!C11=Trendlines!C11,Price!C11=ZigZag!C11,Price!C11=Pinbar!C11,Price!C11=SSA!C11) -> TRUE | G11: =Price!D11 -> 5185.23 | H11: =AND(Price!D11=Trendlines!D11,Price!D11=ZigZag!D11,Price!D11=Pinbar!D11,Price!D11=SSA!D11) -> TRUE | J11: =AND(B11=TRUE,D11=TRUE,F11=TRUE,H11=TRUE) -> FALSE
A12: =Price!L12 -> 1772028000 | B12: =AND(Price!L12=Trendlines!Q12,Price!L12=ZigZag!K12,Price!L12=Pinbar!I12,Price!L12=SSA!L12) -> FALSE | C12: =Price!B12 -> XAUUSD | D12: =AND(Price!B12=Trendlines!B12,Price!B12=ZigZag!B12,Price!B12=Pinbar!B12,Price!B12=SSA!B12) -> TRUE | E12: =Price!C12 -> M5 | F12: =AND(Price!C12=Trendlines!C12,Price!C12=ZigZag!C12,Price!C12=Pinbar!C12,Price!C12=SSA!C12) -> TRUE | G12: =Price!D12 -> 5187.18 | H12: =AND(Price!D12=Trendlines!D12,Price!D12=ZigZag!D12,Price!D12=Pinbar!D12,Price!D12=SSA!D12) -> TRUE | J12: =AND(B12=TRUE,D12=TRUE,F12=TRUE,H12=TRUE) -> FALSE
A13: =Price!L13 -> 1772028300 | B13: =AND(Price!L13=Trendlines!Q13,Price!L13=ZigZag!K13,Price!L13=Pinbar!I13,Price!L13=SSA!L13) -> FALSE | C13: =Price!B13 -> XAUUSD | D13: =AND(Price!B13=Trendlines!B13,Price!B13=ZigZag!B13,Price!B13=Pinbar!B13,Price!B13=SSA!B13) -> TRUE | E13: =Price!C13 -> M5 | F13: =AND(Price!C13=Trendlines!C13,Price!C13=ZigZag!C13,Price!C13=Pinbar!C13,Price!C13=SSA!C13) -> TRUE | G13: =Price!D13 -> 5189.99 | H13: =AND(Price!D13=Trendlines!D13,Price!D13=ZigZag!D13,Price!D13=Pinbar!D13,Price!D13=SSA!D13) -> TRUE | J13: =AND(B13=TRUE,D13=TRUE,F13=TRUE,H13=TRUE) -> FALSE
A14: =Price!L14 -> 1772028600 | B14: =AND(Price!L14=Trendlines!Q14,Price!L14=ZigZag!K14,Price!L14=Pinbar!I14,Price!L14=SSA!L14) -> FALSE | C14: =Price!B14 -> XAUUSD | D14: =AND(Price!B14=Trendlines!B14,Price!B14=ZigZag!B14,Price!B14=Pinbar!B14,Price!B14=SSA!B14) -> TRUE | E14: =Price!C14 -> M5 | F14: =AND(Price!C14=Trendlines!C14,Price!C14=ZigZag!C14,Price!C14=Pinbar!C14,Price!C14=SSA!C14) -> TRUE | G14: =Price!D14 -> 5185.44 | H14: =AND(Price!D14=Trendlines!D14,Price!D14=ZigZag!D14,Price!D14=Pinbar!D14,Price!D14=SSA!D14) -> TRUE | J14: =AND(B14=TRUE,D14=TRUE,F14=TRUE,H14=TRUE) -> FALSE
... A500: =Price!L500 -> 1772181600 | B500: =AND(Price!L500=Trendlines!Q500,Price!L500=ZigZag!K500,Price!L500=Pinbar!I500,Price!L500=SSA!L500) -> FALSE | C500: =Price!B500 -> XAUUSD | D500: =AND(Price!B500=Trendlines!B500,Price!B500=ZigZag!B500,Price!B500=Pinbar!B500,Price!B500=SSA!B500) -> TRUE | E500: =Price!C500 -> M5 | F500: =AND(Price!C500=Trendlines!C500,Price!C500=ZigZag!C500,Price!C500=Pinbar!C500,Price!C500=SSA!C500) -> TRUE | G500: =Price!D500 -> 5180.32 | H500: =AND(Price!D500=Trendlines!D500,Price!D500=ZigZag!D500,Price!D500=Pinbar!D500,Price!D500=SSA!D500) -> TRUE | J500: =AND(B500=TRUE,D500=TRUE,F500=TRUE,H500=TRUE) -> FALSE

Sheet S&R Level Analysis
A1: ='Data Validation'!A1 -> timestamp_adjusted | B1: ='Data Validation'!C1 -> symbol | C1: ='Data Validation'!E1 -> timeframe | D1: ='Data Validation'!G1 -> close | E1: =Price!F1 -> high | F1: =Price!G1 -> low | G1: =Price!H1 -> volume | H1: =SSA!E1 -> ssa | I1: =SSA!F1 -> ema_ssa | J1: =SSA!G1 -> ssa_high | K1: =SSA!H1 -> ssa_low | L1: =Trendlines!K1 -> horiz_high_map | M1: =Trendlines!L1 -> horiz_low_map | N1: =ZigZag!E1 -> zigzag_high | O1: =ZigZag!F1 -> zigzag_low | P1: =Pinbar!E1 -> pinbar | Q1: =Trendlines!E1 -> horiz_peak_line_1 | R1: =Trendlines!H1 -> horiz_bottom_line_1 | S1: 5m_prev_high | T1: 5m_prev_low | U1: 5m_high_diff | V1: 5m_low_diff | W1: 5m_h_l | X1: 5m_h_prev_close | Y1: 5m_l_prev_close | Z1: 5m_tr | AA1: 5m_ssa_emassa | AB1: 5m_ssa_emassa_direction | AC1: 5m_ssa_ema_counter | AD1: 5m_max_ssa_counter | AE1: 5m_min_ssa_counter | AF1: up_ssa_counter | AG1: down_ssa_counter | AH1: 5m_ssa_emassa_crossover | AI1: 5m_ssa_emassa_crossunder | AJ1: 5m_high_ssahigh | AK1: 5m_low_ssalow | AL1: 5m_high_ssahigh_reverse | AM1: 5m_high_ssahigh_direct | AN1: 5m_low_ssalow_reverse | AO1: 5m_low_ssalow_direct | AP1: zscore_ssahigh_reverse | AQ1: zscore_ssahigh_direct | AR1: norm_area_ssahigh_reverse | AS1: norm_area_ssahigh_direct | AT1: zscore_ssalow_reverse | AU1: zscore_ssalow_direct | AV1: norm_area_ssalow_reverse | AW1: norm_area_ssalow_direct | AY1: 5m_ssa_p1_nearness | AZ1: 5m_ssa_p1_direction | BA1: 5m_ssa_p1_counter | BB1: 5m_ssa_p1_touch | BC1: 5m_ssa_p1_status | BD1: 5m_ssa_b1_nearness | BE1: 5m_ssa_b1_direction | BF1: 5m_ssa_b1_counter | BG1: 5m_ssa_b1_touch | BH1: 5m_ssa_b1_status | BI1: 5m_imp_high | BJ1: 5m_imp_low | BK1: 5m_eqh | BL1: 5m_high_value | BM1: 5m_ssa_around_eqh | BN1: 5m_emassa_around_eqh | BO1: 5m_eqh_touch | BP1: 5m_eql | BQ1: 5m_low_value | BR1: 5m_ssa_around_eql | BS1: 5m_emassa_around_eql | BT1: 5m_eql_touch | BU1: 5m_tl_touch_zone | BV1: 5m_count_valid | BW1: 5m_ssa_tl_staus | BX1: 5m_eqhl_touch | BY1: 5m_ssa_emassa_status | BZ1: up_count_classification | CA1: down_count_classification | CB1: 5m_sig_high_spike_uptrend | CC1: 5m_high_spike_downtrend | CD1: 5m_sig_high_spike_downtrend | CE1: 5m_sig_low_spike_downtrend | CF1: 5m_low_spike_uptrend | CG1: 5m_sig_low_spike_downtrend | CH1: 5m_volatility_surge | CI1: 5m_volume_surge | CJ1: 5m_pin_check | CK1: 5m_turb_sum | CL1: 5m_turb_index | CM1: 5m_turb_eval
A2: =IF('Data Validation'!$K$2<>TRUE,"",'Data Validation'!A2) | B2: =IF('Data Validation'!$K$2<>TRUE,"",'Data Validation'!C2) | C2: =IF('Data Validation'!$K$2<>TRUE,"",'Data Validation'!E2) | D2: =IF('Data Validation'!$K$2<>TRUE,"",'Data Validation'!G2) | E2: =IF($C2<>"M5","",Price!F2) | F2: =IF($C2<>"M5","",Price!G2) | G2: =IF($C2<>"M5","",Price!H2) | H2: =IF($C2<>"M5","",SSA!E2) | I2: =IF($C2<>"M5","",SSA!F2) | J2: =IF($C2<>"M5","",SSA!G2) | K2: =IF($C2<>"M5","",SSA!H2) | L2: =IF($C2<>"M5","",Trendlines!K2) | M2: =IF($C2<>"M5","",Trendlines!L2) | N2: =IF($C2<>"M5","",ZigZag!E2) | O2: =IF($C2<>"M5","",ZigZag!F2) | P2: =IF($C2<>"M5","",Pinbar!E2) | Q2: =IF($C2<>"M5","",Trendlines!E2) | R2: =IF($C2<>"M5","",Trendlines!H2) | W2: =IFERROR(E2-F2,"") | Z2: =IF(W2="","",W2) | AA2: =IFERROR(H2-I2,"") | AY2: =IF(OR(Q2=0,Q2=""),"",((H2-Q2)/Q2)) | AZ2: =IF(AY2="","",IF(AY2>=0,1,-1)) | BB2: =IF(AY2="","",IF(AND(AY2>-0.1%,AY2<0.1%),"Touch Zone","")) | BC2: =IF(AY2="","",IF(AND(BB2="Touch Zone",AY2>0%),"Above",IF(AND(BB2="Touch Zone",AY2<0%),"Below",""))) | BD2: =IF(OR(R2=0,R2=""),"",((H2-R2)/R2)) | BE2: =IF(BD2="","",IF(BD2>=0,1,-1)) | BG2: =IF(BD2="","",IF(AND(BD2>-0.1%,BD2<0.1%),"Touch Zone","")) | BH2: =IF(BD2="","",IF(AND(BG2="Touch Zone",BD2>0%),"Above",IF(AND(BG2="Touch Zone",BD2<0%),"Below",""))) | BI2: =IF(OR(L2="",N2=""),"",IF(AND(L2=N2,L2>0,N2>0),"Important High","")) | BJ2: =IF(OR(M2="",O2=""),"",IF(AND(M2=O2,M2>0,O2>0),"Important Low","")) | BU2: =IF(OR(BB2="Touch Zone",BG2="Touch Zone"),"TL Touch Zone","") | BV2: =IF(AND(BC2="",BH2=""),"",COUNTIF(BC2,"Above")+COUNTIF(BC2,"Below")+COUNTIF(BH2,"Above")+COUNTIF(BH2,"Below")) | BW2: {=IF(BV2<>1,"",_xlfn.IFS(OR(BC2="Above",BC2="Below"),BC2,OR(BH2="Above",BH2="Below"),BH2,TRUE,""))} | BY2: =IF(AA2="","",IF(AA2>0,"UP","DOWN")) | CJ2: =IF(P2="","",IF(P2=1,1,""))
A3: =IF('Data Validation'!$K$2<>TRUE,"",'Data Validation'!A3) | B3: =IF('Data Validation'!$K$2<>TRUE,"",'Data Validation'!C3) | C3: =IF('Data Validation'!$K$2<>TRUE,"",'Data Validation'!E3) | D3: =IF('Data Validation'!$K$2<>TRUE,"",'Data Validation'!G3) | E3: =IF($C3<>"M5","",Price!F3) | F3: =IF($C3<>"M5","",Price!G3) | G3: =IF($C3<>"M5","",Price!H3) | H3: =IF($C3<>"M5","",SSA!E3) | I3: =IF($C3<>"M5","",SSA!F3) | J3: =IF($C3<>"M5","",SSA!G3) | K3: =IF($C3<>"M5","",SSA!H3) | L3: =IF($C3<>"M5","",Trendlines!K3) | M3: =IF($C3<>"M5","",Trendlines!L3) | N3: =IF($C3<>"M5","",ZigZag!E3) | O3: =IF($C3<>"M5","",ZigZag!F3) | P3: =IF($C3<>"M5","",Pinbar!E3) | Q3: =IF($C3<>"M5","",Trendlines!E3) | R3: =IF($C3<>"M5","",Trendlines!H3) | W3: =IFERROR(E3-F3,"") | X3: =IFERROR(ABS(E3-D2),"") | Y3: =IFERROR(ABS(F3-D2),"") | Z3: =IF(MAX(W3:Y3)=0,"",MAX(W3:Y3)) | AA3: =IFERROR(H3-I3,"") | AB3: =IF(AA3="","",IF(AA3>=0,1,-1)) | AC3: {=IFERROR((AB3=AB2,AC2+AB3,AB3),"")} | AH3: =IF(AND(H3>I3,H2<I2),"crossover","") | AI3: =IF(AND(H3<I3,H2>I2),"crossunder","") | AJ3: =IFERROR(IF(E3-J3<0,"",(E3-J3)/J3),"") | AK3: =IFERROR(IF(F3-K3>0,"",(F3-K3)/K3),"") | AL3: =IF(AND(AJ3<>"",CC3="High Spike @ Downtrend"),AJ3,"") | AM3: =IF(AND(AJ3<>"",AL3=""),AJ3,"") | AN3: =IF(AND(AK3<>"",CF3="Low Spike @ Uptrend"),AK3,"") | AO3: =IF(AND(AK3<>"",AN3=""),AK3,"") | AY3: =IF(OR(Q3=0,Q3=""),"",((H3-Q3)/Q3)) | AZ3: =IF(AY3="","",IF(AY3>=0,1,-1)) | BA3: =IF(AZ3="","",IF(AZ3=AZ2,BA2+AZ3,AZ3)) | BB3: =IF(AY3="","",IF(AND(AY3>-0.1%,AY3<0.1%),"Touch Zone","")) | BC3: =IF(AY3="","",IF(AND(BB3="Touch Zone",AY3>0%),"Above",IF(AND(BB3="Touch Zone",AY3<0%),"Below",""))) | BD3: =IF(OR(R3=0,R3=""),"",((H3-R3)/R3)) | BE3: =IF(BD3="","",IF(BD3>=0,1,-1)) | BF3: =IF(BE3="","",IF(BE3=BE2,BF2+BE3,BE3)) | BG3: =IF(BD3="","",IF(AND(BD3>-0.1%,BD3<0.1%),"Touch Zone","")) | BH3: =IF(BD3="","",IF(AND(BG3="Touch Zone",BD3>0%),"Above",IF(AND(BG3="Touch Zone",BD3<0%),"Below",""))) | BI3: =IF(OR(L3="",N3=""),"",IF(AND(L3=N3,L3>0,N3>0),"Important High","")) | BJ3: =IF(OR(M3="",O3=""),"",IF(AND(M3=O3,M3>0,O3>0),"Important Low","")) | BU3: =IF(OR(BB3="Touch Zone",BG3="Touch Zone"),"TL Touch Zone","") | BV3: =IF(AND(BC3="",BH3=""),"",COUNTIF(BC3,"Above")+COUNTIF(BC3,"Below")+COUNTIF(BH3,"Above")+COUNTIF(BH3,"Below")) | BW3: {=IF(BV3<>1,"",_xlfn.IFS(OR(BC3="Above",BC3="Below"),BC3,OR(BH3="Above",BH3="Below"),BH3,TRUE,""))} | BY3: =IF(AA3="","",IF(AA3>0,"UP","DOWN")) | BZ3: =IF(AF3="","",IF(AF3<50%,"Early Up Stage",IF(AF3>100%,"Extended Up Stage","Late Up Stage"))) | CA3: =IF(AG3="","",IF(AG3<50%,"Early Down Stage",IF(AG3>100%,"Extended Down Stage","Late Down Stage"))) | CB3: =IF(AS3="","",IF(AS3>90%,"Sig High Spike @ Uptrend","")) | CC3: =IF(AJ3="","",IF(AND(AC3<0,AJ3>0),"High Spike @ Downtrend","")) | CD3: =IF(AND(CC3="High Spike @ Downtrend",AR3>50%),"Sig High Spike @ Downtrend","") | CE3: =IF(AW3="","",IF(AW3>90%,"Sig Low Spike @ Downtrend","")) | CF3: =IF(AK3="","",IF(AND(AC3>0,AK3>0),"Low Spike @ Uptrend","")) | CG3: =IF(AND(CF3="Low Spike @ Uptrend",AV3>50%),"Sig Low Spike @ Uptrend","") | CJ3: =IF(P3="","",IF(P3=1,1,""))
A4: =IF('Data Validation'!$K$2<>TRUE,"",'Data Validation'!A4) | B4: =IF('Data Validation'!$K$2<>TRUE,"",'Data Validation'!C4) | C4: =IF('Data Validation'!$K$2<>TRUE,"",'Data Validation'!E4) | D4: =IF('Data Validation'!$K$2<>TRUE,"",'Data Validation'!G4) | E4: =IF($C4<>"M5","",Price!F4) | F4: =IF($C4<>"M5","",Price!G4) | G4: =IF($C4<>"M5","",Price!H4) | H4: =IF($C4<>"M5","",SSA!E4) | I4: =IF($C4<>"M5","",SSA!F4) | J4: =IF($C4<>"M5","",SSA!G4) | K4: =IF($C4<>"M5","",SSA!H4) | L4: =IF($C4<>"M5","",Trendlines!K4) | M4: =IF($C4<>"M5","",Trendlines!L4) | N4: =IF($C4<>"M5","",ZigZag!E4) | O4: =IF($C4<>"M5","",ZigZag!F4) | P4: =IF($C4<>"M5","",Pinbar!E4) | Q4: =IF($C4<>"M5","",Trendlines!E4) | R4: =IF($C4<>"M5","",Trendlines!H4) | W4: =IFERROR(E4-F4,"") | X4: =IFERROR(ABS(E4-D3),"") | Y4: =IFERROR(ABS(F4-D3),"") | Z4: =IF(MAX(W4:Y4)=0,"",MAX(W4:Y4)) | AA4: =IFERROR(H4-I4,"") | AB4: =IF(AA4="","",IF(AA4>=0,1,-1)) | AC4: {=IFERROR((AB4=AB3,AC3+AB4,AB4),"")} | AH4: =IF(AND(H4>I4,H3<I3),"crossover","") | AI4: =IF(AND(H4<I4,H3>I3),"crossunder","") | AJ4: =IFERROR(IF(E4-J4<0,"",(E4-J4)/J4),"") | AK4: =IFERROR(IF(F4-K4>0,"",(F4-K4)/K4),"") | AL4: =IF(AND(AJ4<>"",CC4="High Spike @ Downtrend"),AJ4,"") | AM4: =IF(AND(AJ4<>"",AL4=""),AJ4,"") | AN4: =IF(AND(AK4<>"",CF4="Low Spike @ Uptrend"),AK4,"") | AO4: =IF(AND(AK4<>"",AN4=""),AK4,"") | AY4: =IF(OR(Q4=0,Q4=""),"",((H4-Q4)/Q4)) | AZ4: =IF(AY4="","",IF(AY4>=0,1,-1)) | BA4: =IF(AZ4="","",IF(AZ4=AZ3,BA3+AZ4,AZ4)) | BB4: =IF(AY4="","",IF(AND(AY4>-0.1%,AY4<0.1%),"Touch Zone","")) | BC4: =IF(AY4="","",IF(AND(BB4="Touch Zone",AY4>0%),"Above",IF(AND(BB4="Touch Zone",AY4<0%),"Below",""))) | BD4: =IF(OR(R4=0,R4=""),"",((H4-R4)/R4)) | BE4: =IF(BD4="","",IF(BD4>=0,1,-1)) | BF4: =IF(BE4="","",IF(BE4=BE3,BF3+BE4,BE4)) | BG4: =IF(BD4="","",IF(AND(BD4>-0.1%,BD4<0.1%),"Touch Zone","")) | BH4: =IF(BD4="","",IF(AND(BG4="Touch Zone",BD4>0%),"Above",IF(AND(BG4="Touch Zone",BD4<0%),"Below",""))) | BI4: =IF(OR(L4="",N4=""),"",IF(AND(L4=N4,L4>0,N4>0),"Important High","")) | BJ4: =IF(OR(M4="",O4=""),"",IF(AND(M4=O4,M4>0,O4>0),"Important Low","")) | BU4: =IF(OR(BB4="Touch Zone",BG4="Touch Zone"),"TL Touch Zone","") | BV4: =IF(AND(BC4="",BH4=""),"",COUNTIF(BC4,"Above")+COUNTIF(BC4,"Below")+COUNTIF(BH4,"Above")+COUNTIF(BH4,"Below")) | BW4: {=IF(BV4<>1,"",_xlfn.IFS(OR(BC4="Above",BC4="Below"),BC4,OR(BH4="Above",BH4="Below"),BH4,TRUE,""))} | BY4: =IF(AA4="","",IF(AA4>0,"UP","DOWN")) | BZ4: =IF(AF4="","",IF(AF4<50%,"Early Up Stage",IF(AF4>100%,"Extended Up Stage","Late Up Stage"))) | CA4: =IF(AG4="","",IF(AG4<50%,"Early Down Stage",IF(AG4>100%,"Extended Down Stage","Late Down Stage"))) | CB4: =IF(AS4="","",IF(AS4>90%,"Sig High Spike @ Uptrend","")) | CC4: =IF(AJ4="","",IF(AND(AC4<0,AJ4>0),"High Spike @ Downtrend","")) | CD4: =IF(AND(CC4="High Spike @ Downtrend",AR4>50%),"Sig High Spike @ Downtrend","") | CE4: =IF(AW4="","",IF(AW4>90%,"Sig Low Spike @ Downtrend","")) | CF4: =IF(AK4="","",IF(AND(AC4>0,AK4>0),"Low Spike @ Uptrend","")) | CG4: =IF(AND(CF4="Low Spike @ Uptrend",AV4>50%),"Sig Low Spike @ Uptrend","") | CJ4: =IF(P4="","",IF(P4=1,1,""))
A5: =IF('Data Validation'!$K$2<>TRUE,"",'Data Validation'!A5) | B5: =IF('Data Validation'!$K$2<>TRUE,"",'Data Validation'!C5) | C5: =IF('Data Validation'!$K$2<>TRUE,"",'Data Validation'!E5) | D5: =IF('Data Validation'!$K$2<>TRUE,"",'Data Validation'!G5) | E5: =IF($C5<>"M5","",Price!F5) | F5: =IF($C5<>"M5","",Price!G5) | G5: =IF($C5<>"M5","",Price!H5) | H5: =IF($C5<>"M5","",SSA!E5) | I5: =IF($C5<>"M5","",SSA!F5) | J5: =IF($C5<>"M5","",SSA!G5) | K5: =IF($C5<>"M5","",SSA!H5) | L5: =IF($C5<>"M5","",Trendlines!K5) | M5: =IF($C5<>"M5","",Trendlines!L5) | N5: =IF($C5<>"M5","",ZigZag!E5) | O5: =IF($C5<>"M5","",ZigZag!F5) | P5: =IF($C5<>"M5","",Pinbar!E5) | Q5: =IF($C5<>"M5","",Trendlines!E5) | R5: =IF($C5<>"M5","",Trendlines!H5) | W5: =IFERROR(E5-F5,"") | X5: =IFERROR(ABS(E5-D4),"") | Y5: =IFERROR(ABS(F5-D4),"") | Z5: =IF(MAX(W5:Y5)=0,"",MAX(W5:Y5)) | AA5: =IFERROR(H5-I5,"") | AB5: =IF(AA5="","",IF(AA5>=0,1,-1)) | AC5: {=IFERROR((AB5=AB4,AC4+AB5,AB5),"")} | AH5: =IF(AND(H5>I5,H4<I4),"crossover","") | AI5: =IF(AND(H5<I5,H4>I4),"crossunder","") | AJ5: =IFERROR(IF(E5-J5<0,"",(E5-J5)/J5),"") | AK5: =IFERROR(IF(F5-K5>0,"",(F5-K5)/K5),"") | AL5: =IF(AND(AJ5<>"",CC5="High Spike @ Downtrend"),AJ5,"") | AM5: =IF(AND(AJ5<>"",AL5=""),AJ5,"") | AN5: =IF(AND(AK5<>"",CF5="Low Spike @ Uptrend"),AK5,"") | AO5: =IF(AND(AK5<>"",AN5=""),AK5,"") | AY5: =IF(OR(Q5=0,Q5=""),"",((H5-Q5)/Q5)) | AZ5: =IF(AY5="","",IF(AY5>=0,1,-1)) | BA5: =IF(AZ5="","",IF(AZ5=AZ4,BA4+AZ5,AZ5)) | BB5: =IF(AY5="","",IF(AND(AY5>-0.1%,AY5<0.1%),"Touch Zone","")) | BC5: =IF(AY5="","",IF(AND(BB5="Touch Zone",AY5>0%),"Above",IF(AND(BB5="Touch Zone",AY5<0%),"Below",""))) | BD5: =IF(OR(R5=0,R5=""),"",((H5-R5)/R5)) | BE5: =IF(BD5="","",IF(BD5>=0,1,-1)) | BF5: =IF(BE5="","",IF(BE5=BE4,BF4+BE5,BE5)) | BG5: =IF(BD5="","",IF(AND(BD5>-0.1%,BD5<0.1%),"Touch Zone","")) | BH5: =IF(BD5="","",IF(AND(BG5="Touch Zone",BD5>0%),"Above",IF(AND(BG5="Touch Zone",BD5<0%),"Below",""))) | BI5: =IF(OR(L5="",N5=""),"",IF(AND(L5=N5,L5>0,N5>0),"Important High","")) | BJ5: =IF(OR(M5="",O5=""),"",IF(AND(M5=O5,M5>0,O5>0),"Important Low","")) | BU5: =IF(OR(BB5="Touch Zone",BG5="Touch Zone"),"TL Touch Zone","") | BV5: =IF(AND(BC5="",BH5=""),"",COUNTIF(BC5,"Above")+COUNTIF(BC5,"Below")+COUNTIF(BH5,"Above")+COUNTIF(BH5,"Below")) | BW5: {=IF(BV5<>1,"",_xlfn.IFS(OR(BC5="Above",BC5="Below"),BC5,OR(BH5="Above",BH5="Below"),BH5,TRUE,""))} | BY5: =IF(AA5="","",IF(AA5>0,"UP","DOWN")) | BZ5: =IF(AF5="","",IF(AF5<50%,"Early Up Stage",IF(AF5>100%,"Extended Up Stage","Late Up Stage"))) | CA5: =IF(AG5="","",IF(AG5<50%,"Early Down Stage",IF(AG5>100%,"Extended Down Stage","Late Down Stage"))) | CB5: =IF(AS5="","",IF(AS5>90%,"Sig High Spike @ Uptrend","")) | CC5: =IF(AJ5="","",IF(AND(AC5<0,AJ5>0),"High Spike @ Downtrend","")) | CD5: =IF(AND(CC5="High Spike @ Downtrend",AR5>50%),"Sig High Spike @ Downtrend","") | CE5: =IF(AW5="","",IF(AW5>90%,"Sig Low Spike @ Downtrend","")) | CF5: =IF(AK5="","",IF(AND(AC5>0,AK5>0),"Low Spike @ Uptrend","")) | CG5: =IF(AND(CF5="Low Spike @ Uptrend",AV5>50%),"Sig Low Spike @ Uptrend","") | CJ5: =IF(P5="","",IF(P5=1,1,""))
A6: =IF('Data Validation'!$K$2<>TRUE,"",'Data Validation'!A6) | B6: =IF('Data Validation'!$K$2<>TRUE,"",'Data Validation'!C6) | C6: =IF('Data Validation'!$K$2<>TRUE,"",'Data Validation'!E6) | D6: =IF('Data Validation'!$K$2<>TRUE,"",'Data Validation'!G6) | E6: =IF($C6<>"M5","",Price!F6) | F6: =IF($C6<>"M5","",Price!G6) | G6: =IF($C6<>"M5","",Price!H6) | H6: =IF($C6<>"M5","",SSA!E6) | I6: =IF($C6<>"M5","",SSA!F6) | J6: =IF($C6<>"M5","",SSA!G6) | K6: =IF($C6<>"M5","",SSA!H6) | L6: =IF($C6<>"M5","",Trendlines!K6) | M6: =IF($C6<>"M5","",Trendlines!L6) | N6: =IF($C6<>"M5","",ZigZag!E6) | O6: =IF($C6<>"M5","",ZigZag!F6) | P6: =IF($C6<>"M5","",Pinbar!E6) | Q6: =IF($C6<>"M5","",Trendlines!E6) | R6: =IF($C6<>"M5","",Trendlines!H6) | W6: =IFERROR(E6-F6,"") | X6: =IFERROR(ABS(E6-D5),"") | Y6: =IFERROR(ABS(F6-D5),"") | Z6: =IF(MAX(W6:Y6)=0,"",MAX(W6:Y6)) | AA6: =IFERROR(H6-I6,"") | AB6: =IF(AA6="","",IF(AA6>=0,1,-1)) | AC6: {=IFERROR((AB6=AB5,AC5+AB6,AB6),"")} | AH6: =IF(AND(H6>I6,H5<I5),"crossover","") | AI6: =IF(AND(H6<I6,H5>I5),"crossunder","") | AJ6: =IFERROR(IF(E6-J6<0,"",(E6-J6)/J6),"") | AK6: =IFERROR(IF(F6-K6>0,"",(F6-K6)/K6),"") | AL6: =IF(AND(AJ6<>"",CC6="High Spike @ Downtrend"),AJ6,"") | AM6: =IF(AND(AJ6<>"",AL6=""),AJ6,"") | AN6: =IF(AND(AK6<>"",CF6="Low Spike @ Uptrend"),AK6,"") | AO6: =IF(AND(AK6<>"",AN6=""),AK6,"") | AY6: =IF(OR(Q6=0,Q6=""),"",((H6-Q6)/Q6)) | AZ6: =IF(AY6="","",IF(AY6>=0,1,-1)) | BA6: =IF(AZ6="","",IF(AZ6=AZ5,BA5+AZ6,AZ6)) | BB6: =IF(AY6="","",IF(AND(AY6>-0.1%,AY6<0.1%),"Touch Zone","")) | BC6: =IF(AY6="","",IF(AND(BB6="Touch Zone",AY6>0%),"Above",IF(AND(BB6="Touch Zone",AY6<0%),"Below",""))) | BD6: =IF(OR(R6=0,R6=""),"",((H6-R6)/R6)) | BE6: =IF(BD6="","",IF(BD6>=0,1,-1)) | BF6: =IF(BE6="","",IF(BE6=BE5,BF5+BE6,BE6)) | BG6: =IF(BD6="","",IF(AND(BD6>-0.1%,BD6<0.1%),"Touch Zone","")) | BH6: =IF(BD6="","",IF(AND(BG6="Touch Zone",BD6>0%),"Above",IF(AND(BG6="Touch Zone",BD6<0%),"Below",""))) | BI6: =IF(OR(L6="",N6=""),"",IF(AND(L6=N6,L6>0,N6>0),"Important High","")) | BJ6: =IF(OR(M6="",O6=""),"",IF(AND(M6=O6,M6>0,O6>0),"Important Low","")) | BU6: =IF(OR(BB6="Touch Zone",BG6="Touch Zone"),"TL Touch Zone","") | BV6: =IF(AND(BC6="",BH6=""),"",COUNTIF(BC6,"Above")+COUNTIF(BC6,"Below")+COUNTIF(BH6,"Above")+COUNTIF(BH6,"Below")) | BW6: {=IF(BV6<>1,"",_xlfn.IFS(OR(BC6="Above",BC6="Below"),BC6,OR(BH6="Above",BH6="Below"),BH6,TRUE,""))} | BY6: =IF(AA6="","",IF(AA6>0,"UP","DOWN")) | BZ6: =IF(AF6="","",IF(AF6<50%,"Early Up Stage",IF(AF6>100%,"Extended Up Stage","Late Up Stage"))) | CA6: =IF(AG6="","",IF(AG6<50%,"Early Down Stage",IF(AG6>100%,"Extended Down Stage","Late Down Stage"))) | CB6: =IF(AS6="","",IF(AS6>90%,"Sig High Spike @ Uptrend","")) | CC6: =IF(AJ6="","",IF(AND(AC6<0,AJ6>0),"High Spike @ Downtrend","")) | CD6: =IF(AND(CC6="High Spike @ Downtrend",AR6>50%),"Sig High Spike @ Downtrend","") | CE6: =IF(AW6="","",IF(AW6>90%,"Sig Low Spike @ Downtrend","")) | CF6: =IF(AK6="","",IF(AND(AC6>0,AK6>0),"Low Spike @ Uptrend","")) | CG6: =IF(AND(CF6="Low Spike @ Uptrend",AV6>50%),"Sig Low Spike @ Uptrend","") | CJ6: =IF(P6="","",IF(P6=1,1,""))
A7: =IF('Data Validation'!$K$2<>TRUE,"",'Data Validation'!A7) | B7: =IF('Data Validation'!$K$2<>TRUE,"",'Data Validation'!C7) | C7: =IF('Data Validation'!$K$2<>TRUE,"",'Data Validation'!E7) | D7: =IF('Data Validation'!$K$2<>TRUE,"",'Data Validation'!G7) | E7: =IF($C7<>"M5","",Price!F7) | F7: =IF($C7<>"M5","",Price!G7) | G7: =IF($C7<>"M5","",Price!H7) | H7: =IF($C7<>"M5","",SSA!E7) | I7: =IF($C7<>"M5","",SSA!F7) | J7: =IF($C7<>"M5","",SSA!G7) | K7: =IF($C7<>"M5","",SSA!H7) | L7: =IF($C7<>"M5","",Trendlines!K7) | M7: =IF($C7<>"M5","",Trendlines!L7) | N7: =IF($C7<>"M5","",ZigZag!E7) | O7: =IF($C7<>"M5","",ZigZag!F7) | P7: =IF($C7<>"M5","",Pinbar!E7) | Q7: =IF($C7<>"M5","",Trendlines!E7) | R7: =IF($C7<>"M5","",Trendlines!H7) | W7: =IFERROR(E7-F7,"") | X7: =IFERROR(ABS(E7-D6),"") | Y7: =IFERROR(ABS(F7-D6),"") | Z7: =IF(MAX(W7:Y7)=0,"",MAX(W7:Y7)) | AA7: =IFERROR(H7-I7,"") | AB7: =IF(AA7="","",IF(AA7>=0,1,-1)) | AC7: {=IFERROR((AB7=AB6,AC6+AB7,AB7),"")} | AH7: =IF(AND(H7>I7,H6<I6),"crossover","") | AI7: =IF(AND(H7<I7,H6>I6),"crossunder","") | AJ7: =IFERROR(IF(E7-J7<0,"",(E7-J7)/J7),"") | AK7: =IFERROR(IF(F7-K7>0,"",(F7-K7)/K7),"") | AL7: =IF(AND(AJ7<>"",CC7="High Spike @ Downtrend"),AJ7,"") | AM7: =IF(AND(AJ7<>"",AL7=""),AJ7,"") | AN7: =IF(AND(AK7<>"",CF7="Low Spike @ Uptrend"),AK7,"") | AO7: =IF(AND(AK7<>"",AN7=""),AK7,"") | AY7: =IF(OR(Q7=0,Q7=""),"",((H7-Q7)/Q7)) | AZ7: =IF(AY7="","",IF(AY7>=0,1,-1)) | BA7: =IF(AZ7="","",IF(AZ7=AZ6,BA6+AZ7,AZ7)) | BB7: =IF(AY7="","",IF(AND(AY7>-0.1%,AY7<0.1%),"Touch Zone","")) | BC7: =IF(AY7="","",IF(AND(BB7="Touch Zone",AY7>0%),"Above",IF(AND(BB7="Touch Zone",AY7<0%),"Below",""))) | BD7: =IF(OR(R7=0,R7=""),"",((H7-R7)/R7)) | BE7: =IF(BD7="","",IF(BD7>=0,1,-1)) | BF7: =IF(BE7="","",IF(BE7=BE6,BF6+BE7,BE7)) | BG7: =IF(BD7="","",IF(AND(BD7>-0.1%,BD7<0.1%),"Touch Zone","")) | BH7: =IF(BD7="","",IF(AND(BG7="Touch Zone",BD7>0%),"Above",IF(AND(BG7="Touch Zone",BD7<0%),"Below",""))) | BI7: =IF(OR(L7="",N7=""),"",IF(AND(L7=N7,L7>0,N7>0),"Important High","")) | BJ7: =IF(OR(M7="",O7=""),"",IF(AND(M7=O7,M7>0,O7>0),"Important Low","")) | BU7: =IF(OR(BB7="Touch Zone",BG7="Touch Zone"),"TL Touch Zone","") | BV7: =IF(AND(BC7="",BH7=""),"",COUNTIF(BC7,"Above")+COUNTIF(BC7,"Below")+COUNTIF(BH7,"Above")+COUNTIF(BH7,"Below")) | BW7: {=IF(BV7<>1,"",_xlfn.IFS(OR(BC7="Above",BC7="Below"),BC7,OR(BH7="Above",BH7="Below"),BH7,TRUE,""))} | BY7: =IF(AA7="","",IF(AA7>0,"UP","DOWN")) | BZ7: =IF(AF7="","",IF(AF7<50%,"Early Up Stage",IF(AF7>100%,"Extended Up Stage","Late Up Stage"))) | CA7: =IF(AG7="","",IF(AG7<50%,"Early Down Stage",IF(AG7>100%,"Extended Down Stage","Late Down Stage"))) | CB7: =IF(AS7="","",IF(AS7>90%,"Sig High Spike @ Uptrend","")) | CC7: =IF(AJ7="","",IF(AND(AC7<0,AJ7>0),"High Spike @ Downtrend","")) | CD7: =IF(AND(CC7="High Spike @ Downtrend",AR7>50%),"Sig High Spike @ Downtrend","") | CE7: =IF(AW7="","",IF(AW7>90%,"Sig Low Spike @ Downtrend","")) | CF7: =IF(AK7="","",IF(AND(AC7>0,AK7>0),"Low Spike @ Uptrend","")) | CG7: =IF(AND(CF7="Low Spike @ Uptrend",AV7>50%),"Sig Low Spike @ Uptrend","") | CJ7: =IF(P7="","",IF(P7=1,1,""))
A8: =IF('Data Validation'!$K$2<>TRUE,"",'Data Validation'!A8) | B8: =IF('Data Validation'!$K$2<>TRUE,"",'Data Validation'!C8) | C8: =IF('Data Validation'!$K$2<>TRUE,"",'Data Validation'!E8) | D8: =IF('Data Validation'!$K$2<>TRUE,"",'Data Validation'!G8) | E8: =IF($C8<>"M5","",Price!F8) | F8: =IF($C8<>"M5","",Price!G8) | G8: =IF($C8<>"M5","",Price!H8) | H8: =IF($C8<>"M5","",SSA!E8) | I8: =IF($C8<>"M5","",SSA!F8) | J8: =IF($C8<>"M5","",SSA!G8) | K8: =IF($C8<>"M5","",SSA!H8) | L8: =IF($C8<>"M5","",Trendlines!K8) | M8: =IF($C8<>"M5","",Trendlines!L8) | N8: =IF($C8<>"M5","",ZigZag!E8) | O8: =IF($C8<>"M5","",ZigZag!F8) | P8: =IF($C8<>"M5","",Pinbar!E8) | Q8: =IF($C8<>"M5","",Trendlines!E8) | R8: =IF($C8<>"M5","",Trendlines!H8) | W8: =IFERROR(E8-F8,"") | X8: =IFERROR(ABS(E8-D7),"") | Y8: =IFERROR(ABS(F8-D7),"") | Z8: =IF(MAX(W8:Y8)=0,"",MAX(W8:Y8)) | AA8: =IFERROR(H8-I8,"") | AB8: =IF(AA8="","",IF(AA8>=0,1,-1)) | AC8: {=IFERROR((AB8=AB7,AC7+AB8,AB8),"")} | AH8: =IF(AND(H8>I8,H7<I7),"crossover","") | AI8: =IF(AND(H8<I8,H7>I7),"crossunder","") | AJ8: =IFERROR(IF(E8-J8<0,"",(E8-J8)/J8),"") | AK8: =IFERROR(IF(F8-K8>0,"",(F8-K8)/K8),"") | AL8: =IF(AND(AJ8<>"",CC8="High Spike @ Downtrend"),AJ8,"") | AM8: =IF(AND(AJ8<>"",AL8=""),AJ8,"") | AN8: =IF(AND(AK8<>"",CF8="Low Spike @ Uptrend"),AK8,"") | AO8: =IF(AND(AK8<>"",AN8=""),AK8,"") | AY8: =IF(OR(Q8=0,Q8=""),"",((H8-Q8)/Q8)) | AZ8: =IF(AY8="","",IF(AY8>=0,1,-1)) | BA8: =IF(AZ8="","",IF(AZ8=AZ7,BA7+AZ8,AZ8)) | BB8: =IF(AY8="","",IF(AND(AY8>-0.1%,AY8<0.1%),"Touch Zone","")) | BC8: =IF(AY8="","",IF(AND(BB8="Touch Zone",AY8>0%),"Above",IF(AND(BB8="Touch Zone",AY8<0%),"Below",""))) | BD8: =IF(OR(R8=0,R8=""),"",((H8-R8)/R8)) | BE8: =IF(BD8="","",IF(BD8>=0,1,-1)) | BF8: =IF(BE8="","",IF(BE8=BE7,BF7+BE8,BE8)) | BG8: =IF(BD8="","",IF(AND(BD8>-0.1%,BD8<0.1%),"Touch Zone","")) | BH8: =IF(BD8="","",IF(AND(BG8="Touch Zone",BD8>0%),"Above",IF(AND(BG8="Touch Zone",BD8<0%),"Below",""))) | BI8: =IF(OR(L8="",N8=""),"",IF(AND(L8=N8,L8>0,N8>0),"Important High","")) | BJ8: =IF(OR(M8="",O8=""),"",IF(AND(M8=O8,M8>0,O8>0),"Important Low","")) | BU8: =IF(OR(BB8="Touch Zone",BG8="Touch Zone"),"TL Touch Zone","") | BV8: =IF(AND(BC8="",BH8=""),"",COUNTIF(BC8,"Above")+COUNTIF(BC8,"Below")+COUNTIF(BH8,"Above")+COUNTIF(BH8,"Below")) | BW8: {=IF(BV8<>1,"",_xlfn.IFS(OR(BC8="Above",BC8="Below"),BC8,OR(BH8="Above",BH8="Below"),BH8,TRUE,""))} | BY8: =IF(AA8="","",IF(AA8>0,"UP","DOWN")) | BZ8: =IF(AF8="","",IF(AF8<50%,"Early Up Stage",IF(AF8>100%,"Extended Up Stage","Late Up Stage"))) | CA8: =IF(AG8="","",IF(AG8<50%,"Early Down Stage",IF(AG8>100%,"Extended Down Stage","Late Down Stage"))) | CB8: =IF(AS8="","",IF(AS8>90%,"Sig High Spike @ Uptrend","")) | CC8: =IF(AJ8="","",IF(AND(AC8<0,AJ8>0),"High Spike @ Downtrend","")) | CD8: =IF(AND(CC8="High Spike @ Downtrend",AR8>50%),"Sig High Spike @ Downtrend","") | CE8: =IF(AW8="","",IF(AW8>90%,"Sig Low Spike @ Downtrend","")) | CF8: =IF(AK8="","",IF(AND(AC8>0,AK8>0),"Low Spike @ Uptrend","")) | CG8: =IF(AND(CF8="Low Spike @ Uptrend",AV8>50%),"Sig Low Spike @ Uptrend","") | CJ8: =IF(P8="","",IF(P8=1,1,""))
A9: =IF('Data Validation'!$K$2<>TRUE,"",'Data Validation'!A9) | B9: =IF('Data Validation'!$K$2<>TRUE,"",'Data Validation'!C9) | C9: =IF('Data Validation'!$K$2<>TRUE,"",'Data Validation'!E9) | D9: =IF('Data Validation'!$K$2<>TRUE,"",'Data Validation'!G9) | E9: =IF($C9<>"M5","",Price!F9) | F9: =IF($C9<>"M5","",Price!G9) | G9: =IF($C9<>"M5","",Price!H9) | H9: =IF($C9<>"M5","",SSA!E9) | I9: =IF($C9<>"M5","",SSA!F9) | J9: =IF($C9<>"M5","",SSA!G9) | K9: =IF($C9<>"M5","",SSA!H9) | L9: =IF($C9<>"M5","",Trendlines!K9) | M9: =IF($C9<>"M5","",Trendlines!L9) | N9: =IF($C9<>"M5","",ZigZag!E9) | O9: =IF($C9<>"M5","",ZigZag!F9) | P9: =IF($C9<>"M5","",Pinbar!E9) | Q9: =IF($C9<>"M5","",Trendlines!E9) | R9: =IF($C9<>"M5","",Trendlines!H9) | W9: =IFERROR(E9-F9,"") | X9: =IFERROR(ABS(E9-D8),"") | Y9: =IFERROR(ABS(F9-D8),"") | Z9: =IF(MAX(W9:Y9)=0,"",MAX(W9:Y9)) | AA9: =IFERROR(H9-I9,"") | AB9: =IF(AA9="","",IF(AA9>=0,1,-1)) | AC9: {=IFERROR((AB9=AB8,AC8+AB9,AB9),"")} | AH9: =IF(AND(H9>I9,H8<I8),"crossover","") | AI9: =IF(AND(H9<I9,H8>I8),"crossunder","") | AJ9: =IFERROR(IF(E9-J9<0,"",(E9-J9)/J9),"") | AK9: =IFERROR(IF(F9-K9>0,"",(F9-K9)/K9),"") | AL9: =IF(AND(AJ9<>"",CC9="High Spike @ Downtrend"),AJ9,"") | AM9: =IF(AND(AJ9<>"",AL9=""),AJ9,"") | AN9: =IF(AND(AK9<>"",CF9="Low Spike @ Uptrend"),AK9,"") | AO9: =IF(AND(AK9<>"",AN9=""),AK9,"") | AY9: =IF(OR(Q9=0,Q9=""),"",((H9-Q9)/Q9)) | AZ9: =IF(AY9="","",IF(AY9>=0,1,-1)) | BA9: =IF(AZ9="","",IF(AZ9=AZ8,BA8+AZ9,AZ9)) | BB9: =IF(AY9="","",IF(AND(AY9>-0.1%,AY9<0.1%),"Touch Zone","")) | BC9: =IF(AY9="","",IF(AND(BB9="Touch Zone",AY9>0%),"Above",IF(AND(BB9="Touch Zone",AY9<0%),"Below",""))) | BD9: =IF(OR(R9=0,R9=""),"",((H9-R9)/R9)) | BE9: =IF(BD9="","",IF(BD9>=0,1,-1)) | BF9: =IF(BE9="","",IF(BE9=BE8,BF8+BE9,BE9)) | BG9: =IF(BD9="","",IF(AND(BD9>-0.1%,BD9<0.1%),"Touch Zone","")) | BH9: =IF(BD9="","",IF(AND(BG9="Touch Zone",BD9>0%),"Above",IF(AND(BG9="Touch Zone",BD9<0%),"Below",""))) | BI9: =IF(OR(L9="",N9=""),"",IF(AND(L9=N9,L9>0,N9>0),"Important High","")) | BJ9: =IF(OR(M9="",O9=""),"",IF(AND(M9=O9,M9>0,O9>0),"Important Low","")) | BU9: =IF(OR(BB9="Touch Zone",BG9="Touch Zone"),"TL Touch Zone","") | BV9: =IF(AND(BC9="",BH9=""),"",COUNTIF(BC9,"Above")+COUNTIF(BC9,"Below")+COUNTIF(BH9,"Above")+COUNTIF(BH9,"Below")) | BW9: {=IF(BV9<>1,"",_xlfn.IFS(OR(BC9="Above",BC9="Below"),BC9,OR(BH9="Above",BH9="Below"),BH9,TRUE,""))} | BY9: =IF(AA9="","",IF(AA9>0,"UP","DOWN")) | BZ9: =IF(AF9="","",IF(AF9<50%,"Early Up Stage",IF(AF9>100%,"Extended Up Stage","Late Up Stage"))) | CA9: =IF(AG9="","",IF(AG9<50%,"Early Down Stage",IF(AG9>100%,"Extended Down Stage","Late Down Stage"))) | CB9: =IF(AS9="","",IF(AS9>90%,"Sig High Spike @ Uptrend","")) | CC9: =IF(AJ9="","",IF(AND(AC9<0,AJ9>0),"High Spike @ Downtrend","")) | CD9: =IF(AND(CC9="High Spike @ Downtrend",AR9>50%),"Sig High Spike @ Downtrend","") | CE9: =IF(AW9="","",IF(AW9>90%,"Sig Low Spike @ Downtrend","")) | CF9: =IF(AK9="","",IF(AND(AC9>0,AK9>0),"Low Spike @ Uptrend","")) | CG9: =IF(AND(CF9="Low Spike @ Uptrend",AV9>50%),"Sig Low Spike @ Uptrend","") | CJ9: =IF(P9="","",IF(P9=1,1,""))
A10: =IF('Data Validation'!$K$2<>TRUE,"",'Data Validation'!A10) | B10: =IF('Data Validation'!$K$2<>TRUE,"",'Data Validation'!C10) | C10: =IF('Data Validation'!$K$2<>TRUE,"",'Data Validation'!E10) | D10: =IF('Data Validation'!$K$2<>TRUE,"",'Data Validation'!G10) | E10: =IF($C10<>"M5","",Price!F10) | F10: =IF($C10<>"M5","",Price!G10) | G10: =IF($C10<>"M5","",Price!H10) | H10: =IF($C10<>"M5","",SSA!E10) | I10: =IF($C10<>"M5","",SSA!F10) | J10: =IF($C10<>"M5","",SSA!G10) | K10: =IF($C10<>"M5","",SSA!H10) | L10: =IF($C10<>"M5","",Trendlines!K10) | M10: =IF($C10<>"M5","",Trendlines!L10) | N10: =IF($C10<>"M5","",ZigZag!E10) | O10: =IF($C10<>"M5","",ZigZag!F10) | P10: =IF($C10<>"M5","",Pinbar!E10) | Q10: =IF($C10<>"M5","",Trendlines!E10) | R10: =IF($C10<>"M5","",Trendlines!H10) | W10: =IFERROR(E10-F10,"") | X10: =IFERROR(ABS(E10-D9),"") | Y10: =IFERROR(ABS(F10-D9),"") | Z10: =IF(MAX(W10:Y10)=0,"",MAX(W10:Y10)) | AA10: =IFERROR(H10-I10,"") | AB10: =IF(AA10="","",IF(AA10>=0,1,-1)) | AC10: {=IFERROR((AB10=AB9,AC9+AB10,AB10),"")} | AH10: =IF(AND(H10>I10,H9<I9),"crossover","") | AI10: =IF(AND(H10<I10,H9>I9),"crossunder","") | AJ10: =IFERROR(IF(E10-J10<0,"",(E10-J10)/J10),"") | AK10: =IFERROR(IF(F10-K10>0,"",(F10-K10)/K10),"") | AL10: =IF(AND(AJ10<>"",CC10="High Spike @ Downtrend"),AJ10,"") | AM10: =IF(AND(AJ10<>"",AL10=""),AJ10,"") | AN10: =IF(AND(AK10<>"",CF10="Low Spike @ Uptrend"),AK10,"") | AO10: =IF(AND(AK10<>"",AN10=""),AK10,"") | AY10: =IF(OR(Q10=0,Q10=""),"",((H10-Q10)/Q10)) | AZ10: =IF(AY10="","",IF(AY10>=0,1,-1)) | BA10: =IF(AZ10="","",IF(AZ10=AZ9,BA9+AZ10,AZ10)) | BB10: =IF(AY10="","",IF(AND(AY10>-0.1%,AY10<0.1%),"Touch Zone","")) | BC10: =IF(AY10="","",IF(AND(BB10="Touch Zone",AY10>0%),"Above",IF(AND(BB10="Touch Zone",AY10<0%),"Below",""))) | BD10: =IF(OR(R10=0,R10=""),"",((H10-R10)/R10)) | BE10: =IF(BD10="","",IF(BD10>=0,1,-1)) | BF10: =IF(BE10="","",IF(BE10=BE9,BF9+BE10,BE10)) | BG10: =IF(BD10="","",IF(AND(BD10>-0.1%,BD10<0.1%),"Touch Zone","")) | BH10: =IF(BD10="","",IF(AND(BG10="Touch Zone",BD10>0%),"Above",IF(AND(BG10="Touch Zone",BD10<0%),"Below",""))) | BI10: =IF(OR(L10="",N10=""),"",IF(AND(L10=N10,L10>0,N10>0),"Important High","")) | BJ10: =IF(OR(M10="",O10=""),"",IF(AND(M10=O10,M10>0,O10>0),"Important Low","")) | BU10: =IF(OR(BB10="Touch Zone",BG10="Touch Zone"),"TL Touch Zone","") | BV10: =IF(AND(BC10="",BH10=""),"",COUNTIF(BC10,"Above")+COUNTIF(BC10,"Below")+COUNTIF(BH10,"Above")+COUNTIF(BH10,"Below")) | BW10: {=IF(BV10<>1,"",_xlfn.IFS(OR(BC10="Above",BC10="Below"),BC10,OR(BH10="Above",BH10="Below"),BH10,TRUE,""))} | BY10: =IF(AA10="","",IF(AA10>0,"UP","DOWN")) | BZ10: =IF(AF10="","",IF(AF10<50%,"Early Up Stage",IF(AF10>100%,"Extended Up Stage","Late Up Stage"))) | CA10: =IF(AG10="","",IF(AG10<50%,"Early Down Stage",IF(AG10>100%,"Extended Down Stage","Late Down Stage"))) | CB10: =IF(AS10="","",IF(AS10>90%,"Sig High Spike @ Uptrend","")) | CC10: =IF(AJ10="","",IF(AND(AC10<0,AJ10>0),"High Spike @ Downtrend","")) | CD10: =IF(AND(CC10="High Spike @ Downtrend",AR10>50%),"Sig High Spike @ Downtrend","") | CE10: =IF(AW10="","",IF(AW10>90%,"Sig Low Spike @ Downtrend","")) | CF10: =IF(AK10="","",IF(AND(AC10>0,AK10>0),"Low Spike @ Uptrend","")) | CG10: =IF(AND(CF10="Low Spike @ Uptrend",AV10>50%),"Sig Low Spike @ Uptrend","") | CJ10: =IF(P10="","",IF(P10=1,1,""))
