Workbook

Sheet Price
A1: timestamp | B1: symbol | C1: timeframe | D1: close | E1: open | F1: high | G1: low | H1: volume | J1: convert_to_readable_datetime | K1: round_to_nearest_datetime_5m | L1: timestamp_adjusted
A2: 1772024998 | B2: XAUUSD | C2: M5 | D2: 5187.2 | E2: 5188.44 | F2: 5189.22 | G2: 5185.5 | H2: 567 | J2: =(A2/86400)+25569 -> 46078.549 | K2: =CEILING(INT(J2*1440)/1440*288,1)/288 -> 46078.549 | L2: =MROUND((K2-25569)*86400,300) -> 1772025000
A3: 1772025298 | B3: XAUUSD | C3: M5 | D3: 5187 | E3: 5187.22 | F3: 5189.54 | G3: 5185.97 | H3: 574 | J3: =(A3/86400)+25569 -> 46078.552 | K3: =CEILING(INT(J3*1440)/1440*288,1)/288 -> 46078.552 | L3: =MROUND((K3-25569)*86400,300) -> 1772025300
A4: 1772025598 | B4: XAUUSD | C4: M5 | D4: 5191.13 | E4: 5186.81 | F4: 5191.47 | G4: 5186.14 | H4: 583 | J4: =(A4/86400)+25569 -> 46078.556 | K4: =CEILING(INT(J4*1440)/1440*288,1)/288 -> 46078.556 | L4: =MROUND((K4-25569)*86400,300) -> 1772025600
A5: 1772025898 | B5: XAUUSD | C5: M5 | D5: 5188.07 | E5: 5191.14 | F5: 5191.36 | G5: 5186.93 | H5: 547 | J5: =(A5/86400)+25569 -> 46078.559 | K5: =CEILING(INT(J5*1440)/1440*288,1)/288 -> 46078.559 | L5: =MROUND((K5-25569)*86400,300) -> 1772025900
A6: 1772026198 | B6: XAUUSD | C6: M5 | D6: 5188.16 | E6: 5188.07 | F6: 5190.35 | G6: 5186.62 | H6: 516 | J6: =(A6/86400)+25569 -> 46078.562 | K6: =CEILING(INT(J6*1440)/1440*288,1)/288 -> 46078.562 | L6: =MROUND((K6-25569)*86400,300) -> 1772026200
A7: 1772026498 | B7: XAUUSD | C7: M5 | D7: 5189.61 | E7: 5188.16 | F7: 5190.35 | G7: 5187.73 | H7: 524 | J7: =(A7/86400)+25569 -> 46078.566 | K7: =CEILING(INT(J7*1440)/1440*288,1)/288 -> 46078.566 | L7: =MROUND((K7-25569)*86400,300) -> 1772026500
A8: 1772026798 | B8: XAUUSD | C8: M5 | D8: 5186.84 | E8: 5189.93 | F8: 5191.33 | G8: 5182.03 | H8: 660 | J8: =(A8/86400)+25569 -> 46078.569 | K8: =CEILING(INT(J8*1440)/1440*288,1)/288 -> 46078.569 | L8: =MROUND((K8-25569)*86400,300) -> 1772026800
A9: 1772027098 | B9: XAUUSD | C9: M5 | D9: 5186.59 | E9: 5187.12 | F9: 5191.12 | G9: 5185.65 | H9: 585 | J9: =(A9/86400)+25569 -> 46078.573 | K9: =CEILING(INT(J9*1440)/1440*288,1)/288 -> 46078.573 | L9: =MROUND((K9-25569)*86400,300) -> 1772027100
A10: 1772027398 | B10: XAUUSD | C10: M5 | D10: 5186.07 | E10: 5187.03 | F10: 5187.42 | G10: 5184.3 | H10: 628 | J10: =(A10/86400)+25569 -> 46078.576 | K10: =CEILING(INT(J10*1440)/1440*288,1)/288 -> 46078.576 | L10: =MROUND((K10-25569)*86400,300) -> 1772027400
A11: 1772027698 | B11: XAUUSD | C11: M5 | D11: 5185.23 | E11: 5186.04 | F11: 5188.5 | G11: 5184.76 | H11: 572 | J11: =(A11/86400)+25569 -> 46078.58 | K11: =CEILING(INT(J11*1440)/1440*288,1)/288 -> 46078.58 | L11: =MROUND((K11-25569)*86400,300) -> 1772027700
A12: 1772027998 | B12: XAUUSD | C12: M5 | D12: 5187.18 | E12: 5185.22 | F12: 5187.34 | G12: 5183.76 | H12: 641 | J12: =(A12/86400)+25569 -> 46078.583 | K12: =CEILING(INT(J12*1440)/1440*288,1)/288 -> 46078.583 | L12: =MROUND((K12-25569)*86400,300) -> 1772028000
A13: 1772028298 | B13: XAUUSD | C13: M5 | D13: 5189.99 | E13: 5187.18 | F13: 5191.07 | G13: 5186.8 | H13: 582 | J13: =(A13/86400)+25569 -> 46078.587 | K13: =CEILING(INT(J13*1440)/1440*288,1)/288 -> 46078.587 | L13: =MROUND((K13-25569)*86400,300) -> 1772028300
... A501: 1772181898 | B501: XAUUSD | C501: M5 | D501: 5181.66 | E501: 5180.32 | F501: 5182.14 | G501: 5179.99 | H501: 92 | J501: =(A501/86400)+25569 -> 46080.365 | K501: =CEILING(INT(J501*1440)/1440*288,1)/288 -> 46080.365 | L501: =MROUND((K501-25569)*86400,300) -> 1772181900

Sheet Trendlines
A1: timestamp | B1: symbol | C1: timeframe | D1: close | E1: horiz_peak_line_1 | F1: horiz_peak_line_2 | G1: horiz_peak_line_3 | H1: horiz_bottom_line_1 | I1: horiz_bottom_line_2 | J1: horiz_bottom_line_3 | K1: horiz_high_map | L1: horiz_low_map | O1: convert_to_readable_datetime | P1: round_to_nearest_datetime_5m | Q1: timestamp_adjusted
A2: 1772024999 | B2: XAUUSD | C2: M5 | D2: 5187.2 | O2: =(A2/86400)+25569 -> 46078.549 | P2: =CEILING(INT(O2*1440)/1440*288,1)/288 -> 46078.549 | Q2: =MROUND((P2-25569)*86400,300) -> 1772025000
A3: 1772025299 | B3: XAUUSD | C3: M5 | D3: 5187 | O3: =(A3/86400)+25569 -> 46078.552 | P3: =CEILING(INT(O3*1440)/1440*288,1)/288 -> 46078.552 | Q3: =MROUND((P3-25569)*86400,300) -> 1772025300
A4: 1772025599 | B4: XAUUSD | C4: M5 | D4: 5191.13 | K4: 5191.47 | O4: =(A4/86400)+25569 -> 46078.556 | P4: =CEILING(INT(O4*1440)/1440*288,1)/288 -> 46078.556 | Q4: =MROUND((P4-25569)*86400,300) -> 1772025600
A5: 1772025899 | B5: XAUUSD | C5: M5 | D5: 5188.07 | O5: =(A5/86400)+25569 -> 46078.559 | P5: =CEILING(INT(O5*1440)/1440*288,1)/288 -> 46078.559 | Q5: =MROUND((P5-25569)*86400,300) -> 1772025900
A6: 1772026199 | B6: XAUUSD | C6: M5 | D6: 5188.16 | O6: =(A6/86400)+25569 -> 46078.562 | P6: =CEILING(INT(O6*1440)/1440*288,1)/288 -> 46078.562 | Q6: =MROUND((P6-25569)*86400,300) -> 1772026200
A7: 1772026499 | B7: XAUUSD | C7: M5 | D7: 5189.61 | O7: =(A7/86400)+25569 -> 46078.566 | P7: =CEILING(INT(O7*1440)/1440*288,1)/288 -> 46078.566 | Q7: =MROUND((P7-25569)*86400,300) -> 1772026500
A8: 1772026799 | B8: XAUUSD | C8: M5 | D8: 5186.84 | O8: =(A8/86400)+25569 -> 46078.569 | P8: =CEILING(INT(O8*1440)/1440*288,1)/288 -> 46078.569 | Q8: =MROUND((P8-25569)*86400,300) -> 1772026800
A9: 1772027099 | B9: XAUUSD | C9: M5 | D9: 5186.59 | O9: =(A9/86400)+25569 -> 46078.573 | P9: =CEILING(INT(O9*1440)/1440*288,1)/288 -> 46078.573 | Q9: =MROUND((P9-25569)*86400,300) -> 1772027100
A10: 1772027399 | B10: XAUUSD | C10: M5 | D10: 5186.07 | O10: =(A10/86400)+25569 -> 46078.576 | P10: =CEILING(INT(O10*1440)/1440*288,1)/288 -> 46078.576 | Q10: =MROUND((P10-25569)*86400,300) -> 1772027400
A11: 1772027699 | B11: XAUUSD | C11: M5 | D11: 5185.23 | O11: =(A11/86400)+25569 -> 46078.58 | P11: =CEILING(INT(O11*1440)/1440*288,1)/288 -> 46078.58 | Q11: =MROUND((P11-25569)*86400,300) -> 1772027700
A12: 1772027999 | B12: XAUUSD | C12: M5 | D12: 5187.18 | O12: =(A12/86400)+25569 -> 46078.583 | P12: =CEILING(INT(O12*1440)/1440*288,1)/288 -> 46078.583 | Q12: =MROUND((P12-25569)*86400,300) -> 1772028000
A13: 1772028299 | B13: XAUUSD | C13: M5 | D13: 5189.99 | O13: =(A13/86400)+25569 -> 46078.587 | P13: =CEILING(INT(O13*1440)/1440*288,1)/288 -> 46078.587 | Q13: =MROUND((P13-25569)*86400,300) -> 1772028300
A14: 1772028599 | B14: XAUUSD | C14: M5 | D14: 5185.44 | O14: =(A14/86400)+25569 -> 46078.59 | P14: =CEILING(INT(O14*1440)/1440*288,1)/288 -> 46078.59 | Q14: =MROUND((P14-25569)*86400,300) -> 1772028600
A15: 1772028899 | B15: XAUUSD | C15: M5 | D15: 5182.68 | O15: =(A15/86400)+25569 -> 46078.594 | P15: =CEILING(INT(O15*1440)/1440*288,1)/288 -> 46078.594 | Q15: =MROUND((P15-25569)*86400,300) -> 1772028900
A16: 1772029199 | B16: XAUUSD | C16: M5 | D16: 5181.49 | O16: =(A16/86400)+25569 -> 46078.597 | P16: =CEILING(INT(O16*1440)/1440*288,1)/288 -> 46078.597 | Q16: =MROUND((P16-25569)*86400,300) -> 1772029200
... A18: 1772029799 | B18: XAUUSD | C18: M5 | D18: 5174.14 | O18: =(A18/86400)+25569 -> 46078.604 | P18: =CEILING(INT(O18*1440)/1440*288,1)/288 -> 46078.604 | Q18: =MROUND((P18-25569)*86400,300) -> 1772029800
A19: 1772030099 | B19: XAUUSD | C19: M5 | D19: 5159.73 | L19: 5158.94 | O19: =(A19/86400)+25569 -> 46078.608 | P19: =CEILING(INT(O19*1440)/1440*288,1)/288 -> 46078.608 | Q19: =MROUND((P19-25569)*86400,300) -> 1772030100
A20: 1772030399 | B20: XAUUSD | C20: M5 | D20: 5174.91 | O20: =(A20/86400)+25569 -> 46078.611 | P20: =CEILING(INT(O20*1440)/1440*288,1)/288 -> 46078.611 | Q20: =MROUND((P20-25569)*86400,300) -> 1772030400
A21: 1772030699 | B21: XAUUSD | C21: M5 | D21: 5181.79 | O21: =(A21/86400)+25569 -> 46078.615 | P21: =CEILING(INT(O21*1440)/1440*288,1)/288 -> 46078.615 | Q21: =MROUND((P21-25569)*86400,300) -> 1772030700
A22: 1772030999 | B22: XAUUSD | C22: M5 | D22: 5188.55 | O22: =(A22/86400)+25569 -> 46078.618 | P22: =CEILING(INT(O22*1440)/1440*288,1)/288 -> 46078.618 | Q22: =MROUND((P22-25569)*86400,300) -> 1772031000
A23: 1772031299 | B23: XAUUSD | C23: M5 | D23: 5191.25 | O23: =(A23/86400)+25569 -> 46078.622 | P23: =CEILING(INT(O23*1440)/1440*288,1)/288 -> 46078.622 | Q23: =MROUND((P23-25569)*86400,300) -> 1772031300
A24: 1772031599 | B24: XAUUSD | C24: M5 | D24: 5198.64 | O24: =(A24/86400)+25569 -> 46078.625 | P24: =CEILING(INT(O24*1440)/1440*288,1)/288 -> 46078.625 | Q24: =MROUND((P24-25569)*86400,300) -> 1772031600
A25: 1772031899 | B25: XAUUSD | C25: M5 | D25: 5195.89 | O25: =(A25/86400)+25569 -> 46078.628 | P25: =CEILING(INT(O25*1440)/1440*288,1)/288 -> 46078.628 | Q25: =MROUND((P25-25569)*86400,300) -> 1772031900
A26: 1772032199 | B26: XAUUSD | C26: M5 | D26: 5193.17 | O26: =(A26/86400)+25569 -> 46078.632 | P26: =CEILING(INT(O26*1440)/1440*288,1)/288 -> 46078.632 | Q26: =MROUND((P26-25569)*86400,300) -> 1772032200
A27: 1772032499 | B27: XAUUSD | C27: M5 | D27: 5188.97 | O27: =(A27/86400)+25569 -> 46078.635 | P27: =CEILING(INT(O27*1440)/1440*288,1)/288 -> 46078.635 | Q27: =MROUND((P27-25569)*86400,300) -> 1772032500
A28: 1772032799 | B28: XAUUSD | C28: M5 | D28: 5185.46 | O28: =(A28/86400)+25569 -> 46078.639 | P28: =CEILING(INT(O28*1440)/1440*288,1)/288 -> 46078.639 | Q28: =MROUND((P28-25569)*86400,300) -> 1772032800
A29: 1772033099 | B29: XAUUSD | C29: M5 | D29: 5180.33 | O29: =(A29/86400)+25569 -> 46078.642 | P29: =CEILING(INT(O29*1440)/1440*288,1)/288 -> 46078.642 | Q29: =MROUND((P29-25569)*86400,300) -> 1772033100
A30: 1772033399 | B30: XAUUSD | C30: M5 | D30: 5181.68 | O30: =(A30/86400)+25569 -> 46078.646 | P30: =CEILING(INT(O30*1440)/1440*288,1)/288 -> 46078.646 | Q30: =MROUND((P30-25569)*86400,300) -> 1772033400
A31: 1772033699 | B31: XAUUSD | C31: M5 | D31: 5187.95 | O31: =(A31/86400)+25569 -> 46078.649 | P31: =CEILING(INT(O31*1440)/1440*288,1)/288 -> 46078.649 | Q31: =MROUND((P31-25569)*86400,300) -> 1772033700
... A49: 1772039099 | B49: XAUUSD | C49: M5 | D49: 5214.69 | O49: =(A49/86400)+25569 -> 46078.712 | P49: =CEILING(INT(O49*1440)/1440*288,1)/288 -> 46078.712 | Q49: =MROUND((P49-25569)*86400,300) -> 1772039100
A50: 1772039399 | B50: XAUUSD | C50: M5 | D50: 5215.17 | K50: 5217.63 | O50: =(A50/86400)+25569 -> 46078.715 | P50: =CEILING(INT(O50*1440)/1440*288,1)/288 -> 46078.715 | Q50: =MROUND((P50-25569)*86400,300) -> 1772039400
A51: 1772039699 | B51: XAUUSD | C51: M5 | D51: 5214.53 | O51: =(A51/86400)+25569 -> 46078.719 | P51: =CEILING(INT(O51*1440)/1440*288,1)/288 -> 46078.719 | Q51: =MROUND((P51-25569)*86400,300) -> 1772039700
A52: 1772039999 | B52: XAUUSD | C52: M5 | D52: 5213.27 | O52: =(A52/86400)+25569 -> 46078.722 | P52: =CEILING(INT(O52*1440)/1440*288,1)/288 -> 46078.722 | Q52: =MROUND((P52-25569)*86400,300) -> 1772040000
A53: 1772040299 | B53: XAUUSD | C53: M5 | D53: 5213.1 | O53: =(A53/86400)+25569 -> 46078.726 | P53: =CEILING(INT(O53*1440)/1440*288,1)/288 -> 46078.726 | Q53: =MROUND((P53-25569)*86400,300) -> 1772040300
A54: 1772040599 | B54: XAUUSD | C54: M5 | D54: 5211.85 | O54: =(A54/86400)+25569 -> 46078.729 | P54: =CEILING(INT(O54*1440)/1440*288,1)/288 -> 46078.729 | Q54: =MROUND((P54-25569)*86400,300) -> 1772040600
A55: 1772040899 | B55: XAUUSD | C55: M5 | D55: 5213.17 | O55: =(A55/86400)+25569 -> 46078.733 | P55: =CEILING(INT(O55*1440)/1440*288,1)/288 -> 46078.733 | Q55: =MROUND((P55-25569)*86400,300) -> 1772040900
A56: 1772041199 | B56: XAUUSD | C56: M5 | D56: 5208.33 | O56: =(A56/86400)+25569 -> 46078.736 | P56: =CEILING(INT(O56*1440)/1440*288,1)/288 -> 46078.736 | Q56: =MROUND((P56-25569)*86400,300) -> 1772041200
A57: 1772041499 | B57: XAUUSD | C57: M5 | D57: 5206.71 | O57: =(A57/86400)+25569 -> 46078.74 | P57: =CEILING(INT(O57*1440)/1440*288,1)/288 -> 46078.74 | Q57: =MROUND((P57-25569)*86400,300) -> 1772041500
A58: 1772041799 | B58: XAUUSD | C58: M5 | D58: 5206.32 | O58: =(A58/86400)+25569 -> 46078.743 | P58: =CEILING(INT(O58*1440)/1440*288,1)/288 -> 46078.743 | Q58: =MROUND((P58-25569)*86400,300) -> 1772041800
...

Sheet ZigZag
A1: timestamp | B1: symbol | C1: timeframe | D1: close | E1: zigzag_high | F1: zigzag_low | G1: ema | I1: convert_to_readable_datetime | J1: round_to_nearest_datetime_5m | K1: timestamp_adjusted
A2: 1772024998 | B2: XAUUSD | C2: M5 | D2: 5187.2 | E2: 0 | F2: 0 | G2: 5181.08 | I2: =(A2/86400)+25569 -> 46078.549 | J2: =CEILING(INT(I2*1440)/1440*288,1)/288 -> 46078.549 | K2: =MROUND((J2-25569)*86400,300) -> 1772025000
A3: 1772025298 | B3: XAUUSD | C3: M5 | D3: 5187 | E3: 0 | F3: 0 | G3: 5181.54 | I3: =(A3/86400)+25569 -> 46078.552 | J3: =CEILING(INT(I3*1440)/1440*288,1)/288 -> 46078.552 | K3: =MROUND((J3-25569)*86400,300) -> 1772025300
A4: 1772025598 | B4: XAUUSD | C4: M5 | D4: 5191.13 | E4: 5191.47 | F4: 0 | G4: 5182.12 | I4: =(A4/86400)+25569 -> 46078.556 | J4: =CEILING(INT(I4*1440)/1440*288,1)/288 -> 46078.556 | K4: =MROUND((J4-25569)*86400,300) -> 1772025600
A5: 1772025898 | B5: XAUUSD | C5: M5 | D5: 5188.07 | E5: 0 | F5: 0 | G5: 5182.59 | I5: =(A5/86400)+25569 -> 46078.559 | J5: =CEILING(INT(I5*1440)/1440*288,1)/288 -> 46078.559 | K5: =MROUND((J5-25569)*86400,300) -> 1772025900
A6: 1772026198 | B6: XAUUSD | C6: M5 | D6: 5188.16 | E6: 0 | F6: 0 | G6: 5183 | I6: =(A6/86400)+25569 -> 46078.562 | J6: =CEILING(INT(I6*1440)/1440*288,1)/288 -> 46078.562 | K6: =MROUND((J6-25569)*86400,300) -> 1772026200
A7: 1772026498 | B7: XAUUSD | C7: M5 | D7: 5189.61 | E7: 0 | F7: 0 | G7: 5183.45 | I7: =(A7/86400)+25569 -> 46078.566 | J7: =CEILING(INT(I7*1440)/1440*288,1)/288 -> 46078.566 | K7: =MROUND((J7-25569)*86400,300) -> 1772026500
A8: 1772026798 | B8: XAUUSD | C8: M5 | D8: 5186.84 | E8: 0 | F8: 0 | G8: 5183.68 | I8: =(A8/86400)+25569 -> 46078.569 | J8: =CEILING(INT(I8*1440)/1440*288,1)/288 -> 46078.569 | K8: =MROUND((J8-25569)*86400,300) -> 1772026800
A9: 1772027098 | B9: XAUUSD | C9: M5 | D9: 5186.59 | E9: 0 | F9: 0 | G9: 5183.98 | I9: =(A9/86400)+25569 -> 46078.573 | J9: =CEILING(INT(I9*1440)/1440*288,1)/288 -> 46078.573 | K9: =MROUND((J9-25569)*86400,300) -> 1772027100
A10: 1772027398 | B10: XAUUSD | C10: M5 | D10: 5186.07 | E10: 0 | F10: 0 | G10: 5184.12 | I10: =(A10/86400)+25569 -> 46078.576 | J10: =CEILING(INT(I10*1440)/1440*288,1)/288 -> 46078.576 | K10: =MROUND((J10-25569)*86400,300) -> 1772027400
A11: 1772027698 | B11: XAUUSD | C11: M5 | D11: 5185.23 | E11: 0 | F11: 0 | G11: 5184.26 | I11: =(A11/86400)+25569 -> 46078.58 | J11: =CEILING(INT(I11*1440)/1440*288,1)/288 -> 46078.58 | K11: =MROUND((J11-25569)*86400,300) -> 1772027700
A12: 1772027998 | B12: XAUUSD | C12: M5 | D12: 5187.18 | E12: 0 | F12: 0 | G12: 5184.39 | I12: =(A12/86400)+25569 -> 46078.583 | J12: =CEILING(INT(I12*1440)/1440*288,1)/288 -> 46078.583 | K12: =MROUND((J12-25569)*86400,300) -> 1772028000
A13: 1772028298 | B13: XAUUSD | C13: M5 | D13: 5189.99 | E13: 0 | F13: 0 | G13: 5184.74 | I13: =(A13/86400)+25569 -> 46078.587 | J13: =CEILING(INT(I13*1440)/1440*288,1)/288 -> 46078.587 | K13: =MROUND((J13-25569)*86400,300) -> 1772028300
... A501: 1772181898 | B501: XAUUSD | C501: M5 | D501: 5180.67 | E501: 0 | F501: 0 | G501: 5182.26 | I501: =(A501/86400)+25569 -> 46080.365 | J501: =CEILING(INT(I501*1440)/1440*288,1)/288 -> 46080.365 | K501: =MROUND((J501-25569)*86400,300) -> 1772181900

Sheet Dual_Tema
A1: timestamp | B1: symbol | C1: timeframe | D1: close | E1: dual_tema_high | F1: dual_tema_low | H1: convert_to_readable_datetime | I1: round_to_nearest_datetime_5m | J1: timestamp_adjusted
A2: 1772024998 | B2: XAUUSD | C2: M5 | D2: 5187.2 | E2: 5188.55 | F2: 5184.29 | H2: =(A2/86400)+25569 -> 46078.549 | I2: =CEILING(INT(H2*1440)/1440*288,1)/288 -> 46078.549 | J2: =MROUND((I2-25569)*86400,300) -> 1772025000
A3: 1772025298 | B3: XAUUSD | C3: M5 | D3: 5187 | E3: 5189.36 | F3: 5185.43 | H3: =(A3/86400)+25569 -> 46078.552 | I3: =CEILING(INT(H3*1440)/1440*288,1)/288 -> 46078.552 | J3: =MROUND((I3-25569)*86400,300) -> 1772025300
A4: 1772025598 | B4: XAUUSD | C4: M5 | D4: 5191.13 | E4: 5190.73 | F4: 5186.16 | H4: =(A4/86400)+25569 -> 46078.556 | I4: =CEILING(INT(H4*1440)/1440*288,1)/288 -> 46078.556 | J4: =MROUND((I4-25569)*86400,300) -> 1772025600
A5: 1772025898 | B5: XAUUSD | C5: M5 | D5: 5188.07 | E5: 5191.47 | F5: 5186.92 | H5: =(A5/86400)+25569 -> 46078.559 | I5: =CEILING(INT(H5*1440)/1440*288,1)/288 -> 46078.559 | J5: =MROUND((I5-25569)*86400,300) -> 1772025900
A6: 1772026198 | B6: XAUUSD | C6: M5 | D6: 5188.16 | E6: 5191.36 | F6: 5187.17 | H6: =(A6/86400)+25569 -> 46078.562 | I6: =CEILING(INT(H6*1440)/1440*288,1)/288 -> 46078.562 | J6: =MROUND((I6-25569)*86400,300) -> 1772026200
A7: 1772026498 | B7: XAUUSD | C7: M5 | D7: 5189.61 | E7: 5191.2 | F7: 5187.78 | H7: =(A7/86400)+25569 -> 46078.566 | I7: =CEILING(INT(H7*1440)/1440*288,1)/288 -> 46078.566 | J7: =MROUND((I7-25569)*86400,300) -> 1772026500
A8: 1772026798 | B8: XAUUSD | C8: M5 | D8: 5186.84 | E8: 5191.5 | F8: 5185.31 | H8: =(A8/86400)+25569 -> 46078.569 | I8: =CEILING(INT(H8*1440)/1440*288,1)/288 -> 46078.569 | J8: =MROUND((I8-25569)*86400,300) -> 1772026800
A9: 1772027098 | B9: XAUUSD | C9: M5 | D9: 5186.59 | E9: 5191.53 | F9: 5185.45 | H9: =(A9/86400)+25569 -> 46078.573 | I9: =CEILING(INT(H9*1440)/1440*288,1)/288 -> 46078.573 | J9: =MROUND((I9-25569)*86400,300) -> 1772027100
A10: 1772027398 | B10: XAUUSD | C10: M5 | D10: 5186.07 | E10: 5189.69 | F10: 5184.86 | H10: =(A10/86400)+25569 -> 46078.576 | I10: =CEILING(INT(H10*1440)/1440*288,1)/288 -> 46078.576 | J10: =MROUND((I10-25569)*86400,300) -> 1772027400
A11: 1772027698 | B11: XAUUSD | C11: M5 | D11: 5185.23 | E11: 5189.01 | F11: 5184.7 | H11: =(A11/86400)+25569 -> 46078.58 | I11: =CEILING(INT(H11*1440)/1440*288,1)/288 -> 46078.58 | J11: =MROUND((I11-25569)*86400,300) -> 1772027700
A12: 1772027998 | B12: XAUUSD | C12: M5 | D12: 5187.18 | E12: 5188.01 | F12: 5184.11 | H12: =(A12/86400)+25569 -> 46078.583 | I12: =CEILING(INT(H12*1440)/1440*288,1)/288 -> 46078.583 | J12: =MROUND((I12-25569)*86400,300) -> 1772028000
A13: 1772028298 | B13: XAUUSD | C13: M5 | D13: 5189.99 | E13: 5189.22 | F13: 5185.22 | H13: =(A13/86400)+25569 -> 46078.587 | I13: =CEILING(INT(H13*1440)/1440*288,1)/288 -> 46078.587 | J13: =MROUND((I13-25569)*86400,300) -> 1772028300
... A501: 1772181898 | B501: XAUUSD | C501: M5 | D501: 5180 | E501: 5181.09 | F501: 5179.72 | H501: =(A501/86400)+25569 -> 46080.365 | I501: =CEILING(INT(H501*1440)/1440*288,1)/288 -> 46080.365 | J501: =MROUND((I501-25569)*86400,300) -> 1772181900

Sheet Pinbar
A1: timestamp | B1: symbol | C1: timeframe | D1: close | E1: pinbar | G1: convert_to_readable_datetime | H1: round_to_nearest_datetime_5m | I1: timestamp_adjusted
A2: 1772024998 | B2: XAUUSD | C2: M5 | D2: 5187.2 | E2: 0 | G2: =(A2/86400)+25569 -> 46078.549 | H2: =CEILING(INT(G2*1440)/1440*288,1)/288 -> 46078.549 | I2: =MROUND((H2-25569)*86400,300) -> 1772025000
A3: 1772025298 | B3: XAUUSD | C3: M5 | D3: 5187 | E3: 0 | G3: =(A3/86400)+25569 -> 46078.552 | H3: =CEILING(INT(G3*1440)/1440*288,1)/288 -> 46078.552 | I3: =MROUND((H3-25569)*86400,300) -> 1772025300
A4: 1772025598 | B4: XAUUSD | C4: M5 | D4: 5191.13 | E4: 0 | G4: =(A4/86400)+25569 -> 46078.556 | H4: =CEILING(INT(G4*1440)/1440*288,1)/288 -> 46078.556 | I4: =MROUND((H4-25569)*86400,300) -> 1772025600
A5: 1772025898 | B5: XAUUSD | C5: M5 | D5: 5188.07 | E5: 0 | G5: =(A5/86400)+25569 -> 46078.559 | H5: =CEILING(INT(G5*1440)/1440*288,1)/288 -> 46078.559 | I5: =MROUND((H5-25569)*86400,300) -> 1772025900
A6: 1772026198 | B6: XAUUSD | C6: M5 | D6: 5188.16 | E6: 0 | G6: =(A6/86400)+25569 -> 46078.562 | H6: =CEILING(INT(G6*1440)/1440*288,1)/288 -> 46078.562 | I6: =MROUND((H6-25569)*86400,300) -> 1772026200
A7: 1772026498 | B7: XAUUSD | C7: M5 | D7: 5189.61 | E7: 0 | G7: =(A7/86400)+25569 -> 46078.566 | H7: =CEILING(INT(G7*1440)/1440*288,1)/288 -> 46078.566 | I7: =MROUND((H7-25569)*86400,300) -> 1772026500
A8: 1772026798 | B8: XAUUSD | C8: M5 | D8: 5186.84 | E8: 0 | G8: =(A8/86400)+25569 -> 46078.569 | H8: =CEILING(INT(G8*1440)/1440*288,1)/288 -> 46078.569 | I8: =MROUND((H8-25569)*86400,300) -> 1772026800
A9: 1772027098 | B9: XAUUSD | C9: M5 | D9: 5186.59 | E9: 0 | G9: =(A9/86400)+25569 -> 46078.573 | H9: =CEILING(INT(G9*1440)/1440*288,1)/288 -> 46078.573 | I9: =MROUND((H9-25569)*86400,300) -> 1772027100
A10: 1772027398 | B10: XAUUSD | C10: M5 | D10: 5186.07 | E10: 0 | G10: =(A10/86400)+25569 -> 46078.576 | H10: =CEILING(INT(G10*1440)/1440*288,1)/288 -> 46078.576 | I10: =MROUND((H10-25569)*86400,300) -> 1772027400
A11: 1772027698 | B11: XAUUSD | C11: M5 | D11: 5185.23 | E11: 0 | G11: =(A11/86400)+25569 -> 46078.58 | H11: =CEILING(INT(G11*1440)/1440*288,1)/288 -> 46078.58 | I11: =MROUND((H11-25569)*86400,300) -> 1772027700
A12: 1772027998 | B12: XAUUSD | C12: M5 | D12: 5187.18 | E12: 0 | G12: =(A12/86400)+25569 -> 46078.583 | H12: =CEILING(INT(G12*1440)/1440*288,1)/288 -> 46078.583 | I12: =MROUND((H12-25569)*86400,300) -> 1772028000
A13: 1772028298 | B13: XAUUSD | C13: M5 | D13: 5189.99 | E13: 0 | G13: =(A13/86400)+25569 -> 46078.587 | H13: =CEILING(INT(G13*1440)/1440*288,1)/288 -> 46078.587 | I13: =MROUND((H13-25569)*86400,300) -> 1772028300
... A501: 1772181898 | B501: XAUUSD | C501: M5 | D501: 5181.1 | E501: 0 | G501: =(A501/86400)+25569 -> 46080.365 | H501: =CEILING(INT(G501*1440)/1440*288,1)/288 -> 46080.365 | I501: =MROUND((H501-25569)*86400,300) -> 1772181900

Sheet SSA
A1: timestamp | B1: symbol | C1: timeframe | D1: close | E1: ssa | F1: ema_ssa | H1: convert_to_readable_datetime | I1: round_to_nearest_datetime_5m | J1: timestamp_adjusted
A2: 1772025000 | B2: XAUUSD | C2: M5 | D2: 5187.2 | E2: 5187.5351 | F2: 5186.6253 | H2: =(A2/86400)+25569 -> 46078.549 | I2: =CEILING(INT(H2*1440)/1440*288,1)/288 -> 46078.549 | J2: =MROUND((I2-25569)*86400,300) -> 1772025000
A3: 1772025300 | B3: XAUUSD | C3: M5 | D3: 5187 | E3: 5187.9737 | F3: 5187.2995 | H3: =(A3/86400)+25569 -> 46078.552 | I3: =CEILING(INT(H3*1440)/1440*288,1)/288 -> 46078.552 | J3: =MROUND((I3-25569)*86400,300) -> 1772025300
A4: 1772025600 | B4: XAUUSD | C4: M5 | D4: 5191.13 | E4: 5188.112 | F4: 5187.7058 | H4: =(A4/86400)+25569 -> 46078.556 | I4: =CEILING(INT(H4*1440)/1440*288,1)/288 -> 46078.556 | J4: =MROUND((I4-25569)*86400,300) -> 1772025600
A5: 1772025900 | B5: XAUUSD | C5: M5 | D5: 5188.07 | E5: 5187.9842 | F5: 5187.845 | H5: =(A5/86400)+25569 -> 46078.559 | I5: =CEILING(INT(H5*1440)/1440*288,1)/288 -> 46078.559 | J5: =MROUND((I5-25569)*86400,300) -> 1772025900
A6: 1772026200 | B6: XAUUSD | C6: M5 | D6: 5188.16 | E6: 5187.8513 | F6: 5187.8481 | H6: =(A6/86400)+25569 -> 46078.562 | I6: =CEILING(INT(H6*1440)/1440*288,1)/288 -> 46078.562 | J6: =MROUND((I6-25569)*86400,300) -> 1772026200
A7: 1772026500 | B7: XAUUSD | C7: M5 | D7: 5189.61 | E7: 5187.8602 | F7: 5187.8542 | H7: =(A7/86400)+25569 -> 46078.566 | I7: =CEILING(INT(H7*1440)/1440*288,1)/288 -> 46078.566 | J7: =MROUND((I7-25569)*86400,300) -> 1772026500
A8: 1772026800 | B8: XAUUSD | C8: M5 | D8: 5186.84 | E8: 5188.0224 | F8: 5187.9383 | H8: =(A8/86400)+25569 -> 46078.569 | I8: =CEILING(INT(H8*1440)/1440*288,1)/288 -> 46078.569 | J8: =MROUND((I8-25569)*86400,300) -> 1772026800
A9: 1772027100 | B9: XAUUSD | C9: M5 | D9: 5186.59 | E9: 5188.327 | F9: 5188.1327 | H9: =(A9/86400)+25569 -> 46078.573 | I9: =CEILING(INT(H9*1440)/1440*288,1)/288 -> 46078.573 | J9: =MROUND((I9-25569)*86400,300) -> 1772027100
A10: 1772027400 | B10: XAUUSD | C10: M5 | D10: 5186.07 | E10: 5188.5571 | F10: 5188.3449 | H10: =(A10/86400)+25569 -> 46078.576 | I10: =CEILING(INT(H10*1440)/1440*288,1)/288 -> 46078.576 | J10: =MROUND((I10-25569)*86400,300) -> 1772027400
A11: 1772027700 | B11: XAUUSD | C11: M5 | D11: 5185.23 | E11: 5188.4097 | F11: 5188.3773 | H11: =(A11/86400)+25569 -> 46078.58 | I11: =CEILING(INT(H11*1440)/1440*288,1)/288 -> 46078.58 | J11: =MROUND((I11-25569)*86400,300) -> 1772027700
A12: 1772028000 | B12: XAUUSD | C12: M5 | D12: 5187.18 | E12: 5187.6246 | F12: 5188.0009 | H12: =(A12/86400)+25569 -> 46078.583 | I12: =CEILING(INT(H12*1440)/1440*288,1)/288 -> 46078.583 | J12: =MROUND((I12-25569)*86400,300) -> 1772028000
A13: 1772028300 | B13: XAUUSD | C13: M5 | D13: 5189.99 | E13: 5185.986 | F13: 5186.9935 | H13: =(A13/86400)+25569 -> 46078.587 | I13: =CEILING(INT(H13*1440)/1440*288,1)/288 -> 46078.587 | J13: =MROUND((I13-25569)*86400,300) -> 1772028300
... A500: 1772181600 | B500: XAUUSD | C500: M5 | D500: 5180.32 | E500: 5179.5827 | F500: 5179.4282 | H500: =(A500/86400)+25569 -> 46080.361 | I500: =CEILING(INT(H500*1440)/1440*288,1)/288 -> 46080.361 | J500: =MROUND((I500-25569)*86400,300) -> 1772181600

Sheet SSA_new
A1: timestamp | B1: symbol | C1: timeframe | D1: high | E1: low | F1: ssa | G1: ema_ssa | H1: ssa_high | I1: ssa_low | K1: convert_to_readable_datetime | L1: round_to_nearest_datetime_5m | M1: timestamp_adjusted
A2: 1773636603 | B2: XAUUSD | C2: M5 | D2: 5016 | E2: 5013.94 | F2: 5013.6718 | G2: 5013.7627 | H2: 5015.5347 | I2: 5013.3035 | K2: =(A2/86400)+25569 -> 46097.201 | L2: =CEILING(INT(K2*1440)/1440*288,1)/288 -> 46097.201 | M2: =MROUND((L2-25569)*86400,300) -> 1773636600
A3: 1773636903 | B3: XAUUSD | C3: M5 | D3: 5015.23 | E3: 5012.56 | F3: 5013.4438 | G3: 5013.6033 | H3: 5015.3755 | I3: 5012.6907 | K3: =(A3/86400)+25569 -> 46097.205 | L3: =CEILING(INT(K3*1440)/1440*288,1)/288 -> 46097.205 | M3: =MROUND((L3-25569)*86400,300) -> 1773636900
A4: 1773637203 | B4: XAUUSD | C4: M5 | D4: 5015.8 | E4: 5012.24 | F4: 5013.2638 | G4: 5013.4335 | H4: 5015.2864 | I4: 5012.0865 | K4: =(A4/86400)+25569 -> 46097.208 | L4: =CEILING(INT(K4*1440)/1440*288,1)/288 -> 46097.208 | M4: =MROUND((L4-25569)*86400,300) -> 1773637200
A5: 1773637503 | B5: XAUUSD | C5: M5 | D5: 5015.26 | E5: 5011.3 | F5: 5012.8401 | G5: 5013.1368 | H5: 5015.0382 | I5: 5011.323 | K5: =(A5/86400)+25569 -> 46097.212 | L5: =CEILING(INT(K5*1440)/1440*288,1)/288 -> 46097.212 | M5: =MROUND((L5-25569)*86400,300) -> 1773637500
A6: 1773637803 | B6: XAUUSD | C6: M5 | D6: 5014.91 | E6: 5011.98 | F6: 5012.2479 | G6: 5012.6924 | H6: 5014.6268 | I6: 5010.4915 | K6: =(A6/86400)+25569 -> 46097.215 | L6: =CEILING(INT(K6*1440)/1440*288,1)/288 -> 46097.215 | M6: =MROUND((L6-25569)*86400,300) -> 1773637800
A7: 1773638103 | B7: XAUUSD | C7: M5 | D7: 5013 | E7: 5008.17 | F7: 5011.5365 | G7: 5012.1144 | H7: 5014.0961 | I7: 5009.5117 | K7: =(A7/86400)+25569 -> 46097.219 | L7: =CEILING(INT(K7*1440)/1440*288,1)/288 -> 46097.219 | M7: =MROUND((L7-25569)*86400,300) -> 1773638100
A8: 1773638403 | B8: XAUUSD | C8: M5 | D8: 5012.93 | E8: 5008.79 | F8: 5010.8773 | G8: 5011.4959 | H8: 5013.5584 | I8: 5008.6122 | K8: =(A8/86400)+25569 -> 46097.222 | L8: =CEILING(INT(K8*1440)/1440*288,1)/288 -> 46097.222 | M8: =MROUND((L8-25569)*86400,300) -> 1773638400
A9: 1773638703 | B9: XAUUSD | C9: M5 | D9: 5013.24 | E9: 5008.88 | F9: 5010.3514 | G9: 5010.9236 | H9: 5013.1017 | I9: 5007.8467 | K9: =(A9/86400)+25569 -> 46097.226 | L9: =CEILING(INT(K9*1440)/1440*288,1)/288 -> 46097.226 | M9: =MROUND((L9-25569)*86400,300) -> 1773638700
A10: 1773639003 | B10: XAUUSD | C10: M5 | D10: 5010.97 | E10: 5004.12 | F10: 5010.2166 | G10: 5010.5701 | H10: 5012.8825 | I10: 5007.391 | K10: =(A10/86400)+25569 -> 46097.229 | L10: =CEILING(INT(K10*1440)/1440*288,1)/288 -> 46097.229 | M10: =MROUND((L10-25569)*86400,300) -> 1773639000
A11: 1773639303 | B11: XAUUSD | C11: M5 | D11: 5011.89 | E11: 5003.22 | F11: 5010.9042 | G11: 5010.7372 | H11: 5013.1678 | I11: 5007.6073 | K11: =(A11/86400)+25569 -> 46097.233 | L11: =CEILING(INT(K11*1440)/1440*288,1)/288 -> 46097.233 | M11: =MROUND((L11-25569)*86400,300) -> 1773639300
A12: 1773639603 | B12: XAUUSD | C12: M5 | D12: 5017.3 | E12: 5010.88 | F12: 5012.2555 | G12: 5011.4963 | H12: 5014.087 | I12: 5008.6286 | K12: =(A12/86400)+25569 -> 46097.236 | L12: =CEILING(INT(K12*1440)/1440*288,1)/288 -> 46097.236 | M12: =MROUND((L12-25569)*86400,300) -> 1773639600
A13: 1773639903 | B13: XAUUSD | C13: M5 | D13: 5017.9 | E13: 5015.92 | F13: 5014.2112 | G13: 5012.8538 | H13: 5015.5945 | I13: 5010.2851 | K13: =(A13/86400)+25569 -> 46097.24 | L13: =CEILING(INT(K13*1440)/1440*288,1)/288 -> 46097.24 | M13: =MROUND((L13-25569)*86400,300) -> 1773639900
... A500: 1773793203 | B500: XAUUSD | C500: M5 | D500: 5007.2 | E500: 5004.45 | F500: 5008.2216 | G500: 5008.187 | H500: 5010.9969 | I500: 5006.9621 | K500: =(A500/86400)+25569 -> 46099.014 | L500: =CEILING(INT(K500*1440)/1440*288,1)/288 -> 46099.014 | M500: =MROUND((L500-25569)*86400,300) -> 1773793200

Sheet Data Validation
A1: =Price!L1 -> timestamp_adjusted | B1: timestamp_adjusted_check | C1: =Price!B1 -> symbol | D1: symbol_check | E1: =Price!C1 -> timeframe | F1: timeframe_check | G1: =Price!D1 -> close | H1: close_check | J1: check_all | K1: check_all_batch
A2: =Price!L2 -> 1772025000 | B2: =AND(Price!L2=Trendlines!Q2,Price!L2=ZigZag!K2,Price!L2=Dual_Tema!J2,Price!L2=Pinbar!I2,Price!L2=SSA!J2) -> TRUE | C2: =Price!B2 -> XAUUSD | D2: =AND(Price!B2=Trendlines!B2,Price!B2=ZigZag!B2,Price!B2=Dual_Tema!B2,Price!B2=Pinbar!B2,Price!B2=SSA!B2) -> TRUE | E2: =Price!C2 -> M5 | F2: =AND(Price!C2=Trendlines!C2,Price!C2=ZigZag!C2,Price!C2=Dual_Tema!C2,Price!C2=Pinbar!C2,Price!C2=SSA!C2) -> TRUE | G2: =Price!D2 -> 5187.2 | H2: =AND(Price!D2=Trendlines!D2,Price!D2=ZigZag!D2,Price!D2=Pinbar!D2,Price!D2=SSA!D2) -> TRUE | J2: =AND(B2=TRUE,D2=TRUE,F2=TRUE,H2=TRUE) -> TRUE | K2: =AND(J2:J500) -> TRUE
A3: =Price!L3 -> 1772025300 | B3: =AND(Price!L3=Trendlines!Q3,Price!L3=ZigZag!K3,Price!L3=Dual_Tema!J3,Price!L3=Pinbar!I3,Price!L3=SSA!J3) -> TRUE | C3: =Price!B3 -> XAUUSD | D3: =AND(Price!B3=Trendlines!B3,Price!B3=ZigZag!B3,Price!B3=Dual_Tema!B3,Price!B3=Pinbar!B3,Price!B3=SSA!B3) -> TRUE | E3: =Price!C3 -> M5 | F3: =AND(Price!C3=Trendlines!C3,Price!C3=ZigZag!C3,Price!C3=Dual_Tema!C3,Price!C3=Pinbar!C3,Price!C3=SSA!C3) -> TRUE | G3: =Price!D3 -> 5187 | H3: =AND(Price!D3=Trendlines!D3,Price!D3=ZigZag!D3,Price!D3=Pinbar!D3,Price!D3=SSA!D3) -> TRUE | J3: =AND(B3=TRUE,D3=TRUE,F3=TRUE,H3=TRUE) -> TRUE
A4: =Price!L4 -> 1772025600 | B4: =AND(Price!L4=Trendlines!Q4,Price!L4=ZigZag!K4,Price!L4=Dual_Tema!J4,Price!L4=Pinbar!I4,Price!L4=SSA!J4) -> TRUE | C4: =Price!B4 -> XAUUSD | D4: =AND(Price!B4=Trendlines!B4,Price!B4=ZigZag!B4,Price!B4=Dual_Tema!B4,Price!B4=Pinbar!B4,Price!B4=SSA!B4) -> TRUE | E4: =Price!C4 -> M5 | F4: =AND(Price!C4=Trendlines!C4,Price!C4=ZigZag!C4,Price!C4=Dual_Tema!C4,Price!C4=Pinbar!C4,Price!C4=SSA!C4) -> TRUE | G4: =Price!D4 -> 5191.13 | H4: =AND(Price!D4=Trendlines!D4,Price!D4=ZigZag!D4,Price!D4=Pinbar!D4,Price!D4=SSA!D4) -> TRUE | J4: =AND(B4=TRUE,D4=TRUE,F4=TRUE,H4=TRUE) -> TRUE
A5: =Price!L5 -> 1772025900 | B5: =AND(Price!L5=Trendlines!Q5,Price!L5=ZigZag!K5,Price!L5=Dual_Tema!J5,Price!L5=Pinbar!I5,Price!L5=SSA!J5) -> TRUE | C5: =Price!B5 -> XAUUSD | D5: =AND(Price!B5=Trendlines!B5,Price!B5=ZigZag!B5,Price!B5=Dual_Tema!B5,Price!B5=Pinbar!B5,Price!B5=SSA!B5) -> TRUE | E5: =Price!C5 -> M5 | F5: =AND(Price!C5=Trendlines!C5,Price!C5=ZigZag!C5,Price!C5=Dual_Tema!C5,Price!C5=Pinbar!C5,Price!C5=SSA!C5) -> TRUE | G5: =Price!D5 -> 5188.07 | H5: =AND(Price!D5=Trendlines!D5,Price!D5=ZigZag!D5,Price!D5=Pinbar!D5,Price!D5=SSA!D5) -> TRUE | J5: =AND(B5=TRUE,D5=TRUE,F5=TRUE,H5=TRUE) -> TRUE
A6: =Price!L6 -> 1772026200 | B6: =AND(Price!L6=Trendlines!Q6,Price!L6=ZigZag!K6,Price!L6=Dual_Tema!J6,Price!L6=Pinbar!I6,Price!L6=SSA!J6) -> TRUE | C6: =Price!B6 -> XAUUSD | D6: =AND(Price!B6=Trendlines!B6,Price!B6=ZigZag!B6,Price!B6=Dual_Tema!B6,Price!B6=Pinbar!B6,Price!B6=SSA!B6) -> TRUE | E6: =Price!C6 -> M5 | F6: =AND(Price!C6=Trendlines!C6,Price!C6=ZigZag!C6,Price!C6=Dual_Tema!C6,Price!C6=Pinbar!C6,Price!C6=SSA!C6) -> TRUE | G6: =Price!D6 -> 5188.16 | H6: =AND(Price!D6=Trendlines!D6,Price!D6=ZigZag!D6,Price!D6=Pinbar!D6,Price!D6=SSA!D6) -> TRUE | J6: =AND(B6=TRUE,D6=TRUE,F6=TRUE,H6=TRUE) -> TRUE
A7: =Price!L7 -> 1772026500 | B7: =AND(Price!L7=Trendlines!Q7,Price!L7=ZigZag!K7,Price!L7=Dual_Tema!J7,Price!L7=Pinbar!I7,Price!L7=SSA!J7) -> TRUE | C7: =Price!B7 -> XAUUSD | D7: =AND(Price!B7=Trendlines!B7,Price!B7=ZigZag!B7,Price!B7=Dual_Tema!B7,Price!B7=Pinbar!B7,Price!B7=SSA!B7) -> TRUE | E7: =Price!C7 -> M5 | F7: =AND(Price!C7=Trendlines!C7,Price!C7=ZigZag!C7,Price!C7=Dual_Tema!C7,Price!C7=Pinbar!C7,Price!C7=SSA!C7) -> TRUE | G7: =Price!D7 -> 5189.61 | H7: =AND(Price!D7=Trendlines!D7,Price!D7=ZigZag!D7,Price!D7=Pinbar!D7,Price!D7=SSA!D7) -> TRUE | J7: =AND(B7=TRUE,D7=TRUE,F7=TRUE,H7=TRUE) -> TRUE
A8: =Price!L8 -> 1772026800 | B8: =AND(Price!L8=Trendlines!Q8,Price!L8=ZigZag!K8,Price!L8=Dual_Tema!J8,Price!L8=Pinbar!I8,Price!L8=SSA!J8) -> TRUE | C8: =Price!B8 -> XAUUSD | D8: =AND(Price!B8=Trendlines!B8,Price!B8=ZigZag!B8,Price!B8=Dual_Tema!B8,Price!B8=Pinbar!B8,Price!B8=SSA!B8) -> TRUE | E8: =Price!C8 -> M5 | F8: =AND(Price!C8=Trendlines!C8,Price!C8=ZigZag!C8,Price!C8=Dual_Tema!C8,Price!C8=Pinbar!C8,Price!C8=SSA!C8) -> TRUE | G8: =Price!D8 -> 5186.84 | H8: =AND(Price!D8=Trendlines!D8,Price!D8=ZigZag!D8,Price!D8=Pinbar!D8,Price!D8=SSA!D8) -> TRUE | J8: =AND(B8=TRUE,D8=TRUE,F8=TRUE,H8=TRUE) -> TRUE
A9: =Price!L9 -> 1772027100 | B9: =AND(Price!L9=Trendlines!Q9,Price!L9=ZigZag!K9,Price!L9=Dual_Tema!J9,Price!L9=Pinbar!I9,Price!L9=SSA!J9) -> TRUE | C9: =Price!B9 -> XAUUSD | D9: =AND(Price!B9=Trendlines!B9,Price!B9=ZigZag!B9,Price!B9=Dual_Tema!B9,Price!B9=Pinbar!B9,Price!B9=SSA!B9) -> TRUE | E9: =Price!C9 -> M5 | F9: =AND(Price!C9=Trendlines!C9,Price!C9=ZigZag!C9,Price!C9=Dual_Tema!C9,Price!C9=Pinbar!C9,Price!C9=SSA!C9) -> TRUE | G9: =Price!D9 -> 5186.59 | H9: =AND(Price!D9=Trendlines!D9,Price!D9=ZigZag!D9,Price!D9=Pinbar!D9,Price!D9=SSA!D9) -> TRUE | J9: =AND(B9=TRUE,D9=TRUE,F9=TRUE,H9=TRUE) -> TRUE
A10: =Price!L10 -> 1772027400 | B10: =AND(Price!L10=Trendlines!Q10,Price!L10=ZigZag!K10,Price!L10=Dual_Tema!J10,Price!L10=Pinbar!I10,Price!L10=SSA!J10) -> TRUE | C10: =Price!B10 -> XAUUSD | D10: =AND(Price!B10=Trendlines!B10,Price!B10=ZigZag!B10,Price!B10=Dual_Tema!B10,Price!B10=Pinbar!B10,Price!B10=SSA!B10) -> TRUE | E10: =Price!C10 -> M5 | F10: =AND(Price!C10=Trendlines!C10,Price!C10=ZigZag!C10,Price!C10=Dual_Tema!C10,Price!C10=Pinbar!C10,Price!C10=SSA!C10) -> TRUE | G10: =Price!D10 -> 5186.07 | H10: =AND(Price!D10=Trendlines!D10,Price!D10=ZigZag!D10,Price!D10=Pinbar!D10,Price!D10=SSA!D10) -> TRUE | J10: =AND(B10=TRUE,D10=TRUE,F10=TRUE,H10=TRUE) -> TRUE
A11: =Price!L11 -> 1772027700 | B11: =AND(Price!L11=Trendlines!Q11,Price!L11=ZigZag!K11,Price!L11=Dual_Tema!J11,Price!L11=Pinbar!I11,Price!L11=SSA!J11) -> TRUE | C11: =Price!B11 -> XAUUSD | D11: =AND(Price!B11=Trendlines!B11,Price!B11=ZigZag!B11,Price!B11=Dual_Tema!B11,Price!B11=Pinbar!B11,Price!B11=SSA!B11) -> TRUE | E11: =Price!C11 -> M5 | F11: =AND(Price!C11=Trendlines!C11,Price!C11=ZigZag!C11,Price!C11=Dual_Tema!C11,Price!C11=Pinbar!C11,Price!C11=SSA!C11) -> TRUE | G11: =Price!D11 -> 5185.23 | H11: =AND(Price!D11=Trendlines!D11,Price!D11=ZigZag!D11,Price!D11=Pinbar!D11,Price!D11=SSA!D11) -> TRUE | J11: =AND(B11=TRUE,D11=TRUE,F11=TRUE,H11=TRUE) -> TRUE
A12: =Price!L12 -> 1772028000 | B12: =AND(Price!L12=Trendlines!Q12,Price!L12=ZigZag!K12,Price!L12=Dual_Tema!J12,Price!L12=Pinbar!I12,Price!L12=SSA!J12) -> TRUE | C12: =Price!B12 -> XAUUSD | D12: =AND(Price!B12=Trendlines!B12,Price!B12=ZigZag!B12,Price!B12=Dual_Tema!B12,Price!B12=Pinbar!B12,Price!B12=SSA!B12) -> TRUE | E12: =Price!C12 -> M5 | F12: =AND(Price!C12=Trendlines!C12,Price!C12=ZigZag!C12,Price!C12=Dual_Tema!C12,Price!C12=Pinbar!C12,Price!C12=SSA!C12) -> TRUE | G12: =Price!D12 -> 5187.18 | H12: =AND(Price!D12=Trendlines!D12,Price!D12=ZigZag!D12,Price!D12=Pinbar!D12,Price!D12=SSA!D12) -> TRUE | J12: =AND(B12=TRUE,D12=TRUE,F12=TRUE,H12=TRUE) -> TRUE
A13: =Price!L13 -> 1772028300 | B13: =AND(Price!L13=Trendlines!Q13,Price!L13=ZigZag!K13,Price!L13=Dual_Tema!J13,Price!L13=Pinbar!I13,Price!L13=SSA!J13) -> TRUE | C13: =Price!B13 -> XAUUSD | D13: =AND(Price!B13=Trendlines!B13,Price!B13=ZigZag!B13,Price!B13=Dual_Tema!B13,Price!B13=Pinbar!B13,Price!B13=SSA!B13) -> TRUE | E13: =Price!C13 -> M5 | F13: =AND(Price!C13=Trendlines!C13,Price!C13=ZigZag!C13,Price!C13=Dual_Tema!C13,Price!C13=Pinbar!C13,Price!C13=SSA!C13) -> TRUE | G13: =Price!D13 -> 5189.99 | H13: =AND(Price!D13=Trendlines!D13,Price!D13=ZigZag!D13,Price!D13=Pinbar!D13,Price!D13=SSA!D13) -> TRUE | J13: =AND(B13=TRUE,D13=TRUE,F13=TRUE,H13=TRUE) -> TRUE
A14: =Price!L14 -> 1772028600 | B14: =AND(Price!L14=Trendlines!Q14,Price!L14=ZigZag!K14,Price!L14=Dual_Tema!J14,Price!L14=Pinbar!I14,Price!L14=SSA!J14) -> TRUE | C14: =Price!B14 -> XAUUSD | D14: =AND(Price!B14=Trendlines!B14,Price!B14=ZigZag!B14,Price!B14=Dual_Tema!B14,Price!B14=Pinbar!B14,Price!B14=SSA!B14) -> TRUE | E14: =Price!C14 -> M5 | F14: =AND(Price!C14=Trendlines!C14,Price!C14=ZigZag!C14,Price!C14=Dual_Tema!C14,Price!C14=Pinbar!C14,Price!C14=SSA!C14) -> TRUE | G14: =Price!D14 -> 5185.44 | H14: =AND(Price!D14=Trendlines!D14,Price!D14=ZigZag!D14,Price!D14=Pinbar!D14,Price!D14=SSA!D14) -> TRUE | J14: =AND(B14=TRUE,D14=TRUE,F14=TRUE,H14=TRUE) -> TRUE
... A500: =Price!L500 -> 1772181600 | B500: =AND(Price!L500=Trendlines!Q500,Price!L500=ZigZag!K500,Price!L500=Dual_Tema!J500,Price!L500=Pinbar!I500,Price!L500=SSA!J500) -> TRUE | C500: =Price!B500 -> XAUUSD | D500: =AND(Price!B500=Trendlines!B500,Price!B500=ZigZag!B500,Price!B500=Dual_Tema!B500,Price!B500=Pinbar!B500,Price!B500=SSA!B500) -> TRUE | E500: =Price!C500 -> M5 | F500: =AND(Price!C500=Trendlines!C500,Price!C500=ZigZag!C500,Price!C500=Dual_Tema!C500,Price!C500=Pinbar!C500,Price!C500=SSA!C500) -> TRUE | G500: =Price!D500 -> 5180.32 | H500: =AND(Price!D500=Trendlines!D500,Price!D500=ZigZag!D500,Price!D500=Pinbar!D500,Price!D500=SSA!D500) -> TRUE | J500: =AND(B500=TRUE,D500=TRUE,F500=TRUE,H500=TRUE) -> TRUE

Sheet Trendline Selection
A1: ='Data Validation'!A1 -> timestamp_adjusted | B1: ='Data Validation'!C1 -> symbol | C1: ='Data Validation'!E1 -> timeframe | D1: ='Data Validation'!G1 -> close | E1: =Trendlines!E1 -> horiz_peak_line_1 | F1: =Trendlines!F1 -> horiz_peak_line_2 | G1: =Trendlines!G1 -> horiz_peak_line_3 | H1: =Trendlines!H1 -> horiz_bottom_line_1 | I1: =Trendlines!I1 -> horiz_bottom_line_2 | J1: =Trendlines!J1 -> horiz_bottom_line_3 | K1: slope_period | L1: slope_p1 | M1: slope_2 | N1: slope_p3 | O1: slope_b1 | P1: slope_b2 | Q1: slope_b3 | S1: p1_p2 | T1: p1_p3 | U1: p1_b1 | V1: p1_b2 | W1: p1_b3 | X1: p2_p3 | Y1: p2_b1 | Z1: p2_b2 | AA1: p2_b3 | AB1: p3_b1 | AC1: p3_b2 | AD1: p3_b3 | AE1: b1_b2 | AF1: b1_b3 | AG1: b2_b3 | AI1: prox_p1_p2 | AJ1: prox_p1_p3 | AK1: prox_p1_b1 | AL1: prox_p1_b2 | AM1: prox_p1_b3 | AN1: prox_p2_p3 | AO1: prox_p2_b1 | AP1: prox_p2_b2 | AQ1: prox_p2_b3 | AR1: prox_p3_b1 | AS1: prox_p3_b2 | AT1: prox_p3_b3 | AU1: prox_b1_b2 | AV1: prox_b1_b3 | AW1: prox_b2_b3 | AY1: prox_p1_p2 | AZ1: prox_p1_p3 | BA1: prox_p1_b1 | BB1: prox_p1_b2 | BC1: prox_p1_b3 | BD1: prox_p2_p3 | BE1: prox_p2_b1 | BF1: prox_p2_b2 | BG1: prox_p2_b3 | BH1: prox_p3_b1 | BI1: prox_p3_b2 | BJ1: prox_p3_b3 | BK1: prox_b1_b2 | BL1: prox_b1_b3 | BM1: prox_b2_b3 | BO1: prox_p1p2_p1 | BP1: prox_p1p2_p2 | BQ1: prox_p1p3_p1 | BR1: prox_p1p3_p3 | BS1: prox_p1b1_p1 | BT1: prox_p1b1_b1 | BU1: prox_p1b2_p1 | BV1: prox_p1b2_b2 | BW1: prox_p1b3_p1 | BX1: prox_p1b3_b3 | BY1: prox_p2p3_p2 | BZ1: prox_p2p3_p3 | CA1: prox_p2b1_p2 | CB1: prox_p2b1_b1 | CC1: prox_p2b2_p2 | CD1: prox_p2b2_b2 | CE1: prox_p2b3_p2 | CF1: prox_p2b3_b3 | CG1: prox_p3b1_p3 | CH1: prox_p3b1_b1 | CI1: prox_p3b2_p3 | CJ1: prox_p3b2_b2 | CK1: prox_p3b3_p3 | CL1: prox_p3b3_b3 | CM1: prox_b1b2_b1 | CN1: prox_b1b2_b2 | CO1: prox_b1b3_b1 | CP1: prox_b1b3_b3 | CQ1: prox_b2b3_b2 | CR1: prox_b2b3_b3 | CT1: large_1 | CU1: large_2 | CV1: large_3 | CW1: large_4 | CY1: slope_large_1 | CZ1: slope_large_2 | DA1: slope_large_3 | DB1: slope_large_4 | DD1: angle_large_1 | DE1: angle_large_2 | DF1: angle_large_3 | DG1: angle_large_4 | DI1: sd_angle | DK1: max_allow_angle | DL1: min_allow_angle | DN1: slope_large_1_check | DO1: slope_large_2_check | DP1: slope_large_3_check | DQ1: slope_large_4_check | DS1: filter_large_1 | DT1: filter_large_2 | DU1: filter_large_3 | DV1: filter_large_4 | DX1: max_filter | DY1: min_filter | EA1: select_trendline_1 | EB1: select_trendline_2 | ED1: eff_trendline_1 | EE1: eff_trendline_2
A2: =IF('Data Validation'!$K$2<>TRUE,"",'Data Validation'!A304) -> 1772119200 | B2: =IF('Data Validation'!$K$2<>TRUE,"",'Data Validation'!C304) -> XAUUSD | C2: =IF('Data Validation'!$K$2<>TRUE,"",'Data Validation'!E304) -> M5 | D2: =IF('Data Validation'!$K$2<>TRUE,"",'Data Validation'!G304) -> 5154.46 | E2: =IF($C2<>"M5","",Trendlines!E304) -> 5199.45 | F2: =IF($C2<>"M5","",Trendlines!F304) -> 5194.02 | G2: =IF($C2<>"M5","",Trendlines!G304) -> 5203.22 | H2: =IF($C2<>"M5","",Trendlines!H304) -> 5169.63 | I2: =IF($C2<>"M5","",Trendlines!I304) -> 5177.71 | J2: =IF($C2<>"M5","",Trendlines!J304) -> 5162.83 | K2: 96 | CY2: =IFERROR(INDEX($L2:$Q2,MATCH(CT2,$E2:$J2,0)),"") | CZ2: =IFERROR(INDEX($L2:$Q2,MATCH(CU2,$E2:$J2,0)),"") | DA2: =IFERROR(INDEX($L2:$Q2,MATCH(CV2,$E2:$J2,0)),"") | DB2: =IFERROR(INDEX($L2:$Q2,MATCH(CW2,$E2:$J2,0)),"") | DD2: =IFERROR(DEGREES(ATAN(CY2)),"") | DE2: =IFERROR(DEGREES(ATAN(CZ2)),"") | DF2: =IFERROR(DEGREES(ATAN(DA2)),"") | DG2: =IFERROR(DEGREES(ATAN(DB2)),"")
A3: =IF('Data Validation'!$K$2<>TRUE,"",'Data Validation'!A305) -> 1772119500 | B3: =IF('Data Validation'!$K$2<>TRUE,"",'Data Validation'!C305) -> XAUUSD | C3: =IF('Data Validation'!$K$2<>TRUE,"",'Data Validation'!E305) -> M5 | D3: =IF('Data Validation'!$K$2<>TRUE,"",'Data Validation'!G305) -> 5141.51 | E3: =IF($C3<>"M5","",Trendlines!E305) -> 5199.46 | F3: =IF($C3<>"M5","",Trendlines!F305) -> 5194 | G3: =IF($C3<>"M5","",Trendlines!G305) -> 5203.2 | H3: =IF($C3<>"M5","",Trendlines!H305) -> 5169.7 | I3: =IF($C3<>"M5","",Trendlines!I305) -> 5177.73 | J3: =IF($C3<>"M5","",Trendlines!J305) -> 5162.87 | K3: 96 | CY3: =IFERROR(INDEX($L3:$Q3,MATCH(CT3,$E3:$J3,0)),"") | CZ3: =IFERROR(INDEX($L3:$Q3,MATCH(CU3,$E3:$J3,0)),"") | DA3: =IFERROR(INDEX($L3:$Q3,MATCH(CV3,$E3:$J3,0)),"") | DB3: =IFERROR(INDEX($L3:$Q3,MATCH(CW3,$E3:$J3,0)),"") | DD3: =IFERROR(DEGREES(ATAN(CY3)),"") | DE3: =IFERROR(DEGREES(ATAN(CZ3)),"") | DF3: =IFERROR(DEGREES(ATAN(DA3)),"") | DG3: =IFERROR(DEGREES(ATAN(DB3)),"")
A4: =IF('Data Validation'!$K$2<>TRUE,"",'Data Validation'!A306) -> 1772119800 | B4: =IF('Data Validation'!$K$2<>TRUE,"",'Data Validation'!C306) -> XAUUSD | C4: =IF('Data Validation'!$K$2<>TRUE,"",'Data Validation'!E306) -> M5 | D4: =IF('Data Validation'!$K$2<>TRUE,"",'Data Validation'!G306) -> 5153.62 | E4: =IF($C4<>"M5","",Trendlines!E306) -> 5199.46 | F4: =IF($C4<>"M5","",Trendlines!F306) -> 5193.97 | G4: =IF($C4<>"M5","",Trendlines!G306) -> 5203.19 | H4: =IF($C4<>"M5","",Trendlines!H306) -> 5169.78 | I4: =IF($C4<>"M5","",Trendlines!I306) -> 5177.75 | J4: =IF($C4<>"M5","",Trendlines!J306) -> 5162.91 | K4: 96 | CY4: =IFERROR(INDEX($L4:$Q4,MATCH(CT4,$E4:$J4,0)),"") | CZ4: =IFERROR(INDEX($L4:$Q4,MATCH(CU4,$E4:$J4,0)),"") | DA4: =IFERROR(INDEX($L4:$Q4,MATCH(CV4,$E4:$J4,0)),"") | DB4: =IFERROR(INDEX($L4:$Q4,MATCH(CW4,$E4:$J4,0)),"") | DD4: =IFERROR(DEGREES(ATAN(CY4)),"") | DE4: =IFERROR(DEGREES(ATAN(CZ4)),"") | DF4: =IFERROR(DEGREES(ATAN(DA4)),"") | DG4: =IFERROR(DEGREES(ATAN(DB4)),"")
A5: =IF('Data Validation'!$K$2<>TRUE,"",'Data Validation'!A307) -> 1772120100 | B5: =IF('Data Validation'!$K$2<>TRUE,"",'Data Validation'!C307) -> XAUUSD | C5: =IF('Data Validation'!$K$2<>TRUE,"",'Data Validation'!E307) -> M5 | D5: =IF('Data Validation'!$K$2<>TRUE,"",'Data Validation'!G307) -> 5169.23 | E5: =IF($C5<>"M5","",Trendlines!E307) -> 5199.47 | F5: =IF($C5<>"M5","",Trendlines!F307) -> 5193.95 | G5: =IF($C5<>"M5","",Trendlines!G307) -> 5203.17 | H5: =IF($C5<>"M5","",Trendlines!H307) -> 5169.86 | I5: =IF($C5<>"M5","",Trendlines!I307) -> 5177.77 | J5: =IF($C5<>"M5","",Trendlines!J307) -> 5162.95 | K5: 96 | CY5: =IFERROR(INDEX($L5:$Q5,MATCH(CT5,$E5:$J5,0)),"") | CZ5: =IFERROR(INDEX($L5:$Q5,MATCH(CU5,$E5:$J5,0)),"") | DA5: =IFERROR(INDEX($L5:$Q5,MATCH(CV5,$E5:$J5,0)),"") | DB5: =IFERROR(INDEX($L5:$Q5,MATCH(CW5,$E5:$J5,0)),"") | DD5: =IFERROR(DEGREES(ATAN(CY5)),"") | DE5: =IFERROR(DEGREES(ATAN(CZ5)),"") | DF5: =IFERROR(DEGREES(ATAN(DA5)),"") | DG5: =IFERROR(DEGREES(ATAN(DB5)),"")
A6: =IF('Data Validation'!$K$2<>TRUE,"",'Data Validation'!A308) -> 1772120400 | B6: =IF('Data Validation'!$K$2<>TRUE,"",'Data Validation'!C308) -> XAUUSD | C6: =IF('Data Validation'!$K$2<>TRUE,"",'Data Validation'!E308) -> M5 | D6: =IF('Data Validation'!$K$2<>TRUE,"",'Data Validation'!G308) -> 5175.56 | E6: =IF($C6<>"M5","",Trendlines!E308) -> 5199.47 | F6: =IF($C6<>"M5","",Trendlines!F308) -> 5193.92 | G6: =IF($C6<>"M5","",Trendlines!G308) -> 5203.15 | H6: =IF($C6<>"M5","",Trendlines!H308) -> 5169.93 | I6: =IF($C6<>"M5","",Trendlines!I308) -> 5177.79 | J6: =IF($C6<>"M5","",Trendlines!J308) -> 5162.99 | K6: 96 | CY6: =IFERROR(INDEX($L6:$Q6,MATCH(CT6,$E6:$J6,0)),"") | CZ6: =IFERROR(INDEX($L6:$Q6,MATCH(CU6,$E6:$J6,0)),"") | DA6: =IFERROR(INDEX($L6:$Q6,MATCH(CV6,$E6:$J6,0)),"") | DB6: =IFERROR(INDEX($L6:$Q6,MATCH(CW6,$E6:$J6,0)),"") | DD6: =IFERROR(DEGREES(ATAN(CY6)),"") | DE6: =IFERROR(DEGREES(ATAN(CZ6)),"") | DF6: =IFERROR(DEGREES(ATAN(DA6)),"") | DG6: =IFERROR(DEGREES(ATAN(DB6)),"")
A7: =IF('Data Validation'!$K$2<>TRUE,"",'Data Validation'!A309) -> 1772120700 | B7: =IF('Data Validation'!$K$2<>TRUE,"",'Data Validation'!C309) -> XAUUSD | C7: =IF('Data Validation'!$K$2<>TRUE,"",'Data Validation'!E309) -> M5 | D7: =IF('Data Validation'!$K$2<>TRUE,"",'Data Validation'!G309) -> 5182.38 | E7: =IF($C7<>"M5","",Trendlines!E309) -> 5199.48 | F7: =IF($C7<>"M5","",Trendlines!F309) -> 5193.89 | G7: =IF($C7<>"M5","",Trendlines!G309) -> 5203.13 | H7: =IF($C7<>"M5","",Trendlines!H309) -> 5170.01 | I7: =IF($C7<>"M5","",Trendlines!I309) -> 5177.82 | J7: =IF($C7<>"M5","",Trendlines!J309) -> 5163.03 | K7: 96 | CY7: =IFERROR(INDEX($L7:$Q7,MATCH(CT7,$E7:$J7,0)),"") | CZ7: =IFERROR(INDEX($L7:$Q7,MATCH(CU7,$E7:$J7,0)),"") | DA7: =IFERROR(INDEX($L7:$Q7,MATCH(CV7,$E7:$J7,0)),"") | DB7: =IFERROR(INDEX($L7:$Q7,MATCH(CW7,$E7:$J7,0)),"") | DD7: =IFERROR(DEGREES(ATAN(CY7)),"") | DE7: =IFERROR(DEGREES(ATAN(CZ7)),"") | DF7: =IFERROR(DEGREES(ATAN(DA7)),"") | DG7: =IFERROR(DEGREES(ATAN(DB7)),"")
A8: =IF('Data Validation'!$K$2<>TRUE,"",'Data Validation'!A310) -> 1772121000 | B8: =IF('Data Validation'!$K$2<>TRUE,"",'Data Validation'!C310) -> XAUUSD | C8: =IF('Data Validation'!$K$2<>TRUE,"",'Data Validation'!E310) -> M5 | D8: =IF('Data Validation'!$K$2<>TRUE,"",'Data Validation'!G310) -> 5189.7 | E8: =IF($C8<>"M5","",Trendlines!E310) -> 5199.48 | F8: =IF($C8<>"M5","",Trendlines!F310) -> 5193.87 | G8: =IF($C8<>"M5","",Trendlines!G310) -> 5203.12 | H8: =IF($C8<>"M5","",Trendlines!H310) -> 5170.08 | I8: =IF($C8<>"M5","",Trendlines!I310) -> 5177.84 | J8: =IF($C8<>"M5","",Trendlines!J310) -> 5163.07 | K8: 96 | CY8: =IFERROR(INDEX($L8:$Q8,MATCH(CT8,$E8:$J8,0)),"") | CZ8: =IFERROR(INDEX($L8:$Q8,MATCH(CU8,$E8:$J8,0)),"") | DA8: =IFERROR(INDEX($L8:$Q8,MATCH(CV8,$E8:$J8,0)),"") | DB8: =IFERROR(INDEX($L8:$Q8,MATCH(CW8,$E8:$J8,0)),"") | DD8: =IFERROR(DEGREES(ATAN(CY8)),"") | DE8: =IFERROR(DEGREES(ATAN(CZ8)),"") | DF8: =IFERROR(DEGREES(ATAN(DA8)),"") | DG8: =IFERROR(DEGREES(ATAN(DB8)),"")
A9: =IF('Data Validation'!$K$2<>TRUE,"",'Data Validation'!A311) -> 1772121300 | B9: =IF('Data Validation'!$K$2<>TRUE,"",'Data Validation'!C311) -> XAUUSD | C9: =IF('Data Validation'!$K$2<>TRUE,"",'Data Validation'!E311) -> M5 | D9: =IF('Data Validation'!$K$2<>TRUE,"",'Data Validation'!G311) -> 5185.86 | E9: =IF($C9<>"M5","",Trendlines!E311) -> 5199.49 | F9: =IF($C9<>"M5","",Trendlines!F311) -> 5193.84 | G9: =IF($C9<>"M5","",Trendlines!G311) -> 5203.1 | H9: =IF($C9<>"M5","",Trendlines!H311) -> 5170.16 | I9: =IF($C9<>"M5","",Trendlines!I311) -> 5177.86 | J9: =IF($C9<>"M5","",Trendlines!J311) -> 5163.11 | K9: 96 | CY9: =IFERROR(INDEX($L9:$Q9,MATCH(CT9,$E9:$J9,0)),"") | CZ9: =IFERROR(INDEX($L9:$Q9,MATCH(CU9,$E9:$J9,0)),"") | DA9: =IFERROR(INDEX($L9:$Q9,MATCH(CV9,$E9:$J9,0)),"") | DB9: =IFERROR(INDEX($L9:$Q9,MATCH(CW9,$E9:$J9,0)),"") | DD9: =IFERROR(DEGREES(ATAN(CY9)),"") | DE9: =IFERROR(DEGREES(ATAN(CZ9)),"") | DF9: =IFERROR(DEGREES(ATAN(DA9)),"") | DG9: =IFERROR(DEGREES(ATAN(DB9)),"")
A10: =IF('Data Validation'!$K$2<>TRUE,"",'Data Validation'!A312) -> 1772121600 | B10: =IF('Data Validation'!$K$2<>TRUE,"",'Data Validation'!C312) -> XAUUSD | C10: =IF('Data Validation'!$K$2<>TRUE,"",'Data Validation'!E312) -> M5 | D10: =IF('Data Validation'!$K$2<>TRUE,"",'Data Validation'!G312) -> 5178.92 | E10: =IF($C10<>"M5","",Trendlines!E312) -> 5199.49 | F10: =IF($C10<>"M5","",Trendlines!F312) -> 5193.82 | G10: =IF($C10<>"M5","",Trendlines!G312) -> 5203.08 | H10: =IF($C10<>"M5","",Trendlines!H312) -> 5170.23 | I10: =IF($C10<>"M5","",Trendlines!I312) -> 5177.88 | J10: =IF($C10<>"M5","",Trendlines!J312) -> 5163.14 | K10: 96 | CY10: =IFERROR(INDEX($L10:$Q10,MATCH(CT10,$E10:$J10,0)),"") | CZ10: =IFERROR(INDEX($L10:$Q10,MATCH(CU10,$E10:$J10,0)),"") | DA10: =IFERROR(INDEX($L10:$Q10,MATCH(CV10,$E10:$J10,0)),"") | DB10: =IFERROR(INDEX($L10:$Q10,MATCH(CW10,$E10:$J10,0)),"") | DD10: =IFERROR(DEGREES(ATAN(CY10)),"") | DE10: =IFERROR(DEGREES(ATAN(CZ10)),"") | DF10: =IFERROR(DEGREES(ATAN(DA10)),"") | DG10: =IFERROR(DEGREES(ATAN(DB10)),"")
A11: =IF('Data Validation'!$K$2<>TRUE,"",'Data Validation'!A313) -> 1772121900 | B11: =IF('Data Validation'!$K$2<>TRUE,"",'Data Validation'!C313) -> XAUUSD | C11: =IF('Data Validation'!$K$2<>TRUE,"",'Data Validation'!E313) -> M5 | D11: =IF('Data Validation'!$K$2<>TRUE,"",'Data Validation'!G313) -> 5177.76 | E11: =IF($C11<>"M5","",Trendlines!E313) -> 5199.5 | F11: =IF($C11<>"M5","",Trendlines!F313) -> 5193.79 | G11: =IF($C11<>"M5","",Trendlines!G313) -> 5203.06 | H11: =IF($C11<>"M5","",Trendlines!H313) -> 5170.31 | I11: =IF($C11<>"M5","",Trendlines!I313) -> 5177.91 | J11: =IF($C11<>"M5","",Trendlines!J313) -> 5163.18 | K11: 96 | CY11: =IFERROR(INDEX($L11:$Q11,MATCH(CT11,$E11:$J11,0)),"") | CZ11: =IFERROR(INDEX($L11:$Q11,MATCH(CU11,$E11:$J11,0)),"") | DA11: =IFERROR(INDEX($L11:$Q11,MATCH(CV11,$E11:$J11,0)),"") | DB11: =IFERROR(INDEX($L11:$Q11,MATCH(CW11,$E11:$J11,0)),"") | DD11: =IFERROR(DEGREES(ATAN(CY11)),"") | DE11: =IFERROR(DEGREES(ATAN(CZ11)),"") | DF11: =IFERROR(DEGREES(ATAN(DA11)),"") | DG11: =IFERROR(DEGREES(ATAN(DB11)),"")
A12: =IF('Data Validation'!$K$2<>TRUE,"",'Data Validation'!A314) -> 1772122200 | B12: =IF('Data Validation'!$K$2<>TRUE,"",'Data Validation'!C314) -> XAUUSD | C12: =IF('Data Validation'!$K$2<>TRUE,"",'Data Validation'!E314) -> M5 | D12: =IF('Data Validation'!$K$2<>TRUE,"",'Data Validation'!G314) -> 5176.76 | E12: =IF($C12<>"M5","",Trendlines!E314) -> 5199.51 | F12: =IF($C12<>"M5","",Trendlines!F314) -> 5193.76 | G12: =IF($C12<>"M5","",Trendlines!G314) -> 5203.05 | H12: =IF($C12<>"M5","",Trendlines!H314) -> 5170.38 | I12: =IF($C12<>"M5","",Trendlines!I314) -> 5177.93 | J12: =IF($C12<>"M5","",Trendlines!J314) -> 5163.22 | K12: 96 | CY12: =IFERROR(INDEX($L12:$Q12,MATCH(CT12,$E12:$J12,0)),"") | CZ12: =IFERROR(INDEX($L12:$Q12,MATCH(CU12,$E12:$J12,0)),"") | DA12: =IFERROR(INDEX($L12:$Q12,MATCH(CV12,$E12:$J12,0)),"") | DB12: =IFERROR(INDEX($L12:$Q12,MATCH(CW12,$E12:$J12,0)),"") | DD12: =IFERROR(DEGREES(ATAN(CY12)),"") | DE12: =IFERROR(DEGREES(ATAN(CZ12)),"") | DF12: =IFERROR(DEGREES(ATAN(DA12)),"") | DG12: =IFERROR(DEGREES(ATAN(DB12)),"")
A13: =IF('Data Validation'!$K$2<>TRUE,"",'Data Validation'!A315) -> 1772122500 | B13: =IF('Data Validation'!$K$2<>TRUE,"",'Data Validation'!C315) -> XAUUSD | C13: =IF('Data Validation'!$K$2<>TRUE,"",'Data Validation'!E315) -> M5 | D13: =IF('Data Validation'!$K$2<>TRUE,"",'Data Validation'!G315) -> 5181.4 | E13: =IF($C13<>"M5","",Trendlines!E315) -> 5199.51 | F13: =IF($C13<>"M5","",Trendlines!F315) -> 5193.74 | G13: =IF($C13<>"M5","",Trendlines!G315) -> 5203.03 | H13: =IF($C13<>"M5","",Trendlines!H315) -> 5170.46 | I13: =IF($C13<>"M5","",Trendlines!I315) -> 5177.95 | J13: =IF($C13<>"M5","",Trendlines!J315) -> 5163.26 | K13: 96 | CY13: =IFERROR(INDEX($L13:$Q13,MATCH(CT13,$E13:$J13,0)),"") | CZ13: =IFERROR(INDEX($L13:$Q13,MATCH(CU13,$E13:$J13,0)),"") | DA13: =IFERROR(INDEX($L13:$Q13,MATCH(CV13,$E13:$J13,0)),"") | DB13: =IFERROR(INDEX($L13:$Q13,MATCH(CW13,$E13:$J13,0)),"") | DD13: =IFERROR(DEGREES(ATAN(CY13)),"") | DE13: =IFERROR(DEGREES(ATAN(CZ13)),"") | DF13: =IFERROR(DEGREES(ATAN(DA13)),"") | DG13: =IFERROR(DEGREES(ATAN(DB13)),"")
... A97: =IF('Data Validation'!$K$2<>TRUE,"",'Data Validation'!A399) -> 1772151300 | B97: =IF('Data Validation'!$K$2<>TRUE,"",'Data Validation'!C399) -> XAUUSD | C97: =IF('Data Validation'!$K$2<>TRUE,"",'Data Validation'!E399) -> M5 | D97: =IF('Data Validation'!$K$2<>TRUE,"",'Data Validation'!G399) -> 5189.28 | E97: =IF($C97<>"M5","",Trendlines!E399) -> 5199.98 | F97: =IF($C97<>"M5","",Trendlines!F399) -> 5191.56 | G97: =IF($C97<>"M5","",Trendlines!G399) -> 5201.55 | H97: =IF($C97<>"M5","",Trendlines!H399) -> 5176.81 | I97: =IF($C97<>"M5","",Trendlines!I399) -> 5179.81 | J97: =IF($C97<>"M5","",Trendlines!J399) -> 5166.51 | K97: 96 | CY97: =IFERROR(INDEX($L97:$Q97,MATCH(CT97,$E97:$J97,0)),"") | CZ97: =IFERROR(INDEX($L97:$Q97,MATCH(CU97,$E97:$J97,0)),"") | DA97: =IFERROR(INDEX($L97:$Q97,MATCH(CV97,$E97:$J97,0)),"") | DB97: =IFERROR(INDEX($L97:$Q97,MATCH(CW97,$E97:$J97,0)),"") | DD97: =IFERROR(DEGREES(ATAN(CY97)),"") | DE97: =IFERROR(DEGREES(ATAN(CZ97)),"") | DF97: =IFERROR(DEGREES(ATAN(DA97)),"") | DG97: =IFERROR(DEGREES(ATAN(DB97)),"")
A98: =IF('Data Validation'!$K$2<>TRUE,"",'Data Validation'!A400) -> 1772151600 | B98: =IF('Data Validation'!$K$2<>TRUE,"",'Data Validation'!C400) -> XAUUSD | C98: =IF('Data Validation'!$K$2<>TRUE,"",'Data Validation'!E400) -> M5 | D98: =IF('Data Validation'!$K$2<>TRUE,"",'Data Validation'!G400) -> 5192.47 | E98: =IF($C98<>"M5","",Trendlines!E400) -> 5199.99 | F98: =IF($C98<>"M5","",Trendlines!F400) -> 5191.53 | G98: =IF($C98<>"M5","",Trendlines!G400) -> 5201.54 | H98: =IF($C98<>"M5","",Trendlines!H400) -> 5176.89 | I98: =IF($C98<>"M5","",Trendlines!I400) -> 5179.83 | J98: =IF($C98<>"M5","",Trendlines!J400) -> 5166.55 | K98: 96 | L98: =(E98-E2)/$K98 -> 0.005625 | M98: =(F98-F2)/$K98 -> -0.0259375 | N98: =(G98-G2)/$K98 -> -0.0175 | O98: =(H98-H2)/$K98 -> 0.075625 | P98: =(I98-I2)/$K98 -> 0.022083333 | Q98: =(J98-J2)/$K98 -> 0.03875 | S98: =ABS($E98-F98) -> 8.46 | T98: =ABS($E98-G98) -> 1.55 | U98: =ABS($E98-H98) -> 23.1 | V98: =ABS($E98-I98) -> 20.16 | W98: =ABS($E98-J98) -> 33.44 | X98: =ABS($F98-G98) -> 10.01 | Y98: =ABS($F98-H98) -> 14.64 | Z98: =ABS($F98-I98) -> 11.7 | AA98: =ABS($F98-J98) -> 24.98 | AB98: =ABS($G98-H98) -> 24.65 | AC98: =ABS($G98-I98) -> 21.71 | AD98: =ABS($G98-J98) -> 34.99 | AE98: =ABS($H98-I98) -> 2.94 | AF98: =ABS($H98-J98) -> 10.34 | AG98: =ABS(I98-J98) -> 13.28 | AI98: =AVERAGE(S$98:S$198) -> 10.03297 | AJ98: =AVERAGE(T$98:T$198) -> 0.65049505 | AK98: =AVERAGE(U$98:U$198) -> 19.593366 | AL98: =AVERAGE(V$98:V$198) -> 19.325941 | AM98: =AVERAGE(W$98:W$198) -> 31.777624 | AN98: =AVERAGE(X$98:X$198) -> 10.426238 | AO98: =AVERAGE(Y$98:Y$198) -> 9.560396 | AP98: =AVERAGE(Z$98:Z$198) -> 9.2929703 | ... AW98: =AVERAGE(AG$98:AG$198) -> 12.451683 | AY98: =_xlfn.RANK.EQ(AI98,$AI98:$AW98,1) -> 5 | AZ98: =_xlfn.RANK.EQ(AJ98,$AI98:$AW98,1) -> 1 | BA98: =_xlfn.RANK.EQ(AK98,$AI98:$AW98,1) -> 10 | BB98: =_xlfn.RANK.EQ(AL98,$AI98:$AW98,1) -> 9 | BC98: =_xlfn.RANK.EQ(AM98,$AI98:$AW98,1) -> 14 | BD98: =_xlfn.RANK.EQ(AN98,$AI98:$AW98,1) -> 6 | BE98: =_xlfn.RANK.EQ(AO98,$AI98:$AW98,1) -> 4 | BF98: =_xlfn.RANK.EQ(AP98,$AI98:$AW98,1) -> 3 | ... BM98: =_xlfn.RANK.EQ(AW98,$AI98:$AW98,1) -> 8 | BO98: =IF(OR(AY98=1,AY98=2),E98,"") | BP98: =IF(OR(AY98=1,AY98=2),F98,"") | BQ98: =IF(OR(AZ98=1,AZ98=2),E98,"") -> 5199.99 | BR98: =IF(OR(AZ98=1,AZ98=2),G98,"") -> 5201.54 | BS98: =IF(OR(BA98=1,BA98=2),E98,"") | BT98: =IF(OR(BA98=1,BA98=2),H98,"") | BU98: =IF(OR(BB98=1,BB98=2,),E98,"") | BV98: =IF(OR(BB98=1,BB98=2,),I98,"") | BW98: =IF(OR(BC98=1,BC98=2),E98,"") | BX98: =IF(OR(BC98=1,BC98=2),J98,"") | BY98: =IF(OR(BD98=1,BD98=2),F98,"") | BZ98: =IF(OR(BD98=1,BD98=2),G98,"") | CA98: =IF(OR(BE98=1,BE98=2),F98,"") | CB98: =IF(OR(BE98=1,BE98=2),H98,"") | CC98: =IF(OR(BF98=1,BF98=2),F98,"") | CD98: =IF(OR(BF98=1,BF98=2),I98,"") | CE98: =IF(OR(BG98=1,BG98=2),F98,"") | CF98: =IF(OR(BG98=1,BG98=2),J98,"") | CG98: =IF(OR(BH98=1,BH98=2),G98,"") | CH98: =IF(OR(BH98=1,BH98=2),H98,"") | CI98: =IF(OR(BI98=1,BI98=2),G98,"") | CJ98: =IF(OR(BI98=1,BI98=2),I98,"") | CK98: =IF(OR(BJ98=1,BJ98=2),G98,"") | CL98: =IF(OR(BJ98=1,BJ98=2),J98,"") | CM98: =IF(OR(BK98=1,BK98=2),H98,"") -> 5176.89 | CN98: =IF(OR(BK98=1,BK98=2),I98,"") -> 5179.83 | CO98: =IF(OR(BL98=1,BL98=2),H98,"") | CP98: =IF(OR(BL98=1,BL98=2),J98,"") | CQ98: =IF(OR(BM98=1,BM98=2),I98,"") | CR98: =IF(OR(BM98=1,BM98=2),J98,"") | CT98: =LARGE(BO98:CR98,1) -> 5201.54 | CU98: =LARGE(BO98:CR98,2) -> 5199.99 | CV98: =LARGE(BO98:CR98,3) -> 5179.83 | CW98: =LARGE(BO98:CR98,4) -> 5176.89 | CY98: =IFERROR(INDEX($L98:$Q98,MATCH(CT98,$E98:$J98,0)),"") -> -0.0175 | CZ98: =IFERROR(INDEX($L98:$Q98,MATCH(CU98,$E98:$J98,0)),"") -> 0.005625 | DA98: =IFERROR(INDEX($L98:$Q98,MATCH(CV98,$E98:$J98,0)),"") -> 0.022083333 | DB98: =IFERROR(INDEX($L98:$Q98,MATCH(CW98,$E98:$J98,0)),"") -> 0.075625 | DD98: =IFERROR(DEGREES(ATAN(CY98)),"") -> -1.0025738 | DE98: =IFERROR(DEGREES(ATAN(CZ98)),"") -> 0.32228536 | DF98: =IFERROR(DEGREES(ATAN(DA98)),"") -> 1.2650762 | DG98: =IFERROR(DEGREES(ATAN(DB98)),"") -> 4.3247612 | DI98: =_xlfn.STDEV.P(DD98:DG98) -> 1.9613185 | DK98: =ABS(DI98) -> 1.9613185 | DL98: =DK98*-1 -> -1.9613185 | DN98: =IF(OR(DD98<$DL98,DD98>$DK98),"Invalid Slope","") | DO98: =IF(OR(DE98<$DL98,DE98>$DK98),"Invalid Slope","") | DP98: =IF(OR(DF98<$DL98,DF98>$DK98),"Invalid Slope","") | DQ98: =IF(OR(DG98<$DL98,DG98>$DK98),"Invalid Slope","") -> Invalid Slope | DS98: =IF(DN98="",CT98,"") -> 5201.54 | DT98: =IF(DO98="",CU98,"") -> 5199.99 | DU98: =IF(DP98="",CV98,"") -> 5179.83 | DV98: =IF(DQ98="",CW98,"") | DX98: =MAX(DS98:DV98) -> 5201.54 | DY98: =MIN(DS98:DV98) -> 5179.83 | EA98: =IF(DX98=E98,$E$1,IF(DX98=F98,$F$1,IF(DX98=G98,$G$1,IF(DX98=H98,$H$1,IF(DX98=I98,$I$1,IF(DX98=J98,$J$1,"")))))) -> horiz_peak_line_3 | EB98: =IF(DY98=E98,$E$1,IF(DY98=F98,$F$1,IF(DY98=G98,$G$1,IF(DY98=H98,$H$1,IF(DY98=I98,$I$1,IF(DY98=J98,$J$1,"")))))) -> horiz_bottom_line_2 | ED98: =IF(EA98="horiz_peak_line_1","peak_line_1",IF(EA98="horiz_peak_line_2","peak_line_2",IF(EA98="horiz_peak_line_3","peak_line_3",IF(EA98="horiz_bottom_line_1","bottom_line_1",IF(EA98="horiz_bottom_line_2","bottom_line_2",IF(EA98="horiz_bottom_line_3","bottom_line_3","")))))) -> peak_line_3 | EE98: =IF(EB98="horiz_peak_line_1","peak_line_1",IF(EB98="horiz_peak_line_2","peak_line_2",IF(EB98="horiz_peak_line_3","peak_line_3",IF(EB98="horiz_bottom_line_1","bottom_line_1",IF(EB98="horiz_bottom_line_2","bottom_line_2",IF(EB98="horiz_bottom_line_3","bottom_line_3","")))))) -> bottom_line_2
