Workbook

Sheet Statistic2
A1: Regression Centroids (Box B): 4
A2: Excluded Recent Centroids (Box A): 2
A3: Math Search Window (Bars): 3000
A4: Visual EDT Window (Bars): 1496
A5: Observation Window (Box B Bars): 1135
A6: Total 171 Crossings (n): 107
A7: Timeframe (Sec): 900
A8: Raw Slope (b): -0.26760
A9: Regression Angle: -29.73
A10: Anchored Y-Int: 4417.30201
A12: [MODEL A; CROSSINGS]
A13: Sample (n): 107
... A26: Kurtosis: 2.33

Sheet Data Export2
A1: MQL DATA EXPORT | AE1: SW_Base_FL2 Sheet | AK1: JB_BaseFL2 Sheet | AS1: BP_BaseFL2 Sheet | AY1: White_BaseFL2
A2: timestamp | B2: symbol | C2: timeframe | D2: close | E2: CEN_0 | F2: CEN_1 | G2: CEN_2 | H2: CEN_3 | I2: CEN_4 | J2: CEN_5 | K2: CEN_6 | L2: CEN_7 | M2: CEN_8 | N2: CEN_9 | O2: CEN_10 | P2: CEN_11 | Q2: Base_FL | R2: EDT_1 | S2: EDT_2 | T2: EDT_3 | U2: EDT_4 | V2: EDT_5 | W2: EDT_6 | X2: EDT_7 | Y2: EDT_8 | Z2: horiz_high_map | AA2: horiz_low_map | AB2: ssa | AC2: ema_ssa | AD2: crossing | AE2: i | AF2: Bar Index | AG2: SSA | AH2: Base_FL (MQL5) | AI2: Residual eᵢ | AJ2: eᵢ² | AK2: i | AL2: Bar Index | AM2: Close | AN2: Base_FL (MQL5) | AO2: eᵢ | AP2: eᵢ² | AQ2: (eᵢ/σ)³ | AR2: (eᵢ/σ)⁴ | AS2: i | AT2: Bar Index (X) | AU2: SSA | AV2: Base_FL (MQL5) | AW2: eᵢ | AX2: eᵢ² (dep.var.) | AY2: i | AZ2: Bar Index (X) | BA2: Close | BB2: Base_FL (MQL5) | BC2: eᵢ | BD2: eᵢ² | BE2: X²
A3: 1776351602 | B3: XAUUSD | C3: M15 | D3: 4806.71 | E3: 4518.5928 | F3: 4596.0559 | G3: 4755.4035 | H3: 4792.7697 | Q3: 4817.3701 | R3: 4846.7334 | S3: 4873.3222 | V3: 4782.4304 | W3: 4748.8654 | AB3: 4798.9749 | AC3: 4798.2946 | AD3: 1 | AE3: 1 | AF3: 0 | AG3: 4798.9749 | AH3: 4817.3701 | AI3: -18.3952 | AJ3: 338.3841 | AK3: 1 | AL3: 0 | AM3: 4806.71 | AN3: 4817.3701 | AO3: -10.6601 | AP3: 113.6384 | AQ3: -0.027868 | AR3: 0.008449 | AS3: 1 | AT3: 0 | AU3: 4798.9749 | AV3: 4817.3701 | AW3: -18.3952 | AX3: 338.3841 | AY3: 1 | AZ3: 0 | BA3: 4806.71 | BB3: 4817.3701 | BC3: -10.6601 | BD3: 113.6384 | BE3: 0
A4: 1776352502 | B4: XAUUSD | C4: M15 | D4: 4802.1 | E4: 4518.5928 | F4: 4596.0559 | G4: 4755.4035 | H4: 4792.7697 | Q4: 4817.1025 | R4: 4846.4658 | S4: 4873.0546 | V4: 4782.1628 | W4: 4748.5978 | AB4: 4800.8624 | AC4: 4799.5785 | AD4: 0 | AE4: 2 | AF4: 4 | AG4: 4801.7586 | AH4: 4816.2997 | AI4: -14.5411 | AJ4: 211.4448 | AK4: 2 | AL4: 1 | AM4: 4802.1 | AN4: 4817.1025 | AO4: -15.0025 | AP4: 225.0756 | AQ4: -0.07768 | AR4: 0.033144 | AS4: 2 | AT4: 4 | AU4: 4801.7586 | AV4: 4816.2997 | AW4: -14.5411 | AX4: 211.4448 | AY4: 2 | AZ4: 1 | BA4: 4802.1 | BB4: 4817.1025 | BC4: -15.0025 | BD4: 225.0756 | BE4: 1
A5: 1776353402 | B5: XAUUSD | C5: M15 | D5: 4802.98 | E5: 4518.5928 | F5: 4596.0559 | G5: 4755.4035 | H5: 4792.7697 | Q5: 4816.8349 | R5: 4846.1982 | S5: 4872.787 | V5: 4781.8952 | W5: 4748.3301 | AB5: 4802.265 | AC5: 4800.9218 | AD5: 0 | AE5: 3 | AF5: 13 | AG5: 4788.1799 | AH5: 4813.8913 | AI5: -25.7114 | AJ5: 661.0761 | AK5: 3 | AL5: 2 | AM5: 4802.98 | AN5: 4816.8349 | AO5: -13.8549 | AP5: 191.9588 | AQ5: -0.061183 | AR5: 0.024109 | AS5: 3 | AT5: 13 | AU5: 4788.1799 | AV5: 4813.8913 | AW5: -25.7114 | AX5: 661.0761 | AY5: 3 | AZ5: 2 | BA5: 4802.98 | BB5: 4816.8349 | BC5: -13.8549 | BD5: 191.9588 | BE5: 4
A6: 1776354302 | B6: XAUUSD | C6: M15 | D6: 4807.09 | E6: 4518.5928 | F6: 4596.0559 | G6: 4755.4035 | H6: 4792.7697 | Q6: 4816.5673 | R6: 4845.9306 | S6: 4872.5194 | V6: 4781.6275 | W6: 4748.0625 | AB6: 4802.689 | AC6: 4801.8054 | AD6: 0 | AE6: 4 | AF6: 20 | AG6: 4791.7372 | AH6: 4812.018 | AI6: -20.2809 | AJ6: 411.3137 | AK6: 4 | AL6: 3 | AM6: 4807.09 | AN6: 4816.5673 | AO6: -9.4773 | AP6: 89.8194 | AQ6: -0.019583 | AR6: 0.005278 | AS6: 4 | AT6: 20 | AU6: 4791.7372 | AV6: 4812.018 | AW6: -20.2809 | AX6: 411.3137 | AY6: 4 | AZ6: 3 | BA6: 4807.09 | BB6: 4816.5673 | BC6: -9.4773 | BD6: 89.8194 | BE6: 9
A7: 1776355202 | B7: XAUUSD | C7: M15 | D7: 4805.02 | E7: 4518.5928 | F7: 4596.0559 | G7: 4755.4035 | H7: 4792.7697 | Q7: 4816.2997 | R7: 4845.663 | S7: 4872.2518 | V7: 4781.3599 | W7: 4747.7949 | AB7: 4801.7586 | AC7: 4801.782 | AD7: 1 | AE7: 5 | AF7: 24 | AG7: 4791.9693 | AH7: 4810.9476 | AI7: -18.9783 | AJ7: 360.1766 | AK7: 5 | AL7: 4 | AM7: 4805.02 | AN7: 4816.2997 | AO7: -11.2797 | AP7: 127.2319 | AQ7: -0.033015 | AR7: 0.010591 | AS7: 5 | AT7: 24 | AU7: 4791.9693 | AV7: 4810.9476 | AW7: -18.9783 | AX7: 360.1766 | AY7: 5 | AZ7: 4 | BA7: 4805.02 | BB7: 4816.2997 | BC7: -11.2797 | BD7: 127.2319 | BE7: 16
A8: 1776356102 | B8: XAUUSD | C8: M15 | D8: 4799.31 | E8: 4518.5928 | F8: 4596.0559 | G8: 4755.4035 | H8: 4792.7697 | Q8: 4816.0321 | R8: 4845.3954 | S8: 4871.9842 | V8: 4781.0923 | W8: 4747.5273 | AB8: 4799.5437 | AC8: 4800.6628 | AD8: 0 | AE8: 6 | AF8: 31 | AG8: 4794.635 | AH8: 4809.0744 | AI8: -14.4394 | AJ8: 208.4963 | AK8: 6 | AL8: 5 | AM8: 4799.31 | AN8: 4816.0321 | AO8: -16.7221 | AP8: 279.629 | AQ8: -0.107569 | AR8: 0.051159 | AS8: 6 | AT8: 31 | AU8: 4794.635 | AV8: 4809.0744 | AW8: -14.4394 | AX8: 208.4963 | AY8: 6 | AZ8: 5 | BA8: 4799.31 | BB8: 4816.0321 | BC8: -16.7221 | BD8: 279.629 | BE8: 25
A9: 1776357002 | B9: XAUUSD | C9: M15 | D9: 4790.11 | E9: 4518.5928 | F9: 4596.0559 | G9: 4755.4035 | H9: 4792.7697 | Q9: 4815.7645 | R9: 4845.1278 | S9: 4871.7166 | V9: 4780.8247 | W9: 4747.2597 | AB9: 4796.4861 | AC9: 4798.5745 | AD9: 0 | AE9: 7 | AF9: 39 | AG9: 4784.2445 | AH9: 4806.9336 | AI9: -22.689 | AJ9: 514.7925 | AK9: 7 | AL9: 6 | AM9: 4790.11 | AN9: 4815.7645 | AO9: -25.6545 | AP9: 658.1534 | AQ9: -0.388424 | AR9: 0.283406 | AS9: 7 | AT9: 39 | AU9: 4784.2445 | AV9: 4806.9336 | AW9: -22.689 | AX9: 514.7925 | AY9: 7 | AZ9: 6 | BA9: 4790.11 | BB9: 4815.7645 | BC9: -25.6545 | BD9: 658.1534 | BE9: 36
A10: 1776357902 | B10: XAUUSD | C10: M15 | D10: 4791.99 | E10: 4518.5928 | F10: 4596.0559 | G10: 4755.4035 | H10: 4792.7697 | Q10: 4815.4969 | R10: 4844.8602 | S10: 4871.449 | V10: 4780.5571 | W10: 4746.9921 | AB10: 4793.2914 | AC10: 4795.9329 | AD10: 0 | AE10: 8 | AF10: 53 | AG10: 4799.4912 | AH10: 4803.1871 | AI10: -3.696 | AJ10: 13.66 | AK10: 8 | AL10: 7 | AM10: 4791.99 | AN10: 4815.4969 | AO10: -23.5069 | AP10: 552.5743 | AQ10: -0.298814 | AR10: 0.199772 | AS10: 8 | AT10: 53 | AU10: 4799.4912 | AV10: 4803.1871 | AW10: -3.696 | AX10: 13.66 | AY10: 8 | AZ10: 7 | BA10: 4791.99 | BB10: 4815.4969 | BC10: -23.5069 | BD10: 552.5743 | BE10: 49
A11: 1776358802 | B11: XAUUSD | C11: M15 | D11: 4791.41 | E11: 4518.5928 | F11: 4596.0559 | G11: 4755.4035 | H11: 4792.7697 | Q11: 4815.2293 | R11: 4844.5926 | S11: 4871.1814 | V11: 4780.2895 | W11: 4746.7245 | AB11: 4790.3715 | AC11: 4793.1522 | AD11: 0 | AE11: 9 | AF11: 62 | AG11: 4785.2155 | AH11: 4800.7787 | AI11: -15.5631 | AJ11: 242.211 | AK11: 9 | AL11: 8 | AM11: 4791.41 | AN11: 4815.2293 | AO11: -23.8193 | AP11: 567.3586 | AQ11: -0.310887 | AR11: 0.210605 | AS11: 9 | AT11: 62 | AU11: 4785.2155 | AV11: 4800.7787 | AW11: -15.5631 | AX11: 242.211 | AY11: 9 | AZ11: 8 | BA11: 4791.41 | BB11: 4815.2293 | BC11: -23.8193 | BD11: 567.3586 | BE11: 64
A12: 1776359702 | B12: XAUUSD | C12: M15 | D12: 4785.04 | E12: 4518.5928 | F12: 4596.0559 | G12: 4755.4035 | H12: 4792.7697 | Q12: 4814.9617 | R12: 4844.325 | S12: 4870.9138 | V12: 4780.0219 | W12: 4746.4569 | AB12: 4788.0806 | AC12: 4790.6164 | AD12: 0 | AE12: 10 | AF12: 71 | AG12: 4792.9258 | AH12: 4798.3702 | AI12: -5.4444 | AJ12: 29.6418 | AK12: 10 | AL12: 9 | AM12: 4785.04 | AN12: 4814.9617 | AO12: -29.9217 | AP12: 895.3075 | AQ12: -0.616274 | AR12: 0.524443 | AS12: 10 | AT12: 71 | AU12: 4792.9258 | AV12: 4798.3702 | AW12: -5.4444 | AX12: 29.6418 | AY12: 10 | AZ12: 9 | BA12: 4785.04 | BB12: 4814.9617 | BC12: -29.9217 | BD12: 895.3075 | BE12: 81
A13: 1776360602 | B13: XAUUSD | C13: M15 | D13: 4787.16 | E13: 4518.5928 | F13: 4596.0559 | G13: 4755.4035 | H13: 4792.7697 | Q13: 4814.6941 | R13: 4844.0574 | S13: 4870.6462 | V13: 4779.7543 | W13: 4746.1893 | AB13: 4786.7966 | AC13: 4788.7065 | AD13: 0 | AE13: 11 | AF13: 77 | AG13: 4789.136 | AH13: 4796.7646 | AI13: -7.6286 | AJ13: 58.196 | AK13: 11 | AL13: 10 | AM13: 4787.16 | AN13: 4814.6941 | AO13: -27.5341 | AP13: 758.1261 | AQ13: -0.480206 | AR13: 0.376043 | AS13: 11 | AT13: 77 | AU13: 4789.136 | AV13: 4796.7646 | AW13: -7.6286 | AX13: 58.196 | AY13: 11 | AZ13: 10 | BA13: 4787.16 | BB13: 4814.6941 | BC13: -27.5341 | BD13: 758.1261 | BE13: 100
A14: 1776361502 | B14: XAUUSD | C14: M15 | D14: 4789.22 | E14: 4518.5928 | F14: 4596.0559 | G14: 4755.4035 | H14: 4792.7697 | Q14: 4814.4265 | R14: 4843.7898 | S14: 4870.3786 | V14: 4779.4867 | W14: 4745.9217 | AB14: 4786.5161 | AC14: 4787.6113 | AD14: 0 | AE14: 12 | AF14: 90 | AG14: 4872.1414 | AH14: 4793.2858 | AI14: 78.8557 | AJ14: 6218.2183 | AK14: 12 | AL14: 11 | AM14: 4789.22 | AN14: 4814.4265 | AO14: -25.2065 | AP14: 635.3666 | AQ14: -0.368428 | AR14: 0.264121 | AS14: 12 | AT14: 90 | AU14: 4872.1414 | AV14: 4793.2858 | AW14: 78.8557 | AX14: 6218.2183 | AY14: 12 | AZ14: 11 | BA14: 4789.22 | BB14: 4814.4265 | BC14: -25.2065 | BD14: 635.3666 | BE14: 121
... A40: 1776388502 | B40: XAUUSD | C40: M15 | D40: 4769.01 | E40: 4518.5928 | F40: 4596.0559 | G40: 4755.4035 | H40: 4792.7697 | Q40: 4807.4688 | R40: 4836.8321 | S40: 4863.4209 | V40: 4772.529 | W40: 4738.964 | AB40: 4783.176 | AC40: 4784.8672 | AD40: 0 | AE40: 38 | AF40: 363 | AG40: 4748.0625 | AH40: 4720.2298 | AI40: 27.8327 | AJ40: 774.6581 | AK40: 38 | AL40: 37 | AM40: 4769.01 | AN40: 4807.4688 | AO40: -38.4588 | AP40: 1479.0778 | AQ40: -1.308585 | AR40: 1.431318 | AS40: 38 | AT40: 363 | AU40: 4748.0625 | AV40: 4720.2298 | AW40: 27.8327 | AX40: 774.6581 | AY40: 38 | AZ40: 37 | BA40: 4769.01 | BB40: 4807.4688 | BC40: -38.4588 | BD40: 1479.0778 | BE40: 1369
A41: 1776389402 | B41: XAUUSD | C41: M15 | D41: 4777.87 | E41: 4518.5928 | F41: 4596.0559 | G41: 4755.4035 | H41: 4792.7697 | Q41: 4807.2012 | R41: 4836.5645 | S41: 4863.1532 | V41: 4772.2614 | W41: 4738.6964 | AA41: 4768.07 | AB41: 4783.2232 | AC41: 4784.0452 | AD41: 0 | AE41: 39 | AF41: 374 | AG41: 4729.4164 | AH41: 4717.2862 | AI41: 12.1302 | AJ41: 147.1415 | AK41: 39 | AL41: 38 | AM41: 4777.87 | AN41: 4807.2012 | AO41: -29.3312 | AP41: 860.3175 | AQ41: -0.580502 | AR41: 0.484252 | AS41: 39 | AT41: 374 | AU41: 4729.4164 | AV41: 4717.2862 | AW41: 12.1302 | AX41: 147.1415 | AY41: 39 | AZ41: 38 | BA41: 4777.87 | BB41: 4807.2012 | BC41: -29.3312 | BD41: 860.3175 | BE41: 1444
A42: 1776390302 | B42: XAUUSD | C42: M15 | D42: 4789.48 | E42: 4518.5928 | F42: 4596.0559 | G42: 4755.4035 | H42: 4792.7697 | Q42: 4806.9336 | R42: 4836.2969 | S42: 4862.8856 | V42: 4771.9938 | W42: 4738.4288 | AB42: 4784.2445 | AC42: 4784.1449 | AD42: 1 | AE42: 40 | AF42: 390 | AG42: 4739.1687 | AH42: 4713.0045 | AI42: 26.1642 | AJ42: 684.5643 | AK42: 40 | AL42: 39 | AM42: 4789.48 | AN42: 4806.9336 | AO42: -17.4536 | AP42: 304.6271 | AQ42: -0.122312 | AR42: 0.060714 | AS42: 40 | AT42: 390 | AU42: 4739.1687 | AV42: 4713.0045 | AW42: 26.1642 | AX42: 684.5643 | AY42: 40 | AZ42: 39 | BA42: 4789.48 | BB42: 4806.9336 | BC42: -17.4536 | BD42: 304.6271 | BE42: 1521
A43: 1776391202 | B43: XAUUSD | C43: M15 | D43: 4791.35 | E43: 4518.5928 | F43: 4596.0559 | G43: 4755.4035 | H43: 4792.7697 | Q43: 4806.666 | R43: 4836.0293 | S43: 4862.618 | V43: 4771.7262 | W43: 4738.1612 | AB43: 4785.6992 | AC43: 4784.9221 | AD43: 0 | AE43: 41 | AF43: 399 | AG43: 4725.8976 | AH43: 4710.5961 | AI43: 15.3015 | AJ43: 234.135 | AK43: 41 | AL43: 40 | AM43: 4791.35 | AN43: 4806.666 | AO43: -15.316 | AP43: 234.5786 | AQ43: -0.082651 | AR43: 0.036002 | AS43: 41 | AT43: 399 | AU43: 4725.8976 | AV43: 4710.5961 | AW43: 15.3015 | AX43: 234.135 | AY43: 41 | AZ43: 40 | BA43: 4791.35 | BB43: 4806.666 | BC43: -15.316 | BD43: 234.5786 | BE43: 1600
A44: 1776392102 | B44: XAUUSD | C44: M15 | D44: 4788.86 | E44: 4518.5928 | F44: 4596.0559 | G44: 4755.4035 | H44: 4792.7697 | Q44: 4806.3984 | R44: 4835.7617 | S44: 4862.3504 | V44: 4771.4586 | W44: 4737.8936 | AB44: 4787.2894 | AC44: 4786.1057 | AD44: 0 | AE44: 42 | AF44: 405 | AG44: 4733.9721 | AH44: 4708.9905 | AI44: 24.9816 | AJ44: 624.0823 | AK44: 42 | AL44: 41 | AM44: 4788.86 | AN44: 4806.3984 | AO44: -17.5384 | AP44: 307.5941 | AQ44: -0.124103 | AR44: 0.061903 | AS44: 42 | AT44: 405 | AU44: 4733.9721 | AV44: 4708.9905 | AW44: 24.9816 | AX44: 624.0823 | AY44: 42 | AZ44: 41 | BA44: 4788.86 | BB44: 4806.3984 | BC44: -17.5384 | BD44: 307.5941 | BE44: 1681
A45: 1776393002 | B45: XAUUSD | C45: M15 | D45: 4791.57 | E45: 4518.5928 | F45: 4596.0559 | G45: 4755.4035 | H45: 4792.7697 | Q45: 4806.1308 | R45: 4835.4941 | S45: 4862.0828 | V45: 4771.191 | W45: 4737.626 | AB45: 4788.9024 | AC45: 4787.5041 | AD45: 0 | AE45: 43 | AF45: 415 | AG45: 4703.263 | AH45: 4706.3144 | AI45: -3.0514 | AJ45: 9.3113 | AK45: 43 | AL45: 42 | AM45: 4791.57 | AN45: 4806.1308 | AO45: -14.5608 | AP45: 212.0154 | AQ45: -0.071018 | AR45: 0.02941 | AS45: 43 | AT45: 415 | AU45: 4703.263 | AV45: 4706.3144 | AW45: -3.0514 | AX45: 9.3113 | AY45: 43 | AZ45: 42 | BA45: 4791.57 | BB45: 4806.1308 | BC45: -14.5608 | BD45: 212.0154 | BE45: 1764
A46: 1776393902 | B46: XAUUSD | C46: M15 | D46: 4784.81 | E46: 4518.5928 | F46: 4596.0559 | G46: 4755.4035 | H46: 4792.7697 | Q46: 4805.8632 | R46: 4835.2265 | S46: 4861.8152 | V46: 4770.9234 | W46: 4737.3584 | AB46: 4790.3727 | AC46: 4788.9384 | AD46: 0 | AE46: 44 | AF46: 432 | AG46: 4713.1717 | AH46: 4701.7652 | AI46: 11.4066 | AJ46: 130.1096 | AK46: 44 | AL46: 43 | AM46: 4784.81 | AN46: 4805.8632 | AO46: -21.0531 | AP46: 443.2351 | AQ46: -0.214668 | AR46: 0.128535 | AS46: 44 | AT46: 432 | AU46: 4713.1717 | AV46: 4701.7652 | AW46: 11.4066 | AX46: 130.1096 | AY46: 44 | AZ46: 43 | BA46: 4784.81 | BB46: 4805.8632 | BC46: -21.0531 | BD46: 443.2351 | BE46: 1849
A47: 1776394802 | B47: XAUUSD | C47: M15 | D47: 4795.86 | E47: 4518.5928 | F47: 4596.0559 | G47: 4755.4035 | H47: 4792.7697 | Q47: 4805.5956 | R47: 4834.9588 | S47: 4861.5476 | V47: 4770.6558 | W47: 4737.0908 | AB47: 4791.8981 | AC47: 4790.4182 | AD47: 0 | AE47: 45 | AF47: 443 | AG47: 4693.4593 | AH47: 4698.8215 | AI47: -5.3623 | AJ47: 28.7537 | AK47: 45 | AL47: 44 | AM47: 4795.86 | AN47: 4805.5956 | AO47: -9.7356 | AP47: 94.7809 | AQ47: -0.021227 | AR47: 0.005878 | AS47: 45 | AT47: 443 | AU47: 4693.4593 | AV47: 4698.8215 | AW47: -5.3623 | AX47: 28.7537 | AY47: 45 | AZ47: 44 | BA47: 4795.86 | BB47: 4805.5956 | BC47: -9.7356 | BD47: 94.7809 | BE47: 1936
A48: 1776395702 | B48: XAUUSD | C48: M15 | D48: 4793.93 | E48: 4518.5928 | F48: 4596.0559 | G48: 4755.4035 | H48: 4792.7697 | Q48: 4805.3279 | R48: 4834.6912 | S48: 4861.28 | V48: 4770.3882 | W48: 4736.8232 | AB48: 4793.245 | AC48: 4791.8316 | AD48: 0 | AE48: 46 | AF48: 453 | AG48: 4732.4203 | AH48: 4696.1455 | AI48: 36.2748 | AJ48: 1315.8626 | AK48: 46 | AL48: 45 | AM48: 4793.93 | AN48: 4805.3279 | AO48: -11.3979 | AP48: 129.913 | AQ48: -0.034064 | AR48: 0.011042 | AS48: 46 | AT48: 453 | AU48: 4732.4203 | AV48: 4696.1455 | AW48: 36.2748 | AX48: 1315.8626 | AY48: 46 | AZ48: 45 | BA48: 4793.93 | BB48: 4805.3279 | BC48: -11.3979 | BD48: 129.913 | BE48: 2025
A49: 1776396602 | B49: XAUUSD | C49: M15 | D49: 4794.26 | E49: 4518.5928 | F49: 4596.0559 | G49: 4755.4035 | H49: 4792.7697 | Q49: 4805.0603 | R49: 4834.4236 | S49: 4861.0124 | V49: 4770.1206 | W49: 4736.5556 | AB49: 4794.5677 | AC49: 4793.1997 | AD49: 0 | AE49: 47 | AF49: 458 | AG49: 4728.4898 | AH49: 4694.8075 | AI49: 33.6823 | AJ49: 1134.4987 | AK49: 47 | AL49: 46 | AM49: 4794.26 | AN49: 4805.0603 | AO49: -10.8003 | AP49: 116.6473 | AQ49: -0.028982 | AR49: 0.008902 | AS49: 47 | AT49: 458 | AU49: 4728.4898 | AV49: 4694.8075 | AW49: 33.6823 | AX49: 1134.4987 | AY49: 47 | AZ49: 46 | BA49: 4794.26 | BB49: 4805.0603 | BC49: -10.8003 | BD49: 116.6473 | BE49: 2116
A50: 1776397502 | B50: XAUUSD | C50: M15 | D50: 4793.09 | E50: 4518.5928 | F50: 4596.0559 | G50: 4755.4035 | H50: 4792.7697 | Q50: 4804.7927 | R50: 4834.156 | S50: 4860.7448 | V50: 4769.853 | W50: 4736.288 | AB50: 4795.955 | AC50: 4794.5773 | AD50: 0 | AE50: 48 | AF50: 463 | AG50: 4729.1198 | AH50: 4693.4694 | AI50: 35.6504 | AJ50: 1270.9517 | AK50: 48 | AL50: 47 | AM50: 4793.09 | AN50: 4804.7927 | AO50: -11.7027 | AP50: 136.9539 | AQ50: -0.03687 | AR50: 0.012272 | AS50: 48 | AT50: 463 | AU50: 4729.1198 | AV50: 4693.4694 | AW50: 35.6504 | AX50: 1270.9517 | AY50: 48 | AZ50: 47 | BA50: 4793.09 | BB50: 4804.7927 | BC50: -11.7027 | BD50: 136.9539 | BE50: 2209
A51: 1776398402 | B51: XAUUSD | C51: M15 | D51: 4795.16 | E51: 4518.5928 | F51: 4596.0559 | G51: 4755.4035 | H51: 4792.7697 | Q51: 4804.5251 | R51: 4833.8884 | S51: 4860.4772 | V51: 4769.5854 | W51: 4736.0204 | AB51: 4797.4545 | AC51: 4796.0159 | AD51: 0 | AE51: 49 | AF51: 485 | AG51: 4692.6568 | AH51: 4687.5821 | AI51: 5.0747 | AJ51: 25.7523 | AK51: 49 | AL51: 48 | AM51: 4795.16 | AN51: 4804.5251 | AO51: -9.3651 | AP51: 87.7057 | AQ51: -0.018895 | AR51: 0.005033 | AS51: 49 | AT51: 485 | AU51: 4692.6568 | AV51: 4687.5821 | AW51: 5.0747 | AX51: 25.7523 | AY51: 49 | AZ51: 48 | BA51: 4795.16 | BB51: 4804.5251 | BC51: -9.3651 | BD51: 87.7057 | BE51: 2304
A52: 1776399302 | B52: XAUUSD | C52: M15 | D52: 4795.87 | E52: 4518.5928 | F52: 4596.0559 | G52: 4755.4035 | H52: 4792.7697 | Q52: 4804.2575 | R52: 4833.6208 | S52: 4860.2096 | V52: 4769.3178 | W52: 4735.7528 | AB52: 4798.9172 | AC52: 4797.4665 | AD52: 0 | AE52: 50 | AF52: 497 | AG52: 4701.3644 | AH52: 4684.3709 | AI52: 16.9935 | AJ52: 288.7794 | AK52: 50 | AL52: 49 | AM52: 4795.87 | AN52: 4804.2575 | AO52: -8.3875 | AP52: 70.3507 | AQ52: -0.013574 | AR52: 0.003238 | AS52: 50 | AT52: 497 | AU52: 4701.3644 | AV52: 4684.3709 | AW52: 16.9935 | AX52: 288.7794 | AY52: 50 | AZ52: 49 | BA52: 4795.87 | BB52: 4804.2575 | BC52: -8.3875 | BD52: 70.3507 | BE52: 2401
A53: 1776400202 | B53: XAUUSD | C53: M15 | D53: 4801.05 | E53: 4518.5928 | F53: 4596.0559 | G53: 4755.4035 | H53: 4792.7697 | Q53: 4803.9899 | R53: 4833.3532 | S53: 4859.942 | V53: 4769.0502 | W53: 4735.4852 | AB53: 4800.1665 | AC53: 4798.8165 | AD53: 0 | AE53: 51 | AF53: 510 | AG53: 4671.0085 | AH53: 4680.892 | AI53: -9.8835 | AJ53: 97.684 | AK53: 51 | AL53: 50 | AM53: 4801.05 | AN53: 4803.9899 | AO53: -2.9399 | AP53: 8.6431 | AQ53: -0.000585 | AR53: 4.9e-05 | AS53: 51 | AT53: 510 | AU53: 4671.0085 | AV53: 4680.892 | AW53: -9.8835 | AX53: 97.684 | AY53: 51 | AZ53: 50 | BA53: 4801.05 | BB53: 4803.9899 | BC53: -2.9399 | BD53: 8.6431 | BE53: 2500
A54: 1776401102 | B54: XAUUSD | C54: M15 | D54: 4803.04 | E54: 4518.5928 | F54: 4596.0559 | G54: 4755.4035 | H54: 4792.7697 | Q54: 4803.7223 | R54: 4833.0856 | S54: 4859.6744 | V54: 4768.7825 | W54: 4735.2176 | AB54: 4800.8418 | AC54: 4799.8292 | AD54: 0 | AE54: 52 | AF54: 517 | AG54: 4677.5968 | AH54: 4679.0188 | AI54: -1.422 | AJ54: 2.0221 | AK54: 52 | AL54: 51 | AM54: 4803.04 | AN54: 4803.7223 | AO54: -0.6823 | AP54: 0.4656 | AQ54: -7e-06 | AR54: 0 | AS54: 52 | AT54: 517 | AU54: 4677.5968 | AV54: 4679.0188 | AW54: -1.422 | AX54: 2.0221 | AY54: 52 | AZ54: 51 | BA54: 4803.04 | BB54: 4803.7223 | BC54: -0.6823 | BD54: 0.4656 | BE54: 2601
A55: 1776402002 | B55: XAUUSD | C55: M15 | D55: 4804.78 | E55: 4518.5928 | F55: 4596.0559 | G55: 4755.4035 | H55: 4792.7697 | Q55: 4803.4547 | R55: 4832.818 | S55: 4859.4068 | V55: 4768.5149 | W55: 4734.95 | Z55: 4805.97 | AB55: 4800.6718 | AC55: 4800.2505 | AD55: 0 | AE55: 53 | AF55: 519 | AG55: 4677.6687 | AH55: 4678.4836 | AI55: -0.8149 | AJ55: 0.664 | AK55: 53 | AL55: 52 | AM55: 4804.78 | AN55: 4803.4547 | AO55: 1.3253 | AP55: 1.7564 | AQ55: 5.4e-05 | AR55: 2e-06 | AS55: 53 | AT55: 519 | AU55: 4677.6687 | AV55: 4678.4836 | AW55: -0.8149 | AX55: 0.664 | AY55: 53 | AZ55: 52 | BA55: 4804.78 | BB55: 4803.4547 | BC55: 1.3253 | BD55: 1.7564 | BE55: 2704
A56: 1776402902 | B56: XAUUSD | C56: M15 | D56: 4803.25 | E56: 4518.5928 | F56: 4596.0559 | G56: 4755.4035 | H56: 4792.7697 | Q56: 4803.1871 | R56: 4832.5504 | S56: 4859.1392 | V56: 4768.2473 | W56: 4734.6823 | AB56: 4799.4912 | AC56: 4799.8708 | AD56: 1 | AE56: 54 | AF56: 528 | AG56: 4688.6921 | AH56: 4676.0752 | AI56: 12.617 | AJ56: 159.1882 | AK56: 54 | AL56: 53 | AM56: 4803.25 | AN56: 4803.1871 | AO56: 0.0629 | AP56: 0.004 | AQ56: 0 | AR56: 0 | AS56: 54 | AT56: 528 | AU56: 4688.6921 | AV56: 4676.0752 | AW56: 12.617 | AX56: 159.1882 | AY56: 54 | AZ56: 53 | BA56: 4803.25 | BB56: 4803.1871 | BC56: 0.0629 | BD56: 0.004 | BE56: 2809
A57: 1776403802 | B57: XAUUSD | C57: M15 | D57: 4796.48 | E57: 4518.5928 | F57: 4596.0559 | G57: 4755.4035 | H57: 4792.7697 | Q57: 4802.9195 | R57: 4832.2828 | S57: 4858.8716 | V57: 4767.9797 | W57: 4734.4147 | AB57: 4797.3362 | AC57: 4798.6035 | AD57: 0 | AE57: 55 | AF57: 533 | AG57: 4682.0741 | AH57: 4674.7371 | AI57: 7.337 | AJ57: 53.8311 | AK57: 55 | AL57: 54 | AM57: 4796.48 | AN57: 4802.9195 | AO57: -6.4395 | AP57: 41.4673 | AQ57: -0.006143 | AR57: 0.001125 | AS57: 55 | AT57: 533 | AU57: 4682.0741 | AV57: 4674.7371 | AW57: 7.337 | AX57: 53.8311 | AY57: 55 | AZ57: 54 | BA57: 4796.48 | BB57: 4802.9195 | BC57: -6.4395 | BD57: 41.4673 | BE57: 2916
A58: 1776404702 | B58: XAUUSD | C58: M15 | D58: 4794.41 | E58: 4518.5928 | F58: 4596.0559 | G58: 4755.4035 | H58: 4792.7697 | Q58: 4802.6519 | R58: 4832.0152 | S58: 4858.604 | V58: 4767.7121 | W58: 4734.1471 | AB58: 4794.5247 | AC58: 4796.5641 | AD58: 0 | AE58: 56 | AF58: 542 | AG58: 4703.9862 | AH58: 4672.3287 | AI58: 31.6575 | AJ58: 1002.1979 | AK58: 56 | AL58: 55 | AM58: 4794.41 | AN58: 4802.6519 | AO58: -8.2419 | AP58: 67.9289 | AQ58: -0.012879 | AR58: 0.003019 | AS58: 56 | AT58: 542 | AU58: 4703.9862 | AV58: 4672.3287 | AW58: 31.6575 | AX58: 1002.1979 | AY58: 56 | AZ58: 55 | BA58: 4794.41 | BB58: 4802.6519 | BC58: -8.2419 | BD58: 67.9289 | BE58: 3025
A59: 1776405602 | B59: XAUUSD | C59: M15 | D59: 4787.73 | E59: 4518.5928 | F59: 4596.0559 | G59: 4755.4035 | H59: 4792.7697 | Q59: 4802.3843 | R59: 4831.7476 | S59: 4858.3364 | V59: 4767.4445 | W59: 4733.8795 | AB59: 4791.4825 | AC59: 4794.0233 | AD59: 0 | AE59: 57 | AF59: 545 | AG59: 4705.476 | AH59: 4671.5259 | AI59: 33.9501 | AJ59: 1152.6093 | AK59: 57 | AL59: 56 | AM59: 4787.73 | AN59: 4802.3843 | AO59: -14.6543 | AP59: 214.7485 | AQ59: -0.072395 | AR59: 0.030173 | AS59: 57 | AT59: 545 | AU59: 4705.476 | AV59: 4671.5259 | AW59: 33.9501 | AX59: 1152.6093 | AY59: 57 | AZ59: 56 | BA59: 4787.73 | BB59: 4802.3843 | BC59: -14.6543 | BD59: 214.7485 | BE59: 3136
A60: 1776406502 | B60: XAUUSD | C60: M15 | D60: 4783.78 | E60: 4518.5928 | F60: 4596.0559 | G60: 4755.4035 | H60: 4792.7697 | Q60: 4802.1167 | R60: 4831.48 | S60: 4858.0688 | V60: 4767.1769 | W60: 4733.6119 | AB60: 4788.6996 | AC60: 4791.3615 | AD60: 0 | AE60: 58 | AF60: 554 | AG60: 4725.9997 | AH60: 4669.1175 | AI60: 56.8823 | AJ60: 3235.5938 | AK60: 58 | AL60: 57 | AM60: 4783.78 | AN60: 4802.1167 | AO60: -18.3367 | AP60: 336.2342 | AQ60: -0.141833 | AR60: 0.073967 | AS60: 58 | AT60: 554 | AU60: 4725.9997 | AV60: 4669.1175 | AW60: 56.8823 | AX60: 3235.5938 | AY60: 58 | AZ60: 57 | BA60: 4783.78 | BB60: 4802.1167 | BC60: -18.3367 | BD60: 336.2342 | BE60: 3249
A61: 1776407402 | B61: XAUUSD | C61: M15 | D61: 4785.67 | E61: 4518.5928 | F61: 4596.0559 | G61: 4755.4035 | H61: 4792.7697 | Q61: 4801.8491 | R61: 4831.2124 | S61: 4857.8012 | V61: 4766.9093 | W61: 4733.3443 | AB61: 4786.5307 | AC61: 4788.9461 | AD61: 0 | AE61: 59 | AF61: 559 | AG61: 4723.6963 | AH61: 4667.7794 | AI61: 55.9168 | AJ61: 3126.6908 | AK61: 59 | AL61: 58 | AM61: 4785.67 | AN61: 4801.8491 | AO61: -16.1791 | AP61: 261.763 | AQ61: -0.097427 | AR61: 0.04483 | AS61: 59 | AT61: 559 | AU61: 4723.6963 | AV61: 4667.7794 | AW61: 55.9168 | AX61: 3126.6908 | AY61: 59 | AZ61: 58 | BA61: 4785.67 | BB61: 4801.8491 | BC61: -16.1791 | BD61: 261.763 | BE61: 3364
A62: 1776408302 | B62: XAUUSD | C62: M15 | D62: 4785.07 | E62: 4518.5928 | F62: 4596.0559 | G62: 4755.4035 | H62: 4792.7697 | Q62: 4801.5815 | R62: 4830.9448 | S62: 4857.5336 | V62: 4766.6417 | W62: 4733.0767 | AB62: 4785.1178 | AC62: 4787.032 | AD62: 0 | AE62: 60 | AF62: 562 | AG62: 4723.8595 | AH62: 4666.9766 | AI62: 56.8829 | AJ62: 3235.6655 | AK62: 60 | AL62: 59 | AM62: 4785.07 | AN62: 4801.5815 | AO62: -16.5115 | AP62: 272.6293 | AQ62: -0.103556 | AR62: 0.048629 | AS62: 60 | AT62: 562 | AU62: 4723.8595 | AV62: 4666.9766 | AW62: 56.8829 | AX62: 3235.6655 | AY62: 60 | AZ62: 59 | BA62: 4785.07 | BB62: 4801.5815 | BC62: -16.5115 | BD62: 272.6293 | BE62: 3481
A63: 1776409202 | B63: XAUUSD | C63: M15 | D63: 4787.12 | E63: 4518.5928 | F63: 4596.0559 | G63: 4755.4035 | H63: 4792.7697 | Q63: 4801.3139 | R63: 4830.6772 | S63: 4857.2659 | V63: 4766.3741 | W63: 4732.8091 | AB63: 4784.5163 | AC63: 4785.7741 | AD63: 0 | AE63: 61 | AF63: 584 | AG63: 4680.7626 | AH63: 4661.0893 | AI63: 19.6733 | AJ63: 387.0379 | AK63: 61 | AL63: 60 | AM63: 4787.12 | AN63: 4801.3139 | AO63: -14.1939 | AP63: 201.4662 | AQ63: -0.065784 | AR63: 0.026556 | AS63: 61 | AT63: 584 | AU63: 4680.7626 | AV63: 4661.0893 | AW63: 19.6733 | AX63: 387.0379 | AY63: 61 | AZ63: 60 | BA63: 4787.12 | BB63: 4801.3139 | BC63: -14.1939 | BD63: 201.4662 | BE63: 3600
A64: 1776410102 | B64: XAUUSD | C64: M15 | D64: 4791.72 | E64: 4518.5928 | F64: 4596.0559 | G64: 4755.4035 | H64: 4792.7697 | Q64: 4801.0463 | R64: 4830.4096 | S64: 4856.9983 | V64: 4766.1065 | W64: 4732.5415 | AB64: 4784.6154 | AC64: 4785.1948 | AD64: 0 | AE64: 62 | AF64: 602 | AG64: 4725.1237 | AH64: 4656.2725 | AI64: 68.8513 | AJ64: 4740.4974 | AK64: 62 | AL64: 61 | AM64: 4791.72 | AN64: 4801.0463 | AO64: -9.3263 | AP64: 86.9795 | AQ64: -0.018661 | AR64: 0.00495 | AS64: 62 | AT64: 602 | AU64: 4725.1237 | AV64: 4656.2725 | AW64: 68.8513 | AX64: 4740.4974 | AY64: 62 | AZ64: 61 | BA64: 4791.72 | BB64: 4801.0463 | BC64: -9.3263 | BD64: 86.9795 | BE64: 3721
A65: 1776411002 | B65: XAUUSD | C65: M15 | D65: 4785.87 | E65: 4518.5928 | F65: 4596.0559 | G65: 4755.4035 | H65: 4792.7697 | Q65: 4800.7787 | R65: 4830.142 | S65: 4856.7307 | V65: 4765.8389 | W65: 4732.2739 | AB65: 4785.2155 | AC65: 4785.2052 | AD65: 1 | AE65: 63 | AF65: 611 | AG65: 4713.8471 | AH65: 4653.864 | AI65: 59.983 | AJ65: 3597.9651 | AK65: 63 | AL65: 62 | AM65: 4785.87 | AN65: 4800.7787 | AO65: -14.9087 | AP65: 222.2684 | AQ65: -0.076231 | AR65: 0.032323 | AS65: 63 | AT65: 611 | AU65: 4713.8471 | AV65: 4653.864 | AW65: 59.983 | AX65: 3597.9651 | AY65: 63 | AZ65: 62 | BA65: 4785.87 | BB65: 4800.7787 | BC65: -14.9087 | BD65: 222.2684 | BE65: 3844
...

Sheet Data Export2 Refine
A1: MQL DATA EXPORT | AE1: Jarque-Bera Test and White's Test
A2: timestamp | B2: symbol | C2: timeframe | D2: close | E2: CEN_0 | F2: CEN_1 | G2: CEN_2 | H2: CEN_3 | I2: CEN_4 | J2: CEN_5 | K2: CEN_6 | L2: CEN_7 | M2: CEN_8 | N2: CEN_9 | O2: CEN_10 | P2: CEN_11 | Q2: Base_FL | R2: EDT_1 | S2: EDT_2 | T2: EDT_3 | U2: EDT_4 | V2: EDT_5 | W2: EDT_6 | X2: EDT_7 | Y2: EDT_8 | Z2: horiz_high_map | AA2: horiz_low_map | AB2: ssa | AC2: ema_ssa | AD2: crossing | AE2: i | AF2: Bar Index | AG2: eᵢ | AH2: eᵢ² | AI2: (eᵢ/σ)³ | AJ2: (eᵢ/σ)⁴ | AK2: X² | AL2: SSA Last Cross | AM2: SSA Cross Dist
A3: 1776351602 | B3: XAUUSD | C3: M15 | D3: 4806.71 | E3: 4518.5928 | F3: 4596.0559 | G3: 4755.4035 | H3: 4792.7697 | Q3: 4817.3701 | R3: 4846.7334 | S3: 4873.3222 | V3: 4782.4304 | W3: 4748.8654 | AB3: 4798.9749 | AC3: 4798.2946 | AD3: 1 | AE3: 1 | AF3: 0 | AG3: =D3-Q3 -> -10.66013 | AH3: =AG3^2 -> 113.63837 | AI3: =(AG3/STDEV($AG$3:$AG$1137))^3 -> -0.027867826 | AJ3: =(AG3/STDEV($AG$3:$AG$1137))^4 -> 0.0084489768 | AK3: =AF3^2 -> 0 | AL3: =IF(AD3=1,AB3,"") -> 4798.9749 | AM3: ""
A4: 1776352502 | B4: XAUUSD | C4: M15 | D4: 4802.1 | E4: 4518.5928 | F4: 4596.0559 | G4: 4755.4035 | H4: 4792.7697 | Q4: 4817.1025 | R4: 4846.4658 | S4: 4873.0546 | V4: 4782.1628 | W4: 4748.5978 | AB4: 4800.8624 | AC4: 4799.5785 | AD4: 0 | AE4: =AE3+1 -> 2 | AF4: =AF3+1 -> 1 | AG4: =D4-Q4 -> -15.00252 | AH4: =AG4^2 -> 225.07561 | AI4: =(AG4/STDEV($AG$3:$AG$1137))^3 -> -0.077679823 | AJ4: =(AG4/STDEV($AG$3:$AG$1137))^4 -> 0.033144462 | AK4: =AF4^2 -> 1 | AL4: =IF(AD4=1,AB4,IF(AL3<>"",AL3,"")) -> 4798.9749 | AM4: =IF(AND(AD4=1,AL3<>""),ABS(AB4-AL3),"")
A5: 1776353402 | B5: XAUUSD | C5: M15 | D5: 4802.98 | E5: 4518.5928 | F5: 4596.0559 | G5: 4755.4035 | H5: 4792.7697 | Q5: 4816.8349 | R5: 4846.1982 | S5: 4872.787 | V5: 4781.8952 | W5: 4748.3301 | AB5: 4802.265 | AC5: 4800.9218 | AD5: 0 | AE5: =AE4+1 -> 3 | AF5: =AF4+1 -> 2 | AG5: =D5-Q5 -> -13.85492 | AH5: =AG5^2 -> 191.95881 | AI5: =(AG5/STDEV($AG$3:$AG$1137))^3 -> -0.061182561 | AJ5: =(AG5/STDEV($AG$3:$AG$1137))^4 -> 0.024108501 | AK5: =AF5^2 -> 4 | AL5: =IF(AD5=1,AB5,IF(AL4<>"",AL4,"")) -> 4798.9749 | AM5: =IF(AND(AD5=1,AL4<>""),ABS(AB5-AL4),"")
A6: 1776354302 | B6: XAUUSD | C6: M15 | D6: 4807.09 | E6: 4518.5928 | F6: 4596.0559 | G6: 4755.4035 | H6: 4792.7697 | Q6: 4816.5673 | R6: 4845.9306 | S6: 4872.5194 | V6: 4781.6275 | W6: 4748.0625 | AB6: 4802.689 | AC6: 4801.8054 | AD6: 0 | AE6: =AE5+1 -> 4 | AF6: =AF5+1 -> 3 | AG6: =D6-Q6 -> -9.47731 | AH6: =AG6^2 -> 89.819405 | AI6: =(AG6/STDEV($AG$3:$AG$1137))^3 -> -0.019582622 | AJ6: =(AG6/STDEV($AG$3:$AG$1137))^4 -> 0.0052783047 | AK6: =AF6^2 -> 9 | AL6: =IF(AD6=1,AB6,IF(AL5<>"",AL5,"")) -> 4798.9749 | AM6: =IF(AND(AD6=1,AL5<>""),ABS(AB6-AL5),"")
A7: 1776355202 | B7: XAUUSD | C7: M15 | D7: 4805.02 | E7: 4518.5928 | F7: 4596.0559 | G7: 4755.4035 | H7: 4792.7697 | Q7: 4816.2997 | R7: 4845.663 | S7: 4872.2518 | V7: 4781.3599 | W7: 4747.7949 | AB7: 4801.7586 | AC7: 4801.782 | AD7: 1 | AE7: =AE6+1 -> 5 | AF7: =AF6+1 -> 4 | AG7: =D7-Q7 -> -11.27971 | AH7: =AG7^2 -> 127.23186 | AI7: =(AG7/STDEV($AG$3:$AG$1137))^3 -> -0.033014854 | AJ7: =(AG7/STDEV($AG$3:$AG$1137))^4 -> 0.010591217 | AK7: =AF7^2 -> 16 | AL7: =IF(AD7=1,AB7,IF(AL6<>"",AL6,"")) -> 4801.7586 | AM7: =IF(AND(AD7=1,AL6<>""),ABS(AB7-AL6),"") -> 2.78366
A8: 1776356102 | B8: XAUUSD | C8: M15 | D8: 4799.31 | E8: 4518.5928 | F8: 4596.0559 | G8: 4755.4035 | H8: 4792.7697 | Q8: 4816.0321 | R8: 4845.3954 | S8: 4871.9842 | V8: 4781.0923 | W8: 4747.5273 | AB8: 4799.5437 | AC8: 4800.6628 | AD8: 0 | AE8: =AE7+1 -> 6 | AF8: =AF7+1 -> 5 | AG8: =D8-Q8 -> -16.72211 | AH8: =AG8^2 -> 279.62896 | AI8: =(AG8/STDEV($AG$3:$AG$1137))^3 -> -0.10756942 | AJ8: =(AG8/STDEV($AG$3:$AG$1137))^4 -> 0.051158572 | AK8: =AF8^2 -> 25 | AL8: =IF(AD8=1,AB8,IF(AL7<>"",AL7,"")) -> 4801.7586 | AM8: =IF(AND(AD8=1,AL7<>""),ABS(AB8-AL7),"")
A9: 1776357002 | B9: XAUUSD | C9: M15 | D9: 4790.11 | E9: 4518.5928 | F9: 4596.0559 | G9: 4755.4035 | H9: 4792.7697 | Q9: 4815.7645 | R9: 4845.1278 | S9: 4871.7166 | V9: 4780.8247 | W9: 4747.2597 | AB9: 4796.4861 | AC9: 4798.5745 | AD9: 0 | AE9: =AE8+1 -> 7 | AF9: =AF8+1 -> 6 | AG9: =D9-Q9 -> -25.6545 | AH9: =AG9^2 -> 658.15337 | AI9: =(AG9/STDEV($AG$3:$AG$1137))^3 -> -0.38842417 | AJ9: =(AG9/STDEV($AG$3:$AG$1137))^4 -> 0.28340554 | AK9: =AF9^2 -> 36 | AL9: =IF(AD9=1,AB9,IF(AL8<>"",AL8,"")) -> 4801.7586 | AM9: =IF(AND(AD9=1,AL8<>""),ABS(AB9-AL8),"")
A10: 1776357902 | B10: XAUUSD | C10: M15 | D10: 4791.99 | E10: 4518.5928 | F10: 4596.0559 | G10: 4755.4035 | H10: 4792.7697 | Q10: 4815.4969 | R10: 4844.8602 | S10: 4871.449 | V10: 4780.5571 | W10: 4746.9921 | AB10: 4793.2914 | AC10: 4795.9329 | AD10: 0 | AE10: =AE9+1 -> 8 | AF10: =AF9+1 -> 7 | AG10: =D10-Q10 -> -23.5069 | AH10: =AG10^2 -> 552.57435 | AI10: =(AG10/STDEV($AG$3:$AG$1137))^3 -> -0.2988145 | AJ10: =(AG10/STDEV($AG$3:$AG$1137))^4 -> 0.19977243 | AK10: =AF10^2 -> 49 | AL10: =IF(AD10=1,AB10,IF(AL9<>"",AL9,"")) -> 4801.7586 | AM10: =IF(AND(AD10=1,AL9<>""),ABS(AB10-AL9),"")
A11: 1776358802 | B11: XAUUSD | C11: M15 | D11: 4791.41 | E11: 4518.5928 | F11: 4596.0559 | G11: 4755.4035 | H11: 4792.7697 | Q11: 4815.2293 | R11: 4844.5926 | S11: 4871.1814 | V11: 4780.2895 | W11: 4746.7245 | AB11: 4790.3715 | AC11: 4793.1522 | AD11: 0 | AE11: =AE10+1 -> 9 | AF11: =AF10+1 -> 8 | AG11: =D11-Q11 -> -23.81929 | AH11: =AG11^2 -> 567.35858 | AI11: =(AG11/STDEV($AG$3:$AG$1137))^3 -> -0.31088661 | AJ11: =(AG11/STDEV($AG$3:$AG$1137))^4 -> 0.21060533 | AK11: =AF11^2 -> 64 | AL11: =IF(AD11=1,AB11,IF(AL10<>"",AL10,"")) -> 4801.7586 | AM11: =IF(AND(AD11=1,AL10<>""),ABS(AB11-AL10),"")
A12: 1776359702 | B12: XAUUSD | C12: M15 | D12: 4785.04 | E12: 4518.5928 | F12: 4596.0559 | G12: 4755.4035 | H12: 4792.7697 | Q12: 4814.9617 | R12: 4844.325 | S12: 4870.9138 | V12: 4780.0219 | W12: 4746.4569 | AB12: 4788.0806 | AC12: 4790.6164 | AD12: 0 | AE12: =AE11+1 -> 10 | AF12: =AF11+1 -> 9 | AG12: =D12-Q12 -> -29.92169 | AH12: =AG12^2 -> 895.30753 | AI12: =(AG12/STDEV($AG$3:$AG$1137))^3 -> -0.61627414 | AJ12: =(AG12/STDEV($AG$3:$AG$1137))^4 -> 0.52444336 | AK12: =AF12^2 -> 81 | AL12: =IF(AD12=1,AB12,IF(AL11<>"",AL11,"")) -> 4801.7586 | AM12: =IF(AND(AD12=1,AL11<>""),ABS(AB12-AL11),"")
A13: 1776360602 | B13: XAUUSD | C13: M15 | D13: 4787.16 | E13: 4518.5928 | F13: 4596.0559 | G13: 4755.4035 | H13: 4792.7697 | Q13: 4814.6941 | R13: 4844.0574 | S13: 4870.6462 | V13: 4779.7543 | W13: 4746.1893 | AB13: 4786.7966 | AC13: 4788.7065 | AD13: 0 | AE13: =AE12+1 -> 11 | AF13: =AF12+1 -> 10 | AG13: =D13-Q13 -> -27.53409 | AH13: =AG13^2 -> 758.12611 | AI13: =(AG13/STDEV($AG$3:$AG$1137))^3 -> -0.4802062 | AJ13: =(AG13/STDEV($AG$3:$AG$1137))^4 -> 0.37604258 | AK13: =AF13^2 -> 100 | AL13: =IF(AD13=1,AB13,IF(AL12<>"",AL12,"")) -> 4801.7586 | AM13: =IF(AND(AD13=1,AL12<>""),ABS(AB13-AL12),"")
A14: 1776361502 | B14: XAUUSD | C14: M15 | D14: 4789.22 | E14: 4518.5928 | F14: 4596.0559 | G14: 4755.4035 | H14: 4792.7697 | Q14: 4814.4265 | R14: 4843.7898 | S14: 4870.3786 | V14: 4779.4867 | W14: 4745.9217 | AB14: 4786.5161 | AC14: 4787.6113 | AD14: 0 | AE14: =AE13+1 -> 12 | AF14: =AF13+1 -> 11 | AG14: =D14-Q14 -> -25.20648 | AH14: =AG14^2 -> 635.36663 | AI14: =(AG14/STDEV($AG$3:$AG$1137))^3 -> -0.36842763 | AJ14: =(AG14/STDEV($AG$3:$AG$1137))^4 -> 0.26412099 | AK14: =AF14^2 -> 121 | AL14: =IF(AD14=1,AB14,IF(AL13<>"",AL13,"")) -> 4801.7586 | AM14: =IF(AND(AD14=1,AL13<>""),ABS(AB14-AL13),"")
A15: 1776362402 | B15: XAUUSD | C15: M15 | D15: 4790.1 | E15: 4518.5928 | F15: 4596.0559 | G15: 4755.4035 | H15: 4792.7697 | Q15: 4814.1589 | R15: 4843.5222 | S15: 4870.111 | V15: 4779.2191 | W15: 4745.6541 | AB15: 4787.0676 | AC15: 4787.3395 | AD15: 0 | AE15: =AE14+1 -> 13 | AF15: =AF14+1 -> 12 | AG15: =D15-Q15 -> -24.05888 | AH15: =AG15^2 -> 578.82971 | AI15: =(AG15/STDEV($AG$3:$AG$1137))^3 -> -0.32036259 | AJ15: =(AG15/STDEV($AG$3:$AG$1137))^4 -> 0.21920767 | AK15: =AF15^2 -> 144 | AL15: =IF(AD15=1,AB15,IF(AL14<>"",AL14,"")) -> 4801.7586 | AM15: =IF(AND(AD15=1,AL14<>""),ABS(AB15-AL14),"")
... A40: 1776388502 | B40: XAUUSD | C40: M15 | D40: 4769.01 | E40: 4518.5928 | F40: 4596.0559 | G40: 4755.4035 | H40: 4792.7697 | Q40: 4807.4688 | R40: 4836.8321 | S40: 4863.4209 | V40: 4772.529 | W40: 4738.964 | AB40: 4783.176 | AC40: 4784.8672 | AD40: 0 | AE40: =AE39+1 -> 38 | AF40: =AF39+1 -> 37 | AG40: =D40-Q40 -> -38.45878 | AH40: =AG40^2 -> 1479.0778 | AI40: =(AG40/STDEV($AG$3:$AG$1137))^3 -> -1.3085855 | AJ40: =(AG40/STDEV($AG$3:$AG$1137))^4 -> 1.431318 | AK40: =AF40^2 -> 1369 | AL40: =IF(AD40=1,AB40,IF(AL39<>"",AL39,"")) -> 4794.635 | AM40: =IF(AND(AD40=1,AL39<>""),ABS(AB40-AL39),"")
A41: 1776389402 | B41: XAUUSD | C41: M15 | D41: 4777.87 | E41: 4518.5928 | F41: 4596.0559 | G41: 4755.4035 | H41: 4792.7697 | Q41: 4807.2012 | R41: 4836.5645 | S41: 4863.1532 | V41: 4772.2614 | W41: 4738.6964 | AA41: 4768.07 | AB41: 4783.2232 | AC41: 4784.0452 | AD41: 0 | AE41: =AE40+1 -> 39 | AF41: =AF40+1 -> 38 | AG41: =D41-Q41 -> -29.33117 | AH41: =AG41^2 -> 860.31753 | AI41: =(AG41/STDEV($AG$3:$AG$1137))^3 -> -0.58050203 | AJ41: =(AG41/STDEV($AG$3:$AG$1137))^4 -> 0.48425227 | AK41: =AF41^2 -> 1444 | AL41: =IF(AD41=1,AB41,IF(AL40<>"",AL40,"")) -> 4794.635 | AM41: =IF(AND(AD41=1,AL40<>""),ABS(AB41-AL40),"")
A42: 1776390302 | B42: XAUUSD | C42: M15 | D42: 4789.48 | E42: 4518.5928 | F42: 4596.0559 | G42: 4755.4035 | H42: 4792.7697 | Q42: 4806.9336 | R42: 4836.2969 | S42: 4862.8856 | V42: 4771.9938 | W42: 4738.4288 | AB42: 4784.2445 | AC42: 4784.1449 | AD42: 1 | AE42: =AE41+1 -> 40 | AF42: =AF41+1 -> 39 | AG42: =D42-Q42 -> -17.45357 | AH42: =AG42^2 -> 304.62711 | AI42: =(AG42/STDEV($AG$3:$AG$1137))^3 -> -0.12231181 | AJ42: =(AG42/STDEV($AG$3:$AG$1137))^4 -> 0.060714329 | AK42: =AF42^2 -> 1521 | AL42: =IF(AD42=1,AB42,IF(AL41<>"",AL41,"")) -> 4784.2445 | AM42: =IF(AND(AD42=1,AL41<>""),ABS(AB42-AL41),"") -> 10.39047
A43: 1776391202 | B43: XAUUSD | C43: M15 | D43: 4791.35 | E43: 4518.5928 | F43: 4596.0559 | G43: 4755.4035 | H43: 4792.7697 | Q43: 4806.666 | R43: 4836.0293 | S43: 4862.618 | V43: 4771.7262 | W43: 4738.1612 | AB43: 4785.6992 | AC43: 4784.9221 | AD43: 0 | AE43: =AE42+1 -> 41 | AF43: =AF42+1 -> 40 | AG43: =D43-Q43 -> -15.31596 | AH43: =AG43^2 -> 234.57863 | AI43: =(AG43/STDEV($AG$3:$AG$1137))^3 -> -0.082651027 | AJ43: =(AG43/STDEV($AG$3:$AG$1137))^4 -> 0.036002363 | AK43: =AF43^2 -> 1600 | AL43: =IF(AD43=1,AB43,IF(AL42<>"",AL42,"")) -> 4784.2445 | AM43: =IF(AND(AD43=1,AL42<>""),ABS(AB43-AL42),"")
A44: 1776392102 | B44: XAUUSD | C44: M15 | D44: 4788.86 | E44: 4518.5928 | F44: 4596.0559 | G44: 4755.4035 | H44: 4792.7697 | Q44: 4806.3984 | R44: 4835.7617 | S44: 4862.3504 | V44: 4771.4586 | W44: 4737.8936 | AB44: 4787.2894 | AC44: 4786.1057 | AD44: 0 | AE44: =AE43+1 -> 42 | AF44: =AF43+1 -> 41 | AG44: =D44-Q44 -> -17.53836 | AH44: =AG44^2 -> 307.59407 | AI44: =(AG44/STDEV($AG$3:$AG$1137))^3 -> -0.12410307 | AJ44: =(AG44/STDEV($AG$3:$AG$1137))^4 -> 0.061902763 | AK44: =AF44^2 -> 1681 | AL44: =IF(AD44=1,AB44,IF(AL43<>"",AL43,"")) -> 4784.2445 | AM44: =IF(AND(AD44=1,AL43<>""),ABS(AB44-AL43),"")
A45: 1776393002 | B45: XAUUSD | C45: M15 | D45: 4791.57 | E45: 4518.5928 | F45: 4596.0559 | G45: 4755.4035 | H45: 4792.7697 | Q45: 4806.1308 | R45: 4835.4941 | S45: 4862.0828 | V45: 4771.191 | W45: 4737.626 | AB45: 4788.9024 | AC45: 4787.5041 | AD45: 0 | AE45: =AE44+1 -> 43 | AF45: =AF44+1 -> 42 | AG45: =D45-Q45 -> -14.56075 | AH45: =AG45^2 -> 212.01544 | AI45: =(AG45/STDEV($AG$3:$AG$1137))^3 -> -0.071017736 | AJ45: =(AG45/STDEV($AG$3:$AG$1137))^4 -> 0.029409598 | AK45: =AF45^2 -> 1764 | AL45: =IF(AD45=1,AB45,IF(AL44<>"",AL44,"")) -> 4784.2445 | AM45: =IF(AND(AD45=1,AL44<>""),ABS(AB45-AL44),"")
A46: 1776393902 | B46: XAUUSD | C46: M15 | D46: 4784.81 | E46: 4518.5928 | F46: 4596.0559 | G46: 4755.4035 | H46: 4792.7697 | Q46: 4805.8632 | R46: 4835.2265 | S46: 4861.8152 | V46: 4770.9234 | W46: 4737.3584 | AB46: 4790.3727 | AC46: 4788.9384 | AD46: 0 | AE46: =AE45+1 -> 44 | AF46: =AF45+1 -> 43 | AG46: =D46-Q46 -> -21.05315 | AH46: =AG46^2 -> 443.23512 | AI46: =(AG46/STDEV($AG$3:$AG$1137))^3 -> -0.21466777 | AJ46: =(AG46/STDEV($AG$3:$AG$1137))^4 -> 0.12853531 | AK46: =AF46^2 -> 1849 | AL46: =IF(AD46=1,AB46,IF(AL45<>"",AL45,"")) -> 4784.2445 | AM46: =IF(AND(AD46=1,AL45<>""),ABS(AB46-AL45),"")
A47: 1776394802 | B47: XAUUSD | C47: M15 | D47: 4795.86 | E47: 4518.5928 | F47: 4596.0559 | G47: 4755.4035 | H47: 4792.7697 | Q47: 4805.5956 | R47: 4834.9588 | S47: 4861.5476 | V47: 4770.6558 | W47: 4737.0908 | AB47: 4791.8981 | AC47: 4790.4182 | AD47: 0 | AE47: =AE46+1 -> 45 | AF47: =AF46+1 -> 44 | AG47: =D47-Q47 -> -9.73555 | AH47: =AG47^2 -> 94.780934 | AI47: =(AG47/STDEV($AG$3:$AG$1137))^3 -> -0.021227412 | AJ47: =(AG47/STDEV($AG$3:$AG$1137))^4 -> 0.0058775466 | AK47: =AF47^2 -> 1936 | AL47: =IF(AD47=1,AB47,IF(AL46<>"",AL46,"")) -> 4784.2445 | AM47: =IF(AND(AD47=1,AL46<>""),ABS(AB47-AL46),"")
A48: 1776395702 | B48: XAUUSD | C48: M15 | D48: 4793.93 | E48: 4518.5928 | F48: 4596.0559 | G48: 4755.4035 | H48: 4792.7697 | Q48: 4805.3279 | R48: 4834.6912 | S48: 4861.28 | V48: 4770.3882 | W48: 4736.8232 | AB48: 4793.245 | AC48: 4791.8316 | AD48: 0 | AE48: =AE47+1 -> 46 | AF48: =AF47+1 -> 45 | AG48: =D48-Q48 -> -11.39794 | AH48: =AG48^2 -> 129.91304 | AI48: =(AG48/STDEV($AG$3:$AG$1137))^3 -> -0.034063925 | AJ48: =(AG48/STDEV($AG$3:$AG$1137))^4 -> 0.011042301 | AK48: =AF48^2 -> 2025 | AL48: =IF(AD48=1,AB48,IF(AL47<>"",AL47,"")) -> 4784.2445 | AM48: =IF(AND(AD48=1,AL47<>""),ABS(AB48-AL47),"")
A49: 1776396602 | B49: XAUUSD | C49: M15 | D49: 4794.26 | E49: 4518.5928 | F49: 4596.0559 | G49: 4755.4035 | H49: 4792.7697 | Q49: 4805.0603 | R49: 4834.4236 | S49: 4861.0124 | V49: 4770.1206 | W49: 4736.5556 | AB49: 4794.5677 | AC49: 4793.1997 | AD49: 0 | AE49: =AE48+1 -> 47 | AF49: =AF48+1 -> 46 | AG49: =D49-Q49 -> -10.80034 | AH49: =AG49^2 -> 116.64734 | AI49: =(AG49/STDEV($AG$3:$AG$1137))^3 -> -0.028981968 | AJ49: =(AG49/STDEV($AG$3:$AG$1137))^4 -> 0.0089023327 | AK49: =AF49^2 -> 2116 | AL49: =IF(AD49=1,AB49,IF(AL48<>"",AL48,"")) -> 4784.2445 | AM49: =IF(AND(AD49=1,AL48<>""),ABS(AB49-AL48),"")
A50: 1776397502 | B50: XAUUSD | C50: M15 | D50: 4793.09 | E50: 4518.5928 | F50: 4596.0559 | G50: 4755.4035 | H50: 4792.7697 | Q50: 4804.7927 | R50: 4834.156 | S50: 4860.7448 | V50: 4769.853 | W50: 4736.288 | AB50: 4795.955 | AC50: 4794.5773 | AD50: 0 | AE50: =AE49+1 -> 48 | AF50: =AF49+1 -> 47 | AG50: =D50-Q50 -> -11.70273 | AH50: =AG50^2 -> 136.95389 | AI50: =(AG50/STDEV($AG$3:$AG$1137))^3 -> -0.03687034 | AJ50: =(AG50/STDEV($AG$3:$AG$1137))^4 -> 0.012271647 | AK50: =AF50^2 -> 2209 | AL50: =IF(AD50=1,AB50,IF(AL49<>"",AL49,"")) -> 4784.2445 | AM50: =IF(AND(AD50=1,AL49<>""),ABS(AB50-AL49),"")
A51: 1776398402 | B51: XAUUSD | C51: M15 | D51: 4795.16 | E51: 4518.5928 | F51: 4596.0559 | G51: 4755.4035 | H51: 4792.7697 | Q51: 4804.5251 | R51: 4833.8884 | S51: 4860.4772 | V51: 4769.5854 | W51: 4736.0204 | AB51: 4797.4545 | AC51: 4796.0159 | AD51: 0 | AE51: =AE50+1 -> 49 | AF51: =AF50+1 -> 48 | AG51: =D51-Q51 -> -9.36513 | AH51: =AG51^2 -> 87.70566 | AI51: =(AG51/STDEV($AG$3:$AG$1137))^3 -> -0.01889544 | AJ51: =(AG51/STDEV($AG$3:$AG$1137))^4 -> 0.0050327963 | AK51: =AF51^2 -> 2304 | AL51: =IF(AD51=1,AB51,IF(AL50<>"",AL50,"")) -> 4784.2445 | AM51: =IF(AND(AD51=1,AL50<>""),ABS(AB51-AL50),"")
A52: 1776399302 | B52: XAUUSD | C52: M15 | D52: 4795.87 | E52: 4518.5928 | F52: 4596.0559 | G52: 4755.4035 | H52: 4792.7697 | Q52: 4804.2575 | R52: 4833.6208 | S52: 4860.2096 | V52: 4769.3178 | W52: 4735.7528 | AB52: 4798.9172 | AC52: 4797.4665 | AD52: 0 | AE52: =AE51+1 -> 50 | AF52: =AF51+1 -> 49 | AG52: =D52-Q52 -> -8.38753 | AH52: =AG52^2 -> 70.35066 | AI52: =(AG52/STDEV($AG$3:$AG$1137))^3 -> -0.013574313 | AJ52: =(AG52/STDEV($AG$3:$AG$1137))^4 -> 0.0032381015 | AK52: =AF52^2 -> 2401 | AL52: =IF(AD52=1,AB52,IF(AL51<>"",AL51,"")) -> 4784.2445 | AM52: =IF(AND(AD52=1,AL51<>""),ABS(AB52-AL51),"")
A53: 1776400202 | B53: XAUUSD | C53: M15 | D53: 4801.05 | E53: 4518.5928 | F53: 4596.0559 | G53: 4755.4035 | H53: 4792.7697 | Q53: 4803.9899 | R53: 4833.3532 | S53: 4859.942 | V53: 4769.0502 | W53: 4735.4852 | AB53: 4800.1665 | AC53: 4798.8165 | AD53: 0 | AE53: =AE52+1 -> 51 | AF53: =AF52+1 -> 50 | AG53: =D53-Q53 -> -2.93992 | AH53: =AG53^2 -> 8.6431296 | AI53: =(AG53/STDEV($AG$3:$AG$1137))^3 -> -0.00058455062 | AJ53: =(AG53/STDEV($AG$3:$AG$1137))^4 -> 4.8876057e-05 | AK53: =AF53^2 -> 2500 | AL53: =IF(AD53=1,AB53,IF(AL52<>"",AL52,"")) -> 4784.2445 | AM53: =IF(AND(AD53=1,AL52<>""),ABS(AB53-AL52),"")
A54: 1776401102 | B54: XAUUSD | C54: M15 | D54: 4803.04 | E54: 4518.5928 | F54: 4596.0559 | G54: 4755.4035 | H54: 4792.7697 | Q54: 4803.7223 | R54: 4833.0856 | S54: 4859.6744 | V54: 4768.7825 | W54: 4735.2176 | AB54: 4800.8418 | AC54: 4799.8292 | AD54: 0 | AE54: =AE53+1 -> 52 | AF54: =AF53+1 -> 51 | AG54: =D54-Q54 -> -0.68232 | AH54: =AG54^2 -> 0.46556058 | AI54: =(AG54/STDEV($AG$3:$AG$1137))^3 -> -7.3076862e-06 | AJ54: =(AG54/STDEV($AG$3:$AG$1137))^4 -> 1.4180989e-07 | AK54: =AF54^2 -> 2601 | AL54: =IF(AD54=1,AB54,IF(AL53<>"",AL53,"")) -> 4784.2445 | AM54: =IF(AND(AD54=1,AL53<>""),ABS(AB54-AL53),"")
A55: 1776402002 | B55: XAUUSD | C55: M15 | D55: 4804.78 | E55: 4518.5928 | F55: 4596.0559 | G55: 4755.4035 | H55: 4792.7697 | Q55: 4803.4547 | R55: 4832.818 | S55: 4859.4068 | V55: 4768.5149 | W55: 4734.95 | Z55: 4805.97 | AB55: 4800.6718 | AC55: 4800.2505 | AD55: 0 | AE55: =AE54+1 -> 53 | AF55: =AF54+1 -> 52 | AG55: =D55-Q55 -> 1.32529 | AH55: =AG55^2 -> 1.7563936 | AI55: =(AG55/STDEV($AG$3:$AG$1137))^3 -> 5.3548628e-05 | AJ55: =(AG55/STDEV($AG$3:$AG$1137))^4 -> 2.0183561e-06 | AK55: =AF55^2 -> 2704 | AL55: =IF(AD55=1,AB55,IF(AL54<>"",AL54,"")) -> 4784.2445 | AM55: =IF(AND(AD55=1,AL54<>""),ABS(AB55-AL54),"")
A56: 1776402902 | B56: XAUUSD | C56: M15 | D56: 4803.25 | E56: 4518.5928 | F56: 4596.0559 | G56: 4755.4035 | H56: 4792.7697 | Q56: 4803.1871 | R56: 4832.5504 | S56: 4859.1392 | V56: 4768.2473 | W56: 4734.6823 | AB56: 4799.4912 | AC56: 4799.8708 | AD56: 1 | AE56: =AE55+1 -> 54 | AF56: =AF55+1 -> 53 | AG56: =D56-Q56 -> 0.06289 | AH56: =AG56^2 -> 0.0039551521 | AI56: =(AG56/STDEV($AG$3:$AG$1137))^3 -> 5.7221649e-09 | AJ56: =(AG56/STDEV($AG$3:$AG$1137))^4 -> 1.0234827e-11 | AK56: =AF56^2 -> 2809 | AL56: =IF(AD56=1,AB56,IF(AL55<>"",AL55,"")) -> 4799.4912 | AM56: =IF(AND(AD56=1,AL55<>""),ABS(AB56-AL55),"") -> 15.24663
A57: 1776403802 | B57: XAUUSD | C57: M15 | D57: 4796.48 | E57: 4518.5928 | F57: 4596.0559 | G57: 4755.4035 | H57: 4792.7697 | Q57: 4802.9195 | R57: 4832.2828 | S57: 4858.8716 | V57: 4767.9797 | W57: 4734.4147 | AB57: 4797.3362 | AC57: 4798.6035 | AD57: 0 | AE57: =AE56+1 -> 55 | AF57: =AF56+1 -> 54 | AG57: =D57-Q57 -> -6.43951 | AH57: =AG57^2 -> 41.467289 | AI57: =(AG57/STDEV($AG$3:$AG$1137))^3 -> -0.0061429086 | AJ57: =(AG57/STDEV($AG$3:$AG$1137))^4 -> 0.0011250334 | AK57: =AF57^2 -> 2916 | AL57: =IF(AD57=1,AB57,IF(AL56<>"",AL56,"")) -> 4799.4912 | AM57: =IF(AND(AD57=1,AL56<>""),ABS(AB57-AL56),"")
A58: 1776404702 | B58: XAUUSD | C58: M15 | D58: 4794.41 | E58: 4518.5928 | F58: 4596.0559 | G58: 4755.4035 | H58: 4792.7697 | Q58: 4802.6519 | R58: 4832.0152 | S58: 4858.604 | V58: 4767.7121 | W58: 4734.1471 | AB58: 4794.5247 | AC58: 4796.5641 | AD58: 0 | AE58: =AE57+1 -> 56 | AF58: =AF57+1 -> 55 | AG58: =D58-Q58 -> -8.2419 | AH58: =AG58^2 -> 67.928916 | AI58: =(AG58/STDEV($AG$3:$AG$1137))^3 -> -0.012879459 | AJ58: =(AG58/STDEV($AG$3:$AG$1137))^4 -> 0.0030190025 | AK58: =AF58^2 -> 3025 | AL58: =IF(AD58=1,AB58,IF(AL57<>"",AL57,"")) -> 4799.4912 | AM58: =IF(AND(AD58=1,AL57<>""),ABS(AB58-AL57),"")
A59: 1776405602 | B59: XAUUSD | C59: M15 | D59: 4787.73 | E59: 4518.5928 | F59: 4596.0559 | G59: 4755.4035 | H59: 4792.7697 | Q59: 4802.3843 | R59: 4831.7476 | S59: 4858.3364 | V59: 4767.4445 | W59: 4733.8795 | AB59: 4791.4825 | AC59: 4794.0233 | AD59: 0 | AE59: =AE58+1 -> 57 | AF59: =AF58+1 -> 56 | AG59: =D59-Q59 -> -14.6543 | AH59: =AG59^2 -> 214.74851 | AI59: =(AG59/STDEV($AG$3:$AG$1137))^3 -> -0.072395374 | AJ59: =(AG59/STDEV($AG$3:$AG$1137))^4 -> 0.030172717 | AK59: =AF59^2 -> 3136 | AL59: =IF(AD59=1,AB59,IF(AL58<>"",AL58,"")) -> 4799.4912 | AM59: =IF(AND(AD59=1,AL58<>""),ABS(AB59-AL58),"")
A60: 1776406502 | B60: XAUUSD | C60: M15 | D60: 4783.78 | E60: 4518.5928 | F60: 4596.0559 | G60: 4755.4035 | H60: 4792.7697 | Q60: 4802.1167 | R60: 4831.48 | S60: 4858.0688 | V60: 4767.1769 | W60: 4733.6119 | AB60: 4788.6996 | AC60: 4791.3615 | AD60: 0 | AE60: =AE59+1 -> 58 | AF60: =AF59+1 -> 57 | AG60: =D60-Q60 -> -18.33669 | AH60: =AG60^2 -> 336.2342 | AI60: =(AG60/STDEV($AG$3:$AG$1137))^3 -> -0.14183337 | AJ60: =(AG60/STDEV($AG$3:$AG$1137))^4 -> 0.073966979 | AK60: =AF60^2 -> 3249 | AL60: =IF(AD60=1,AB60,IF(AL59<>"",AL59,"")) -> 4799.4912 | AM60: =IF(AND(AD60=1,AL59<>""),ABS(AB60-AL59),"")
A61: 1776407402 | B61: XAUUSD | C61: M15 | D61: 4785.67 | E61: 4518.5928 | F61: 4596.0559 | G61: 4755.4035 | H61: 4792.7697 | Q61: 4801.8491 | R61: 4831.2124 | S61: 4857.8012 | V61: 4766.9093 | W61: 4733.3443 | AB61: 4786.5307 | AC61: 4788.9461 | AD61: 0 | AE61: =AE60+1 -> 59 | AF61: =AF60+1 -> 58 | AG61: =D61-Q61 -> -16.17909 | AH61: =AG61^2 -> 261.76295 | AI61: =(AG61/STDEV($AG$3:$AG$1137))^3 -> -0.09742667 | AJ61: =(AG61/STDEV($AG$3:$AG$1137))^4 -> 0.044830179 | AK61: =AF61^2 -> 3364 | AL61: =IF(AD61=1,AB61,IF(AL60<>"",AL60,"")) -> 4799.4912 | AM61: =IF(AND(AD61=1,AL60<>""),ABS(AB61-AL60),"")
A62: 1776408302 | B62: XAUUSD | C62: M15 | D62: 4785.07 | E62: 4518.5928 | F62: 4596.0559 | G62: 4755.4035 | H62: 4792.7697 | Q62: 4801.5815 | R62: 4830.9448 | S62: 4857.5336 | V62: 4766.6417 | W62: 4733.0767 | AB62: 4785.1178 | AC62: 4787.032 | AD62: 0 | AE62: =AE61+1 -> 60 | AF62: =AF61+1 -> 59 | AG62: =D62-Q62 -> -16.51149 | AH62: =AG62^2 -> 272.6293 | AI62: =(AG62/STDEV($AG$3:$AG$1137))^3 -> -0.10355579 | AJ62: =(AG62/STDEV($AG$3:$AG$1137))^4 -> 0.04862943 | AK62: =AF62^2 -> 3481 | AL62: =IF(AD62=1,AB62,IF(AL61<>"",AL61,"")) -> 4799.4912 | AM62: =IF(AND(AD62=1,AL61<>""),ABS(AB62-AL61),"")
A63: 1776409202 | B63: XAUUSD | C63: M15 | D63: 4787.12 | E63: 4518.5928 | F63: 4596.0559 | G63: 4755.4035 | H63: 4792.7697 | Q63: 4801.3139 | R63: 4830.6772 | S63: 4857.2659 | V63: 4766.3741 | W63: 4732.8091 | AB63: 4784.5163 | AC63: 4785.7741 | AD63: 0 | AE63: =AE62+1 -> 61 | AF63: =AF62+1 -> 60 | AG63: =D63-Q63 -> -14.19388 | AH63: =AG63^2 -> 201.46623 | AI63: =(AG63/STDEV($AG$3:$AG$1137))^3 -> -0.065783802 | AJ63: =(AG63/STDEV($AG$3:$AG$1137))^4 -> 0.026555754 | AK63: =AF63^2 -> 3600 | AL63: =IF(AD63=1,AB63,IF(AL62<>"",AL62,"")) -> 4799.4912 | AM63: =IF(AND(AD63=1,AL62<>""),ABS(AB63-AL62),"")
A64: 1776410102 | B64: XAUUSD | C64: M15 | D64: 4791.72 | E64: 4518.5928 | F64: 4596.0559 | G64: 4755.4035 | H64: 4792.7697 | Q64: 4801.0463 | R64: 4830.4096 | S64: 4856.9983 | V64: 4766.1065 | W64: 4732.5415 | AB64: 4784.6154 | AC64: 4785.1948 | AD64: 0 | AE64: =AE63+1 -> 62 | AF64: =AF63+1 -> 61 | AG64: =D64-Q64 -> -9.32628 | AH64: =AG64^2 -> 86.979499 | AI64: =(AG64/STDEV($AG$3:$AG$1137))^3 -> -0.018661259 | AJ64: =(AG64/STDEV($AG$3:$AG$1137))^4 -> 0.004949803 | AK64: =AF64^2 -> 3721 | AL64: =IF(AD64=1,AB64,IF(AL63<>"",AL63,"")) -> 4799.4912 | AM64: =IF(AND(AD64=1,AL63<>""),ABS(AB64-AL63),"")
...

Sheet Statistical Testing Results
A1: Helper Values (used by formulas below)
A2: σ = SQRT(AVERAGE(eᵢ²)) [population std dev of residuals] | B2: =SQRT(AVERAGE('Data Export2 Refine'!AH3:AH1137)) -> 40.755973
A3: n = COUNT(eᵢ) [number of observations] | B3: =COUNT('Data Export2 Refine'!AG3:AG1137) -> 1135
A5: Jarque-Bera Test (residual eᵢ = close − Base_FL)
A6: α (significance level) | B6: =0.05 -> 0.05
A7: n (sample size) | B7: =B3 -> 1135
A8: Skewness S = SKEW(eᵢ) [Excel SKEW = bias-corrected Fisher skewness; matches scipy.stats.skew] | B8: =SKEW('Data Export2 Refine'!AG3:AG1137) -> -0.22013741
A9: Excess Kurtosis K−3 = KURT(eᵢ) [Excel KURT returns K−3 directly; matches scipy.stats.kurtosis] | B9: =KURT('Data Export2 Refine'!AG3:AG1137) -> -0.66774707
A10: JB statistic = (n/6) × [ S² + (K−3)²/4 ] | B10: =B7/6*(B8^2+B9^2/4) -> 30.253807
A11: p-value = CHIDIST(JB, 2) [right-tail chi-squared, df=2] | B11: =CHIDIST(B10,2) -> 2.6944454e-07
A12: Critical χ²(df=2, α) = CHIINV(α, 2) | B12: =CHIINV(B6,2) -> 5.9914645
A13: ="DECISION: JB = "&TEXT(B10,"0.0000")&", p = "&TEXT(B11,"0.00E+00")&" "&IF(B11<B6,"<","≥")&" α = "&TEXT(B6,"0.00")&" ⟹ "&IF(B11<B6,"REJECT H₀ → Base_FL residuals are NOT normally distributed","FAIL TO REJECT H₀ → Base_FL residuals are normally distributed") -> DECISION: JB = 30.2538, p = 2.69E-07 < α = 0.05 ⟹ REJECT H₀ → Base_FL residuals are NOT normally distributed
A15: White's Test (residual eᵢ = close − Base_FL)
A16: α (significance level) | B16: =0.05 -> 0.05
A17: n (sample size) | B17: =B3 -> 1135
A18: Auxiliary regression: eᵢ² ~ β₀ + β₁·(Bar Index) + β₂·(Bar Index²) [Data Export2 Refine cols AH, AF, AK]
A19: R²_aux = INDEX(LINEST(eᵢ²,{Bar Index, Bar Index²},TRUE,TRUE), 3, 1) [Row 3, col 1 of LINEST stats matrix = R² of auxiliary regression] | B19: =INDEX(LINEST('Data Export2 Refine'!AH3:AH1137,CHOOSE({1,2},'Data Export2 Refine'!AF3:AF1137,'Data Export2 Refine'!AK3:AK1137),TRUE,TRUE),3,1) -> 0.11986924
A20: White LM = n × R²_aux | B20: =B17*B19 -> 136.05158
A21: p-value = CHIDIST(LM, 2) [right-tail chi-squared, df=2] | B21: =CHIDIST(B20,2) -> 2.8626874e-30
A22: Critical χ²(df=2, α) = CHIINV(α, 2) | B22: =CHIINV(B16,2) -> 5.9914645
A23: ="DECISION: LM = "&TEXT(B20,"0.0000")&", p = "&TEXT(B21,"0.00E+00")&" "&IF(B21<B16,"<","≥")&" α = "&TEXT(B16,"0.00")&" ⟹ "&IF(B21<B16,"REJECT H₀ → Base_FL residuals are HETEROSCEDASTIC","FAIL TO REJECT H₀ → Base_FL residuals are HOMOSCEDASTIC") -> DECISION: LM = 136.0516, p = 2.86E-30 < α = 0.05 ⟹ REJECT H₀ → Base_FL residuals are HETEROSCEDASTIC

Sheet MACD_H2_Int1
A1: MACD Hybrid v2 (8-Dim) — MACD_H2_Int1
A2: SLOW Window: Bars 136–1135 (n=1000, anchored from bar 136)
A3: FAST Window: Bars 386–635 (n=250, sliding)
A4: 8-Dim model. REI two-sided (below + above) with symmetric anchor = (|EDT_outermost_below| + EDT_outermost_above) / 2 — robust to Base_FL asymmetry. SCD = SSA crossing-to-crossing distance (position-agnostic). Col E = editable threshold. Col F = ALERT when threshold crossed.
A6: Metric | B6: SLOW | C6: FAST | D6: Score | E6: Threshold | F6: Alert
A7: ── Structural & Mean-Reversion Metrics ──
A8: n (observations) | B8: =COUNT('Data Export2 Refine'!AF138:AF1137) -> 1000 | C8: =COUNT('Data Export2 Refine'!AF388:AF637) -> 250
A9: Variance E[eᵢ²] | B9: =AVERAGE('Data Export2 Refine'!AH138:AH1137) -> 1688.3897 | C9: =AVERAGE('Data Export2 Refine'!AH388:AH637) -> 1227.5519
A10: σ_rms (RMS of residuals) | B10: =SQRT(AVERAGE('Data Export2 Refine'!AH138:AH1137)) -> 41.090019 | C10: =SQRT(AVERAGE('Data Export2 Refine'!AH388:AH637)) -> 35.036437
A11: HL Alpha (AR1 no-const) | B11: =SUMPRODUCT(('Data Export2 Refine'!AG139:AG1137-'Data Export2 Refine'!AG138:AG1136),'Data Export2 Refine'!AG138:AG1136)/SUMPRODUCT('Data Export2 Refine'!AG138:AG1136,'Data Export2 Refine'!AG138:AG1136) -> -0.013121629 | C11: =SUMPRODUCT(('Data Export2 Refine'!AG389:AG637-'Data Export2 Refine'!AG388:AG636),'Data Export2 Refine'!AG388:AG636)/SUMPRODUCT('Data Export2 Refine'!AG388:AG636,'Data Export2 Refine'!AG388:AG636) -> -0.018525656
A12: Half-Life (bars) | B12: =IF(B11>=0,9999,-LN(2)/LN(1+B11)) -> 52.477445 | C12: =IF(C11>=0,9999,-LN(2)/LN(1+C11)) -> 37.067872
A13: R²(close ~ BarIdx) — linear trend quality | B13: =RSQ('Data Export2 Refine'!D138:D1137,'Data Export2 Refine'!AF138:AF1137) -> 0.82574393 | C13: =RSQ('Data Export2 Refine'!D388:D637,'Data Export2 Refine'!AF388:AF637) -> 0.050655973
A15: ── Jarque-Bera Normality Test (on eᵢ) ──
A16: Significance level α | B16: =0.05 -> 0.05 | C16: =0.05 -> 0.05
A17: Skewness S (SKEW) | B17: =SKEW('Data Export2 Refine'!AG138:AG1137) -> -0.39770375 | C17: =SKEW('Data Export2 Refine'!AG388:AG637) -> 0.18250965
A18: Excess Kurtosis K-3 (KURT) | B18: =KURT('Data Export2 Refine'!AG138:AG1137) -> -0.41011567 | C18: =KURT('Data Export2 Refine'!AG388:AG637) -> -1.1970249
A19: JB Statistic = n/6·(S²+(K-3)²/4) | B19: =B8/6*(B17^2+B18^2/4) -> 33.369498 | C19: =C8/6*(C17^2+C18^2/4) -> 16.313622
A20: p-value (CHIDIST, df=2) | B20: =CHIDIST(B19,2) -> 5.6742117e-08 | C20: =CHIDIST(C19,2) -> 0.00028677543
A21: Critical value χ²(α,2) (CHIINV) | B21: =CHIINV(B16,2) -> 5.9914645 | C21: =CHIINV(C16,2) -> 5.9914645
A22: JB Decision (Slow) | B22: =IF(B19>B21,"REJECT H₀","FAIL TO REJECT") -> REJECT H₀
A23: JB Decision (Fast) | C23: =IF(C19>C21,"REJECT H₀","FAIL TO REJECT") -> REJECT H₀
A25: ── White's Heteroscedasticity Test (on eᵢ) ──
A26: Significance level α | B26: =0.05 -> 0.05 | C26: =0.05 -> 0.05
A27: R²_aux (eᵢ² ~ BarIdx + BarIdx²) | B27: =INDEX(LINEST('Data Export2 Refine'!AH138:AH1137,CHOOSE({1,2},'Data Export2 Refine'!AF138:AF1137,'Data Export2 Refine'!AK138:AK1137),TRUE,TRUE),3,1) -> 0.14846489 | C27: =INDEX(LINEST('Data Export2 Refine'!AH388:AH637,CHOOSE({1,2},'Data Export2 Refine'!AF388:AF637,'Data Export2 Refine'!AK388:AK637),TRUE,TRUE),3,1) -> 0.60987181
A28: LM = n × R²_aux | B28: =B8*B27 -> 148.46489 | C28: =C8*C27 -> 152.46795
A29: p-value (CHIDIST, df=2) | B29: =CHIDIST(B28,2) -> 5.7711134e-33 | C29: =CHIDIST(C28,2) -> 7.798389e-34
A30: Critical value χ²(α,2) (CHIINV) | B30: =CHIINV(B26,2) -> 5.9914645 | C30: =CHIINV(C26,2) -> 5.9914645
A31: log₁₀(p_White) | B31: =IF(B29=0,-300,LOG10(B29)) -> -32.23874 | C31: =IF(C29=0,-300,LOG10(C29)) -> -33.107995
A32: White's Decision (Slow) | B32: =IF(B28>B30,"REJECT H₀","FAIL TO REJECT") -> REJECT H₀
A33: White's Decision (Fast) | C33: =IF(C28>C30,"REJECT H₀","FAIL TO REJECT") -> REJECT H₀
A35: ── EDT Extremity (REI — two-sided, Symmetric Anchor) ──
A36: Outermost Below EDT offset (EDT_8→EDT_7→EDT_6 fallback) [negative] | B36: =IF(SUMPRODUCT(('Data Export2 Refine'!Y138:Y1137<>"")*1)>0,SUMPRODUCT(('Data Export2 Refine'!Y138:Y1137<>"")*('Data Export2 Refine'!Y138:Y1137-'Data Export2 Refine'!Q138:Q1137))/SUMPRODUCT(('Data Export2 Refine'!Y138:Y1137<>"")*1),IF(SUMPRODUCT(('Data Export2 Refine'!X138:X1137<>"")*1)>0,SUMPRODUCT(('Data Export2 Refine'!X138:X1137<>"")*('Data Export2 Refine'!X138:X1137-'Data Export2 Refine'!Q138:Q1137))/SUMPRODUCT(('Data Export2 Refine'!X138:X1137<>"")*1),SUMPRODUCT(('Data Export2 Refine'!W138:W1137<>"")*('Data Export2 Refine'!W138:W1137-'Data Export2 Refine'!Q138:Q1137))/SUMPRODUCT(('Data Export2 Refine'!W138:W1137<>"")*1))) -> -68.504766 | C36: =IF(SUMPRODUCT(('Data Export2 Refine'!Y388:Y637<>"")*1)>0,SUMPRODUCT(('Data Export2 Refine'!Y388:Y637<>"")*('Data Export2 Refine'!Y388:Y637-'Data Export2 Refine'!Q388:Q637))/SUMPRODUCT(('Data Export2 Refine'!Y388:Y637<>"")*1),IF(SUMPRODUCT(('Data Export2 Refine'!X388:X637<>"")*1)>0,SUMPRODUCT(('Data Export2 Refine'!X388:X637<>"")*('Data Export2 Refine'!X388:X637-'Data Export2 Refine'!Q388:Q637))/SUMPRODUCT(('Data Export2 Refine'!X388:X637<>"")*1),SUMPRODUCT(('Data Export2 Refine'!W388:W637<>"")*('Data Export2 Refine'!W388:W637-'Data Export2 Refine'!Q388:Q637))/SUMPRODUCT(('Data Export2 Refine'!W388:W637<>"")*1))) -> -68.504766
A37: Outermost Above EDT offset (EDT_4→EDT_3→EDT_2→EDT_1 fallback) [positive] | B37: =IF(SUMPRODUCT(('Data Export2 Refine'!U138:U1137<>"")*1)>0,SUMPRODUCT(('Data Export2 Refine'!U138:U1137<>"")*('Data Export2 Refine'!U138:U1137-'Data Export2 Refine'!Q138:Q1137))/SUMPRODUCT(('Data Export2 Refine'!U138:U1137<>"")*1),IF(SUMPRODUCT(('Data Export2 Refine'!T138:T1137<>"")*1)>0,SUMPRODUCT(('Data Export2 Refine'!T138:T1137<>"")*('Data Export2 Refine'!T138:T1137-'Data Export2 Refine'!Q138:Q1137))/SUMPRODUCT(('Data Export2 Refine'!T138:T1137<>"")*1),IF(SUMPRODUCT(('Data Export2 Refine'!S138:S1137<>"")*1)>0,SUMPRODUCT(('Data Export2 Refine'!S138:S1137<>"")*('Data Export2 Refine'!S138:S1137-'Data Export2 Refine'!Q138:Q1137))/SUMPRODUCT(('Data Export2 Refine'!S138:S1137<>"")*1),SUMPRODUCT(('Data Export2 Refine'!R138:R1137<>"")*('Data Export2 Refine'!R138:R1137-'Data Export2 Refine'!Q138:Q1137))/SUMPRODUCT(('Data Export2 Refine'!R138:R1137<>"")*1)))) -> 55.95207 | C37: =IF(SUMPRODUCT(('Data Export2 Refine'!U388:U637<>"")*1)>0,SUMPRODUCT(('Data Export2 Refine'!U388:U637<>"")*('Data Export2 Refine'!U388:U637-'Data Export2 Refine'!Q388:Q637))/SUMPRODUCT(('Data Export2 Refine'!U388:U637<>"")*1),IF(SUMPRODUCT(('Data Export2 Refine'!T388:T637<>"")*1)>0,SUMPRODUCT(('Data Export2 Refine'!T388:T637<>"")*('Data Export2 Refine'!T388:T637-'Data Export2 Refine'!Q388:Q637))/SUMPRODUCT(('Data Export2 Refine'!T388:T637<>"")*1),IF(SUMPRODUCT(('Data Export2 Refine'!S388:S637<>"")*1)>0,SUMPRODUCT(('Data Export2 Refine'!S388:S637<>"")*('Data Export2 Refine'!S388:S637-'Data Export2 Refine'!Q388:Q637))/SUMPRODUCT(('Data Export2 Refine'!S388:S637<>"")*1),SUMPRODUCT(('Data Export2 Refine'!R388:R637<>"")*('Data Export2 Refine'!R388:R637-'Data Export2 Refine'!Q388:Q637))/SUMPRODUCT(('Data Export2 Refine'!R388:R637<>"")*1)))) -> 55.95207
A38: Symmetric Anchor = (|EDT_below| + EDT_above) / 2 — scale reference | B38: =IF(AND(B36<0,B37>0),(ABS(B36)+B37)/2,IF(B36<0,ABS(B36),B37)) -> 62.228418 | C38: =IF(AND(C36<0,C37>0),(ABS(C36)+C37)/2,IF(C36<0,ABS(C36),C37)) -> 62.228418
A39: REI_below = min(eᵢ) / Sym_anchor [negative → below extreme] | B39: =IF(B38>0,MIN('Data Export2 Refine'!AG138:AG1137)/B38,"N/A") -> -1.3272002 | C39: =IF(C38>0,MIN('Data Export2 Refine'!AG388:AG637)/C38,"N/A") -> -0.34565638
A40: REI_above = max(eᵢ) / Sym_anchor [positive → above extreme] | B40: =IF(B38>0,MAX('Data Export2 Refine'!AG138:AG1137)/B38,"N/A") -> 1.7425285 | C40: =IF(C38>0,MAX('Data Export2 Refine'!AG388:AG637)/C38,"N/A") -> 1.1418757
A41: max(eᵢ) — informational | B41: =MAX('Data Export2 Refine'!AG138:AG1137) -> 108.43479 | C41: =MAX('Data Export2 Refine'!AG388:AG637) -> 71.05712
A42: min(eᵢ) — informational | B42: =MIN('Data Export2 Refine'!AG138:AG1137) -> -82.58957 | C42: =MIN('Data Export2 Refine'!AG388:AG637) -> -21.50965
