Workbook

Sheet ALGLIB_SSA_XAUUSD
A1: timestamp_h1 | B1: symbol_h1 | C1: timeframe_h1 | D1: close_h1 | E1: ssa_h1 | F1: ema_ssa_h1 | G1: ssa_high_h1 | H1: ssa_low_h1 | J1: timestamp_m5 | K1: symbol_m5 | L1: timeframe_m5 | M1: close_m5 | N1: ssa_m5 | O1: ema_ssa_m5 | P1: ssa_high_m5 | Q1: ssa_low_m5
A2: 1770285600 | B2: XAUUSD | C2: H1 | D2: 4868.29 | E2: 4838.3861 | F2: 4838.3861 | G2: 4865.928 | H2: 4801.8571 | J2: 1775127600 | K2: XAUUSD | L2: M5 | M2: 4626.58 | N2: 4627.2149 | O2: 4627.2149 | P2: 4628.9427 | Q2: 4622.0951
A3: 1770289200 | B3: XAUUSD | C3: H1 | D3: 4853.79 | E3: 4842.5979 | F3: 4840.492 | G3: 4870.1466 | H3: 4799.0653 | J3: 1775127900 | K3: XAUUSD | L3: M5 | M3: 4625.78 | N3: 4627.1536 | O3: 4627.1842 | P3: 4629.7389 | Q3: 4623.56
A4: 1770292800 | B4: XAUUSD | C4: H1 | D4: 4835.36 | E4: 4850.9081 | F4: 4845.7001 | G4: 4878.4281 | H4: 4808.7922 | J4: 1775128200 | K4: XAUUSD | L4: M5 | M4: 4627.5 | N4: 4626.4943 | O4: 4626.8393 | P4: 4630.0633 | Q4: 4623.5508
A5: 1770296400 | B5: XAUUSD | C5: H1 | D5: 4846.26 | E5: 4860.5814 | F5: 4853.1407 | G5: 4887.4499 | H5: 4823.4157 | J5: 1775128500 | K5: XAUUSD | L5: M5 | M5: 4624.55 | N5: 4624.5197 | O5: 4625.6795 | P5: 4629.3205 | Q5: 4622.127
A6: 1770300000 | B6: XAUUSD | C6: H1 | D6: 4818.33 | E6: 4865.6855 | F6: 4859.4131 | G6: 4893.051 | H6: 4836.3314 | J6: 1775128800 | K6: XAUUSD | L6: M5 | M6: 4625.56 | N6: 4621.2593 | O6: 4623.4694 | P6: 4627.1789 | Q6: 4619.3456
A7: 1770303600 | B7: XAUUSD | C7: H1 | D7: 4888.86 | E7: 4865.2815 | F7: 4862.3473 | G7: 4892.5267 | H7: 4843.0972 | J7: 1775129100 | K7: XAUUSD | L7: M5 | M7: 4614.98 | N7: 4616.8745 | O7: 4620.172 | P7: 4623.8187 | Q7: 4615.1334
A8: 1770307200 | B8: XAUUSD | C8: H1 | D8: 4868.94 | E8: 4853.9564 | F8: 4858.1518 | G8: 4883.0128 | H8: 4839.5011 | J8: 1775129400 | K8: XAUUSD | L8: M5 | M8: 4613.45 | N8: 4612.3584 | O8: 4616.2652 | P8: 4619.472 | Q8: 4610.3074
A9: 1770310800 | B9: XAUUSD | C9: H1 | D9: 4857.99 | E9: 4835.6818 | F9: 4846.9168 | G9: 4867.2408 | H9: 4823.2271 | J9: 1775129700 | K9: XAUUSD | L9: M5 | M9: 4608.84 | N9: 4608.057 | O9: 4612.1611 | P9: 4615.3228 | Q9: 4605.4399
A10: 1770314400 | B10: XAUUSD | C10: H1 | D10: 4829.42 | E10: 4813.8638 | F10: 4830.3903 | G10: 4848.5111 | H10: 4797.9059 | J10: 1775130000 | K10: XAUUSD | L10: M5 | M10: 4600.1 | N10: 4604.4893 | O10: 4608.3252 | P10: 4611.6118 | Q10: 4600.863
A11: 1770318000 | B11: XAUUSD | C11: H1 | D11: 4811.43 | E11: 4793.1035 | F11: 4811.7469 | G11: 4829.8837 | H11: 4769.1734 | J11: 1775130300 | K11: XAUUSD | L11: M5 | M11: 4604.26 | N11: 4602.3008 | O11: 4605.313 | P11: 4608.9235 | Q11: 4597.6154
A12: 1770321600 | B12: XAUUSD | C12: H1 | D12: 4779.67 | E12: 4777.1719 | F12: 4794.4594 | G12: 4814.8349 | H12: 4743.1615 | J12: 1775130600 | K12: XAUUSD | L12: M5 | M12: 4601.44 | N12: 4601.4458 | O12: 4603.3794 | P12: 4607.53 | Q12: 4595.8358
A13: 1770328800 | B13: XAUUSD | C13: H1 | D13: 4703.8 | E13: 4769.2476 | F13: 4781.8535 | G13: 4805.7536 | H13: 4725.2752 | J13: 1775130900 | K13: XAUUSD | L13: M5 | M13: 4600.2 | N13: 4602.115 | O13: 4602.7472 | P13: 4607.235 | Q13: 4595.5989
... A1001: 1775700000 | B1001: XAUUSD | C1001: H1 | D1001: 4725.08 | E1001: 4729.8585 | F1001: 4726.2104 | G1001: 4731.5689 | H1001: 4714.4966 | J1001: 1775700900 | K1001: XAUUSD | L1001: M5 | M1001: 4724.33 | N1001: 4723.4584 | O1001: 4723.57 | P1001: 4725.72 | Q1001: 4722.0739

Sheet Mapped_H1_M5_Interporate
A1: timestamp_m5 | B1: symbol_h1 | C1: timeframe_h1 | D1: close_h1 | E1: ssa_h1 | F1: ema_ssa_h1 | G1: ssa_high_h1 | H1: ssa_low_h1 | I1: symbol_m5 | J1: timeframe_m5 | K1: close_m5 | L1: ssa_m5 | M1: ema_ssa_m5 | N1: ssa_high_m5 | O1: ssa_low_m5 | R1: timestamp | S1: symbol | T1: timeframe | U1: close | V1: ssa_m5_interpolation | W1: ema_ssa_m5_interpolation | X1: ssa_m5 | Y1: ema_ssa_m5 | Z1: ssa_high_m5_interpolation | AA1: ssa_high_m5 | AB1: ssa_low_m5_interpolation | AC1: ssa_low_m5 | AF1: =X1 -> ssa_m5 | AG1: =Z1 -> ssa_high_m5_interpolation | AH1: =AB1 -> ssa_low_m5_interpolation
A2: =ALGLIB_SSA_XAUUSD!J2 -> 1775127600 | B2: =_xlfn.XLOOKUP($A2,ALGLIB_SSA_XAUUSD!$A$2:$A$1000,ALGLIB_SSA_XAUUSD!$B$2:$B$1000,"",0) -> XAUUSD | C2: =_xlfn.XLOOKUP($A2,ALGLIB_SSA_XAUUSD!$A$2:$A$1000,ALGLIB_SSA_XAUUSD!$C$2:$C$1000,"",0) -> H1 | D2: =_xlfn.XLOOKUP($A2,ALGLIB_SSA_XAUUSD!$A$2:$A$1000,ALGLIB_SSA_XAUUSD!$D$2:$D$1000,"",0) -> 4600.2 | E2: =_xlfn.XLOOKUP($A2,ALGLIB_SSA_XAUUSD!$A$2:$A$1000,ALGLIB_SSA_XAUUSD!$E$2:$E$1000,"",0) -> 4619.8464 | F2: =_xlfn.XLOOKUP($A2,ALGLIB_SSA_XAUUSD!$A$2:$A$1000,ALGLIB_SSA_XAUUSD!$F$2:$F$1000,"",0) -> 4616.0957 | G2: =_xlfn.XLOOKUP($A2,ALGLIB_SSA_XAUUSD!$A$2:$A$1000,ALGLIB_SSA_XAUUSD!$G$2:$G$1000,"",0) -> 4639.0441 | H2: =_xlfn.XLOOKUP($A2,ALGLIB_SSA_XAUUSD!$A$2:$A$1000,ALGLIB_SSA_XAUUSD!$H$2:$H$1000,"",0) -> 4598.7185 | I2: =_xlfn.XLOOKUP($A2,ALGLIB_SSA_XAUUSD!$J$2:$J$1000,ALGLIB_SSA_XAUUSD!$K$2:$K$1000,"",0) -> XAUUSD | J2: =_xlfn.XLOOKUP($A2,ALGLIB_SSA_XAUUSD!$J$2:$J$1000,ALGLIB_SSA_XAUUSD!$L$2:$L$1000,"",0) -> M5 | K2: =_xlfn.XLOOKUP($A2,ALGLIB_SSA_XAUUSD!$J$2:$J$1000,ALGLIB_SSA_XAUUSD!$M$2:$M$1000,"",0) -> 4626.58 | L2: =_xlfn.XLOOKUP($A2,ALGLIB_SSA_XAUUSD!$J$2:$J$1000,ALGLIB_SSA_XAUUSD!$N$2:$N$1000,"",0) -> 4627.2149 | M2: =_xlfn.XLOOKUP($A2,ALGLIB_SSA_XAUUSD!$J$2:$J$1000,ALGLIB_SSA_XAUUSD!$O$2:$O$1000,"",0) -> 4627.2149 | N2: =_xlfn.XLOOKUP($A2,ALGLIB_SSA_XAUUSD!$J$2:$J$1000,ALGLIB_SSA_XAUUSD!$P$2:$P$1000,"",0) -> 4628.9427 | O2: =_xlfn.XLOOKUP($A2,ALGLIB_SSA_XAUUSD!$J$2:$J$1000,ALGLIB_SSA_XAUUSD!$Q$2:$Q$1000,"",0) -> 4622.0951 | R2: =A2 -> 1775127600 | S2: =I2 -> XAUUSD | T2: =J2 -> M5 | U2: =K2 -> 4626.58 | V2: =E2 -> 4619.8464 | W2: =F2 -> 4616.0957 | X2: =L2 -> 4627.2149 | Y2: =M2 -> 4627.2149 | Z2: =G2 -> 4639.0441 | AA2: =N2 -> 4628.9427 | AB2: =H2 -> 4598.7185 | AC2: =O2 -> 4622.0951 | AF2: =X2 -> 4627.2149 | AG2: =Z2 -> 4639.0441 | AH2: =AB2 -> 4598.7185
A3: =ALGLIB_SSA_XAUUSD!J3 -> 1775127900 | B3: =_xlfn.XLOOKUP($A3,ALGLIB_SSA_XAUUSD!$A$2:$A$1000,ALGLIB_SSA_XAUUSD!$B$2:$B$1000,"",0) | C3: =_xlfn.XLOOKUP($A3,ALGLIB_SSA_XAUUSD!$A$2:$A$1000,ALGLIB_SSA_XAUUSD!$C$2:$C$1000,"",0) | D3: =D2+(D14-D2)*1/12 -> 4600.3075 | E3: =E2+(E14-E2)*1/12 -> 4620.7067 | F3: =F2+(F14-F2)*1/12 -> 4616.6821 | G3: =G2+(G14-G2)*1/12 -> 4639.8649 | H3: =H2+(H14-H2)*1/12 -> 4599.3722 | I3: =_xlfn.XLOOKUP($A3,ALGLIB_SSA_XAUUSD!$J$2:$J$1000,ALGLIB_SSA_XAUUSD!$K$2:$K$1000,"",0) -> XAUUSD | J3: =_xlfn.XLOOKUP($A3,ALGLIB_SSA_XAUUSD!$J$2:$J$1000,ALGLIB_SSA_XAUUSD!$L$2:$L$1000,"",0) -> M5 | K3: =_xlfn.XLOOKUP($A3,ALGLIB_SSA_XAUUSD!$J$2:$J$1000,ALGLIB_SSA_XAUUSD!$M$2:$M$1000,"",0) -> 4625.78 | L3: =_xlfn.XLOOKUP($A3,ALGLIB_SSA_XAUUSD!$J$2:$J$1000,ALGLIB_SSA_XAUUSD!$N$2:$N$1000,"",0) -> 4627.1536 | M3: =_xlfn.XLOOKUP($A3,ALGLIB_SSA_XAUUSD!$J$2:$J$1000,ALGLIB_SSA_XAUUSD!$O$2:$O$1000,"",0) -> 4627.1842 | N3: =_xlfn.XLOOKUP($A3,ALGLIB_SSA_XAUUSD!$J$2:$J$1000,ALGLIB_SSA_XAUUSD!$P$2:$P$1000,"",0) -> 4629.7389 | O3: =_xlfn.XLOOKUP($A3,ALGLIB_SSA_XAUUSD!$J$2:$J$1000,ALGLIB_SSA_XAUUSD!$Q$2:$Q$1000,"",0) -> 4623.56 | R3: =A3 -> 1775127900 | S3: =I3 -> XAUUSD | T3: =J3 -> M5 | U3: =K3 -> 4625.78 | V3: 4620.7067 | W3: 4616.6821 | X3: 4627.1536 | Y3: 4627.1842 | Z3: =G3 -> 4639.8649 | AA3: =N3 -> 4629.7389 | AB3: =H3 -> 4599.3722 | AC3: =O3 -> 4623.56 | AF3: =X3 -> 4627.1536 | AG3: =Z3 -> 4639.8649 | AH3: =AB3 -> 4599.3722
A4: =ALGLIB_SSA_XAUUSD!J4 -> 1775128200 | B4: =_xlfn.XLOOKUP($A4,ALGLIB_SSA_XAUUSD!$A$2:$A$1000,ALGLIB_SSA_XAUUSD!$B$2:$B$1000,"",0) | C4: =_xlfn.XLOOKUP($A4,ALGLIB_SSA_XAUUSD!$A$2:$A$1000,ALGLIB_SSA_XAUUSD!$C$2:$C$1000,"",0) | D4: =D2+(D14-D2)*2/12 -> 4600.415 | E4: =E2+(E14-E2)*2/12 -> 4621.567 | F4: =F2+(F14-F2)*2/12 -> 4617.2685 | G4: =G2+(G14-G2)*2/12 -> 4640.6856 | H4: =H2+(H14-H2)*2/12 -> 4600.026 | I4: =_xlfn.XLOOKUP($A4,ALGLIB_SSA_XAUUSD!$J$2:$J$1000,ALGLIB_SSA_XAUUSD!$K$2:$K$1000,"",0) -> XAUUSD | J4: =_xlfn.XLOOKUP($A4,ALGLIB_SSA_XAUUSD!$J$2:$J$1000,ALGLIB_SSA_XAUUSD!$L$2:$L$1000,"",0) -> M5 | K4: =_xlfn.XLOOKUP($A4,ALGLIB_SSA_XAUUSD!$J$2:$J$1000,ALGLIB_SSA_XAUUSD!$M$2:$M$1000,"",0) -> 4627.5 | L4: =_xlfn.XLOOKUP($A4,ALGLIB_SSA_XAUUSD!$J$2:$J$1000,ALGLIB_SSA_XAUUSD!$N$2:$N$1000,"",0) -> 4626.4943 | M4: =_xlfn.XLOOKUP($A4,ALGLIB_SSA_XAUUSD!$J$2:$J$1000,ALGLIB_SSA_XAUUSD!$O$2:$O$1000,"",0) -> 4626.8393 | N4: =_xlfn.XLOOKUP($A4,ALGLIB_SSA_XAUUSD!$J$2:$J$1000,ALGLIB_SSA_XAUUSD!$P$2:$P$1000,"",0) -> 4630.0633 | O4: =_xlfn.XLOOKUP($A4,ALGLIB_SSA_XAUUSD!$J$2:$J$1000,ALGLIB_SSA_XAUUSD!$Q$2:$Q$1000,"",0) -> 4623.5508 | R4: =A4 -> 1775128200 | S4: =I4 -> XAUUSD | T4: =J4 -> M5 | U4: =K4 -> 4627.5 | V4: 4621.567 | W4: 4617.2685 | X4: 4626.4943 | Y4: 4626.8393 | Z4: =G4 -> 4640.6856 | AA4: =N4 -> 4630.0633 | AB4: =H4 -> 4600.026 | AC4: =O4 -> 4623.5508 | AF4: =X4 -> 4626.4943 | AG4: =Z4 -> 4640.6856 | AH4: =AB4 -> 4600.026
A5: =ALGLIB_SSA_XAUUSD!J5 -> 1775128500 | B5: =_xlfn.XLOOKUP($A5,ALGLIB_SSA_XAUUSD!$A$2:$A$1000,ALGLIB_SSA_XAUUSD!$B$2:$B$1000,"",0) | C5: =_xlfn.XLOOKUP($A5,ALGLIB_SSA_XAUUSD!$A$2:$A$1000,ALGLIB_SSA_XAUUSD!$C$2:$C$1000,"",0) | D5: =D2+(D14-D2)*3/12 -> 4600.5225 | E5: =E2+(E14-E2)*3/12 -> 4622.4273 | F5: =F2+(F14-F2)*3/12 -> 4617.8549 | G5: =G2+(G14-G2)*3/12 -> 4641.5064 | H5: =H2+(H14-H2)*3/12 -> 4600.6798 | I5: =_xlfn.XLOOKUP($A5,ALGLIB_SSA_XAUUSD!$J$2:$J$1000,ALGLIB_SSA_XAUUSD!$K$2:$K$1000,"",0) -> XAUUSD | J5: =_xlfn.XLOOKUP($A5,ALGLIB_SSA_XAUUSD!$J$2:$J$1000,ALGLIB_SSA_XAUUSD!$L$2:$L$1000,"",0) -> M5 | K5: =_xlfn.XLOOKUP($A5,ALGLIB_SSA_XAUUSD!$J$2:$J$1000,ALGLIB_SSA_XAUUSD!$M$2:$M$1000,"",0) -> 4624.55 | L5: =_xlfn.XLOOKUP($A5,ALGLIB_SSA_XAUUSD!$J$2:$J$1000,ALGLIB_SSA_XAUUSD!$N$2:$N$1000,"",0) -> 4624.5197 | M5: =_xlfn.XLOOKUP($A5,ALGLIB_SSA_XAUUSD!$J$2:$J$1000,ALGLIB_SSA_XAUUSD!$O$2:$O$1000,"",0) -> 4625.6795 | N5: =_xlfn.XLOOKUP($A5,ALGLIB_SSA_XAUUSD!$J$2:$J$1000,ALGLIB_SSA_XAUUSD!$P$2:$P$1000,"",0) -> 4629.3205 | O5: =_xlfn.XLOOKUP($A5,ALGLIB_SSA_XAUUSD!$J$2:$J$1000,ALGLIB_SSA_XAUUSD!$Q$2:$Q$1000,"",0) -> 4622.127 | R5: =A5 -> 1775128500 | S5: =I5 -> XAUUSD | T5: =J5 -> M5 | U5: =K5 -> 4624.55 | V5: 4622.4273 | W5: 4617.8549 | X5: 4624.5197 | Y5: 4625.6795 | Z5: =G5 -> 4641.5064 | AA5: =N5 -> 4629.3205 | AB5: =H5 -> 4600.6798 | AC5: =O5 -> 4622.127 | AF5: =X5 -> 4624.5197 | AG5: =Z5 -> 4641.5064 | AH5: =AB5 -> 4600.6798
A6: =ALGLIB_SSA_XAUUSD!J6 -> 1775128800 | B6: =_xlfn.XLOOKUP($A6,ALGLIB_SSA_XAUUSD!$A$2:$A$1000,ALGLIB_SSA_XAUUSD!$B$2:$B$1000,"",0) | C6: =_xlfn.XLOOKUP($A6,ALGLIB_SSA_XAUUSD!$A$2:$A$1000,ALGLIB_SSA_XAUUSD!$C$2:$C$1000,"",0) | D6: =D2+(D14-D2)*4/12 -> 4600.63 | E6: =E2+(E14-E2)*4/12 -> 4623.2875 | F6: =F2+(F14-F2)*4/12 -> 4618.4414 | G6: =G2+(G14-G2)*4/12 -> 4642.3272 | H6: =H2+(H14-H2)*4/12 -> 4601.3336 | I6: =_xlfn.XLOOKUP($A6,ALGLIB_SSA_XAUUSD!$J$2:$J$1000,ALGLIB_SSA_XAUUSD!$K$2:$K$1000,"",0) -> XAUUSD | J6: =_xlfn.XLOOKUP($A6,ALGLIB_SSA_XAUUSD!$J$2:$J$1000,ALGLIB_SSA_XAUUSD!$L$2:$L$1000,"",0) -> M5 | K6: =_xlfn.XLOOKUP($A6,ALGLIB_SSA_XAUUSD!$J$2:$J$1000,ALGLIB_SSA_XAUUSD!$M$2:$M$1000,"",0) -> 4625.56 | L6: =_xlfn.XLOOKUP($A6,ALGLIB_SSA_XAUUSD!$J$2:$J$1000,ALGLIB_SSA_XAUUSD!$N$2:$N$1000,"",0) -> 4621.2593 | M6: =_xlfn.XLOOKUP($A6,ALGLIB_SSA_XAUUSD!$J$2:$J$1000,ALGLIB_SSA_XAUUSD!$O$2:$O$1000,"",0) -> 4623.4694 | N6: =_xlfn.XLOOKUP($A6,ALGLIB_SSA_XAUUSD!$J$2:$J$1000,ALGLIB_SSA_XAUUSD!$P$2:$P$1000,"",0) -> 4627.1789 | O6: =_xlfn.XLOOKUP($A6,ALGLIB_SSA_XAUUSD!$J$2:$J$1000,ALGLIB_SSA_XAUUSD!$Q$2:$Q$1000,"",0) -> 4619.3456 | R6: =A6 -> 1775128800 | S6: =I6 -> XAUUSD | T6: =J6 -> M5 | U6: =K6 -> 4625.56 | V6: 4623.2876 | W6: 4618.4414 | X6: 4621.2593 | Y6: 4623.4694 | Z6: =G6 -> 4642.3272 | AA6: =N6 -> 4627.1789 | AB6: =H6 -> 4601.3336 | AC6: =O6 -> 4619.3456 | AF6: =X6 -> 4621.2593 | AG6: =Z6 -> 4642.3272 | AH6: =AB6 -> 4601.3336
A7: =ALGLIB_SSA_XAUUSD!J7 -> 1775129100 | B7: =_xlfn.XLOOKUP($A7,ALGLIB_SSA_XAUUSD!$A$2:$A$1000,ALGLIB_SSA_XAUUSD!$B$2:$B$1000,"",0) | C7: =_xlfn.XLOOKUP($A7,ALGLIB_SSA_XAUUSD!$A$2:$A$1000,ALGLIB_SSA_XAUUSD!$C$2:$C$1000,"",0) | D7: =D2+(D14-D2)*5/12 -> 4600.7375 | E7: =E2+(E14-E2)*5/12 -> 4624.1478 | F7: =F2+(F14-F2)*5/12 -> 4619.0278 | G7: =G2+(G14-G2)*5/12 -> 4643.1479 | H7: =H2+(H14-H2)*5/12 -> 4601.9874 | I7: =_xlfn.XLOOKUP($A7,ALGLIB_SSA_XAUUSD!$J$2:$J$1000,ALGLIB_SSA_XAUUSD!$K$2:$K$1000,"",0) -> XAUUSD | J7: =_xlfn.XLOOKUP($A7,ALGLIB_SSA_XAUUSD!$J$2:$J$1000,ALGLIB_SSA_XAUUSD!$L$2:$L$1000,"",0) -> M5 | K7: =_xlfn.XLOOKUP($A7,ALGLIB_SSA_XAUUSD!$J$2:$J$1000,ALGLIB_SSA_XAUUSD!$M$2:$M$1000,"",0) -> 4614.98 | L7: =_xlfn.XLOOKUP($A7,ALGLIB_SSA_XAUUSD!$J$2:$J$1000,ALGLIB_SSA_XAUUSD!$N$2:$N$1000,"",0) -> 4616.8745 | M7: =_xlfn.XLOOKUP($A7,ALGLIB_SSA_XAUUSD!$J$2:$J$1000,ALGLIB_SSA_XAUUSD!$O$2:$O$1000,"",0) -> 4620.172 | N7: =_xlfn.XLOOKUP($A7,ALGLIB_SSA_XAUUSD!$J$2:$J$1000,ALGLIB_SSA_XAUUSD!$P$2:$P$1000,"",0) -> 4623.8187 | O7: =_xlfn.XLOOKUP($A7,ALGLIB_SSA_XAUUSD!$J$2:$J$1000,ALGLIB_SSA_XAUUSD!$Q$2:$Q$1000,"",0) -> 4615.1334 | R7: =A7 -> 1775129100 | S7: =I7 -> XAUUSD | T7: =J7 -> M5 | U7: =K7 -> 4614.98 | V7: 4624.1478 | W7: 4619.0278 | X7: 4616.8745 | Y7: 4620.172 | Z7: =G7 -> 4643.1479 | AA7: =N7 -> 4623.8187 | AB7: =H7 -> 4601.9874 | AC7: =O7 -> 4615.1334 | AF7: =X7 -> 4616.8745 | AG7: =Z7 -> 4643.1479 | AH7: =AB7 -> 4601.9874
A8: =ALGLIB_SSA_XAUUSD!J8 -> 1775129400 | B8: =_xlfn.XLOOKUP($A8,ALGLIB_SSA_XAUUSD!$A$2:$A$1000,ALGLIB_SSA_XAUUSD!$B$2:$B$1000,"",0) | C8: =_xlfn.XLOOKUP($A8,ALGLIB_SSA_XAUUSD!$A$2:$A$1000,ALGLIB_SSA_XAUUSD!$C$2:$C$1000,"",0) | D8: =D2+(D14-D2)*6/12 -> 4600.845 | E8: =E2+(E14-E2)*6/12 -> 4625.0081 | F8: =F2+(F14-F2)*6/12 -> 4619.6142 | G8: =G2+(G14-G2)*6/12 -> 4643.9687 | H8: =H2+(H14-H2)*6/12 -> 4602.6412 | I8: =_xlfn.XLOOKUP($A8,ALGLIB_SSA_XAUUSD!$J$2:$J$1000,ALGLIB_SSA_XAUUSD!$K$2:$K$1000,"",0) -> XAUUSD | J8: =_xlfn.XLOOKUP($A8,ALGLIB_SSA_XAUUSD!$J$2:$J$1000,ALGLIB_SSA_XAUUSD!$L$2:$L$1000,"",0) -> M5 | K8: =_xlfn.XLOOKUP($A8,ALGLIB_SSA_XAUUSD!$J$2:$J$1000,ALGLIB_SSA_XAUUSD!$M$2:$M$1000,"",0) -> 4613.45 | L8: =_xlfn.XLOOKUP($A8,ALGLIB_SSA_XAUUSD!$J$2:$J$1000,ALGLIB_SSA_XAUUSD!$N$2:$N$1000,"",0) -> 4612.3584 | M8: =_xlfn.XLOOKUP($A8,ALGLIB_SSA_XAUUSD!$J$2:$J$1000,ALGLIB_SSA_XAUUSD!$O$2:$O$1000,"",0) -> 4616.2652 | N8: =_xlfn.XLOOKUP($A8,ALGLIB_SSA_XAUUSD!$J$2:$J$1000,ALGLIB_SSA_XAUUSD!$P$2:$P$1000,"",0) -> 4619.472 | O8: =_xlfn.XLOOKUP($A8,ALGLIB_SSA_XAUUSD!$J$2:$J$1000,ALGLIB_SSA_XAUUSD!$Q$2:$Q$1000,"",0) -> 4610.3074 | R8: =A8 -> 1775129400 | S8: =I8 -> XAUUSD | T8: =J8 -> M5 | U8: =K8 -> 4613.45 | V8: 4625.0081 | W8: 4619.6142 | X8: 4612.3584 | Y8: 4616.2652 | Z8: =G8 -> 4643.9687 | AA8: =N8 -> 4619.472 | AB8: =H8 -> 4602.6412 | AC8: =O8 -> 4610.3074 | AF8: =X8 -> 4612.3584 | AG8: =Z8 -> 4643.9687 | AH8: =AB8 -> 4602.6412
A9: =ALGLIB_SSA_XAUUSD!J9 -> 1775129700 | B9: =_xlfn.XLOOKUP($A9,ALGLIB_SSA_XAUUSD!$A$2:$A$1000,ALGLIB_SSA_XAUUSD!$B$2:$B$1000,"",0) | C9: =_xlfn.XLOOKUP($A9,ALGLIB_SSA_XAUUSD!$A$2:$A$1000,ALGLIB_SSA_XAUUSD!$C$2:$C$1000,"",0) | D9: =D2+(D14-D2)*7/12 -> 4600.9525 | E9: =E2+(E14-E2)*7/12 -> 4625.8684 | F9: =F2+(F14-F2)*7/12 -> 4620.2006 | G9: =G2+(G14-G2)*7/12 -> 4644.7894 | H9: =H2+(H14-H2)*7/12 -> 4603.295 | I9: =_xlfn.XLOOKUP($A9,ALGLIB_SSA_XAUUSD!$J$2:$J$1000,ALGLIB_SSA_XAUUSD!$K$2:$K$1000,"",0) -> XAUUSD | J9: =_xlfn.XLOOKUP($A9,ALGLIB_SSA_XAUUSD!$J$2:$J$1000,ALGLIB_SSA_XAUUSD!$L$2:$L$1000,"",0) -> M5 | K9: =_xlfn.XLOOKUP($A9,ALGLIB_SSA_XAUUSD!$J$2:$J$1000,ALGLIB_SSA_XAUUSD!$M$2:$M$1000,"",0) -> 4608.84 | L9: =_xlfn.XLOOKUP($A9,ALGLIB_SSA_XAUUSD!$J$2:$J$1000,ALGLIB_SSA_XAUUSD!$N$2:$N$1000,"",0) -> 4608.057 | M9: =_xlfn.XLOOKUP($A9,ALGLIB_SSA_XAUUSD!$J$2:$J$1000,ALGLIB_SSA_XAUUSD!$O$2:$O$1000,"",0) -> 4612.1611 | N9: =_xlfn.XLOOKUP($A9,ALGLIB_SSA_XAUUSD!$J$2:$J$1000,ALGLIB_SSA_XAUUSD!$P$2:$P$1000,"",0) -> 4615.3228 | O9: =_xlfn.XLOOKUP($A9,ALGLIB_SSA_XAUUSD!$J$2:$J$1000,ALGLIB_SSA_XAUUSD!$Q$2:$Q$1000,"",0) -> 4605.4399 | R9: =A9 -> 1775129700 | S9: =I9 -> XAUUSD | T9: =J9 -> M5 | U9: =K9 -> 4608.84 | V9: 4625.8684 | W9: 4620.2006 | X9: 4608.057 | Y9: 4612.1611 | Z9: =G9 -> 4644.7894 | AA9: =N9 -> 4615.3228 | AB9: =H9 -> 4603.295 | AC9: =O9 -> 4605.4399 | AF9: =X9 -> 4608.057 | AG9: =Z9 -> 4644.7894 | AH9: =AB9 -> 4603.295
A10: =ALGLIB_SSA_XAUUSD!J10 -> 1775130000 | B10: =_xlfn.XLOOKUP($A10,ALGLIB_SSA_XAUUSD!$A$2:$A$1000,ALGLIB_SSA_XAUUSD!$B$2:$B$1000,"",0) | C10: =_xlfn.XLOOKUP($A10,ALGLIB_SSA_XAUUSD!$A$2:$A$1000,ALGLIB_SSA_XAUUSD!$C$2:$C$1000,"",0) | D10: =D2+(D14-D2)*8/12 -> 4601.06 | E10: =E2+(E14-E2)*8/12 -> 4626.7287 | F10: =F2+(F14-F2)*8/12 -> 4620.787 | G10: =G2+(G14-G2)*8/12 -> 4645.6102 | H10: =H2+(H14-H2)*8/12 -> 4603.9488 | I10: =_xlfn.XLOOKUP($A10,ALGLIB_SSA_XAUUSD!$J$2:$J$1000,ALGLIB_SSA_XAUUSD!$K$2:$K$1000,"",0) -> XAUUSD | J10: =_xlfn.XLOOKUP($A10,ALGLIB_SSA_XAUUSD!$J$2:$J$1000,ALGLIB_SSA_XAUUSD!$L$2:$L$1000,"",0) -> M5 | K10: =_xlfn.XLOOKUP($A10,ALGLIB_SSA_XAUUSD!$J$2:$J$1000,ALGLIB_SSA_XAUUSD!$M$2:$M$1000,"",0) -> 4600.1 | L10: =_xlfn.XLOOKUP($A10,ALGLIB_SSA_XAUUSD!$J$2:$J$1000,ALGLIB_SSA_XAUUSD!$N$2:$N$1000,"",0) -> 4604.4893 | M10: =_xlfn.XLOOKUP($A10,ALGLIB_SSA_XAUUSD!$J$2:$J$1000,ALGLIB_SSA_XAUUSD!$O$2:$O$1000,"",0) -> 4608.3252 | N10: =_xlfn.XLOOKUP($A10,ALGLIB_SSA_XAUUSD!$J$2:$J$1000,ALGLIB_SSA_XAUUSD!$P$2:$P$1000,"",0) -> 4611.6118 | O10: =_xlfn.XLOOKUP($A10,ALGLIB_SSA_XAUUSD!$J$2:$J$1000,ALGLIB_SSA_XAUUSD!$Q$2:$Q$1000,"",0) -> 4600.863 | R10: =A10 -> 1775130000 | S10: =I10 -> XAUUSD | T10: =J10 -> M5 | U10: =K10 -> 4600.1 | V10: 4626.7287 | W10: 4620.787 | X10: 4604.4893 | Y10: 4608.3252 | Z10: =G10 -> 4645.6102 | AA10: =N10 -> 4611.6118 | AB10: =H10 -> 4603.9488 | AC10: =O10 -> 4600.863 | AF10: =X10 -> 4604.4893 | AG10: =Z10 -> 4645.6102 | AH10: =AB10 -> 4603.9488
A11: =ALGLIB_SSA_XAUUSD!J11 -> 1775130300 | B11: =_xlfn.XLOOKUP($A11,ALGLIB_SSA_XAUUSD!$A$2:$A$1000,ALGLIB_SSA_XAUUSD!$B$2:$B$1000,"",0) | C11: =_xlfn.XLOOKUP($A11,ALGLIB_SSA_XAUUSD!$A$2:$A$1000,ALGLIB_SSA_XAUUSD!$C$2:$C$1000,"",0) | D11: =D2+(D14-D2)*9/12 -> 4601.1675 | E11: =E2+(E14-E2)*9/12 -> 4627.5889 | F11: =F2+(F14-F2)*9/12 -> 4621.3735 | G11: =G2+(G14-G2)*9/12 -> 4646.431 | H11: =H2+(H14-H2)*9/12 -> 4604.6025 | I11: =_xlfn.XLOOKUP($A11,ALGLIB_SSA_XAUUSD!$J$2:$J$1000,ALGLIB_SSA_XAUUSD!$K$2:$K$1000,"",0) -> XAUUSD | J11: =_xlfn.XLOOKUP($A11,ALGLIB_SSA_XAUUSD!$J$2:$J$1000,ALGLIB_SSA_XAUUSD!$L$2:$L$1000,"",0) -> M5 | K11: =_xlfn.XLOOKUP($A11,ALGLIB_SSA_XAUUSD!$J$2:$J$1000,ALGLIB_SSA_XAUUSD!$M$2:$M$1000,"",0) -> 4604.26 | L11: =_xlfn.XLOOKUP($A11,ALGLIB_SSA_XAUUSD!$J$2:$J$1000,ALGLIB_SSA_XAUUSD!$N$2:$N$1000,"",0) -> 4602.3008 | M11: =_xlfn.XLOOKUP($A11,ALGLIB_SSA_XAUUSD!$J$2:$J$1000,ALGLIB_SSA_XAUUSD!$O$2:$O$1000,"",0) -> 4605.313 | N11: =_xlfn.XLOOKUP($A11,ALGLIB_SSA_XAUUSD!$J$2:$J$1000,ALGLIB_SSA_XAUUSD!$P$2:$P$1000,"",0) -> 4608.9235 | O11: =_xlfn.XLOOKUP($A11,ALGLIB_SSA_XAUUSD!$J$2:$J$1000,ALGLIB_SSA_XAUUSD!$Q$2:$Q$1000,"",0) -> 4597.6154 | R11: =A11 -> 1775130300 | S11: =I11 -> XAUUSD | T11: =J11 -> M5 | U11: =K11 -> 4604.26 | V11: 4627.5889 | W11: 4621.3735 | X11: 4602.3008 | Y11: 4605.313 | Z11: =G11 -> 4646.431 | AA11: =N11 -> 4608.9235 | AB11: =H11 -> 4604.6025 | AC11: =O11 -> 4597.6154 | AF11: =X11 -> 4602.3008 | AG11: =Z11 -> 4646.431 | AH11: =AB11 -> 4604.6025
A12: =ALGLIB_SSA_XAUUSD!J12 -> 1775130600 | B12: =_xlfn.XLOOKUP($A12,ALGLIB_SSA_XAUUSD!$A$2:$A$1000,ALGLIB_SSA_XAUUSD!$B$2:$B$1000,"",0) | C12: =_xlfn.XLOOKUP($A12,ALGLIB_SSA_XAUUSD!$A$2:$A$1000,ALGLIB_SSA_XAUUSD!$C$2:$C$1000,"",0) | D12: =D2+(D14-D2)*10/12 -> 4601.275 | E12: =E2+(E14-E2)*10/12 -> 4628.4492 | F12: =F2+(F14-F2)*10/12 -> 4621.9599 | G12: =G2+(G14-G2)*10/12 -> 4647.2517 | H12: =H2+(H14-H2)*10/12 -> 4605.2563 | I12: =_xlfn.XLOOKUP($A12,ALGLIB_SSA_XAUUSD!$J$2:$J$1000,ALGLIB_SSA_XAUUSD!$K$2:$K$1000,"",0) -> XAUUSD | J12: =_xlfn.XLOOKUP($A12,ALGLIB_SSA_XAUUSD!$J$2:$J$1000,ALGLIB_SSA_XAUUSD!$L$2:$L$1000,"",0) -> M5 | K12: =_xlfn.XLOOKUP($A12,ALGLIB_SSA_XAUUSD!$J$2:$J$1000,ALGLIB_SSA_XAUUSD!$M$2:$M$1000,"",0) -> 4601.44 | L12: =_xlfn.XLOOKUP($A12,ALGLIB_SSA_XAUUSD!$J$2:$J$1000,ALGLIB_SSA_XAUUSD!$N$2:$N$1000,"",0) -> 4601.4458 | M12: =_xlfn.XLOOKUP($A12,ALGLIB_SSA_XAUUSD!$J$2:$J$1000,ALGLIB_SSA_XAUUSD!$O$2:$O$1000,"",0) -> 4603.3794 | N12: =_xlfn.XLOOKUP($A12,ALGLIB_SSA_XAUUSD!$J$2:$J$1000,ALGLIB_SSA_XAUUSD!$P$2:$P$1000,"",0) -> 4607.53 | O12: =_xlfn.XLOOKUP($A12,ALGLIB_SSA_XAUUSD!$J$2:$J$1000,ALGLIB_SSA_XAUUSD!$Q$2:$Q$1000,"",0) -> 4595.8358 | R12: =A12 -> 1775130600 | S12: =I12 -> XAUUSD | T12: =J12 -> M5 | U12: =K12 -> 4601.44 | V12: 4628.4492 | W12: 4621.9599 | X12: 4601.4458 | Y12: 4603.3794 | Z12: =G12 -> 4647.2517 | AA12: =N12 -> 4607.53 | AB12: =H12 -> 4605.2563 | AC12: =O12 -> 4595.8358 | AF12: =X12 -> 4601.4458 | AG12: =Z12 -> 4647.2517 | AH12: =AB12 -> 4605.2563
A13: =ALGLIB_SSA_XAUUSD!J13 -> 1775130900 | B13: =_xlfn.XLOOKUP($A13,ALGLIB_SSA_XAUUSD!$A$2:$A$1000,ALGLIB_SSA_XAUUSD!$B$2:$B$1000,"",0) | C13: =_xlfn.XLOOKUP($A13,ALGLIB_SSA_XAUUSD!$A$2:$A$1000,ALGLIB_SSA_XAUUSD!$C$2:$C$1000,"",0) | D13: =D2+(D14-D2)*11/12 -> 4601.3825 | E13: =E2+(E14-E2)*11/12 -> 4629.3095 | F13: =F2+(F14-F2)*11/12 -> 4622.5463 | G13: =G2+(G14-G2)*11/12 -> 4648.0725 | H13: =H2+(H14-H2)*11/12 -> 4605.9101 | I13: =_xlfn.XLOOKUP($A13,ALGLIB_SSA_XAUUSD!$J$2:$J$1000,ALGLIB_SSA_XAUUSD!$K$2:$K$1000,"",0) -> XAUUSD | J13: =_xlfn.XLOOKUP($A13,ALGLIB_SSA_XAUUSD!$J$2:$J$1000,ALGLIB_SSA_XAUUSD!$L$2:$L$1000,"",0) -> M5 | K13: =_xlfn.XLOOKUP($A13,ALGLIB_SSA_XAUUSD!$J$2:$J$1000,ALGLIB_SSA_XAUUSD!$M$2:$M$1000,"",0) -> 4600.2 | L13: =_xlfn.XLOOKUP($A13,ALGLIB_SSA_XAUUSD!$J$2:$J$1000,ALGLIB_SSA_XAUUSD!$N$2:$N$1000,"",0) -> 4602.115 | M13: =_xlfn.XLOOKUP($A13,ALGLIB_SSA_XAUUSD!$J$2:$J$1000,ALGLIB_SSA_XAUUSD!$O$2:$O$1000,"",0) -> 4602.7472 | N13: =_xlfn.XLOOKUP($A13,ALGLIB_SSA_XAUUSD!$J$2:$J$1000,ALGLIB_SSA_XAUUSD!$P$2:$P$1000,"",0) -> 4607.235 | O13: =_xlfn.XLOOKUP($A13,ALGLIB_SSA_XAUUSD!$J$2:$J$1000,ALGLIB_SSA_XAUUSD!$Q$2:$Q$1000,"",0) -> 4595.5989 | R13: =A13 -> 1775130900 | S13: =I13 -> XAUUSD | T13: =J13 -> M5 | U13: =K13 -> 4600.2 | V13: 4629.3095 | W13: 4622.5463 | X13: 4602.115 | Y13: 4602.7472 | Z13: =G13 -> 4648.0725 | AA13: =N13 -> 4607.235 | AB13: =H13 -> 4605.9101 | AC13: =O13 -> 4595.5989 | AF13: =X13 -> 4602.115 | AG13: =Z13 -> 4648.0725 | AH13: =AB13 -> 4605.9101
A14: =ALGLIB_SSA_XAUUSD!J14 -> 1775131200 | B14: =_xlfn.XLOOKUP($A14,ALGLIB_SSA_XAUUSD!$A$2:$A$1000,ALGLIB_SSA_XAUUSD!$B$2:$B$1000,"",0) -> XAUUSD | C14: =_xlfn.XLOOKUP($A14,ALGLIB_SSA_XAUUSD!$A$2:$A$1000,ALGLIB_SSA_XAUUSD!$C$2:$C$1000,"",0) -> H1 | D14: =_xlfn.XLOOKUP($A14,ALGLIB_SSA_XAUUSD!$A$2:$A$1000,ALGLIB_SSA_XAUUSD!$D$2:$D$1000,"",0) -> 4601.49 | E14: =_xlfn.XLOOKUP($A14,ALGLIB_SSA_XAUUSD!$A$2:$A$1000,ALGLIB_SSA_XAUUSD!$E$2:$E$1000,"",0) -> 4630.1698 | F14: =_xlfn.XLOOKUP($A14,ALGLIB_SSA_XAUUSD!$A$2:$A$1000,ALGLIB_SSA_XAUUSD!$F$2:$F$1000,"",0) -> 4623.1327 | G14: =_xlfn.XLOOKUP($A14,ALGLIB_SSA_XAUUSD!$A$2:$A$1000,ALGLIB_SSA_XAUUSD!$G$2:$G$1000,"",0) -> 4648.8933 | H14: =_xlfn.XLOOKUP($A14,ALGLIB_SSA_XAUUSD!$A$2:$A$1000,ALGLIB_SSA_XAUUSD!$H$2:$H$1000,"",0) -> 4606.5639 | I14: =_xlfn.XLOOKUP($A14,ALGLIB_SSA_XAUUSD!$J$2:$J$1000,ALGLIB_SSA_XAUUSD!$K$2:$K$1000,"",0) -> XAUUSD | J14: =_xlfn.XLOOKUP($A14,ALGLIB_SSA_XAUUSD!$J$2:$J$1000,ALGLIB_SSA_XAUUSD!$L$2:$L$1000,"",0) -> M5 | K14: =_xlfn.XLOOKUP($A14,ALGLIB_SSA_XAUUSD!$J$2:$J$1000,ALGLIB_SSA_XAUUSD!$M$2:$M$1000,"",0) -> 4607.01 | L14: =_xlfn.XLOOKUP($A14,ALGLIB_SSA_XAUUSD!$J$2:$J$1000,ALGLIB_SSA_XAUUSD!$N$2:$N$1000,"",0) -> 4604.3495 | M14: =_xlfn.XLOOKUP($A14,ALGLIB_SSA_XAUUSD!$J$2:$J$1000,ALGLIB_SSA_XAUUSD!$O$2:$O$1000,"",0) -> 4603.5483 | N14: =_xlfn.XLOOKUP($A14,ALGLIB_SSA_XAUUSD!$J$2:$J$1000,ALGLIB_SSA_XAUUSD!$P$2:$P$1000,"",0) -> 4608.377 | O14: =_xlfn.XLOOKUP($A14,ALGLIB_SSA_XAUUSD!$J$2:$J$1000,ALGLIB_SSA_XAUUSD!$Q$2:$Q$1000,"",0) -> 4597.0596 | R14: =A14 -> 1775131200 | S14: =I14 -> XAUUSD | T14: =J14 -> M5 | U14: =K14 -> 4607.01 | V14: 4630.1698 | W14: 4623.1327 | X14: 4604.3495 | Y14: 4603.5483 | Z14: =G14 -> 4648.8933 | AA14: =N14 -> 4608.377 | AB14: =H14 -> 4606.5639 | AC14: =O14 -> 4597.0596 | AF14: =X14 -> 4604.3495 | AG14: =Z14 -> 4648.8933 | AH14: =AB14 -> 4606.5639
A15: =ALGLIB_SSA_XAUUSD!J15 -> 1775131500 | B15: =_xlfn.XLOOKUP($A15,ALGLIB_SSA_XAUUSD!$A$2:$A$1000,ALGLIB_SSA_XAUUSD!$B$2:$B$1000,"",0) | C15: =_xlfn.XLOOKUP($A15,ALGLIB_SSA_XAUUSD!$A$2:$A$1000,ALGLIB_SSA_XAUUSD!$C$2:$C$1000,"",0) | D15: =D14+(D26-D14)*1/12 -> 4605.1433 | E15: =E14+(E26-E14)*1/12 -> 4631.1781 | F15: =F14+(F26-F14)*1/12 -> 4623.9301 | G15: =G14+(G26-G14)*1/12 -> 4649.8081 | H15: =H14+(H26-H14)*1/12 -> 4607.3696 | I15: =_xlfn.XLOOKUP($A15,ALGLIB_SSA_XAUUSD!$J$2:$J$1000,ALGLIB_SSA_XAUUSD!$K$2:$K$1000,"",0) -> XAUUSD | J15: =_xlfn.XLOOKUP($A15,ALGLIB_SSA_XAUUSD!$J$2:$J$1000,ALGLIB_SSA_XAUUSD!$L$2:$L$1000,"",0) -> M5 | K15: =_xlfn.XLOOKUP($A15,ALGLIB_SSA_XAUUSD!$J$2:$J$1000,ALGLIB_SSA_XAUUSD!$M$2:$M$1000,"",0) -> 4603.93 | L15: =_xlfn.XLOOKUP($A15,ALGLIB_SSA_XAUUSD!$J$2:$J$1000,ALGLIB_SSA_XAUUSD!$N$2:$N$1000,"",0) -> 4607.7338 | M15: =_xlfn.XLOOKUP($A15,ALGLIB_SSA_XAUUSD!$J$2:$J$1000,ALGLIB_SSA_XAUUSD!$O$2:$O$1000,"",0) -> 4605.6411 | N15: =_xlfn.XLOOKUP($A15,ALGLIB_SSA_XAUUSD!$J$2:$J$1000,ALGLIB_SSA_XAUUSD!$P$2:$P$1000,"",0) -> 4610.7752 | O15: =_xlfn.XLOOKUP($A15,ALGLIB_SSA_XAUUSD!$J$2:$J$1000,ALGLIB_SSA_XAUUSD!$Q$2:$Q$1000,"",0) -> 4600.2291 | R15: =A15 -> 1775131500 | S15: =I15 -> XAUUSD | T15: =J15 -> M5 | U15: =K15 -> 4603.93 | V15: 4631.1781 | W15: 4623.9301 | X15: 4607.7338 | Y15: 4605.6411 | Z15: =G15 -> 4649.8081 | AA15: =N15 -> 4610.7752 | AB15: =H15 -> 4607.3696 | AC15: =O15 -> 4600.2291 | AF15: =X15 -> 4607.7338 | AG15: =Z15 -> 4649.8081 | AH15: =AB15 -> 4607.3696
A16: =ALGLIB_SSA_XAUUSD!J16 -> 1775131800 | B16: =_xlfn.XLOOKUP($A16,ALGLIB_SSA_XAUUSD!$A$2:$A$1000,ALGLIB_SSA_XAUUSD!$B$2:$B$1000,"",0) | C16: =_xlfn.XLOOKUP($A16,ALGLIB_SSA_XAUUSD!$A$2:$A$1000,ALGLIB_SSA_XAUUSD!$C$2:$C$1000,"",0) | D16: =D14+(D26-D14)*2/12 -> 4608.7967 | E16: =E14+(E26-E14)*2/12 -> 4632.1864 | F16: =F14+(F26-F14)*2/12 -> 4624.7275 | G16: =G14+(G26-G14)*2/12 -> 4650.723 | H16: =H14+(H26-H14)*2/12 -> 4608.1752 | I16: =_xlfn.XLOOKUP($A16,ALGLIB_SSA_XAUUSD!$J$2:$J$1000,ALGLIB_SSA_XAUUSD!$K$2:$K$1000,"",0) -> XAUUSD | J16: =_xlfn.XLOOKUP($A16,ALGLIB_SSA_XAUUSD!$J$2:$J$1000,ALGLIB_SSA_XAUUSD!$L$2:$L$1000,"",0) -> M5 | K16: =_xlfn.XLOOKUP($A16,ALGLIB_SSA_XAUUSD!$J$2:$J$1000,ALGLIB_SSA_XAUUSD!$M$2:$M$1000,"",0) -> 4612.54 | L16: =_xlfn.XLOOKUP($A16,ALGLIB_SSA_XAUUSD!$J$2:$J$1000,ALGLIB_SSA_XAUUSD!$N$2:$N$1000,"",0) -> 4611.9904 | M16: =_xlfn.XLOOKUP($A16,ALGLIB_SSA_XAUUSD!$J$2:$J$1000,ALGLIB_SSA_XAUUSD!$O$2:$O$1000,"",0) -> 4608.8158 | N16: =_xlfn.XLOOKUP($A16,ALGLIB_SSA_XAUUSD!$J$2:$J$1000,ALGLIB_SSA_XAUUSD!$P$2:$P$1000,"",0) -> 4614.0696 | O16: =_xlfn.XLOOKUP($A16,ALGLIB_SSA_XAUUSD!$J$2:$J$1000,ALGLIB_SSA_XAUUSD!$Q$2:$Q$1000,"",0) -> 4604.528 | R16: =A16 -> 1775131800 | S16: =I16 -> XAUUSD | T16: =J16 -> M5 | U16: =K16 -> 4612.54 | V16: 4632.1864 | W16: 4624.7275 | X16: 4611.9904 | Y16: 4608.8158 | Z16: =G16 -> 4650.723 | AA16: =N16 -> 4614.0696 | AB16: =H16 -> 4608.1752 | AC16: =O16 -> 4604.528 | AF16: =X16 -> 4611.9904 | AG16: =Z16 -> 4650.723 | AH16: =AB16 -> 4608.1752
A17: =ALGLIB_SSA_XAUUSD!J17 -> 1775132100 | B17: =_xlfn.XLOOKUP($A17,ALGLIB_SSA_XAUUSD!$A$2:$A$1000,ALGLIB_SSA_XAUUSD!$B$2:$B$1000,"",0) | C17: =_xlfn.XLOOKUP($A17,ALGLIB_SSA_XAUUSD!$A$2:$A$1000,ALGLIB_SSA_XAUUSD!$C$2:$C$1000,"",0) | D17: =D14+(D26-D14)*3/12 -> 4612.45 | E17: =E14+(E26-E14)*3/12 -> 4633.1948 | F17: =F14+(F26-F14)*3/12 -> 4625.5248 | G17: =G14+(G26-G14)*3/12 -> 4651.6378 | H17: =H14+(H26-H14)*3/12 -> 4608.9809 | I17: =_xlfn.XLOOKUP($A17,ALGLIB_SSA_XAUUSD!$J$2:$J$1000,ALGLIB_SSA_XAUUSD!$K$2:$K$1000,"",0) -> XAUUSD | J17: =_xlfn.XLOOKUP($A17,ALGLIB_SSA_XAUUSD!$J$2:$J$1000,ALGLIB_SSA_XAUUSD!$L$2:$L$1000,"",0) -> M5 | K17: =_xlfn.XLOOKUP($A17,ALGLIB_SSA_XAUUSD!$J$2:$J$1000,ALGLIB_SSA_XAUUSD!$M$2:$M$1000,"",0) -> 4613.71 | L17: =_xlfn.XLOOKUP($A17,ALGLIB_SSA_XAUUSD!$J$2:$J$1000,ALGLIB_SSA_XAUUSD!$N$2:$N$1000,"",0) -> 4616.4376 | M17: =_xlfn.XLOOKUP($A17,ALGLIB_SSA_XAUUSD!$J$2:$J$1000,ALGLIB_SSA_XAUUSD!$O$2:$O$1000,"",0) -> 4612.6267 | N17: =_xlfn.XLOOKUP($A17,ALGLIB_SSA_XAUUSD!$J$2:$J$1000,ALGLIB_SSA_XAUUSD!$P$2:$P$1000,"",0) -> 4617.9351 | O17: =_xlfn.XLOOKUP($A17,ALGLIB_SSA_XAUUSD!$J$2:$J$1000,ALGLIB_SSA_XAUUSD!$Q$2:$Q$1000,"",0) -> 4609.5104 | R17: =A17 -> 1775132100 | S17: =I17 -> XAUUSD | T17: =J17 -> M5 | U17: =K17 -> 4613.71 | V17: 4633.1948 | W17: 4625.5248 | X17: 4616.4376 | Y17: 4612.6267 | Z17: =G17 -> 4651.6378 | AA17: =N17 -> 4617.9351 | AB17: =H17 -> 4608.9809 | AC17: =O17 -> 4609.5104 | AF17: =X17 -> 4616.4376 | AG17: =Z17 -> 4651.6378 | AH17: =AB17 -> 4608.9809
A18: =ALGLIB_SSA_XAUUSD!J18 -> 1775132400 | B18: =_xlfn.XLOOKUP($A18,ALGLIB_SSA_XAUUSD!$A$2:$A$1000,ALGLIB_SSA_XAUUSD!$B$2:$B$1000,"",0) | C18: =_xlfn.XLOOKUP($A18,ALGLIB_SSA_XAUUSD!$A$2:$A$1000,ALGLIB_SSA_XAUUSD!$C$2:$C$1000,"",0) | D18: =D14+(D26-D14)*4/12 -> 4616.1033 | E18: =E14+(E26-E14)*4/12 -> 4634.2031 | F18: =F14+(F26-F14)*4/12 -> 4626.3222 | G18: =G14+(G26-G14)*4/12 -> 4652.5527 | H18: =H14+(H26-H14)*4/12 -> 4609.7865 | I18: =_xlfn.XLOOKUP($A18,ALGLIB_SSA_XAUUSD!$J$2:$J$1000,ALGLIB_SSA_XAUUSD!$K$2:$K$1000,"",0) -> XAUUSD | J18: =_xlfn.XLOOKUP($A18,ALGLIB_SSA_XAUUSD!$J$2:$J$1000,ALGLIB_SSA_XAUUSD!$L$2:$L$1000,"",0) -> M5 | K18: =_xlfn.XLOOKUP($A18,ALGLIB_SSA_XAUUSD!$J$2:$J$1000,ALGLIB_SSA_XAUUSD!$M$2:$M$1000,"",0) -> 4628.26 | L18: =_xlfn.XLOOKUP($A18,ALGLIB_SSA_XAUUSD!$J$2:$J$1000,ALGLIB_SSA_XAUUSD!$N$2:$N$1000,"",0) -> 4620.5756 | M18: =_xlfn.XLOOKUP($A18,ALGLIB_SSA_XAUUSD!$J$2:$J$1000,ALGLIB_SSA_XAUUSD!$O$2:$O$1000,"",0) -> 4616.6012 | N18: =_xlfn.XLOOKUP($A18,ALGLIB_SSA_XAUUSD!$J$2:$J$1000,ALGLIB_SSA_XAUUSD!$P$2:$P$1000,"",0) -> 4621.9336 | O18: =_xlfn.XLOOKUP($A18,ALGLIB_SSA_XAUUSD!$J$2:$J$1000,ALGLIB_SSA_XAUUSD!$Q$2:$Q$1000,"",0) -> 4614.2645 | R18: =A18 -> 1775132400 | S18: =I18 -> XAUUSD | T18: =J18 -> M5 | U18: =K18 -> 4628.26 | V18: 4634.2031 | W18: 4626.3222 | X18: 4620.5756 | Y18: 4616.6012 | Z18: =G18 -> 4652.5527 | AA18: =N18 -> 4621.9336 | AB18: =H18 -> 4609.7865 | AC18: =O18 -> 4614.2645 | AF18: =X18 -> 4620.5756 | AG18: =Z18 -> 4652.5527 | AH18: =AB18 -> 4609.7865
A19: =ALGLIB_SSA_XAUUSD!J19 -> 1775132700 | B19: =_xlfn.XLOOKUP($A19,ALGLIB_SSA_XAUUSD!$A$2:$A$1000,ALGLIB_SSA_XAUUSD!$B$2:$B$1000,"",0) | C19: =_xlfn.XLOOKUP($A19,ALGLIB_SSA_XAUUSD!$A$2:$A$1000,ALGLIB_SSA_XAUUSD!$C$2:$C$1000,"",0) | D19: =D14+(D26-D14)*5/12 -> 4619.7567 | E19: =E14+(E26-E14)*5/12 -> 4635.2114 | F19: =F14+(F26-F14)*5/12 -> 4627.1196 | G19: =G14+(G26-G14)*5/12 -> 4653.4675 | H19: =H14+(H26-H14)*5/12 -> 4610.5922 | I19: =_xlfn.XLOOKUP($A19,ALGLIB_SSA_XAUUSD!$J$2:$J$1000,ALGLIB_SSA_XAUUSD!$K$2:$K$1000,"",0) -> XAUUSD | J19: =_xlfn.XLOOKUP($A19,ALGLIB_SSA_XAUUSD!$J$2:$J$1000,ALGLIB_SSA_XAUUSD!$L$2:$L$1000,"",0) -> M5 | K19: =_xlfn.XLOOKUP($A19,ALGLIB_SSA_XAUUSD!$J$2:$J$1000,ALGLIB_SSA_XAUUSD!$M$2:$M$1000,"",0) -> 4626.08 | L19: =_xlfn.XLOOKUP($A19,ALGLIB_SSA_XAUUSD!$J$2:$J$1000,ALGLIB_SSA_XAUUSD!$N$2:$N$1000,"",0) -> 4623.5375 | M19: =_xlfn.XLOOKUP($A19,ALGLIB_SSA_XAUUSD!$J$2:$J$1000,ALGLIB_SSA_XAUUSD!$O$2:$O$1000,"",0) -> 4620.0693 | N19: =_xlfn.XLOOKUP($A19,ALGLIB_SSA_XAUUSD!$J$2:$J$1000,ALGLIB_SSA_XAUUSD!$P$2:$P$1000,"",0) -> 4625.3803 | O19: =_xlfn.XLOOKUP($A19,ALGLIB_SSA_XAUUSD!$J$2:$J$1000,ALGLIB_SSA_XAUUSD!$Q$2:$Q$1000,"",0) -> 4618.0848 | R19: =A19 -> 1775132700 | S19: =I19 -> XAUUSD | T19: =J19 -> M5 | U19: =K19 -> 4626.08 | V19: 4635.2114 | W19: 4627.1196 | X19: 4623.5375 | Y19: 4620.0693 | Z19: =G19 -> 4653.4675 | AA19: =N19 -> 4625.3803 | AB19: =H19 -> 4610.5922 | AC19: =O19 -> 4618.0848 | AF19: =X19 -> 4623.5375 | AG19: =Z19 -> 4653.4675 | AH19: =AB19 -> 4610.5922
A20: =ALGLIB_SSA_XAUUSD!J20 -> 1775133000 | B20: =_xlfn.XLOOKUP($A20,ALGLIB_SSA_XAUUSD!$A$2:$A$1000,ALGLIB_SSA_XAUUSD!$B$2:$B$1000,"",0) | C20: =_xlfn.XLOOKUP($A20,ALGLIB_SSA_XAUUSD!$A$2:$A$1000,ALGLIB_SSA_XAUUSD!$C$2:$C$1000,"",0) | D20: =D14+(D26-D14)*6/12 -> 4623.41 | E20: =E14+(E26-E14)*6/12 -> 4636.2198 | F20: =F14+(F26-F14)*6/12 -> 4627.917 | G20: =G14+(G26-G14)*6/12 -> 4654.3824 | H20: =H14+(H26-H14)*6/12 -> 4611.3978 | I20: =_xlfn.XLOOKUP($A20,ALGLIB_SSA_XAUUSD!$J$2:$J$1000,ALGLIB_SSA_XAUUSD!$K$2:$K$1000,"",0) -> XAUUSD | J20: =_xlfn.XLOOKUP($A20,ALGLIB_SSA_XAUUSD!$J$2:$J$1000,ALGLIB_SSA_XAUUSD!$L$2:$L$1000,"",0) -> M5 | K20: =_xlfn.XLOOKUP($A20,ALGLIB_SSA_XAUUSD!$J$2:$J$1000,ALGLIB_SSA_XAUUSD!$M$2:$M$1000,"",0) -> 4621.94 | L20: =_xlfn.XLOOKUP($A20,ALGLIB_SSA_XAUUSD!$J$2:$J$1000,ALGLIB_SSA_XAUUSD!$N$2:$N$1000,"",0) -> 4624.9415 | M20: =_xlfn.XLOOKUP($A20,ALGLIB_SSA_XAUUSD!$J$2:$J$1000,ALGLIB_SSA_XAUUSD!$O$2:$O$1000,"",0) -> 4622.5054 | N20: =_xlfn.XLOOKUP($A20,ALGLIB_SSA_XAUUSD!$J$2:$J$1000,ALGLIB_SSA_XAUUSD!$P$2:$P$1000,"",0) -> 4627.8036 | O20: =_xlfn.XLOOKUP($A20,ALGLIB_SSA_XAUUSD!$J$2:$J$1000,ALGLIB_SSA_XAUUSD!$Q$2:$Q$1000,"",0) -> 4620.1751 | R20: =A20 -> 1775133000 | S20: =I20 -> XAUUSD | T20: =J20 -> M5 | U20: =K20 -> 4621.94 | V20: 4636.2198 | W20: 4627.917 | X20: 4624.9415 | Y20: 4622.5054 | Z20: =G20 -> 4654.3824 | AA20: =N20 -> 4627.8036 | AB20: =H20 -> 4611.3978 | AC20: =O20 -> 4620.1751 | AF20: =X20 -> 4624.9415 | AG20: =Z20 -> 4654.3824 | AH20: =AB20 -> 4611.3978
A21: =ALGLIB_SSA_XAUUSD!J21 -> 1775133300 | B21: =_xlfn.XLOOKUP($A21,ALGLIB_SSA_XAUUSD!$A$2:$A$1000,ALGLIB_SSA_XAUUSD!$B$2:$B$1000,"",0) | C21: =_xlfn.XLOOKUP($A21,ALGLIB_SSA_XAUUSD!$A$2:$A$1000,ALGLIB_SSA_XAUUSD!$C$2:$C$1000,"",0) | D21: =D14+(D26-D14)*7/12 -> 4627.0633 | E21: =E14+(E26-E14)*7/12 -> 4637.2281 | F21: =F14+(F26-F14)*7/12 -> 4628.7144 | G21: =G14+(G26-G14)*7/12 -> 4655.2972 | H21: =H14+(H26-H14)*7/12 -> 4612.2035 | I21: =_xlfn.XLOOKUP($A21,ALGLIB_SSA_XAUUSD!$J$2:$J$1000,ALGLIB_SSA_XAUUSD!$K$2:$K$1000,"",0) -> XAUUSD | J21: =_xlfn.XLOOKUP($A21,ALGLIB_SSA_XAUUSD!$J$2:$J$1000,ALGLIB_SSA_XAUUSD!$L$2:$L$1000,"",0) -> M5 | K21: =_xlfn.XLOOKUP($A21,ALGLIB_SSA_XAUUSD!$J$2:$J$1000,ALGLIB_SSA_XAUUSD!$M$2:$M$1000,"",0) -> 4621.45 | L21: =_xlfn.XLOOKUP($A21,ALGLIB_SSA_XAUUSD!$J$2:$J$1000,ALGLIB_SSA_XAUUSD!$N$2:$N$1000,"",0) -> 4624.5641 | M21: =_xlfn.XLOOKUP($A21,ALGLIB_SSA_XAUUSD!$J$2:$J$1000,ALGLIB_SSA_XAUUSD!$O$2:$O$1000,"",0) -> 4623.5348 | N21: =_xlfn.XLOOKUP($A21,ALGLIB_SSA_XAUUSD!$J$2:$J$1000,ALGLIB_SSA_XAUUSD!$P$2:$P$1000,"",0) -> 4628.8857 | O21: =_xlfn.XLOOKUP($A21,ALGLIB_SSA_XAUUSD!$J$2:$J$1000,ALGLIB_SSA_XAUUSD!$Q$2:$Q$1000,"",0) -> 4620.2812 | R21: =A21 -> 1775133300 | S21: =I21 -> XAUUSD | T21: =J21 -> M5 | U21: =K21 -> 4621.45 | V21: 4637.2281 | W21: 4628.7144 | X21: 4624.5641 | Y21: 4623.5348 | Z21: =G21 -> 4655.2972 | AA21: =N21 -> 4628.8857 | AB21: =H21 -> 4612.2035 | AC21: =O21 -> 4620.2812 | AF21: =X21 -> 4624.5641 | AG21: =Z21 -> 4655.2972 | AH21: =AB21 -> 4612.2035
A22: =ALGLIB_SSA_XAUUSD!J22 -> 1775133600 | B22: =_xlfn.XLOOKUP($A22,ALGLIB_SSA_XAUUSD!$A$2:$A$1000,ALGLIB_SSA_XAUUSD!$B$2:$B$1000,"",0) | C22: =_xlfn.XLOOKUP($A22,ALGLIB_SSA_XAUUSD!$A$2:$A$1000,ALGLIB_SSA_XAUUSD!$C$2:$C$1000,"",0) | D22: =D14+(D26-D14)*8/12 -> 4630.7167 | E22: =E14+(E26-E14)*8/12 -> 4638.2364 | F22: =F14+(F26-F14)*8/12 -> 4629.5117 | G22: =G14+(G26-G14)*8/12 -> 4656.2121 | H22: =H14+(H26-H14)*8/12 -> 4613.0091 | I22: =_xlfn.XLOOKUP($A22,ALGLIB_SSA_XAUUSD!$J$2:$J$1000,ALGLIB_SSA_XAUUSD!$K$2:$K$1000,"",0) -> XAUUSD | J22: =_xlfn.XLOOKUP($A22,ALGLIB_SSA_XAUUSD!$J$2:$J$1000,ALGLIB_SSA_XAUUSD!$L$2:$L$1000,"",0) -> M5 | K22: =_xlfn.XLOOKUP($A22,ALGLIB_SSA_XAUUSD!$J$2:$J$1000,ALGLIB_SSA_XAUUSD!$M$2:$M$1000,"",0) -> 4618.28 | L22: =_xlfn.XLOOKUP($A22,ALGLIB_SSA_XAUUSD!$J$2:$J$1000,ALGLIB_SSA_XAUUSD!$N$2:$N$1000,"",0) -> 4622.2757 | M22: =_xlfn.XLOOKUP($A22,ALGLIB_SSA_XAUUSD!$J$2:$J$1000,ALGLIB_SSA_XAUUSD!$O$2:$O$1000,"",0) -> 4622.9052 | N22: =_xlfn.XLOOKUP($A22,ALGLIB_SSA_XAUUSD!$J$2:$J$1000,ALGLIB_SSA_XAUUSD!$P$2:$P$1000,"",0) -> 4628.3622 | O22: =_xlfn.XLOOKUP($A22,ALGLIB_SSA_XAUUSD!$J$2:$J$1000,ALGLIB_SSA_XAUUSD!$Q$2:$Q$1000,"",0) -> 4618.254 | R22: =A22 -> 1775133600 | S22: =I22 -> XAUUSD | T22: =J22 -> M5 | U22: =K22 -> 4618.28 | V22: 4638.2364 | W22: 4629.5117 | X22: 4622.2757 | Y22: 4622.9052 | Z22: =G22 -> 4656.2121 | AA22: =N22 -> 4628.3622 | AB22: =H22 -> 4613.0091 | AC22: =O22 -> 4618.254 | AF22: =X22 -> 4622.2757 | AG22: =Z22 -> 4656.2121 | AH22: =AB22 -> 4613.0091
A23: =ALGLIB_SSA_XAUUSD!J23 -> 1775133900 | B23: =_xlfn.XLOOKUP($A23,ALGLIB_SSA_XAUUSD!$A$2:$A$1000,ALGLIB_SSA_XAUUSD!$B$2:$B$1000,"",0) | C23: =_xlfn.XLOOKUP($A23,ALGLIB_SSA_XAUUSD!$A$2:$A$1000,ALGLIB_SSA_XAUUSD!$C$2:$C$1000,"",0) | D23: =D14+(D26-D14)*9/12 -> 4634.37 | E23: =E14+(E26-E14)*9/12 -> 4639.2448 | F23: =F14+(F26-F14)*9/12 -> 4630.3091 | G23: =G14+(G26-G14)*9/12 -> 4657.1269 | H23: =H14+(H26-H14)*9/12 -> 4613.8148 | I23: =_xlfn.XLOOKUP($A23,ALGLIB_SSA_XAUUSD!$J$2:$J$1000,ALGLIB_SSA_XAUUSD!$K$2:$K$1000,"",0) -> XAUUSD | J23: =_xlfn.XLOOKUP($A23,ALGLIB_SSA_XAUUSD!$J$2:$J$1000,ALGLIB_SSA_XAUUSD!$L$2:$L$1000,"",0) -> M5 | K23: =_xlfn.XLOOKUP($A23,ALGLIB_SSA_XAUUSD!$J$2:$J$1000,ALGLIB_SSA_XAUUSD!$M$2:$M$1000,"",0) -> 4619.49 | L23: =_xlfn.XLOOKUP($A23,ALGLIB_SSA_XAUUSD!$J$2:$J$1000,ALGLIB_SSA_XAUUSD!$N$2:$N$1000,"",0) -> 4618.1843 | M23: =_xlfn.XLOOKUP($A23,ALGLIB_SSA_XAUUSD!$J$2:$J$1000,ALGLIB_SSA_XAUUSD!$O$2:$O$1000,"",0) -> 4620.5448 | N23: =_xlfn.XLOOKUP($A23,ALGLIB_SSA_XAUUSD!$J$2:$J$1000,ALGLIB_SSA_XAUUSD!$P$2:$P$1000,"",0) -> 4626.1302 | O23: =_xlfn.XLOOKUP($A23,ALGLIB_SSA_XAUUSD!$J$2:$J$1000,ALGLIB_SSA_XAUUSD!$Q$2:$Q$1000,"",0) -> 4614.2645 | R23: =A23 -> 1775133900 | S23: =I23 -> XAUUSD | T23: =J23 -> M5 | U23: =K23 -> 4619.49 | V23: 4639.2448 | W23: 4630.3091 | X23: 4618.1843 | Y23: 4620.5448 | Z23: =G23 -> 4657.1269 | AA23: =N23 -> 4626.1302 | AB23: =H23 -> 4613.8148 | AC23: =O23 -> 4614.2645 | AF23: =X23 -> 4618.1843 | AG23: =Z23 -> 4657.1269 | AH23: =AB23 -> 4613.8148
A24: =ALGLIB_SSA_XAUUSD!J24 -> 1775134200 | B24: =_xlfn.XLOOKUP($A24,ALGLIB_SSA_XAUUSD!$A$2:$A$1000,ALGLIB_SSA_XAUUSD!$B$2:$B$1000,"",0) | C24: =_xlfn.XLOOKUP($A24,ALGLIB_SSA_XAUUSD!$A$2:$A$1000,ALGLIB_SSA_XAUUSD!$C$2:$C$1000,"",0) | D24: =D14+(D26-D14)*10/12 -> 4638.0233 | E24: =E14+(E26-E14)*10/12 -> 4640.2531 | F24: =F14+(F26-F14)*10/12 -> 4631.1065 | G24: =G14+(G26-G14)*10/12 -> 4658.0418 | H24: =H14+(H26-H14)*10/12 -> 4614.6205 | I24: =_xlfn.XLOOKUP($A24,ALGLIB_SSA_XAUUSD!$J$2:$J$1000,ALGLIB_SSA_XAUUSD!$K$2:$K$1000,"",0) -> XAUUSD | J24: =_xlfn.XLOOKUP($A24,ALGLIB_SSA_XAUUSD!$J$2:$J$1000,ALGLIB_SSA_XAUUSD!$L$2:$L$1000,"",0) -> M5 | K24: =_xlfn.XLOOKUP($A24,ALGLIB_SSA_XAUUSD!$J$2:$J$1000,ALGLIB_SSA_XAUUSD!$M$2:$M$1000,"",0) -> 4620.28 | L24: =_xlfn.XLOOKUP($A24,ALGLIB_SSA_XAUUSD!$J$2:$J$1000,ALGLIB_SSA_XAUUSD!$N$2:$N$1000,"",0) -> 4612.5639 | M24: =_xlfn.XLOOKUP($A24,ALGLIB_SSA_XAUUSD!$J$2:$J$1000,ALGLIB_SSA_XAUUSD!$O$2:$O$1000,"",0) -> 4616.5543 | N24: =_xlfn.XLOOKUP($A24,ALGLIB_SSA_XAUUSD!$J$2:$J$1000,ALGLIB_SSA_XAUUSD!$P$2:$P$1000,"",0) -> 4622.2283 | O24: =_xlfn.XLOOKUP($A24,ALGLIB_SSA_XAUUSD!$J$2:$J$1000,ALGLIB_SSA_XAUUSD!$Q$2:$Q$1000,"",0) -> 4608.6793 | R24: =A24 -> 1775134200 | S24: =I24 -> XAUUSD | T24: =J24 -> M5 | U24: =K24 -> 4620.28 | V24: 4640.2531 | W24: 4631.1065 | X24: 4612.5639 | Y24: 4616.5543 | Z24: =G24 -> 4658.0418 | AA24: =N24 -> 4622.2283 | AB24: =H24 -> 4614.6205 | AC24: =O24 -> 4608.6793 | AF24: =X24 -> 4612.5639 | AG24: =Z24 -> 4658.0418 | AH24: =AB24 -> 4614.6205
A25: =ALGLIB_SSA_XAUUSD!J25 -> 1775134500 | B25: =_xlfn.XLOOKUP($A25,ALGLIB_SSA_XAUUSD!$A$2:$A$1000,ALGLIB_SSA_XAUUSD!$B$2:$B$1000,"",0) | C25: =_xlfn.XLOOKUP($A25,ALGLIB_SSA_XAUUSD!$A$2:$A$1000,ALGLIB_SSA_XAUUSD!$C$2:$C$1000,"",0) | D25: =D14+(D26-D14)*11/12 -> 4641.6767 | E25: =E14+(E26-E14)*11/12 -> 4641.2614 | F25: =F14+(F26-F14)*11/12 -> 4631.9039 | G25: =G14+(G26-G14)*11/12 -> 4658.9567 | H25: =H14+(H26-H14)*11/12 -> 4615.4261 | I25: =_xlfn.XLOOKUP($A25,ALGLIB_SSA_XAUUSD!$J$2:$J$1000,ALGLIB_SSA_XAUUSD!$K$2:$K$1000,"",0) -> XAUUSD | J25: =_xlfn.XLOOKUP($A25,ALGLIB_SSA_XAUUSD!$J$2:$J$1000,ALGLIB_SSA_XAUUSD!$L$2:$L$1000,"",0) -> M5 | K25: =_xlfn.XLOOKUP($A25,ALGLIB_SSA_XAUUSD!$J$2:$J$1000,ALGLIB_SSA_XAUUSD!$M$2:$M$1000,"",0) -> 4601.49 | L25: =_xlfn.XLOOKUP($A25,ALGLIB_SSA_XAUUSD!$J$2:$J$1000,ALGLIB_SSA_XAUUSD!$N$2:$N$1000,"",0) -> 4605.9619 | M25: =_xlfn.XLOOKUP($A25,ALGLIB_SSA_XAUUSD!$J$2:$J$1000,ALGLIB_SSA_XAUUSD!$O$2:$O$1000,"",0) -> 4611.2581 | N25: =_xlfn.XLOOKUP($A25,ALGLIB_SSA_XAUUSD!$J$2:$J$1000,ALGLIB_SSA_XAUUSD!$P$2:$P$1000,"",0) -> 4616.9907 | O25: =_xlfn.XLOOKUP($A25,ALGLIB_SSA_XAUUSD!$J$2:$J$1000,ALGLIB_SSA_XAUUSD!$Q$2:$Q$1000,"",0) -> 4601.9814 | R25: =A25 -> 1775134500 | S25: =I25 -> XAUUSD | T25: =J25 -> M5 | U25: =K25 -> 4601.49 | V25: 4641.2614 | W25: 4631.9039 | X25: 4605.9619 | Y25: 4611.2581 | Z25: =G25 -> 4658.9567 | AA25: =N25 -> 4616.9907 | AB25: =H25 -> 4615.4261 | AC25: =O25 -> 4601.9814 | AF25: =X25 -> 4605.9619 | AG25: =Z25 -> 4658.9567 | AH25: =AB25 -> 4615.4261
A26: =ALGLIB_SSA_XAUUSD!J26 -> 1775134800 | B26: =_xlfn.XLOOKUP($A26,ALGLIB_SSA_XAUUSD!$A$2:$A$1000,ALGLIB_SSA_XAUUSD!$B$2:$B$1000,"",0) -> XAUUSD | C26: =_xlfn.XLOOKUP($A26,ALGLIB_SSA_XAUUSD!$A$2:$A$1000,ALGLIB_SSA_XAUUSD!$C$2:$C$1000,"",0) -> H1 | D26: =_xlfn.XLOOKUP($A26,ALGLIB_SSA_XAUUSD!$A$2:$A$1000,ALGLIB_SSA_XAUUSD!$D$2:$D$1000,"",0) -> 4645.33 | E26: =_xlfn.XLOOKUP($A26,ALGLIB_SSA_XAUUSD!$A$2:$A$1000,ALGLIB_SSA_XAUUSD!$E$2:$E$1000,"",0) -> 4642.2698 | F26: =_xlfn.XLOOKUP($A26,ALGLIB_SSA_XAUUSD!$A$2:$A$1000,ALGLIB_SSA_XAUUSD!$F$2:$F$1000,"",0) -> 4632.7012 | G26: =_xlfn.XLOOKUP($A26,ALGLIB_SSA_XAUUSD!$A$2:$A$1000,ALGLIB_SSA_XAUUSD!$G$2:$G$1000,"",0) -> 4659.8715 | H26: =_xlfn.XLOOKUP($A26,ALGLIB_SSA_XAUUSD!$A$2:$A$1000,ALGLIB_SSA_XAUUSD!$H$2:$H$1000,"",0) -> 4616.2318 | I26: =_xlfn.XLOOKUP($A26,ALGLIB_SSA_XAUUSD!$J$2:$J$1000,ALGLIB_SSA_XAUUSD!$K$2:$K$1000,"",0) -> XAUUSD | J26: =_xlfn.XLOOKUP($A26,ALGLIB_SSA_XAUUSD!$J$2:$J$1000,ALGLIB_SSA_XAUUSD!$L$2:$L$1000,"",0) -> M5 | K26: =_xlfn.XLOOKUP($A26,ALGLIB_SSA_XAUUSD!$J$2:$J$1000,ALGLIB_SSA_XAUUSD!$M$2:$M$1000,"",0) -> 4595.07 | L26: =_xlfn.XLOOKUP($A26,ALGLIB_SSA_XAUUSD!$J$2:$J$1000,ALGLIB_SSA_XAUUSD!$N$2:$N$1000,"",0) -> 4599.3974 | M26: =_xlfn.XLOOKUP($A26,ALGLIB_SSA_XAUUSD!$J$2:$J$1000,ALGLIB_SSA_XAUUSD!$O$2:$O$1000,"",0) -> 4605.3277 | N26: =_xlfn.XLOOKUP($A26,ALGLIB_SSA_XAUUSD!$J$2:$J$1000,ALGLIB_SSA_XAUUSD!$P$2:$P$1000,"",0) -> 4611.0778 | O26: =_xlfn.XLOOKUP($A26,ALGLIB_SSA_XAUUSD!$J$2:$J$1000,ALGLIB_SSA_XAUUSD!$Q$2:$Q$1000,"",0) -> 4595.1583 | R26: =A26 -> 1775134800 | S26: =I26 -> XAUUSD | T26: =J26 -> M5 | U26: =K26 -> 4595.07 | V26: 4642.2698 | W26: 4632.7012 | X26: 4599.3974 | Y26: 4605.3277 | Z26: =G26 -> 4659.8715 | AA26: =N26 -> 4611.0778 | AB26: =H26 -> 4616.2318 | AC26: =O26 -> 4595.1583 | AF26: =X26 -> 4599.3974 | AG26: =Z26 -> 4659.8715 | AH26: =AB26 -> 4616.2318
A27: =ALGLIB_SSA_XAUUSD!J27 -> 1775135100 | B27: =_xlfn.XLOOKUP($A27,ALGLIB_SSA_XAUUSD!$A$2:$A$1000,ALGLIB_SSA_XAUUSD!$B$2:$B$1000,"",0) | C27: =_xlfn.XLOOKUP($A27,ALGLIB_SSA_XAUUSD!$A$2:$A$1000,ALGLIB_SSA_XAUUSD!$C$2:$C$1000,"",0) | D27: =D26+(D38-D26)*1/12 -> 4648.3292 | E27: =E26+(E38-E26)*1/12 -> 4643.203 | F27: =F26+(F38-F26)*1/12 -> 4633.5665 | G27: =G26+(G38-G26)*1/12 -> 4660.714 | H27: =H26+(H38-H26)*1/12 -> 4617.1564 | I27: =_xlfn.XLOOKUP($A27,ALGLIB_SSA_XAUUSD!$J$2:$J$1000,ALGLIB_SSA_XAUUSD!$K$2:$K$1000,"",0) -> XAUUSD | J27: =_xlfn.XLOOKUP($A27,ALGLIB_SSA_XAUUSD!$J$2:$J$1000,ALGLIB_SSA_XAUUSD!$L$2:$L$1000,"",0) -> M5 | K27: =_xlfn.XLOOKUP($A27,ALGLIB_SSA_XAUUSD!$J$2:$J$1000,ALGLIB_SSA_XAUUSD!$M$2:$M$1000,"",0) -> 4600.43 | L27: =_xlfn.XLOOKUP($A27,ALGLIB_SSA_XAUUSD!$J$2:$J$1000,ALGLIB_SSA_XAUUSD!$N$2:$N$1000,"",0) -> 4593.7296 | M27: =_xlfn.XLOOKUP($A27,ALGLIB_SSA_XAUUSD!$J$2:$J$1000,ALGLIB_SSA_XAUUSD!$O$2:$O$1000,"",0) -> 4599.5287 | N27: =_xlfn.XLOOKUP($A27,ALGLIB_SSA_XAUUSD!$J$2:$J$1000,ALGLIB_SSA_XAUUSD!$P$2:$P$1000,"",0) -> 4605.5109 | O27: =_xlfn.XLOOKUP($A27,ALGLIB_SSA_XAUUSD!$J$2:$J$1000,ALGLIB_SSA_XAUUSD!$Q$2:$Q$1000,"",0) -> 4589.1929 | R27: =A27 -> 1775135100 | S27: =I27 -> XAUUSD | T27: =J27 -> M5 | U27: =K27 -> 4600.43 | V27: 4643.203 | W27: 4633.5665 | X27: 4593.7296 | Y27: 4599.5287 | Z27: =G27 -> 4660.714 | AA27: =N27 -> 4605.5109 | AB27: =H27 -> 4617.1564 | AC27: =O27 -> 4589.1929 | AF27: =X27 -> 4593.7296 | AG27: =Z27 -> 4660.714 | AH27: =AB27 -> 4617.1564
A28: =ALGLIB_SSA_XAUUSD!J28 -> 1775135400 | B28: =_xlfn.XLOOKUP($A28,ALGLIB_SSA_XAUUSD!$A$2:$A$1000,ALGLIB_SSA_XAUUSD!$B$2:$B$1000,"",0) | C28: =_xlfn.XLOOKUP($A28,ALGLIB_SSA_XAUUSD!$A$2:$A$1000,ALGLIB_SSA_XAUUSD!$C$2:$C$1000,"",0) | D28: =D26+(D38-D26)*2/12 -> 4651.3283 | E28: =E26+(E38-E26)*2/12 -> 4644.1362 | F28: =F26+(F38-F26)*2/12 -> 4634.4319 | G28: =G26+(G38-G26)*2/12 -> 4661.5564 | H28: =H26+(H38-H26)*2/12 -> 4618.081 | I28: =_xlfn.XLOOKUP($A28,ALGLIB_SSA_XAUUSD!$J$2:$J$1000,ALGLIB_SSA_XAUUSD!$K$2:$K$1000,"",0) -> XAUUSD | J28: =_xlfn.XLOOKUP($A28,ALGLIB_SSA_XAUUSD!$J$2:$J$1000,ALGLIB_SSA_XAUUSD!$L$2:$L$1000,"",0) -> M5 | K28: =_xlfn.XLOOKUP($A28,ALGLIB_SSA_XAUUSD!$J$2:$J$1000,ALGLIB_SSA_XAUUSD!$M$2:$M$1000,"",0) -> 4587.61 | L28: =_xlfn.XLOOKUP($A28,ALGLIB_SSA_XAUUSD!$J$2:$J$1000,ALGLIB_SSA_XAUUSD!$N$2:$N$1000,"",0) -> 4589.5883 | M28: =_xlfn.XLOOKUP($A28,ALGLIB_SSA_XAUUSD!$J$2:$J$1000,ALGLIB_SSA_XAUUSD!$O$2:$O$1000,"",0) -> 4594.5585 | N28: =_xlfn.XLOOKUP($A28,ALGLIB_SSA_XAUUSD!$J$2:$J$1000,ALGLIB_SSA_XAUUSD!$P$2:$P$1000,"",0) -> 4600.8794 | O28: =_xlfn.XLOOKUP($A28,ALGLIB_SSA_XAUUSD!$J$2:$J$1000,ALGLIB_SSA_XAUUSD!$Q$2:$Q$1000,"",0) -> 4584.5235 | R28: =A28 -> 1775135400 | S28: =I28 -> XAUUSD | T28: =J28 -> M5 | U28: =K28 -> 4587.61 | V28: 4644.1362 | W28: 4634.4318 | X28: 4589.5883 | Y28: 4594.5585 | Z28: =G28 -> 4661.5564 | AA28: =N28 -> 4600.8794 | AB28: =H28 -> 4618.081 | AC28: =O28 -> 4584.5235 | AF28: =X28 -> 4589.5883 | AG28: =Z28 -> 4661.5564 | AH28: =AB28 -> 4618.081
A29: =ALGLIB_SSA_XAUUSD!J29 -> 1775135700 | B29: =_xlfn.XLOOKUP($A29,ALGLIB_SSA_XAUUSD!$A$2:$A$1000,ALGLIB_SSA_XAUUSD!$B$2:$B$1000,"",0) | C29: =_xlfn.XLOOKUP($A29,ALGLIB_SSA_XAUUSD!$A$2:$A$1000,ALGLIB_SSA_XAUUSD!$C$2:$C$1000,"",0) | D29: =D26+(D38-D26)*3/12 -> 4654.3275 | E29: =E26+(E38-E26)*3/12 -> 4645.0695 | F29: =F26+(F38-F26)*3/12 -> 4635.2972 | G29: =G26+(G38-G26)*3/12 -> 4662.3989 | H29: =H26+(H38-H26)*3/12 -> 4619.0057 | I29: =_xlfn.XLOOKUP($A29,ALGLIB_SSA_XAUUSD!$J$2:$J$1000,ALGLIB_SSA_XAUUSD!$K$2:$K$1000,"",0) -> XAUUSD | J29: =_xlfn.XLOOKUP($A29,ALGLIB_SSA_XAUUSD!$J$2:$J$1000,ALGLIB_SSA_XAUUSD!$L$2:$L$1000,"",0) -> M5 | K29: =_xlfn.XLOOKUP($A29,ALGLIB_SSA_XAUUSD!$J$2:$J$1000,ALGLIB_SSA_XAUUSD!$M$2:$M$1000,"",0) -> 4591.18 | L29: =_xlfn.XLOOKUP($A29,ALGLIB_SSA_XAUUSD!$J$2:$J$1000,ALGLIB_SSA_XAUUSD!$N$2:$N$1000,"",0) -> 4587.7102 | M29: =_xlfn.XLOOKUP($A29,ALGLIB_SSA_XAUUSD!$J$2:$J$1000,ALGLIB_SSA_XAUUSD!$O$2:$O$1000,"",0) -> 4591.1344 | N29: =_xlfn.XLOOKUP($A29,ALGLIB_SSA_XAUUSD!$J$2:$J$1000,ALGLIB_SSA_XAUUSD!$P$2:$P$1000,"",0) -> 4598.0306 | O29: =_xlfn.XLOOKUP($A29,ALGLIB_SSA_XAUUSD!$J$2:$J$1000,ALGLIB_SSA_XAUUSD!$Q$2:$Q$1000,"",0) -> 4581.7385 | R29: =A29 -> 1775135700 | S29: =I29 -> XAUUSD | T29: =J29 -> M5 | U29: =K29 -> 4591.18 | V29: 4645.0695 | W29: 4635.2972 | X29: 4587.7102 | Y29: 4591.1344 | Z29: =G29 -> 4662.3989 | AA29: =N29 -> 4598.0306 | AB29: =H29 -> 4619.0057 | AC29: =O29 -> 4581.7385 | AF29: =X29 -> 4587.7102 | AG29: =Z29 -> 4662.3989 | AH29: =AB29 -> 4619.0057
A30: =ALGLIB_SSA_XAUUSD!J30 -> 1775136000 | B30: =_xlfn.XLOOKUP($A30,ALGLIB_SSA_XAUUSD!$A$2:$A$1000,ALGLIB_SSA_XAUUSD!$B$2:$B$1000,"",0) | C30: =_xlfn.XLOOKUP($A30,ALGLIB_SSA_XAUUSD!$A$2:$A$1000,ALGLIB_SSA_XAUUSD!$C$2:$C$1000,"",0) | D30: =D26+(D38-D26)*4/12 -> 4657.3267 | E30: =E26+(E38-E26)*4/12 -> 4646.0027 | F30: =F26+(F38-F26)*4/12 -> 4636.1625 | G30: =G26+(G38-G26)*4/12 -> 4663.2413 | H30: =H26+(H38-H26)*4/12 -> 4619.9303 | I30: =_xlfn.XLOOKUP($A30,ALGLIB_SSA_XAUUSD!$J$2:$J$1000,ALGLIB_SSA_XAUUSD!$K$2:$K$1000,"",0) -> XAUUSD | J30: =_xlfn.XLOOKUP($A30,ALGLIB_SSA_XAUUSD!$J$2:$J$1000,ALGLIB_SSA_XAUUSD!$L$2:$L$1000,"",0) -> M5 | K30: =_xlfn.XLOOKUP($A30,ALGLIB_SSA_XAUUSD!$J$2:$J$1000,ALGLIB_SSA_XAUUSD!$M$2:$M$1000,"",0) -> 4582.98 | L30: =_xlfn.XLOOKUP($A30,ALGLIB_SSA_XAUUSD!$J$2:$J$1000,ALGLIB_SSA_XAUUSD!$N$2:$N$1000,"",0) -> 4588.3168 | M30: =_xlfn.XLOOKUP($A30,ALGLIB_SSA_XAUUSD!$J$2:$J$1000,ALGLIB_SSA_XAUUSD!$O$2:$O$1000,"",0) -> 4589.7256 | N30: =_xlfn.XLOOKUP($A30,ALGLIB_SSA_XAUUSD!$J$2:$J$1000,ALGLIB_SSA_XAUUSD!$P$2:$P$1000,"",0) -> 4597.5022 | O30: =_xlfn.XLOOKUP($A30,ALGLIB_SSA_XAUUSD!$J$2:$J$1000,ALGLIB_SSA_XAUUSD!$Q$2:$Q$1000,"",0) -> 4581.1429 | R30: =A30 -> 1775136000 | S30: =I30 -> XAUUSD | T30: =J30 -> M5 | U30: =K30 -> 4582.98 | V30: 4646.0027 | W30: 4636.1625 | X30: 4588.3168 | Y30: 4589.7256 | Z30: =G30 -> 4663.2413 | AA30: =N30 -> 4597.5022 | AB30: =H30 -> 4619.9303 | AC30: =O30 -> 4581.1429 | AF30: =X30 -> 4588.3168 | AG30: =Z30 -> 4663.2413 | AH30: =AB30 -> 4619.9303
A31: =ALGLIB_SSA_XAUUSD!J31 -> 1775136300 | B31: =_xlfn.XLOOKUP($A31,ALGLIB_SSA_XAUUSD!$A$2:$A$1000,ALGLIB_SSA_XAUUSD!$B$2:$B$1000,"",0) | C31: =_xlfn.XLOOKUP($A31,ALGLIB_SSA_XAUUSD!$A$2:$A$1000,ALGLIB_SSA_XAUUSD!$C$2:$C$1000,"",0) | D31: =D26+(D38-D26)*5/12 -> 4660.3258 | E31: =E26+(E38-E26)*5/12 -> 4646.9359 | F31: =F26+(F38-F26)*5/12 -> 4637.0278 | G31: =G26+(G38-G26)*5/12 -> 4664.0838 | H31: =H26+(H38-H26)*5/12 -> 4620.855 | I31: =_xlfn.XLOOKUP($A31,ALGLIB_SSA_XAUUSD!$J$2:$J$1000,ALGLIB_SSA_XAUUSD!$K$2:$K$1000,"",0) -> XAUUSD | J31: =_xlfn.XLOOKUP($A31,ALGLIB_SSA_XAUUSD!$J$2:$J$1000,ALGLIB_SSA_XAUUSD!$L$2:$L$1000,"",0) -> M5 | K31: =_xlfn.XLOOKUP($A31,ALGLIB_SSA_XAUUSD!$J$2:$J$1000,ALGLIB_SSA_XAUUSD!$M$2:$M$1000,"",0) -> 4597.48 | L31: =_xlfn.XLOOKUP($A31,ALGLIB_SSA_XAUUSD!$J$2:$J$1000,ALGLIB_SSA_XAUUSD!$N$2:$N$1000,"",0) -> 4591.471 | M31: =_xlfn.XLOOKUP($A31,ALGLIB_SSA_XAUUSD!$J$2:$J$1000,ALGLIB_SSA_XAUUSD!$O$2:$O$1000,"",0) -> 4590.5983 | N31: =_xlfn.XLOOKUP($A31,ALGLIB_SSA_XAUUSD!$J$2:$J$1000,ALGLIB_SSA_XAUUSD!$P$2:$P$1000,"",0) -> 4599.3926 | O31: =_xlfn.XLOOKUP($A31,ALGLIB_SSA_XAUUSD!$J$2:$J$1000,ALGLIB_SSA_XAUUSD!$Q$2:$Q$1000,"",0) -> 4582.855 | R31: =A31 -> 1775136300 | S31: =I31 -> XAUUSD | T31: =J31 -> M5 | U31: =K31 -> 4597.48 | V31: 4646.9359 | W31: 4637.0278 | X31: 4591.471 | Y31: 4590.5983 | Z31: =G31 -> 4664.0838 | AA31: =N31 -> 4599.3926 | AB31: =H31 -> 4620.855 | AC31: =O31 -> 4582.855 | AF31: =X31 -> 4591.471 | AG31: =Z31 -> 4664.0838 | AH31: =AB31 -> 4620.855
A32: =ALGLIB_SSA_XAUUSD!J32 -> 1775136600 | B32: =_xlfn.XLOOKUP($A32,ALGLIB_SSA_XAUUSD!$A$2:$A$1000,ALGLIB_SSA_XAUUSD!$B$2:$B$1000,"",0) | C32: =_xlfn.XLOOKUP($A32,ALGLIB_SSA_XAUUSD!$A$2:$A$1000,ALGLIB_SSA_XAUUSD!$C$2:$C$1000,"",0) | D32: =D26+(D38-D26)*6/12 -> 4663.325 | E32: =E26+(E38-E26)*6/12 -> 4647.8692 | F32: =F26+(F38-F26)*6/12 -> 4637.8931 | G32: =G26+(G38-G26)*6/12 -> 4664.9262 | H32: =H26+(H38-H26)*6/12 -> 4621.7796 | I32: =_xlfn.XLOOKUP($A32,ALGLIB_SSA_XAUUSD!$J$2:$J$1000,ALGLIB_SSA_XAUUSD!$K$2:$K$1000,"",0) -> XAUUSD | J32: =_xlfn.XLOOKUP($A32,ALGLIB_SSA_XAUUSD!$J$2:$J$1000,ALGLIB_SSA_XAUUSD!$L$2:$L$1000,"",0) -> M5 | K32: =_xlfn.XLOOKUP($A32,ALGLIB_SSA_XAUUSD!$J$2:$J$1000,ALGLIB_SSA_XAUUSD!$M$2:$M$1000,"",0) -> 4599.59 | L32: =_xlfn.XLOOKUP($A32,ALGLIB_SSA_XAUUSD!$J$2:$J$1000,ALGLIB_SSA_XAUUSD!$N$2:$N$1000,"",0) -> 4596.8588 | M32: =_xlfn.XLOOKUP($A32,ALGLIB_SSA_XAUUSD!$J$2:$J$1000,ALGLIB_SSA_XAUUSD!$O$2:$O$1000,"",0) -> 4593.7285 | N32: =_xlfn.XLOOKUP($A32,ALGLIB_SSA_XAUUSD!$J$2:$J$1000,ALGLIB_SSA_XAUUSD!$P$2:$P$1000,"",0) -> 4603.6296 | O32: =_xlfn.XLOOKUP($A32,ALGLIB_SSA_XAUUSD!$J$2:$J$1000,ALGLIB_SSA_XAUUSD!$Q$2:$Q$1000,"",0) -> 4586.8313 | R32: =A32 -> 1775136600 | S32: =I32 -> XAUUSD | T32: =J32 -> M5 | U32: =K32 -> 4599.59 | V32: 4647.8692 | W32: 4637.8931 | X32: 4596.8588 | Y32: 4593.7285 | Z32: =G32 -> 4664.9262 | AA32: =N32 -> 4603.6296 | AB32: =H32 -> 4621.7796 | AC32: =O32 -> 4586.8313 | AF32: =X32 -> 4596.8588 | AG32: =Z32 -> 4664.9262 | AH32: =AB32 -> 4621.7796
A33: =ALGLIB_SSA_XAUUSD!J33 -> 1775136900 | B33: =_xlfn.XLOOKUP($A33,ALGLIB_SSA_XAUUSD!$A$2:$A$1000,ALGLIB_SSA_XAUUSD!$B$2:$B$1000,"",0) | C33: =_xlfn.XLOOKUP($A33,ALGLIB_SSA_XAUUSD!$A$2:$A$1000,ALGLIB_SSA_XAUUSD!$C$2:$C$1000,"",0) | D33: =D26+(D38-D26)*7/12 -> 4666.3242 | E33: =E26+(E38-E26)*7/12 -> 4648.8024 | F33: =F26+(F38-F26)*7/12 -> 4638.7584 | G33: =G26+(G38-G26)*7/12 -> 4665.7687 | H33: =H26+(H38-H26)*7/12 -> 4622.7042 | I33: =_xlfn.XLOOKUP($A33,ALGLIB_SSA_XAUUSD!$J$2:$J$1000,ALGLIB_SSA_XAUUSD!$K$2:$K$1000,"",0) -> XAUUSD | J33: =_xlfn.XLOOKUP($A33,ALGLIB_SSA_XAUUSD!$J$2:$J$1000,ALGLIB_SSA_XAUUSD!$L$2:$L$1000,"",0) -> M5 | K33: =_xlfn.XLOOKUP($A33,ALGLIB_SSA_XAUUSD!$J$2:$J$1000,ALGLIB_SSA_XAUUSD!$M$2:$M$1000,"",0) -> 4590.12 | L33: =_xlfn.XLOOKUP($A33,ALGLIB_SSA_XAUUSD!$J$2:$J$1000,ALGLIB_SSA_XAUUSD!$N$2:$N$1000,"",0) -> 4603.9754 | M33: =_xlfn.XLOOKUP($A33,ALGLIB_SSA_XAUUSD!$J$2:$J$1000,ALGLIB_SSA_XAUUSD!$O$2:$O$1000,"",0) -> 4598.852 | N33: =_xlfn.XLOOKUP($A33,ALGLIB_SSA_XAUUSD!$J$2:$J$1000,ALGLIB_SSA_XAUUSD!$P$2:$P$1000,"",0) -> 4609.8396 | O33: =_xlfn.XLOOKUP($A33,ALGLIB_SSA_XAUUSD!$J$2:$J$1000,ALGLIB_SSA_XAUUSD!$Q$2:$Q$1000,"",0) -> 4592.5486 | R33: =A33 -> 1775136900 | S33: =I33 -> XAUUSD | T33: =J33 -> M5 | U33: =K33 -> 4590.12 | V33: 4648.8024 | W33: 4638.7584 | X33: 4603.9754 | Y33: 4598.852 | Z33: =G33 -> 4665.7687 | AA33: =N33 -> 4609.8396 | AB33: =H33 -> 4622.7042 | AC33: =O33 -> 4592.5486 | AF33: =X33 -> 4603.9754 | AG33: =Z33 -> 4665.7687 | AH33: =AB33 -> 4622.7042
A34: =ALGLIB_SSA_XAUUSD!J34 -> 1775137200 | B34: =_xlfn.XLOOKUP($A34,ALGLIB_SSA_XAUUSD!$A$2:$A$1000,ALGLIB_SSA_XAUUSD!$B$2:$B$1000,"",0) | C34: =_xlfn.XLOOKUP($A34,ALGLIB_SSA_XAUUSD!$A$2:$A$1000,ALGLIB_SSA_XAUUSD!$C$2:$C$1000,"",0) | D34: =D26+(D38-D26)*8/12 -> 4669.3233 | E34: =E26+(E38-E26)*8/12 -> 4649.7356 | F34: =F26+(F38-F26)*8/12 -> 4639.6237 | G34: =G26+(G38-G26)*8/12 -> 4666.6111 | H34: =H26+(H38-H26)*8/12 -> 4623.6289 | I34: =_xlfn.XLOOKUP($A34,ALGLIB_SSA_XAUUSD!$J$2:$J$1000,ALGLIB_SSA_XAUUSD!$K$2:$K$1000,"",0) -> XAUUSD | J34: =_xlfn.XLOOKUP($A34,ALGLIB_SSA_XAUUSD!$J$2:$J$1000,ALGLIB_SSA_XAUUSD!$L$2:$L$1000,"",0) -> M5 | K34: =_xlfn.XLOOKUP($A34,ALGLIB_SSA_XAUUSD!$J$2:$J$1000,ALGLIB_SSA_XAUUSD!$M$2:$M$1000,"",0) -> 4602.13 | L34: =_xlfn.XLOOKUP($A34,ALGLIB_SSA_XAUUSD!$J$2:$J$1000,ALGLIB_SSA_XAUUSD!$N$2:$N$1000,"",0) -> 4612.5609 | M34: =_xlfn.XLOOKUP($A34,ALGLIB_SSA_XAUUSD!$J$2:$J$1000,ALGLIB_SSA_XAUUSD!$O$2:$O$1000,"",0) -> 4605.7064 | N34: =_xlfn.XLOOKUP($A34,ALGLIB_SSA_XAUUSD!$J$2:$J$1000,ALGLIB_SSA_XAUUSD!$P$2:$P$1000,"",0) -> 4617.7262 | O34: =_xlfn.XLOOKUP($A34,ALGLIB_SSA_XAUUSD!$J$2:$J$1000,ALGLIB_SSA_XAUUSD!$Q$2:$Q$1000,"",0) -> 4599.7665 | R34: =A34 -> 1775137200 | S34: =I34 -> XAUUSD | T34: =J34 -> M5 | U34: =K34 -> 4602.13 | V34: 4649.7356 | W34: 4639.6237 | X34: 4612.5609 | Y34: 4605.7064 | Z34: =G34 -> 4666.6111 | AA34: =N34 -> 4617.7262 | AB34: =H34 -> 4623.6289 | AC34: =O34 -> 4599.7665 | AF34: =X34 -> 4612.5609 | AG34: =Z34 -> 4666.6111 | AH34: =AB34 -> 4623.6289
A35: =ALGLIB_SSA_XAUUSD!J35 -> 1775137500 | B35: =_xlfn.XLOOKUP($A35,ALGLIB_SSA_XAUUSD!$A$2:$A$1000,ALGLIB_SSA_XAUUSD!$B$2:$B$1000,"",0) | C35: =_xlfn.XLOOKUP($A35,ALGLIB_SSA_XAUUSD!$A$2:$A$1000,ALGLIB_SSA_XAUUSD!$C$2:$C$1000,"",0) | D35: =D26+(D38-D26)*9/12 -> 4672.3225 | E35: =E26+(E38-E26)*9/12 -> 4650.6689 | F35: =F26+(F38-F26)*9/12 -> 4640.489 | G35: =G26+(G38-G26)*9/12 -> 4667.4536 | H35: =H26+(H38-H26)*9/12 -> 4624.5535 | I35: =_xlfn.XLOOKUP($A35,ALGLIB_SSA_XAUUSD!$J$2:$J$1000,ALGLIB_SSA_XAUUSD!$K$2:$K$1000,"",0) -> XAUUSD | J35: =_xlfn.XLOOKUP($A35,ALGLIB_SSA_XAUUSD!$J$2:$J$1000,ALGLIB_SSA_XAUUSD!$L$2:$L$1000,"",0) -> M5 | K35: =_xlfn.XLOOKUP($A35,ALGLIB_SSA_XAUUSD!$J$2:$J$1000,ALGLIB_SSA_XAUUSD!$M$2:$M$1000,"",0) -> 4634.43 | L35: =_xlfn.XLOOKUP($A35,ALGLIB_SSA_XAUUSD!$J$2:$J$1000,ALGLIB_SSA_XAUUSD!$N$2:$N$1000,"",0) -> 4621.749 | M35: =_xlfn.XLOOKUP($A35,ALGLIB_SSA_XAUUSD!$J$2:$J$1000,ALGLIB_SSA_XAUUSD!$O$2:$O$1000,"",0) -> 4613.7277 | N35: =_xlfn.XLOOKUP($A35,ALGLIB_SSA_XAUUSD!$J$2:$J$1000,ALGLIB_SSA_XAUUSD!$P$2:$P$1000,"",0) -> 4626.7141 | O35: =_xlfn.XLOOKUP($A35,ALGLIB_SSA_XAUUSD!$J$2:$J$1000,ALGLIB_SSA_XAUUSD!$Q$2:$Q$1000,"",0) -> 4608.1671 | R35: =A35 -> 1775137500 | S35: =I35 -> XAUUSD | T35: =J35 -> M5 | U35: =K35 -> 4634.43 | V35: 4650.6689 | W35: 4640.489 | X35: 4621.749 | Y35: 4613.7277 | Z35: =G35 -> 4667.4536 | AA35: =N35 -> 4626.7141 | AB35: =H35 -> 4624.5535 | AC35: =O35 -> 4608.1671 | AF35: =X35 -> 4621.749 | AG35: =Z35 -> 4667.4536 | AH35: =AB35 -> 4624.5535
A36: =ALGLIB_SSA_XAUUSD!J36 -> 1775137800 | B36: =_xlfn.XLOOKUP($A36,ALGLIB_SSA_XAUUSD!$A$2:$A$1000,ALGLIB_SSA_XAUUSD!$B$2:$B$1000,"",0) | C36: =_xlfn.XLOOKUP($A36,ALGLIB_SSA_XAUUSD!$A$2:$A$1000,ALGLIB_SSA_XAUUSD!$C$2:$C$1000,"",0) | D36: =D26+(D38-D26)*10/12 -> 4675.3217 | E36: =E26+(E38-E26)*10/12 -> 4651.6021 | F36: =F26+(F38-F26)*10/12 -> 4641.3543 | G36: =G26+(G38-G26)*10/12 -> 4668.2961 | H36: =H26+(H38-H26)*10/12 -> 4625.4782 | I36: =_xlfn.XLOOKUP($A36,ALGLIB_SSA_XAUUSD!$J$2:$J$1000,ALGLIB_SSA_XAUUSD!$K$2:$K$1000,"",0) -> XAUUSD | J36: =_xlfn.XLOOKUP($A36,ALGLIB_SSA_XAUUSD!$J$2:$J$1000,ALGLIB_SSA_XAUUSD!$L$2:$L$1000,"",0) -> M5 | K36: =_xlfn.XLOOKUP($A36,ALGLIB_SSA_XAUUSD!$J$2:$J$1000,ALGLIB_SSA_XAUUSD!$M$2:$M$1000,"",0) -> 4635.58 | L36: =_xlfn.XLOOKUP($A36,ALGLIB_SSA_XAUUSD!$J$2:$J$1000,ALGLIB_SSA_XAUUSD!$N$2:$N$1000,"",0) -> 4630.2641 | M36: =_xlfn.XLOOKUP($A36,ALGLIB_SSA_XAUUSD!$J$2:$J$1000,ALGLIB_SSA_XAUUSD!$O$2:$O$1000,"",0) -> 4621.9959 | N36: =_xlfn.XLOOKUP($A36,ALGLIB_SSA_XAUUSD!$J$2:$J$1000,ALGLIB_SSA_XAUUSD!$P$2:$P$1000,"",0) -> 4635.4238 | O36: =_xlfn.XLOOKUP($A36,ALGLIB_SSA_XAUUSD!$J$2:$J$1000,ALGLIB_SSA_XAUUSD!$Q$2:$Q$1000,"",0) -> 4616.9749 | R36: =A36 -> 1775137800 | S36: =I36 -> XAUUSD | T36: =J36 -> M5 | U36: =K36 -> 4635.58 | V36: 4651.6021 | W36: 4641.3543 | X36: 4630.2641 | Y36: 4621.9959 | Z36: =G36 -> 4668.2961 | AA36: =N36 -> 4635.4238 | AB36: =H36 -> 4625.4782 | AC36: =O36 -> 4616.9749 | AF36: =X36 -> 4630.2641 | AG36: =Z36 -> 4668.2961 | AH36: =AB36 -> 4625.4782
A37: =ALGLIB_SSA_XAUUSD!J37 -> 1775138100 | B37: =_xlfn.XLOOKUP($A37,ALGLIB_SSA_XAUUSD!$A$2:$A$1000,ALGLIB_SSA_XAUUSD!$B$2:$B$1000,"",0) | C37: =_xlfn.XLOOKUP($A37,ALGLIB_SSA_XAUUSD!$A$2:$A$1000,ALGLIB_SSA_XAUUSD!$C$2:$C$1000,"",0) | D37: =D26+(D38-D26)*11/12 -> 4678.3208 | E37: =E26+(E38-E26)*11/12 -> 4652.5353 | F37: =F26+(F38-F26)*11/12 -> 4642.2196 | G37: =G26+(G38-G26)*11/12 -> 4669.1385 | H37: =H26+(H38-H26)*11/12 -> 4626.4028 | I37: =_xlfn.XLOOKUP($A37,ALGLIB_SSA_XAUUSD!$J$2:$J$1000,ALGLIB_SSA_XAUUSD!$K$2:$K$1000,"",0) -> XAUUSD | J37: =_xlfn.XLOOKUP($A37,ALGLIB_SSA_XAUUSD!$J$2:$J$1000,ALGLIB_SSA_XAUUSD!$L$2:$L$1000,"",0) -> M5 | K37: =_xlfn.XLOOKUP($A37,ALGLIB_SSA_XAUUSD!$J$2:$J$1000,ALGLIB_SSA_XAUUSD!$M$2:$M$1000,"",0) -> 4645.33 | L37: =_xlfn.XLOOKUP($A37,ALGLIB_SSA_XAUUSD!$J$2:$J$1000,ALGLIB_SSA_XAUUSD!$N$2:$N$1000,"",0) -> 4637.8591 | M37: =_xlfn.XLOOKUP($A37,ALGLIB_SSA_XAUUSD!$J$2:$J$1000,ALGLIB_SSA_XAUUSD!$O$2:$O$1000,"",0) -> 4629.9275 | N37: =_xlfn.XLOOKUP($A37,ALGLIB_SSA_XAUUSD!$J$2:$J$1000,ALGLIB_SSA_XAUUSD!$P$2:$P$1000,"",0) -> 4643.3449 | O37: =_xlfn.XLOOKUP($A37,ALGLIB_SSA_XAUUSD!$J$2:$J$1000,ALGLIB_SSA_XAUUSD!$Q$2:$Q$1000,"",0) -> 4625.1525 | R37: =A37 -> 1775138100 | S37: =I37 -> XAUUSD | T37: =J37 -> M5 | U37: =K37 -> 4645.33 | V37: 4652.5354 | W37: 4642.2196 | X37: 4637.8591 | Y37: 4629.9275 | Z37: =G37 -> 4669.1385 | AA37: =N37 -> 4643.3449 | AB37: =H37 -> 4626.4028 | AC37: =O37 -> 4625.1525 | AF37: =X37 -> 4637.8591 | AG37: =Z37 -> 4669.1385 | AH37: =AB37 -> 4626.4028
